Workbook
Name __j102: #REF!
Name _j102: #REF!
Name PRINT_AREA_MI: #REF!
Name Tgl: #REF!
Name tgll: #REF!
Name tr: #REF!
Name ﾃﾞｰﾀ海市: #REF!
Name ルピア: #REF!
Name 予算ﾚｰﾄ: #REF!
Name 今: #REF!
Name 印刷領域: #REF!
Name 品種別実績: #REF!
Name 実績レート: #REF!
Name 対象日数: #REF!
Name 技術開発経費181: #REF!
Name 日数: #REF!
Name 期: #REF!
Name 決算期区分: #REF!
Name 為替: #REF!
Name 為替レートEU: #REF!
Name 補助部門比率: #REF!
Name 補助部門費_設計以外181: #REF!
Name 補助部門費_設計以外182: #REF!
Name __j102: #REF!
Name _j102: #REF!
Name aa: #REF!
Name AB: #REF!
Name kissa: #REF!
Name kissakei: #REF!
Name kk: #REF!
Name Print_Area_MI: #REF!
Name PRINT_TITLES_MI: #REF!
Name ry: #REF!
Name Tgl: #REF!
Name tgll: #REF!
Name tr: #REF!
Name ﾃﾞｰﾀ海市: #REF!
Name ルピア: #REF!
Name 予算ﾚｰﾄ: #REF!
Name 今: #REF!
Name 出発: [6]支援計画・０４!$G$4:$G$171
Name 到着: [6]支援計画・０４!$F$4:$F$171
Name 印刷領域: #REF!
Name 品種別実績: #REF!
Name 商品群: [8]テーブル!$B$2:$B$7
Name 実績レート: #REF!
Name 対象日数: #REF!
Name 技術開発経費181: #REF!
Name 担当者: [8]テーブル!$F$2:$F$24
Name 日付: [6]支援計画・０４!$J$4:$CW$4
Name 日数: #REF!
Name 期: #REF!
Name 機能分類リスト: [12]開発計画品番リスト!#REF!
Name 比率: [13]調達計画!#REF!
Name 決算期区分: #REF!
Name 為替: #REF!
Name 為替レートEU: #REF!
Name 生産拠点: [8]テーブル!$C$2:$C$6
Name 立上年: [8]テーブル!$A$2:$A$11
Name 立上月: [8]テーブル!$D$2:$D$13

Sheet Data
A1: BUDGET TYPE | B1: Section Code (From) | C1: Section Name (From/Who Prepare) | D1: Section Code (To) | E1: Section Name (To/Who Use The Cost) | F1: COA-ID | G1: COA NAME | H1: DESCRIPTION | I1: GROUP SECTION | J1: GROUP COST | K1: 2023_10 | L1: 2023_11 | M1: 2023_12 | N1: 2024_01 | O1: 2024_02 | P1: 2024_03 | Q1: 2024_04 | R1: 2024_05 | S1: 2024_06 | T1: 2024_07 | U1: 2024_08 | V1: 2024_09 | W1: 2024_10 | X1: 2024_11 | Y1: 2024_12 | Z1: 2025_01 | AA1: 2025_02 | AB1: 2025_03 | AC1: TOTAL FY124 | AD1: TOTAL FY125 | AE1: TOTAL FY126 | AF1: TOTAL FY127 | AG1: Priority Category | AH1: BUDGET NO.
A2: BEX | B2: B2400 | C2: Information Technology | D2: B2400 | E2: Information Technology | F2: 7515401 | G2: Staff Welfare - Outpatient (Medical) | H2: Outpatient / Medical Expense | I2: ADM | J2: SGA | N2: 750000 | P2: 750000 | R2: 1500000 | T2: 750000 | V2: 750000 | X2: 750000 | Z2: 1500000 | AB2: 750000 | AC2: 1500000 | AD2: 6000000 | AE2: 6000000 | AF2: 6000000 | AG2: A | AH2: BEX25-2400-2400-001
A3: BEX | B3: B2400 | C3: Information Technology | D3: B2400 | E3: Information Technology | F3: 7515402 | G3: Staff Welfare - Hospitalization | H3: Hospitalization Expense | I3: ADM | J3: SGA | Q3: 25000000 | U3: 15000000 | Z3: 15000000 | AD3: 55000000 | AE3: 20000000 | AF3: 20000000 | AG3: A | AH3: BEX25-2400-2400-002
A4: BEX | B4: B2400 | C4: Information Technology | D4: B2400 | E4: Information Technology | F4: 7515404 | G4: Staff Welfare - Dental | H4: Dental Expense | I4: ADM | J4: SGA | N4: 4200000 | Q4: 500000 | S4: 500000 | V4: 1000000 | Y4: 500000 | AB4: 1000000 | AC4: 4200000 | AD4: 3500000 | AE4: 3500000 | AF4: 3500000 | AG4: A | AH4: BEX25-2400-2400-003
A5: BEX | B5: B2400 | C5: Information Technology | D5: B2300 | E5: Accounting & Finance | F5: 7671103 | G5: License fee | H5: Google Apps License | I5: ADM | J5: SGA | M5: 2373532 | N5: 2373532 | O5: 2373532 | P5: 2373532 | Q5: 2373532 | R5: 2373532 | S5: 2373532 | T5: 2373532 | U5: 2373532 | V5: 2373532 | W5: 2373532 | X5: 2373532 | Y5: 2373532 | Z5: 2373532 | AA5: 2373532 | AB5: 2373532 | AE5: 28482382 | AF5: 28482382 | AG5: A | AH5: BEX25-2400-2300-004
A6: BEX | B6: B2400 | C6: Information Technology | D6: B2210 | E6: General Affair | F6: 7671103 | G6: License fee | H6: Google Apps License | I6: ADM | J6: SGA | M6: 1510429 | N6: 1510429 | O6: 1510429 | P6: 1510429 | Q6: 1510429 | R6: 1510429 | S6: 1510429 | T6: 1510429 | U6: 1510429 | V6: 1510429 | W6: 1510429 | X6: 1510429 | Y6: 1510429 | Z6: 1510429 | AA6: 1510429 | AB6: 1510429 | AE6: 18125152 | AF6: 18125152 | AG6: A | AH6: BEX25-2400-2210-004
A7: BEX | B7: B2400 | C7: Information Technology | D7: B2220 | E7: Human Resource | F7: 7671103 | G7: License fee | H7: Google Apps License | I7: ADM | J7: SGA | M7: 2373532 | N7: 2373532 | O7: 2373532 | P7: 2373532 | Q7: 2373532 | R7: 2373532 | S7: 2373532 | T7: 2373532 | U7: 2373532 | V7: 2373532 | W7: 2373532 | X7: 2373532 | Y7: 2373532 | Z7: 2373532 | AA7: 2373532 | AB7: 2373532 | AE7: 28482382 | AF7: 28482382 | AG7: A | AH7: BEX25-2400-2220-004
A8: BEX | B8: B2400 | C8: Information Technology | D8: B1000 | E8: Top Management | F8: 7671103 | G8: License fee | H8: Google Apps License | I8: ADM | J8: SGA | M8: 431551 | N8: 431551 | O8: 431551 | P8: 431551 | Q8: 431551 | R8: 431551 | S8: 431551 | T8: 431551 | U8: 431551 | V8: 431551 | W8: 431551 | X8: 431551 | Y8: 431551 | Z8: 431551 | AA8: 431551 | AB8: 431551 | AE8: 5178615 | AF8: 5178615 | AG8: A | AH8: BEX25-2400-1000-004
A9: BEX | B9: B2400 | C9: Information Technology | D9: B5104 | E9: Production Office (PC) | F9: 7671103 | G9: License fee | H9: Google Apps License | I9: IND | J9: MFG | M9: 431551 | N9: 431551 | O9: 431551 | P9: 431551 | Q9: 431551 | R9: 431551 | S9: 431551 | T9: 431551 | U9: 431551 | V9: 431551 | W9: 431551 | X9: 431551 | Y9: 431551 | Z9: 431551 | AA9: 431551 | AB9: 431551 | AE9: 5178615 | AF9: 5178615 | AG9: A | AH9: BEX25-2400-5104-004
A10: BEX | B10: B2400 | C10: Information Technology | D10: B4110 | E10: SP PD- Assy | F10: 7671103 | G10: License fee | H10: Google Apps License | I10: DIR | J10: MFG | M10: 647327 | N10: 647327 | O10: 647327 | P10: 647327 | Q10: 647327 | R10: 647327 | S10: 647327 | T10: 647327 | U10: 647327 | V10: 647327 | W10: 647327 | X10: 647327 | Y10: 647327 | Z10: 647327 | AA10: 647327 | AB10: 647327 | AE10: 7767922 | AF10: 7767922 | AG10: A | AH10: BEX25-2400-4110-004
A11: BEX | B11: B2400 | C11: Information Technology | D11: B5600 | E11: Production Engineering | F11: 7671103 | G11: License fee | H11: Google Apps License | I11: IND | J11: MFG | M11: 2373532 | N11: 2373532 | O11: 2373532 | P11: 2373532 | Q11: 2373532 | R11: 2373532 | S11: 2373532 | T11: 2373532 | U11: 2373532 | V11: 2373532 | W11: 2373532 | X11: 2373532 | Y11: 2373532 | Z11: 2373532 | AA11: 2373532 | AB11: 2373532 | AE11: 28482382 | AF11: 28482382 | AG11: A | AH11: BEX25-2400-5600-004
A12: BEX | B12: B2400 | C12: Information Technology | D12: B4130 | E12: SP PD- Insulator Sealing | F12: 7671103 | G12: License fee | H12: Google Apps License | I12: DIR | J12: MFG | M12: 215776 | N12: 215776 | O12: 215776 | P12: 215776 | Q12: 215776 | R12: 215776 | S12: 215776 | T12: 215776 | U12: 215776 | V12: 215776 | W12: 215776 | X12: 215776 | Y12: 215776 | Z12: 215776 | AA12: 215776 | AB12: 215776 | AE12: 2589307 | AF12: 2589307 | AG12: A | AH12: BEX25-2400-4130-004
A13: BEX | B13: B2400 | C13: Information Technology | D13: B5000 | E13: Plant Operation (Indirect Mfg) | F13: 7671103 | G13: License fee | H13: Google Apps License | I13: IND | J13: MFG | M13: 431551 | N13: 431551 | O13: 431551 | P13: 431551 | Q13: 431551 | R13: 431551 | S13: 431551 | T13: 431551 | U13: 431551 | V13: 431551 | W13: 431551 | X13: 431551 | Y13: 431551 | Z13: 431551 | AA13: 431551 | AB13: 431551 | AE13: 5178615 | AF13: 5178615 | AG13: A | AH13: BEX25-2400-5000-004
A14: BEX | B14: B2400 | C14: Information Technology | D14: B5900 | E14: Quality Control | F14: 7671103 | G14: License fee | H14: Google Apps License | I14: IND | J14: MFG | M14: 1078878 | N14: 1078878 | O14: 1078878 | P14: 1078878 | Q14: 1078878 | R14: 1078878 | S14: 1078878 | T14: 1078878 | U14: 1078878 | V14: 1078878 | W14: 1078878 | X14: 1078878 | Y14: 1078878 | Z14: 1078878 | AA14: 1078878 | AB14: 1078878 | AE14: 12946537 | AF14: 12946537 | AG14: A | AH14: BEX25-2400-5900-004
A15: BEX | B15: B2400 | C15: Information Technology | D15: B5101 | E15: Production Office (SP) | F15: 7671103 | G15: License fee | H15: Google Apps License | I15: IND | J15: MFG | M15: 431551 | N15: 431551 | O15: 431551 | P15: 431551 | Q15: 431551 | R15: 431551 | S15: 431551 | T15: 431551 | U15: 431551 | V15: 431551 | W15: 431551 | X15: 431551 | Y15: 431551 | Z15: 431551 | AA15: 431551 | AB15: 431551 | AE15: 5178615 | AF15: 5178615 | AG15: A | AH15: BEX25-2400-5101-004
A16: BEX | B16: B2400 | C16: Information Technology | D16: B4105 | E16: SP PD- Plating | F16: 7671103 | G16: License fee | H16: Google Apps License | I16: DIR | J16: MFG | M16: 431551 | N16: 431551 | O16: 431551 | P16: 431551 | Q16: 431551 | R16: 431551 | S16: 431551 | T16: 431551 | U16: 431551 | V16: 431551 | W16: 431551 | X16: 431551 | Y16: 431551 | Z16: 431551 | AA16: 431551 | AB16: 431551 | AE16: 5178615 | AF16: 5178615 | AG16: A | AH16: BEX25-2400-4105-004
... A31: BEX | B31: B2400 | C31: Information Technology | D31: B4120 | E31: SP PD- Final Inspection | F31: 7671103 | G31: License fee | H31: Google Apps License | I31: DIR | J31: MFG | M31: 431551 | N31: 431551 | O31: 431551 | P31: 431551 | Q31: 647327 | R31: 647327 | S31: 647327 | T31: 647327 | U31: 647327 | V31: 647327 | W31: 647327 | X31: 647327 | Y31: 647327 | Z31: 647327 | AA31: 647327 | AB31: 647327 | AE31: 7767922 | AF31: 7767922 | AG31: A | AH31: BEX25-2400-4120-004
A32: BEX | B32: B2400 | C32: Information Technology | D32: B2400 | E32: Information Technology | F32: 7671103 | G32: License fee | H32: New License - 5 Microsoft License Windows 11 | I32: ADM | J32: SGA | Q32: 16000000 | AE32: 16000000 | AF32: 16000000 | AG32: C | AH32: BEX25-2400-2400-005
A33: BEX | B33: B2400 | C33: Information Technology | D33: B2400 | E33: Information Technology | F33: 7671103 | G33: License fee | H33: New License - Google Developer License Fee | I33: ADM | J33: SGA | Q33: 375000 | AE33: 375000 | AF33: 375000 | AG33: A | AH33: BEX25-2400-2400-006
A34: BEX | B34: B2400 | C34: Information Technology | D34: B2400 | E34: Information Technology | F34: 7671103 | G34: License fee | H34: New License - IOS Developer Membership Fee | I34: ADM | J34: SGA | Q34: 123750 | R34: 123750 | S34: 123750 | T34: 123750 | U34: 123750 | V34: 123750 | W34: 123750 | X34: 123750 | Y34: 123750 | Z34: 123750 | AA34: 123750 | AB34: 123750 | AE34: 1485000 | AF34: 1485000 | AG34: A | AH34: BEX25-2400-2400-007
A35: BEX | B35: B2400 | C35: Information Technology | D35: B2400 | E35: Information Technology | F35: 7671103 | G35: License fee | H35: New License - Nitro PDF Pro | I35: ADM | J35: SGA | Q35: 350000 | R35: 350000 | S35: 350000 | T35: 350000 | U35: 350000 | V35: 350000 | W35: 350000 | X35: 350000 | Y35: 350000 | Z35: 350000 | AA35: 350000 | AB35: 350000 | AE35: 4200000 | AF35: 4200000 | AG35: B | AH35: BEX25-2400-2400-008
A36: BEX | B36: B2400 | C36: Information Technology | D36: B1000 | E36: Top Management | F36: 7671103 | G36: License fee | H36: Nrimo Usage License | I36: ADM | J36: SGA | M36: 252109 | N36: 252109 | O36: 252109 | P36: 252109 | Q36: 252109 | R36: 252109 | S36: 252109 | T36: 252109 | U36: 252109 | V36: 252109 | W36: 252109 | X36: 252109 | Y36: 252109 | Z36: 252109 | AA36: 252109 | AB36: 252109 | AE36: 3025303 | AF36: 3025303 | AG36: A | AH36: BEX25-2400-1000-009
A37: BEX | B37: B2400 | C37: Information Technology | D37: B5600 | E37: Production Engineering | F37: 7671103 | G37: License fee | H37: Nrimo Usage License | I37: IND | J37: MFG | M37: 252109 | N37: 252109 | O37: 252109 | P37: 252109 | Q37: 252109 | R37: 252109 | S37: 252109 | T37: 252109 | U37: 252109 | V37: 252109 | W37: 252109 | X37: 252109 | Y37: 252109 | Z37: 252109 | AA37: 252109 | AB37: 252109 | AE37: 3025303 | AF37: 3025303 | AG37: A | AH37: BEX25-2400-5600-009
A38: BEX | B38: B2400 | C38: Information Technology | D38: B2300 | E38: Accounting & Finance | F38: 7671103 | G38: License fee | H38: Nrimo Usage License | I38: ADM | J38: SGA | M38: 1260543 | N38: 1260543 | O38: 1260543 | P38: 1260543 | Q38: 1260543 | R38: 1260543 | S38: 1260543 | T38: 1260543 | U38: 1260543 | V38: 1260543 | W38: 1260543 | X38: 1260543 | Y38: 1260543 | Z38: 1260543 | AA38: 1260543 | AB38: 1260543 | AE38: 15126515 | AF38: 15126515 | AG38: A | AH38: BEX25-2400-2300-009
A39: BEX | B39: B2400 | C39: Information Technology | D39: B5130 | E39: Supply Procurement | F39: 7671103 | G39: License fee | H39: Nrimo Usage License | I39: IND | J39: MFG | M39: 756326 | N39: 756326 | O39: 756326 | P39: 756326 | Q39: 756326 | R39: 756326 | S39: 756326 | T39: 756326 | U39: 756326 | V39: 756326 | W39: 756326 | X39: 756326 | Y39: 756326 | Z39: 756326 | AA39: 756326 | AB39: 756326 | AE39: 9075909 | AF39: 9075909 | AG39: A | AH39: BEX25-2400-5130-009
A40: BEX | B40: B2400 | C40: Information Technology | D40: B3130 | E40: Sales - IAM | F40: 7671103 | G40: License fee | H40: Nrimo Usage License | I40: ADM | J40: SGA | M40: 504217 | N40: 504217 | O40: 504217 | P40: 504217 | Q40: 504217 | R40: 504217 | S40: 504217 | T40: 504217 | U40: 504217 | V40: 504217 | W40: 504217 | X40: 504217 | Y40: 504217 | Z40: 504217 | AA40: 504217 | AB40: 504217 | AE40: 6050606 | AF40: 6050606 | AG40: A | AH40: BEX25-2400-3130-009
A41: BEX | B41: B2400 | C41: Information Technology | D41: B3150 | E41: SCM - FG WH | F41: 7671103 | G41: License fee | H41: Nrimo Usage License | I41: ADM | J41: SGA | M41: 756326 | N41: 756326 | O41: 756326 | P41: 756326 | Q41: 756326 | R41: 756326 | S41: 756326 | T41: 756326 | U41: 756326 | V41: 756326 | W41: 756326 | X41: 756326 | Y41: 756326 | Z41: 756326 | AA41: 756326 | AB41: 756326 | AE41: 9075909 | AF41: 9075909 | AG41: A | AH41: BEX25-2400-3150-009
A42: BEX | B42: B2400 | C42: Information Technology | D42: B5000 | E42: Plant Operation (Indirect Mfg) | F42: 7671103 | G42: License fee | H42: Nrimo Usage License | I42: IND | J42: MFG | M42: 252109 | N42: 252109 | O42: 252109 | P42: 252109 | Q42: 252109 | R42: 252109 | S42: 252109 | T42: 252109 | U42: 252109 | V42: 252109 | W42: 252109 | X42: 252109 | Y42: 252109 | Z42: 252109 | AA42: 252109 | AB42: 252109 | AE42: 3025303 | AF42: 3025303 | AG42: A | AH42: BEX25-2400-5000-009
A43: BEX | B43: B2400 | C43: Information Technology | D43: B3110 | E43: Sales - OEM | F43: 7671103 | G43: License fee | H43: Nrimo Usage License | I43: ADM | J43: SGA | M43: 504217 | N43: 504217 | O43: 504217 | P43: 504217 | Q43: 504217 | R43: 504217 | S43: 504217 | T43: 504217 | U43: 504217 | V43: 504217 | W43: 504217 | X43: 504217 | Y43: 504217 | Z43: 504217 | AA43: 504217 | AB43: 504217 | AE43: 6050606 | AF43: 6050606 | AG43: A | AH43: BEX25-2400-3110-009
A44: BEX | B44: B2400 | C44: Information Technology | D44: B3160 | E44: Marketing | F44: 7671103 | G44: License fee | H44: Nrimo Usage License | I44: ADM | J44: SGA | M44: 252109 | N44: 252109 | O44: 252109 | P44: 252109 | Q44: 252109 | R44: 252109 | S44: 252109 | T44: 252109 | U44: 252109 | V44: 252109 | W44: 252109 | X44: 252109 | Y44: 252109 | Z44: 252109 | AA44: 252109 | AB44: 252109 | AE44: 3025303 | AF44: 3025303 | AG44: A | AH44: BEX25-2400-3160-009
A45: BEX | B45: B2400 | C45: Information Technology | D45: B2400 | E45: Information Technology | F45: 7671103 | G45: License fee | H45: QWORDS - Hosting Website & Domain | I45: ADM | J45: SGA | M45: 319329 | N45: 319329 | O45: 319329 | P45: 319329 | Q45: 319329 | R45: 319329 | S45: 319329 | T45: 319329 | U45: 319329 | V45: 319329 | W45: 319329 | X45: 319329 | Y45: 319329 | Z45: 319329 | AA45: 319329 | AB45: 319329 | AE45: 3831945 | AF45: 3831945 | AG45: A | AH45: BEX25-2400-2400-010
A46: BEX | B46: B2400 | C46: Information Technology | D46: B2400 | E46: Information Technology | F46: 7671103 | G46: License fee | H46: Yearly Renewal - Anydesk License | I46: ADM | J46: SGA | M46: 500194 | N46: 500194 | O46: 500194 | P46: 500194 | Q46: 500194 | R46: 500194 | S46: 500194 | T46: 500194 | U46: 500194 | V46: 500194 | W46: 500194 | X46: 500194 | Y46: 500194 | Z46: 500194 | AA46: 500194 | AB46: 500194 | AE46: 6002325 | AF46: 6002325 | AG46: A | AH46: BEX25-2400-2400-011
A47: BEX | B47: B2400 | C47: Information Technology | D47: B2400 | E47: Information Technology | F47: 7671103 | G47: License fee | H47: Yearly Renewal - Fortigate Firewall Security | I47: ADM | J47: SGA | M47: 8236250 | N47: 8236250 | O47: 8236250 | P47: 8236250 | Q47: 8236250 | R47: 8236250 | S47: 25983500 | T47: 25983500 | U47: 25983500 | V47: 25983500 | W47: 17500000 | X47: 17500000 | Y47: 17500000 | Z47: 17500000 | AA47: 17500000 | AB47: 17500000 | AE47: 210000000 | AF47: 210000000 | AG47: A | AH47: BEX25-2400-2400-012
... A49: BEX | B49: B2400 | C49: Information Technology | D49: B2400 | E49: Information Technology | F49: 7671103 | G49: License fee | H49: Yearly Renewal - JP1 Server Service | I49: ADM | J49: SGA | M49: 3646667 | N49: 3646667 | O49: 3646667 | P49: 3646667 | Q49: 3646667 | R49: 3646667 | S49: 3646667 | T49: 3646667 | U49: 3646667 | V49: 3646667 | W49: 3646667 | X49: 3756167 | Y49: 3756167 | Z49: 3756167 | AA49: 3756167 | AB49: 3756167 | AE49: 46000000 | AF49: 46000000 | AG49: B | AH49: BEX25-2400-2400-014
A50: BEX | B50: B2400 | C50: Information Technology | D50: B2400 | E50: Information Technology | F50: 7671103 | G50: License fee | H50: Yearly Renewal - Microsoft Office 70 Licenses | I50: ADM | J50: SGA | Q50: 7625625 | R50: 7625625 | S50: 7625625 | T50: 7625625 | U50: 7625625 | V50: 7625625 | W50: 7625625 | X50: 7625625 | Y50: 7625625 | Z50: 7625625 | AA50: 7625625 | AB50: 7625625 | AE50: 91507500 | AF50: 91507500 | AG50: B | AH50: BEX25-2400-2400-015
A51: BEX | B51: B2400 | C51: Information Technology | D51: B5800 | E51: Quality Assurance | F51: 7671103 | G51: License fee | H51: Yearly Renewal - Office E1 | I51: IND | J51: MFG | M51: 339500 | N51: 339500 | O51: 339500 | P51: 339500 | Q51: 339500 | R51: 339500 | S51: 339500 | T51: 339500 | U51: 339500 | V51: 339500 | W51: 339500 | X51: 339500 | Y51: 339500 | Z51: 339500 | AA51: 339500 | AB51: 339500 | AE51: 4074000 | AF51: 4074000 | AG51: A | AH51: BEX25-2400-5800-016
A52: BEX | B52: B2400 | C52: Information Technology | D52: B2400 | E52: Information Technology | F52: 7671103 | G52: License fee | H52: Yearly Renewal - Oracle Database | I52: ADM | J52: SGA | M52: 16650000 | N52: 16650000 | O52: 16650000 | P52: 16650000 | Q52: 17482500 | R52: 17482500 | S52: 17482500 | T52: 17482500 | U52: 17482500 | V52: 17482500 | W52: 17482500 | X52: 17482500 | Y52: 17482500 | Z52: 17482500 | AA52: 17482500 | AB52: 17482500 | AE52: 209790000 | AF52: 209790000 | AG52: A | AH52: BEX25-2400-2400-017
A53: BEX | B53: B2400 | C53: Information Technology | D53: B2400 | E53: Information Technology | F53: 7671103 | G53: License fee | H53: Yearly Renewal - VEEAM License | I53: ADM | J53: SGA | M53: 2154167 | N53: 2154167 | O53: 2154167 | P53: 2154167 | Q53: 2154167 | R53: 2154167 | S53: 2154167 | T53: 2154167 | U53: 2154167 | V53: 2154167 | W53: 2154167 | X53: 2154167 | Y53: 2229167 | Z53: 2229167 | AA53: 2229167 | AB53: 2229167 | AE53: 26750000 | AF53: 26750000 | AG53: B | AH53: BEX25-2400-2400-018
A54: BEX | B54: B2400 | C54: Information Technology | D54: B2400 | E54: Information Technology | F54: 7671103 | G54: License fee | H54: Yearly Renewal - VM Ware Server | I54: ADM | J54: SGA | M54: 2995000 | N54: 2995000 | O54: 2995000 | P54: 2995000 | Q54: 2995000 | R54: 2995000 | S54: 2995000 | T54: 2995000 | U54: 2995000 | V54: 2995000 | W54: 2995000 | X54: 3145000 | Y54: 3145000 | Z54: 3145000 | AA54: 3145000 | AB54: 3145000 | AE54: 37740000 | AF54: 37740000 | AG54: A | AH54: BEX25-2400-2400-019
A55: BEX | B55: B2400 | C55: Information Technology | D55: B2400 | E55: Information Technology | F55: 7691000 | G55: Office supply & Stationary Expense | H55: IT Stationary | I55: ADM | J55: SGA | M55: 200000 | N55: 200000 | O55: 200000 | P55: 200000 | Q55: 200000 | R55: 200000 | S55: 200000 | T55: 200000 | U55: 200000 | V55: 200000 | W55: 200000 | X55: 200000 | Y55: 200000 | Z55: 200000 | AA55: 200000 | AB55: 200000 | AE55: 2400000 | AF55: 2400000 | AG55: A | AH55: BEX25-2400-2400-020
...

Sheet Master
A1: COA AX | B1: Name COA AX | C1: COA AX | D1: COA AX | E1: Group Cost | F1: UNIQ | G1: COA Budget | H1: Description | J1: Name | K1: BNGK | L1: GROUP COST | M1: GROUP SECTION | N1: Name | P1: Code | Q1: Name | S1: Priority Code | T1: Priority Name | U1: Description
A2: 7511101 | B2: Salary for Commissioner | C2: 7511101 | D2: 7511101 | E2: SGA | F2: SGA-7511101 | G2: A502 | H2: Salary for Commissioner | J2: Top Management | K2: B1000 | L2: SGA | M2: ADM | N2: Top Management | P2: 53450 | Q2: NGK BUSI INDONESIA | S2: A | T2: Must | U2: If this is not done, the company or our team cannot continue its business.
A3: 7511102 | B3: Salary for Director | C3: 7511102 | D3: 7511102 | E3: SGA | F3: SGA-7511102 | G3: A502 | H3: Salary for Director & Expat | J3: Commissioner | K3: B1001 | L3: SGA | M3: ADM | N3: Commissioner | S3: B | T3: Want to | U3: We want to do it as a team this term. we need it.
A4: 7511103 | B4: Staff Labor - Basic Salary | C4: 7511103 | D4: 7511103 | E4: SGA | F4: SGA-7511103 | G4: A501 | H4: Basic Salary of permanent employee | J4: Admin & HR | K4: B2200 | L4: SGA | M4: ADM | N4: Admin & HR | S4: C | T4: Challenge | U4: We want to do it for this term or the future. But it doesn't matter if it's not this term.
A5: 7511111 | B5: Staff Labor - Allowance | C5: 7511111 | D5: 7511111 | E5: SGA | F5: SGA-7511111 | G5: A501 | H5: Employee allowance | J5: General Affair | K5: B2210 | L5: SGA | M5: ADM | N5: General Affair
A6: 7511112 | B6: Staff Labor - Tax allowance (art.21) | C6: 7511112 | D6: 7511112 | E6: SGA | F6: SGA-7511112 | G6: A501 | H6: Empployee Tax allowance | J6: Human Resource | K6: B2220 | L6: SGA | M6: ADM | N6: Human Resource | P6: BEX
A7: 7511121 | B7: Staff Labor - BPJS JK & JKK (1.19%) | C7: 7511121 | D7: 7511121 | E7: SGA | F7: SGA-7511121 | G7: A501 | H7: BPJS JK & JKK (death warrant, Accident Insurance) | J7: Health, Safety & Environment | K7: B2230 | L7: SGA | M7: ADM | N7: Health, Safety & Environment | P7: BEL
A8: 7511122 | B8: Staff Labor - BPJS Kesehatan (4%) | C8: 7511122 | D8: 7511122 | E8: SGA | F8: SGA-7511122 | G8: A501 | H8: BPJS health insurance | J8: Accounting & Finance | K8: B2300 | L8: SGA | M8: ADM | N8: Accounting & Finance
A9: 7511201 | B9: Staff Overtime | C9: 7511201 | D9: 7511201 | E9: SGA | F9: SGA-7511201 | G9: A503 | H9: Overtime permanent employee | J9: Information Technology | K9: B2400 | L9: SGA | M9: ADM | N9: Information Technology
A10: 7512111 | B10: Staff Welfare - BPJS Dana pensiun (2%) | C10: 7512111 | D10: 7512111 | E10: SGA | F10: SGA-7512111 | G10: A504 | H10: BPJS pension fund | J10: Sales & MKTG Dept.- Automotive | K10: B3100 | L10: SGA | M10: ADM | N10: Sales & MKTG Dept.- Automotive
A11: 7512112 | B11: Staff Welfare - BPJS JHT (3.7%) | C11: 7512112 | D11: 7512112 | E11: SGA | F11: SGA-7512112 | G11: A504 | H11: BPJS Pension plan | J11: Marketing | K11: B3160 | L11: SGA | M11: ADM | N11: Marketing
A12: 7514101 | B12: Staff Bonus / TAT | C12: 7514101 | D12: 7514101 | E12: SGA | F12: SGA-7514101 | G12: A501 | H12: Year-end allowance & Alpha | J12: Sales - OEM | K12: B3110 | L12: SGA | M12: ADM | N12: Sales - OEM
A13: 7514102 | B13: Staff Ramadhan / THR | C13: 7514102 | D13: 7514102 | E13: SGA | F13: SGA-7514102 | G13: A501 | H13: Lebaran bonus | J13: Sales - OES | K13: B3120 | L13: SGA | M13: ADM | N13: Sales - OES
A14: 7515401 | B14: Staff Welfare - Outpatient (Medical) | C14: 7515401 | D14: 7515401 | E14: SGA | F14: SGA-7515401 | G14: A504 | H14: outpatient treatment costs | J14: Sales - IAM | K14: B3130 | L14: SGA | M14: ADM | N14: Sales - IAM
A15: 7515402 | B15: Staff Welfare - Hospitalization | C15: 7515402 | D15: 7515402 | E15: SGA | F15: SGA-7515402 | G15: A504 | H15: hospitalization costs | J15: Sales & MKTG Dept.- DID Chain | K15: B3172 | L15: SGA | M15: ADM | N15: Sales & MKTG Dept.- DID Chain
A16: 7515403 | B16: Staff Welfare - Glasses | C16: 7515403 | D16: 7515403 | E16: SGA | F16: SGA-7515403 | G16: A504 | H16: glasses costs | J16: SP PD- CF | K16: B4101 | L16: MFG | M16: DIR | N16: SP PD- CF
A17: 7515404 | B17: Staff Welfare - Dental | C17: 7515404 | D17: 7515404 | E17: SGA | F17: SGA-7515404 | G17: A504 | H17: dental costs | J17: SP PD- CM | K17: B4102 | L17: MFG | M17: DIR | N17: SP PD- CM
A18: 7515405 | B18: Staff Welfare - Medical Check Up | C18: 7515405 | D18: 7515405 | E18: SGA | F18: SGA-7515405 | G18: A504 | H18: Medical Check Up cost | J18: SP PD- WT | K18: B4103 | L18: MFG | M18: DIR | N18: SP PD- WT
A19: 7515406 | B19: Staff Welfare - Uniform | C19: 7515406 | D19: 7515406 | E19: SGA | F19: SGA-7515406 | G19: A504 | H19: uniform costs | J19: SP PD- Plating | K19: B4105 | L19: MFG | M19: DIR | N19: SP PD- Plating
A20: 7515407 | B20: Staff Welfare - Safety Shoes | C20: 7515407 | D20: 7515407 | E20: SGA | F20: SGA-7515407 | G20: A504 | J20: SP PD- MS Insp. | K20: B4109 | L20: MFG | M20: DIR | N20: SP PD- MS Insp.
A21: 7515408 | B21: Staff Welfare - Family Gathering / Anniversary | C21: 7515408 | D21: 7515408 | E21: SGA | F21: SGA-7515408 | G21: A504 | H21: Family Gathering / Anniversary | J21: SP PD - Insulator Sealing | K21: B4130 | L21: MFG | M21: DIR | N21: SP PD - Insulator Sealing
A22: 7515409 | B22: Staff Welfare - Meals of canteen & other meals | C22: 7515409 | D22: 7515409 | E22: SGA | F22: SGA-7515409 | G22: A504 | H22: Meals of canteen & other meals cost | J22: SP PD- Assy | K22: B4110 | L22: MFG | M22: DIR | N22: SP PD- Assy
A23: 7515410 | B23: Staff Welfare - Kaizen & QCC reward | C23: 7515410 | D23: 7515410 | E23: SGA | F23: SGA-7515410 | G23: A504 | H23: an expense, arising from Kaizen and QCC acitivity | J23: SP-PD-Assy-Auto Assembly | K23: B4115 | L23: MFG | M23: DIR | N23: SP-PD-Assy-Auto Assembly
A24: 7515499 | B24: Staff Welfare - Welfare Others | C24: 7515499 | D24: 7515499 | E24: SGA | F24: SGA-7515499 | G24: A504 | H24: an other welfare expense, arising besides the above welfare expense | J24: SP PD- Bending | K24: B4114 | L24: MFG | M24: DIR | N24: SP PD- Bending
A25: 7516102 | B25: Retirement Allowance | C25: 7516102 | D25: 7516102 | E25: SGA | F25: SGA-7516102 | G25: A505 | H25: employee retirement provission costs | J25: SP PD- Final Inspection | K25: B4120 | L25: MFG | M25: DIR | N25: SP PD- Final Inspection
A26: 7519101 | B26: House Rent Allowance | C26: 7519101 | D26: 7519101 | E26: SGA | F26: SGA-7519101 | G26: A502 | H26: House Rent Allowance for expat | J26: SP PD- QC - OEM | K26: B4121 | L26: MFG | M26: DIR | N26: SP PD- QC - OEM
A27: 7521101 | B27: Casual Staff Labor - Basic Salary | C27: 7521101 | D27: 7521101 | E27: SGA | F27: SGA-7521101 | G27: A501 | H27: All benefit for temporary worker | J27: PC PD- Injection | K27: B4410 | L27: MFG | M27: DIR | N27: PC PD- Injection
A28: 7521102 | B28: Casual Staff Labor - Overtime | C28: 7521102 | D28: 7521102 | E28: SGA | F28: SGA-7521102 | G28: A503 | H28: Overtime temporary worker | J28: PC PD- Assy | K28: B4430 | L28: MFG | M28: DIR | N28: PC PD- Assy
A29: 7571101 | B29: Personnel expense transferred | C29: 7571101 | D29: 7571101 | E29: SGA | F29: SGA-7571101 | G29: A506 | H29: Transfer Labor cost from one section into another section | J29: PC PD- QC | K29: B4440 | L29: MFG | M29: DIR | N29: PC PD- QC
A30: 7611100 | B30: Depreciation-Building | C30: 7611100 | D30: 7611100 | E30: SGA | F30: SGA-7611100 | G30: A601 | H30: the amount of depreciation of tangible assets for building | J30: Plant Operation (Indirect Mfg) | K30: B5000 | L30: MFG | M30: IND | N30: Plant Operation (Indirect Mfg)
A31: 7611300 | B31: Depreciation-Machiney & equipment | C31: 7611300 | D31: 7611300 | E31: SGA | F31: SGA-7611300 | G31: A601 | H31: the amount of depreciation of tangible assets for machinery & factory equipment | J31: Production Office | K31: B5100 | L31: MFG | M31: IND | N31: Production Office
A32: 7611400 | B32: Depreciation-Lease Machinery & equipment | C32: 7611400 | D32: 7611400 | E32: SGA | F32: SGA-7611400 | G32: A601 | H32: the amount of depreciation of tangible assets for machinery & factory equipment (Leases) | J32: Production Office (SP) | K32: B5101 | L32: MFG | M32: IND | N32: Production Office (SP)
... A42: 7641102 | B42: Repair of Equipment | C42: 7641102 | D42: 7641102 | E42: SGA | F42: SGA-7641102 | G42: A1002 | H42: expenses for repair and maintenance tangible assets, intangible assets and other assets beside building | J42: Continuous Improvement | K42: B5007 | L42: MFG | M42: IND | N42: Continuous Improvement
A43: 7641103 | B43: Factory Supply Expense | C43: 7641103 | D43: 7641103 | E43: SGA | F43: SGA-7641103 | G43: A1099 | H43: All cost that arrising to support factory acitivity | J43: All | K43: B0000 | N43: All
A44: 7641104 | B44: Calibration Cost | C44: 7641104 | D44: 7641104 | E44: SGA | F44: SGA-7641104 | G44: A1099 | H44: Cost of calibration for tools and equipment of factory and others
A45: 7651101 | B45: Transportation Fee for employee | C45: 7651101 | D45: 7651101 | E45: SGA | F45: SGA-7651101 | G45: A801 | H45: Gasoline of company cars & expense for Local transportation
A46: 7651102 | B46: Travel Expense-Domestic | C46: 7651102 | D46: 7651102 | E46: SGA | F46: SGA-7651102 | G46: A801 | H46: expenses for business trip, including allowance for business trip to an employee only for domestic travel
A47: 7651103 | B47: Travel Expense-Oversea | C47: 7651103 | D47: 7651103 | E47: SGA | F47: SGA-7651103 | G47: A801 | H47: expenses for business trip, including allowance for business trip to an employee only for overseas travel
A48: 7661101 | B48: Entertainment | C48: 7661101 | D48: 7661101 | E48: SGA | F48: SGA-7661101 | G48: A1001 | H48: the amount of expenses for the act of entertaining the business partner
A49: 7671102 | B49: Amortization of Land & Building tax (PBB) | C49: 7671102 | D49: 7671102 | E49: SGA | F49: SGA-7671102 | G49: A1099 | H49: the amount of depreciation of intangible of Land & Building Tax (PBB)
...

Sheet Priority
A1: Priority Code | B1: Priority Name | C1: Description
A2: A | B2: Must | C2: If this is not done, the company or our team cannot continue its business.
A3: B | B3: Want to | C3: We want to do it as a team this term. we need it.
A4: C | B4: Challenge | C4: We want to do it for this term or the future. But it doesn't matter if it's not this term.

Sheet V1
A1: This is used for version checking on portal, do not delete!.

Sheet Password
A1: Password protect sheet = budget
