Workbook
Name __j102: #REF!
Name __j102: #REF!
Name _1: #N/A
Name _j102: #REF!
Name _j102: #REF!
Name _j102: #REF!
Name aa: #REF!
Name aa: #REF!
Name AB: #REF!
Name AB: #REF!
Name ai: #REF!
Name ai: #REF!
Name as: #REF!
Name as: #REF!
Name assit: #REF!
Name assit: #REF!
Name b: #REF!
Name b: #REF!
Name BC: #REF!
Name BC: #REF!
Name BI: #REF!
Name BI: #REF!
Name BO: #REF!
Name BO: #REF!
Name cc: #REF!
Name cc: #REF!
Name CH: #REF!
Name CH: #REF!
Name CI: #REF!
Name CI: #REF!
Name Ck_for: #REF!
Name Ck_for: #REF!
Name Ck_in: #REF!
Name Ck_in: #REF!
Name Ck_out: #REF!
Name Ck_out: #REF!
Name d: #REF!
Name d: #REF!
Name dd: #REF!
Name dd: #REF!
Name DF: #REF!
Name DF: #REF!
Name e: #REF!
Name e: #REF!
Name edy: #REF!
Name ee: #REF!
Name ee: #REF!
Name eXCRATE: #REF!
Name eXCRATE: #REF!
Name exrate: #REF!
Name exrate: #REF!
Name F: #REF!
Name F: #REF!
Name fcb: #REF!
Name fcb: #REF!
Name FG: #REF!
Name FG: #REF!
Name g: #REF!
Name g: #REF!
Name gg: #REF!

Sheet Data
A1: Budget Type | B1: Section From (Code) | C1: Section From (Name) | D1: To Section (Code) | E1: To Section (Name) | F1: Coa ID | G1: Coa Name | H1: Asset Name | I1: Group Section | J1: Group Cost | K1: Acquisition Value | L1: Useful Life | M1: Allocation % | N1: Depre Start | O1: Priority Code | P1: Budget_Period | Q1: Budget Allocation
B2: =_xlfn.IFNA(VLOOKUP(C2,Master!$H:$I,2,FALSE),"") | D2: =_xlfn.IFNA(VLOOKUP(E2,Master!$H:$I,2,FALSE),"") | F2: =+_xlfn.XLOOKUP(G2,Master!$V$2:$V$8,Master!$U$2:$U$8,"") | I2: =_xlfn.IFNA(VLOOKUP(D2,Master!$I:$K,2,FALSE),"") | J2: =_xlfn.IFNA(VLOOKUP(D2,Master!$I:$K,3,FALSE),"") | L2: =IF(A2<>"CFA",_xlfn.IFNA(VLOOKUP($G2,Master!$V$2:$Z$8,5,0),""),"") | P2: =IF(N2<>"",IF(MONTH(N2)>=4,"FY1"&RIGHT(YEAR(N2)+1,2),"FY1"&RIGHT(YEAR(N2),2)),"") | Q2: =IF(K2>0&M2>0,K2*M2,"") -> 0
B3: =_xlfn.IFNA(VLOOKUP(C3,Master!$H:$I,2,FALSE),"") | D3: =_xlfn.IFNA(VLOOKUP(E3,Master!$H:$I,2,FALSE),"") | F3: =+_xlfn.XLOOKUP(G3,Master!$V$2:$V$8,Master!$U$2:$U$8,"") | I3: =_xlfn.IFNA(VLOOKUP(D3,Master!$I:$K,2,FALSE),"") | J3: =_xlfn.IFNA(VLOOKUP(D3,Master!$I:$K,3,FALSE),"") | L3: =IF(A3<>"CFA",_xlfn.IFNA(VLOOKUP($G3,Master!$V$2:$Z$8,5,0),""),"") | P3: =IF(N3<>"",IF(MONTH(N3)>=4,"FY1"&RIGHT(YEAR(N3)+1,2),"FY1"&RIGHT(YEAR(N3),2)),"") | Q3: =IF(K3>0&M3>0,K3*M3,"") -> 0
B4: =_xlfn.IFNA(VLOOKUP(C4,Master!$H:$I,2,FALSE),"") | D4: =_xlfn.IFNA(VLOOKUP(E4,Master!$H:$I,2,FALSE),"") | F4: =+_xlfn.XLOOKUP(G4,Master!$V$2:$V$8,Master!$U$2:$U$8,"") | I4: =_xlfn.IFNA(VLOOKUP(D4,Master!$I:$K,2,FALSE),"") | J4: =_xlfn.IFNA(VLOOKUP(D4,Master!$I:$K,3,FALSE),"") | L4: =IF(A4<>"CFA",_xlfn.IFNA(VLOOKUP($G4,Master!$V$2:$Z$8,5,0),""),"") | P4: =IF(N4<>"",IF(MONTH(N4)>=4,"FY1"&RIGHT(YEAR(N4)+1,2),"FY1"&RIGHT(YEAR(N4),2)),"") | Q4: =IF(K4>0&M4>0,K4*M4,"") -> 0
B5: =_xlfn.IFNA(VLOOKUP(C5,Master!$H:$I,2,FALSE),"") | D5: =_xlfn.IFNA(VLOOKUP(E5,Master!$H:$I,2,FALSE),"") | F5: =+_xlfn.XLOOKUP(G5,Master!$V$2:$V$8,Master!$U$2:$U$8,"") | I5: =_xlfn.IFNA(VLOOKUP(D5,Master!$I:$K,2,FALSE),"") | J5: =_xlfn.IFNA(VLOOKUP(D5,Master!$I:$K,3,FALSE),"") | L5: =IF(A5<>"CFA",_xlfn.IFNA(VLOOKUP($G5,Master!$V$2:$Z$8,5,0),""),"") | P5: =IF(N5<>"",IF(MONTH(N5)>=4,"FY1"&RIGHT(YEAR(N5)+1,2),"FY1"&RIGHT(YEAR(N5),2)),"") | Q5: =IF(K5>0&M5>0,K5*M5,"") -> 0
B6: =_xlfn.IFNA(VLOOKUP(C6,Master!$H:$I,2,FALSE),"") | D6: =_xlfn.IFNA(VLOOKUP(E6,Master!$H:$I,2,FALSE),"") | F6: =+_xlfn.XLOOKUP(G6,Master!$V$2:$V$8,Master!$U$2:$U$8,"") | I6: =_xlfn.IFNA(VLOOKUP(D6,Master!$I:$K,2,FALSE),"") | J6: =_xlfn.IFNA(VLOOKUP(D6,Master!$I:$K,3,FALSE),"") | L6: =IF(A6<>"CFA",_xlfn.IFNA(VLOOKUP($G6,Master!$V$2:$Z$8,5,0),""),"") | P6: =IF(N6<>"",IF(MONTH(N6)>=4,"FY1"&RIGHT(YEAR(N6)+1,2),"FY1"&RIGHT(YEAR(N6),2)),"") | Q6: =IF(K6>0&M6>0,K6*M6,"") -> 0
B7: =_xlfn.IFNA(VLOOKUP(C7,Master!$H:$I,2,FALSE),"") | D7: =_xlfn.IFNA(VLOOKUP(E7,Master!$H:$I,2,FALSE),"") | F7: =+_xlfn.XLOOKUP(G7,Master!$V$2:$V$8,Master!$U$2:$U$8,"") | I7: =_xlfn.IFNA(VLOOKUP(D7,Master!$I:$K,2,FALSE),"") | J7: =_xlfn.IFNA(VLOOKUP(D7,Master!$I:$K,3,FALSE),"") | L7: =IF(A7<>"CFA",_xlfn.IFNA(VLOOKUP($G7,Master!$V$2:$Z$8,5,0),""),"") | P7: =IF(N7<>"",IF(MONTH(N7)>=4,"FY1"&RIGHT(YEAR(N7)+1,2),"FY1"&RIGHT(YEAR(N7),2)),"") | Q7: =IF(K7>0&M7>0,K7*M7,"") -> 0
B8: =_xlfn.IFNA(VLOOKUP(C8,Master!$H:$I,2,FALSE),"") | D8: =_xlfn.IFNA(VLOOKUP(E8,Master!$H:$I,2,FALSE),"") | F8: =+_xlfn.XLOOKUP(G8,Master!$V$2:$V$8,Master!$U$2:$U$8,"") | I8: =_xlfn.IFNA(VLOOKUP(D8,Master!$I:$K,2,FALSE),"") | J8: =_xlfn.IFNA(VLOOKUP(D8,Master!$I:$K,3,FALSE),"") | L8: =IF(A8<>"CFA",_xlfn.IFNA(VLOOKUP($G8,Master!$V$2:$Z$8,5,0),""),"") | P8: =IF(N8<>"",IF(MONTH(N8)>=4,"FY1"&RIGHT(YEAR(N8)+1,2),"FY1"&RIGHT(YEAR(N8),2)),"") | Q8: =IF(K8>0&M8>0,K8*M8,"") -> 0
B9: =_xlfn.IFNA(VLOOKUP(C9,Master!$H:$I,2,FALSE),"") | D9: =_xlfn.IFNA(VLOOKUP(E9,Master!$H:$I,2,FALSE),"") | F9: =+_xlfn.XLOOKUP(G9,Master!$V$2:$V$8,Master!$U$2:$U$8,"") | I9: =_xlfn.IFNA(VLOOKUP(D9,Master!$I:$K,2,FALSE),"") | J9: =_xlfn.IFNA(VLOOKUP(D9,Master!$I:$K,3,FALSE),"") | L9: =IF(A9<>"CFA",_xlfn.IFNA(VLOOKUP($G9,Master!$V$2:$Z$8,5,0),""),"") | P9: =IF(N9<>"",IF(MONTH(N9)>=4,"FY1"&RIGHT(YEAR(N9)+1,2),"FY1"&RIGHT(YEAR(N9),2)),"") | Q9: =IF(K9>0&M9>0,K9*M9,"") -> 0
B10: =_xlfn.IFNA(VLOOKUP(C10,Master!$H:$I,2,FALSE),"") | D10: =_xlfn.IFNA(VLOOKUP(E10,Master!$H:$I,2,FALSE),"") | F10: =+_xlfn.XLOOKUP(G10,Master!$V$2:$V$8,Master!$U$2:$U$8,"") | I10: =_xlfn.IFNA(VLOOKUP(D10,Master!$I:$K,2,FALSE),"") | J10: =_xlfn.IFNA(VLOOKUP(D10,Master!$I:$K,3,FALSE),"") | L10: =IF(A10<>"CFA",_xlfn.IFNA(VLOOKUP($G10,Master!$V$2:$Z$8,5,0),""),"") | P10: =IF(N10<>"",IF(MONTH(N10)>=4,"FY1"&RIGHT(YEAR(N10)+1,2),"FY1"&RIGHT(YEAR(N10),2)),"") | Q10: =IF(K10>0&M10>0,K10*M10,"") -> 0
B11: =_xlfn.IFNA(VLOOKUP(C11,Master!$H:$I,2,FALSE),"") | D11: =_xlfn.IFNA(VLOOKUP(E11,Master!$H:$I,2,FALSE),"") | F11: =+_xlfn.XLOOKUP(G11,Master!$V$2:$V$8,Master!$U$2:$U$8,"") | I11: =_xlfn.IFNA(VLOOKUP(D11,Master!$I:$K,2,FALSE),"") | J11: =_xlfn.IFNA(VLOOKUP(D11,Master!$I:$K,3,FALSE),"") | L11: =IF(A11<>"CFA",_xlfn.IFNA(VLOOKUP($G11,Master!$V$2:$Z$8,5,0),""),"") | P11: =IF(N11<>"",IF(MONTH(N11)>=4,"FY1"&RIGHT(YEAR(N11)+1,2),"FY1"&RIGHT(YEAR(N11),2)),"") | Q11: =IF(K11>0&M11>0,K11*M11,"") -> 0
B12: =_xlfn.IFNA(VLOOKUP(C12,Master!$H:$I,2,FALSE),"") | D12: =_xlfn.IFNA(VLOOKUP(E12,Master!$H:$I,2,FALSE),"") | F12: =+_xlfn.XLOOKUP(G12,Master!$V$2:$V$8,Master!$U$2:$U$8,"") | I12: =_xlfn.IFNA(VLOOKUP(D12,Master!$I:$K,2,FALSE),"") | J12: =_xlfn.IFNA(VLOOKUP(D12,Master!$I:$K,3,FALSE),"") | L12: =IF(A12<>"CFA",_xlfn.IFNA(VLOOKUP($G12,Master!$V$2:$Z$8,5,0),""),"") | P12: =IF(N12<>"",IF(MONTH(N12)>=4,"FY1"&RIGHT(YEAR(N12)+1,2),"FY1"&RIGHT(YEAR(N12),2)),"") | Q12: =IF(K12>0&M12>0,K12*M12,"") -> 0
B13: =_xlfn.IFNA(VLOOKUP(C13,Master!$H:$I,2,FALSE),"") | D13: =_xlfn.IFNA(VLOOKUP(E13,Master!$H:$I,2,FALSE),"") | F13: =+_xlfn.XLOOKUP(G13,Master!$V$2:$V$8,Master!$U$2:$U$8,"") | I13: =_xlfn.IFNA(VLOOKUP(D13,Master!$I:$K,2,FALSE),"") | J13: =_xlfn.IFNA(VLOOKUP(D13,Master!$I:$K,3,FALSE),"") | L13: =IF(A13<>"CFA",_xlfn.IFNA(VLOOKUP($G13,Master!$V$2:$Z$8,5,0),""),"") | P13: =IF(N13<>"",IF(MONTH(N13)>=4,"FY1"&RIGHT(YEAR(N13)+1,2),"FY1"&RIGHT(YEAR(N13),2)),"") | Q13: =IF(K13>0&M13>0,K13*M13,"") -> 0
... B2500: =_xlfn.IFNA(VLOOKUP(C2500,Master!$H:$I,2,FALSE),"") | D2500: =_xlfn.IFNA(VLOOKUP(E2500,Master!$H:$I,2,FALSE),"") | F2500: =+_xlfn.XLOOKUP(G2500,Master!$V$2:$V$8,Master!$U$2:$U$8,"") | I2500: =_xlfn.IFNA(VLOOKUP(D2500,Master!$I:$K,2,FALSE),"") | J2500: =_xlfn.IFNA(VLOOKUP(D2500,Master!$I:$K,3,FALSE),"") | L2500: =IF(A2500<>"CFA",_xlfn.IFNA(VLOOKUP($G2500,Master!$V$2:$Z$8,5,0),""),"") | P2500: =IF(N2500<>"",IF(MONTH(N2500)>=4,"FY1"&RIGHT(YEAR(N2500)+1,2),"FY1"&RIGHT(YEAR(N2500),2)),"") | Q2500: =IF(K2500>0&M2500>0,K2500*M2500,"") -> 0

Sheet V1
A1: This is used for version checking on portal, do not delete!.

Sheet Password
A1: Password protect sheet = budget

Sheet Priority
A1: Priority Code | B1: Priority Name | C1: Description
A2: A | B2: Must | C2: If this is not done, the company or our team cannot continue its business.
A3: B | B3: Want to | C3: We want to do it as a team this term. we need it.
A4: C | B4: Challenge | C4: We want to do it for this term or the future. But it doesn't matter if it's not this term.

Sheet Master
A1: Name COA D365 | B1: COA D365 | C1: Group Cost | D1: UNIQ | E1: COA Budget | F1: Description | H1: Name | I1: BNGK | J1: GROUP COST | K1: GROUP SECTION | L1: Name | N1: Code | O1: Name | Q1: Priority Code | R1: Priority Name | S1: Description | U1: COA Assets | V1: Name of Asset | W1: COA Assets | X1: COA Depre | Y1: Name of Depre | Z1: Useful Life | AA1: Value | AB1: Description
A2: Salary for Commissioner | B2: 7511101 | C2: SGA | D2: SGA-7511101 | E2: A502 | F2: Salary for Commissioner | H2: Top Management | I2: B1000 | J2: SGA | K2: ADM | L2: Top Management | N2: 53450 | O2: PT Niterra Mobility Indonesia | Q2: A | R2: Must | S2: If this is not done, the company or our team cannot continue its business. | U2: 2111100 | V2: Building (20 years) | W2: 2111100 | X2: 7611100 | Y2: Depreciation-Building | Z2: 240 | AA2: > 25.000.000 | AB2: a construction such as a factory that has a roof and walls and Structure a construction fixed on land other than a building.
A3: Salary for Director | B3: 7511102 | C3: SGA | D3: SGA-7511102 | E3: A502 | F3: Salary for Director & Expat | H3: Commissioner | I3: B1001 | J3: SGA | K3: ADM | L3: Commissioner | Q3: B | R3: Want to | S3: We want to do it as a team this term. we need it. | U3: 2111100 | V3: Building (10 years) | W3: 2111100 | X3: 7611100 | Y3: Depreciation-Building | Z3: 120 | AA3: > 50.000.000 | AB3: a construction such as a factory that has a roof and walls and Structure a construction fixed on land other than a building.
A4: Staff Labor - Basic Salary | B4: 7511103 | C4: SGA | D4: SGA-7511103 | E4: A501 | F4: Basic Salary of permanent employee | H4: Admin & HR | I4: B2200 | J4: SGA | K4: ADM | L4: Admin & HR | Q4: C | R4: Challenge | S4: We want to do it for this term or the future. But it doesn't matter if it's not this term. | U4: 2121000 | V4: Machinery & Equipment - New | W4: 2121000 | X4: 7611300 | Y4: Depreciation-Machiney & equipment | Z4: 120 | AA4: > 250.000.000 | AB4: Devices that used for production, such as cold forming equipment, an assembly machine, and All Factory Equiptment (new)
A5: Staff Labor - Allowance | B5: 7511111 | C5: SGA | D5: SGA-7511111 | E5: A501 | F5: Employee allowance | H5: General Affair | I5: B2210 | J5: SGA | K5: ADM | L5: General Affair | N5: Budget Type | U5: 2121000 | V5: Machinery & Equipment - Second | W5: 2121000 | X5: 7611300 | Y5: Depreciation-Machiney & equipment | Z5: 84 | AA5: > 100.000.000 | AB5: Devices that used for production, such as cold forming equipment, an assembly machine, and All Factory Equiptment (second)
A6: Staff Labor - Tax allowance (art.21) | B6: 7511112 | C6: SGA | D6: SGA-7511112 | E6: A501 | F6: Empployee Tax allowance | H6: Human Resource | I6: B2220 | J6: SGA | K6: ADM | L6: Human Resource | N6: BIP | O6: Budget Investment Plan | U6: 2131000 | V6: Vehicles | W6: 2131000 | X6: 7611500 | Y6: Depreciation-Vehicles | Z6: 60 | AA6: > 50.000.000 | AB6: things that used for surface-transporting people or goods, such as cars, trucks and forklifts.
A7: Staff Labor - BPJS JK & JKK (1.19%) | B7: 7511121 | C7: SGA | D7: SGA-7511121 | E7: A501 | F7: BPJS JK & JKK (death warrant, Accident Insurance) | H7: Health, Safety & Environment | I7: B2230 | J7: SGA | K7: ADM | L7: Health, Safety & Environment | N7: CIP | O7: Construction In Progress | U7: 2141000 | V7: Tools, furniture & office equipment | W7: 2141000 | X7: 7611600 | Y7: Depreciation-Tools, furniture & office equipment | Z7: 60 | AA7: > 5.000.000 | AB7: furniture that we used in office and factory, and Office equipment, such as fax machine, printer, komputer, note book, etc
A8: Staff Labor - BPJS Kesehatan (4%) | B8: 7511122 | C8: SGA | D8: SGA-7511122 | E8: A501 | F8: BPJS health insurance | H8: Accounting & Finance | I8: B2300 | J8: SGA | K8: ADM | L8: Accounting & Finance | N8: CFA | O8: Current Fixed Assets | U8: 2221101 | V8: Software | W8: 2221101 | X8: 7611700 | Y8: Depreciation-Software | Z8: 60 | AA8: > 50.000.000
A9: Staff Overtime | B9: 7511201 | C9: SGA | D9: SGA-7511201 | E9: A503 | F9: Overtime permanent employee | H9: Information Technology | I9: B2400 | J9: SGA | K9: ADM | L9: Information Technology
A10: Staff Welfare - BPJS Dana pensiun (2%) | B10: 7512111 | C10: SGA | D10: SGA-7512111 | E10: A504 | F10: BPJS pension fund | H10: Sales & MKTG Dept.- Automotive | I10: B3100 | J10: SGA | K10: ADM | L10: Sales & MKTG Dept.- Automotive
A11: Staff Welfare - BPJS JHT (3.7%) | B11: 7512112 | C11: SGA | D11: SGA-7512112 | E11: A504 | F11: BPJS Pension plan | H11: Marketing | I11: B3160 | J11: SGA | K11: ADM | L11: Marketing
A12: Staff Bonus / TAT | B12: 7514101 | C12: SGA | D12: SGA-7514101 | E12: A501 | F12: Year-end allowance & Alpha | H12: Sales - OEM | I12: B3110 | J12: SGA | K12: ADM | L12: Sales - OEM
A13: Staff Ramadhan / THR | B13: 7514102 | C13: SGA | D13: SGA-7514102 | E13: A501 | F13: Lebaran bonus | H13: Sales - OES | I13: B3120 | J13: SGA | K13: ADM | L13: Sales - OES
A14: Staff Welfare - Outpatient (Medical) | B14: 7515401 | C14: SGA | D14: SGA-7515401 | E14: A504 | F14: outpatient treatment costs | H14: Sales - IAM | I14: B3130 | J14: SGA | K14: ADM | L14: Sales - IAM
A15: Staff Welfare - Hospitalization | B15: 7515402 | C15: SGA | D15: SGA-7515402 | E15: A504 | F15: hospitalization costs | H15: Sales & MKTG Dept.- DID Chain | I15: B3172 | J15: SGA | K15: ADM | L15: Sales & MKTG Dept.- DID Chain
A16: Staff Welfare - Glasses | B16: 7515403 | C16: SGA | D16: SGA-7515403 | E16: A504 | F16: glasses costs | H16: SP PD- CF | I16: B4101 | J16: MFG | K16: DIR | L16: SP PD- CF
A17: Staff Welfare - Dental | B17: 7515404 | C17: SGA | D17: SGA-7515404 | E17: A504 | F17: dental costs | H17: SP PD- CM | I17: B4102 | J17: MFG | K17: DIR | L17: SP PD- CM
A18: Staff Welfare - Medical Check Up | B18: 7515405 | C18: SGA | D18: SGA-7515405 | E18: A504 | F18: Medical Check Up cost | H18: SP PD- WT | I18: B4103 | J18: MFG | K18: DIR | L18: SP PD- WT
A19: Staff Welfare - Uniform | B19: 7515406 | C19: SGA | D19: SGA-7515406 | E19: A504 | F19: uniform costs | H19: SP PD- Plating | I19: B4105 | J19: MFG | K19: DIR | L19: SP PD- Plating
A20: Staff Welfare - Safety Shoes | B20: 7515407 | C20: SGA | D20: SGA-7515407 | E20: A504 | F20: Safety shoes costs | H20: SP PD- MS Insp. | I20: B4109 | J20: MFG | K20: DIR | L20: SP PD- MS Insp.
... A43: Factory Supply Expense | B43: 7641103 | C43: SGA | D43: SGA-7641103 | E43: A1099 | F43: All cost that arrising to support factory acitivity | H43: Purchasing | I43: B6100 | J43: SGA | K43: ADM | L43: Purchasing
A44: Calibration Cost | B44: 7641104 | C44: SGA | D44: SGA-7641104 | E44: A1099 | F44: Cost of calibration for tools and equipment of factory and others | H44: All | I44: All | L44: All
A45: Transportation Fee for employee | B45: 7651101 | C45: SGA | D45: SGA-7651101 | E45: A801 | F45: Gasoline of company cars & expense for Local transportation
A46: Travel Expense-Domestic | B46: 7651102 | C46: SGA | D46: SGA-7651102 | E46: A801 | F46: expenses for business trip, including allowance for business trip to an employee only for domestic travel
A47: Travel Expense-Oversea | B47: 7651103 | C47: SGA | D47: SGA-7651103 | E47: A801 | F47: expenses for business trip, including allowance for business trip to an employee only for overseas travel
A48: Entertainment | B48: 7661101 | C48: SGA | D48: SGA-7661101 | E48: A1001 | F48: the amount of expenses for the act of entertaining the business partner
A49: Amortization of Land & Building tax (PBB) | B49: 7671102 | C49: SGA | D49: SGA-7671102 | E49: A1099 | F49: the amount of depreciation of intangible of Land & Building Tax (PBB)
A50: License fee | B50: 7671103 | C50: SGA | D50: SGA-7671103 | E50: A1099 | F50: The expense related with the documentation process, such as : KIR, Car lisence, company lisence, etc.
A51: Insurance Premium | B51: 7681101 | C51: SGA | D51: SGA-7681101 | E51: A1099 | F51: expenses for risk management with no premium at the end of the term, such as fire insurance for plants and inventories
A52: Office supply & Stationary Expense | B52: 7691000 | C52: SGA | D52: SGA-7691000 | E52: A1099 | F52: the amount of supplies for office, such as stationery. Small office equipment included
A53: Communication expenses | B53: 7711101 | C53: SGA | D53: SGA-7711101 | E53: A1099 | F53: expenses for communication with a people in remote place, such as expense for telephone and postage
A54: IT Expense | B54: 7711102 | C54: SGA | D54: SGA-7711102 | E54: A1005 | F54: the amount of supplies for IT tools
A55: Stamp/Post Fee | B55: 7711103 | C55: SGA | D55: SGA-7711103 | E55: A1099 | F55: The expenses related with stamp duty
A56: Audit Fee | B56: 7721101 | C56: SGA | D56: SGA-7721101 | E56: A901 | F56: a fee for external auditor of accounting assessment
... A76: Sample expense | B76: 7461101 | C76: SGA | D76: SGA-7461101 | E76: A499 | F76: Sample expense
A77: Sales - Insurance of Delivery or Shipment | B77: 7411105 | C77: SGA | D77: SGA-7411105 | E77: A299
A78: Sales - Insurance of AR (Credit Insurance) | B78: 7471201 | C78: SGA | D78: SGA-7471201 | E78: A1016
A79: Sales - Royalty to NGK Group | B79: 7751101 | C79: SGA | D79: SGA-7751101 | E79: A1201
A80: Sales - Royalty to Independence Party | B80: 7751102 | C80: SGA | D80: SGA-7751102 | E80: A1201
A81: Import Duty-purchased FG from NGK group | B81: 7111211 | C81: MFG | D81: MFG-7111211
...
