Workbook
Name __j102: #REF!
Name __j102: #REF!
Name _1: #N/A
Name _j102: #REF!
Name _j102: #REF!
Name aa: #REF!
Name AB: #REF!
Name ai: #REF!
Name as: #REF!
Name assit: #REF!
Name b: #REF!
Name BC: #REF!
Name BI: #REF!
Name BO: #REF!
Name cc: #REF!
Name CH: #REF!
Name CI: #REF!
Name Ck_for: #REF!
Name Ck_in: #REF!
Name Ck_out: #REF!
Name d: #REF!
Name dd: #REF!
Name DF: #REF!
Name e: #REF!
Name ee: #REF!
Name eXCRATE: #REF!
Name exrate: #REF!
Name F: #REF!
Name fcb: #REF!
Name FG: #REF!
Name g: #REF!
Name gg: #REF!
Name HF: #REF!
Name kissa: #REF!
Name kissakei: #REF!
Name kk: #REF!
Name kkk: #REF!
Name kkkk: #REF!
Name l: #REF!
Name L_01: #REF!
Name LIA: #REF!
Name LILI: #REF!
Name LINA: #REF!
Name m: #REF!
Name Manufacturing: #REF!
Name MR: #REF!
Name nittk: #REF!
Name nittk_ok: #REF!
Name nittoukei: #REF!
Name PRINT_AREA_MI: #REF!
Name PRINT_AREA_MI: #REF!
Name PRINT_TITLES_MI: #REF!
Name ry: #REF!
Name ryohikei: #REF!
Name S: #REF!
Name sais: #REF!
Name saisyuu: #REF!
Name se: #REF!
Name sett: #REF!
Name setta: #REF!

Sheet Upload
A1: BUDGET TYPE | B1: Section Code (From) | C1: Section Name (From/Who Prepare) | D1: Section Code (To) | E1: Section Name (To/Who Use The Cost) | F1: COA-ID | G1: COA NAME | H1: DESCRIPTION | I1: GROUP SECTION | J1: GROUP COST | K1: =$AI$1 & "_" & "10" -> 2021_10 | L1: =$AI$1 & "_" & "11" -> 2021_11 | M1: =$AI$1 & "_" & "12" -> 2021_12 | N1: =$AI$1 + 1 & "_" & "01" -> 2022_01 | O1: =$AI$1 + 1 & "_" & "02" -> 2022_02 | P1: =$AI$1 + 1 & "_" & "03" -> 2022_03 | Q1: =$AI$1 + 1 & "_" & "04" -> 2022_04 | R1: =$AI$1 + 1 & "_" & "05" -> 2022_05 | S1: =$AI$1 + 1 & "_" & "06" -> 2022_06 | T1: =$AI$1 + 1 & "_" & "07" -> 2022_07 | U1: =$AI$1 + 1 & "_" & "08" -> 2022_08 | V1: =$AI$1 + 1 & "_" & "09" -> 2022_09 | W1: =$AI$1 + 1 & "_" & "10" -> 2022_10 | X1: =$AI$1 + 1 & "_" & "11" -> 2022_11 | Y1: =$AI$1 + 1 & "_" & "12" -> 2022_12 | Z1: =$AI$1 + 2 & "_" & "01" -> 2023_01 | AA1: =$AI$1 + 2& "_" & "02" -> 2023_02 | AB1: =$AI$1 + 2 & "_" & "03" -> 2023_03 | AC1: ="TOTAL FY1" & RIGHT(AI1 + 1,2) -> TOTAL FY122 | AD1: ="TOTAL FY1" & RIGHT(AI1 + 2,2) -> TOTAL FY123 | AE1: ="TOTAL FY1" & RIGHT(AI1 + 3,2) -> TOTAL FY124 | AF1: ="TOTAL FY1" & RIGHT(AI1 + 4,2) -> TOTAL FY125 | AG1: Priority Category | AH1: BUDGET NO. | AI1: 2021
A2: BEX | B2: =_xlfn.IFNA(VLOOKUP(C2,Master!$J:$K,2,0),"") -> B1000 | C2: Top Management | D2: =_xlfn.IFNA(VLOOKUP(E2,Master!$J:$K,2,0),"") -> B1000 | E2: Top Management | F2: =_xlfn.IFNA(VLOOKUP(G2,Master!B:C,2,0),"") -> 7781112 | G2: Expatriate expenses exclude labor cost | H2: School fee Aoki san's family | I2: =_xlfn.IFNA(VLOOKUP(E2,Master!$J:$M,4,0),"") -> ADM | J2: =_xlfn.IFNA(VLOOKUP($E2,Master!$J:$M,3,0),"") -> SGA | R2: 57600000 | AC2: =SUM(K2:P2) -> 0 | AD2: =SUM(Q2:AB2) -> 57600000 | AE2: 57600000 | AF2: 57600000 | AG2: A
A3: BEX | B3: =_xlfn.IFNA(VLOOKUP(C3,Master!$J:$K,2,0),"") -> B1000 | C3: Top Management | D3: =_xlfn.IFNA(VLOOKUP(E3,Master!$J:$K,2,0),"") -> B1000 | E3: Top Management | F3: =_xlfn.IFNA(VLOOKUP(G3,Master!B:C,2,0),"") -> 7781112 | G3: Expatriate expenses exclude labor cost | H3: School bus fee Aoki san's family | I3: =_xlfn.IFNA(VLOOKUP(E3,Master!$J:$M,4,0),"") -> ADM | J3: =_xlfn.IFNA(VLOOKUP($E3,Master!$J:$M,3,0),"") -> SGA | R3: 45000000 | AC3: =SUM(K3:P3) -> 0 | AD3: =SUM(Q3:AB3) -> 45000000 | AE3: 45000000 | AF3: 45000000 | AG3: A
A4: BEX | B4: =_xlfn.IFNA(VLOOKUP(C4,Master!$J:$K,2,0),"") -> B1000 | C4: Top Management | D4: =_xlfn.IFNA(VLOOKUP(E4,Master!$J:$K,2,0),"") -> B1000 | E4: Top Management | F4: =_xlfn.IFNA(VLOOKUP(G4,Master!B:C,2,0),"") -> 7651103 | G4: Travel Expense-Oversea | H4: Thaiand for budget fright [2N3D]_Aoki | I4: =_xlfn.IFNA(VLOOKUP(E4,Master!$J:$M,4,0),"") -> ADM | J4: =_xlfn.IFNA(VLOOKUP($E4,Master!$J:$M,3,0),"") -> SGA | Z4: 7100000 | AC4: =SUM(K4:P4) -> 0 | AD4: =SUM(Q4:AB4) -> 7100000 | AE4: 7100000 | AF4: 7100000 | AG4: A
A5: BEX | B5: =_xlfn.IFNA(VLOOKUP(C5,Master!$J:$K,2,0),"") -> B1000 | C5: Top Management | D5: =_xlfn.IFNA(VLOOKUP(E5,Master!$J:$K,2,0),"") -> B1000 | E5: Top Management | F5: =_xlfn.IFNA(VLOOKUP(G5,Master!B:C,2,0),"") -> 7651103 | G5: Travel Expense-Oversea | H5: Thaiand for budget hotel [2N3D]_Aoki | I5: =_xlfn.IFNA(VLOOKUP(E5,Master!$J:$M,4,0),"") -> ADM | J5: =_xlfn.IFNA(VLOOKUP($E5,Master!$J:$M,3,0),"") -> SGA | Z5: =1060000*2 -> 2120000 | AC5: =SUM(K5:P5) -> 0 | AD5: =SUM(Q5:AB5) -> 2120000 | AE5: 2120000 | AF5: 2120000 | AG5: A
A6: BEX | B6: =_xlfn.IFNA(VLOOKUP(C6,Master!$J:$K,2,0),"") -> B1000 | C6: Top Management | D6: =_xlfn.IFNA(VLOOKUP(E6,Master!$J:$K,2,0),"") -> B1000 | E6: Top Management | F6: =_xlfn.IFNA(VLOOKUP(G6,Master!B:C,2,0),"") -> 7651103 | G6: Travel Expense-Oversea | H6: Thaiand for budget daily fee [2N3D]_Aoki | I6: =_xlfn.IFNA(VLOOKUP(E6,Master!$J:$M,4,0),"") -> ADM | J6: =_xlfn.IFNA(VLOOKUP($E6,Master!$J:$M,3,0),"") -> SGA | Z6: =496202*3+170126*3 -> 1998984 | AC6: =SUM(K6:P6) -> 0 | AD6: =SUM(Q6:AB6) -> 1998984 | AE6: 1998984 | AF6: 1998984 | AG6: A
A7: BEX | B7: =_xlfn.IFNA(VLOOKUP(C7,Master!$J:$K,2,0),"") -> B1000 | C7: Top Management | D7: =_xlfn.IFNA(VLOOKUP(E7,Master!$J:$K,2,0),"") -> B1000 | E7: Top Management | F7: =_xlfn.IFNA(VLOOKUP(G7,Master!B:C,2,0),"") -> 7651103 | G7: Travel Expense-Oversea | H7: Thailand for manager meeting fright [3N4D]_Aoki | I7: =_xlfn.IFNA(VLOOKUP(E7,Master!$J:$M,4,0),"") -> ADM | J7: =_xlfn.IFNA(VLOOKUP($E7,Master!$J:$M,3,0),"") -> SGA | AB7: 7100000 | AC7: =SUM(K7:P7) -> 0 | AD7: =SUM(Q7:AB7) -> 7100000 | AE7: 7100000 | AF7: 7100000 | AG7: A
A8: BEX | B8: =_xlfn.IFNA(VLOOKUP(C8,Master!$J:$K,2,0),"") -> B1000 | C8: Top Management | D8: =_xlfn.IFNA(VLOOKUP(E8,Master!$J:$K,2,0),"") -> B1000 | E8: Top Management | F8: =_xlfn.IFNA(VLOOKUP(G8,Master!B:C,2,0),"") -> 7651103 | G8: Travel Expense-Oversea | H8: Thaiand for manager meeting hotel [3N4D]_Aoki | I8: =_xlfn.IFNA(VLOOKUP(E8,Master!$J:$M,4,0),"") -> ADM | J8: =_xlfn.IFNA(VLOOKUP($E8,Master!$J:$M,3,0),"") -> SGA | AB8: =1060000*3 -> 3180000 | AC8: =SUM(K8:P8) -> 0 | AD8: =SUM(Q8:AB8) -> 3180000 | AE8: 3180000 | AF8: 3180000 | AG8: A
A9: BEX | B9: =_xlfn.IFNA(VLOOKUP(C9,Master!$J:$K,2,0),"") -> B1000 | C9: Top Management | D9: =_xlfn.IFNA(VLOOKUP(E9,Master!$J:$K,2,0),"") -> B1000 | E9: Top Management | F9: =_xlfn.IFNA(VLOOKUP(G9,Master!B:C,2,0),"") -> 7651103 | G9: Travel Expense-Oversea | H9: Thaiand for manager meeting daily fee [3N4D]_Aoki | I9: =_xlfn.IFNA(VLOOKUP(E9,Master!$J:$M,4,0),"") -> ADM | J9: =_xlfn.IFNA(VLOOKUP($E9,Master!$J:$M,3,0),"") -> SGA | AB9: =496202*4+170126*4 -> 2665312 | AC9: =SUM(K9:P9) -> 0 | AD9: =SUM(Q9:AB9) -> 2665312 | AE9: 2665312 | AF9: 2665312 | AG9: A
A10: BEX | B10: =_xlfn.IFNA(VLOOKUP(C10,Master!$J:$K,2,0),"") -> B1000 | C10: Top Management | D10: =_xlfn.IFNA(VLOOKUP(E10,Master!$J:$K,2,0),"") -> B1000 | E10: Top Management | F10: =_xlfn.IFNA(VLOOKUP(G10,Master!B:C,2,0),"") -> 7651103 | G10: Travel Expense-Oversea | H10: Thailand for sales meeting fright [3N4D]_Aoki | I10: =_xlfn.IFNA(VLOOKUP(E10,Master!$J:$M,4,0),"") -> ADM | J10: =_xlfn.IFNA(VLOOKUP($E10,Master!$J:$M,3,0),"") -> SGA | R10: 7100000 | W10: 7100000 | AC10: =SUM(K10:P10) -> 0 | AD10: =SUM(Q10:AB10) -> 14200000 | AE10: 14200000 | AF10: 14200000 | AG10: A
A11: BEX | B11: =_xlfn.IFNA(VLOOKUP(C11,Master!$J:$K,2,0),"") -> B1000 | C11: Top Management | D11: =_xlfn.IFNA(VLOOKUP(E11,Master!$J:$K,2,0),"") -> B1000 | E11: Top Management | F11: =_xlfn.IFNA(VLOOKUP(G11,Master!B:C,2,0),"") -> 7651103 | G11: Travel Expense-Oversea | H11: Thaiand for sales meeting hotel [3N4D]_Aoki | I11: =_xlfn.IFNA(VLOOKUP(E11,Master!$J:$M,4,0),"") -> ADM | J11: =_xlfn.IFNA(VLOOKUP($E11,Master!$J:$M,3,0),"") -> SGA | R11: =1060000*3 -> 3180000 | W11: =1060000*3 -> 3180000 | AC11: =SUM(K11:P11) -> 0 | AD11: =SUM(Q11:AB11) -> 6360000 | AE11: 6360000 | AF11: 6360000 | AG11: A
A12: BEX | B12: =_xlfn.IFNA(VLOOKUP(C12,Master!$J:$K,2,0),"") -> B1000 | C12: Top Management | D12: =_xlfn.IFNA(VLOOKUP(E12,Master!$J:$K,2,0),"") -> B1000 | E12: Top Management | F12: =_xlfn.IFNA(VLOOKUP(G12,Master!B:C,2,0),"") -> 7651103 | G12: Travel Expense-Oversea | H12: Thaiand for sales meeting daily fee [3N4D]_Aoki | I12: =_xlfn.IFNA(VLOOKUP(E12,Master!$J:$M,4,0),"") -> ADM | J12: =_xlfn.IFNA(VLOOKUP($E12,Master!$J:$M,3,0),"") -> SGA | R12: =496202*4+170126*4 -> 2665312 | W12: =496202*4+170126*4 -> 2665312 | AC12: =SUM(K12:P12) -> 0 | AD12: =SUM(Q12:AB12) -> 5330624 | AE12: 5330624 | AF12: 5330624 | AG12: A
A13: BEX | B13: =_xlfn.IFNA(VLOOKUP(C13,Master!$J:$K,2,0),"") -> B1000 | C13: Top Management | D13: =_xlfn.IFNA(VLOOKUP(E13,Master!$J:$K,2,0),"") -> B1000 | E13: Top Management | F13: =_xlfn.IFNA(VLOOKUP(G13,Master!B:C,2,0),"") -> 7651103 | G13: Travel Expense-Oversea | H13: Thailand for SVB fright [3N4D]_Aoki | I13: =_xlfn.IFNA(VLOOKUP(E13,Master!$J:$M,4,0),"") -> ADM | J13: =_xlfn.IFNA(VLOOKUP($E13,Master!$J:$M,3,0),"") -> SGA | Y13: 7100000 | AC13: =SUM(K13:P13) -> 0 | AD13: =SUM(Q13:AB13) -> 7100000 | AE13: 7100000 | AF13: 7100000 | AG13: A
A14: BEX | B14: =_xlfn.IFNA(VLOOKUP(C14,Master!$J:$K,2,0),"") -> B1000 | C14: Top Management | D14: =_xlfn.IFNA(VLOOKUP(E14,Master!$J:$K,2,0),"") -> B1000 | E14: Top Management | F14: =_xlfn.IFNA(VLOOKUP(G14,Master!B:C,2,0),"") -> 7651103 | G14: Travel Expense-Oversea | H14: Thaiand for SVB hotel [3N4D]_Aoki | I14: =_xlfn.IFNA(VLOOKUP(E14,Master!$J:$M,4,0),"") -> ADM | J14: =_xlfn.IFNA(VLOOKUP($E14,Master!$J:$M,3,0),"") -> SGA | Y14: =1060000*3 -> 3180000 | AC14: =SUM(K14:P14) -> 0 | AD14: =SUM(Q14:AB14) -> 3180000 | AE14: 3180000 | AF14: 3180000 | AG14: A
A15: BEX | B15: =_xlfn.IFNA(VLOOKUP(C15,Master!$J:$K,2,0),"") -> B1000 | C15: Top Management | D15: =_xlfn.IFNA(VLOOKUP(E15,Master!$J:$K,2,0),"") -> B1000 | E15: Top Management | F15: =_xlfn.IFNA(VLOOKUP(G15,Master!B:C,2,0),"") -> 7651103 | G15: Travel Expense-Oversea | H15: Thaiand for SVB daily fee [3N4D]_Aoki | I15: =_xlfn.IFNA(VLOOKUP(E15,Master!$J:$M,4,0),"") -> ADM | J15: =_xlfn.IFNA(VLOOKUP($E15,Master!$J:$M,3,0),"") -> SGA | Y15: =496202*4+170126*4 -> 2665312 | AC15: =SUM(K15:P15) -> 0 | AD15: =SUM(Q15:AB15) -> 2665312 | AE15: 2665312 | AF15: 2665312 | AG15: A
A16: BEX | B16: =_xlfn.IFNA(VLOOKUP(C16,Master!$J:$K,2,0),"") -> B1000 | C16: Top Management | D16: =_xlfn.IFNA(VLOOKUP(E16,Master!$J:$K,2,0),"") -> B1000 | E16: Top Management | F16: =_xlfn.IFNA(VLOOKUP(G16,Master!B:C,2,0),"") -> 7651102 | G16: Travel Expense-Domestic | H16: Solo fright [1N2D]_Aoki | I16: =_xlfn.IFNA(VLOOKUP(E16,Master!$J:$M,4,0),"") -> ADM | J16: =_xlfn.IFNA(VLOOKUP($E16,Master!$J:$M,3,0),"") -> SGA | R16: 823000 | W16: 823000 | AC16: =SUM(K16:P16) -> 0 | AD16: =SUM(Q16:AB16) -> 1646000 | AE16: 823000 | AF16: 823000 | AG16: A
A17: BEX | B17: =_xlfn.IFNA(VLOOKUP(C17,Master!$J:$K,2,0),"") -> B1000 | C17: Top Management | D17: =_xlfn.IFNA(VLOOKUP(E17,Master!$J:$K,2,0),"") -> B1000 | E17: Top Management | F17: =_xlfn.IFNA(VLOOKUP(G17,Master!B:C,2,0),"") -> 7651102 | G17: Travel Expense-Domestic | H17: Solo hotel [1N2D]_Aoki | I17: =_xlfn.IFNA(VLOOKUP(E17,Master!$J:$M,4,0),"") -> ADM | J17: =_xlfn.IFNA(VLOOKUP($E17,Master!$J:$M,3,0),"") -> SGA | R17: 900000 | W17: 900000 | AC17: =SUM(K17:P17) -> 0 | AD17: =SUM(Q17:AB17) -> 1800000 | AE17: 900000 | AF17: 900000 | AG17: A
A18: BEX | B18: =_xlfn.IFNA(VLOOKUP(C18,Master!$J:$K,2,0),"") -> B1000 | C18: Top Management | D18: =_xlfn.IFNA(VLOOKUP(E18,Master!$J:$K,2,0),"") -> B1000 | E18: Top Management | F18: =_xlfn.IFNA(VLOOKUP(G18,Master!B:C,2,0),"") -> 7651102 | G18: Travel Expense-Domestic | H18: Solo daily fee [1N2D]_Aoki | I18: =_xlfn.IFNA(VLOOKUP(E18,Master!$J:$M,4,0),"") -> ADM | J18: =_xlfn.IFNA(VLOOKUP($E18,Master!$J:$M,3,0),"") -> SGA | R18: 700000 | W18: 700000 | AC18: =SUM(K18:P18) -> 0 | AD18: =SUM(Q18:AB18) -> 1400000 | AE18: 700000 | AF18: 700000 | AG18: A
A19: BEX | B19: =_xlfn.IFNA(VLOOKUP(C19,Master!$J:$K,2,0),"") -> B1000 | C19: Top Management | D19: =_xlfn.IFNA(VLOOKUP(E19,Master!$J:$K,2,0),"") -> B1000 | E19: Top Management | F19: =_xlfn.IFNA(VLOOKUP(G19,Master!B:C,2,0),"") -> 7651102 | G19: Travel Expense-Domestic | H19: Medan fright [1N2D]_Aoki | I19: =_xlfn.IFNA(VLOOKUP(E19,Master!$J:$M,4,0),"") -> ADM | J19: =_xlfn.IFNA(VLOOKUP($E19,Master!$J:$M,3,0),"") -> SGA | S19: 1185000 | X19: 1185000 | AC19: =SUM(K19:P19) -> 0 | AD19: =SUM(Q19:AB19) -> 2370000 | AE19: 1185000 | AF19: 1185000 | AG19: A
A20: BEX | B20: =_xlfn.IFNA(VLOOKUP(C20,Master!$J:$K,2,0),"") -> B1000 | C20: Top Management | D20: =_xlfn.IFNA(VLOOKUP(E20,Master!$J:$K,2,0),"") -> B1000 | E20: Top Management | F20: =_xlfn.IFNA(VLOOKUP(G20,Master!B:C,2,0),"") -> 7651102 | G20: Travel Expense-Domestic | H20: Medan hotel [1N2D]_Aoki | I20: =_xlfn.IFNA(VLOOKUP(E20,Master!$J:$M,4,0),"") -> ADM | J20: =_xlfn.IFNA(VLOOKUP($E20,Master!$J:$M,3,0),"") -> SGA | S20: 900000 | X20: 900000 | AC20: =SUM(K20:P20) -> 0 | AD20: =SUM(Q20:AB20) -> 1800000 | AE20: 900000 | AF20: 900000 | AG20: A
A21: BEX | B21: =_xlfn.IFNA(VLOOKUP(C21,Master!$J:$K,2,0),"") -> B1000 | C21: Top Management | D21: =_xlfn.IFNA(VLOOKUP(E21,Master!$J:$K,2,0),"") -> B1000 | E21: Top Management | F21: =_xlfn.IFNA(VLOOKUP(G21,Master!B:C,2,0),"") -> 7651102 | G21: Travel Expense-Domestic | H21: Medan daily fee [1N2D]_Aoki | I21: =_xlfn.IFNA(VLOOKUP(E21,Master!$J:$M,4,0),"") -> ADM | J21: =_xlfn.IFNA(VLOOKUP($E21,Master!$J:$M,3,0),"") -> SGA | S21: 700000 | X21: 700000 | AC21: =SUM(K21:P21) -> 0 | AD21: =SUM(Q21:AB21) -> 1400000 | AE21: 700000 | AF21: 700000 | AG21: A
A22: BEX | B22: =_xlfn.IFNA(VLOOKUP(C22,Master!$J:$K,2,0),"") -> B1000 | C22: Top Management | D22: =_xlfn.IFNA(VLOOKUP(E22,Master!$J:$K,2,0),"") -> B1000 | E22: Top Management | F22: =_xlfn.IFNA(VLOOKUP(G22,Master!B:C,2,0),"") -> 7651102 | G22: Travel Expense-Domestic | H22: Parenbang fright [1N2D]_Aoki | I22: =_xlfn.IFNA(VLOOKUP(E22,Master!$J:$M,4,0),"") -> ADM | J22: =_xlfn.IFNA(VLOOKUP($E22,Master!$J:$M,3,0),"") -> SGA | T22: 838000 | Y22: 838000 | AC22: =SUM(K22:P22) -> 0 | AD22: =SUM(Q22:AB22) -> 1676000 | AE22: 838000 | AF22: 838000 | AG22: A
A23: BEX | B23: =_xlfn.IFNA(VLOOKUP(C23,Master!$J:$K,2,0),"") -> B1000 | C23: Top Management | D23: =_xlfn.IFNA(VLOOKUP(E23,Master!$J:$K,2,0),"") -> B1000 | E23: Top Management | F23: =_xlfn.IFNA(VLOOKUP(G23,Master!B:C,2,0),"") -> 7651102 | G23: Travel Expense-Domestic | H23: Parenbang hotel [1N2D]_Aoki | I23: =_xlfn.IFNA(VLOOKUP(E23,Master!$J:$M,4,0),"") -> ADM | J23: =_xlfn.IFNA(VLOOKUP($E23,Master!$J:$M,3,0),"") -> SGA | T23: 900000 | Y23: 900000 | AC23: =SUM(K23:P23) -> 0 | AD23: =SUM(Q23:AB23) -> 1800000 | AE23: 900000 | AF23: 900000 | AG23: A
A24: BEX | B24: =_xlfn.IFNA(VLOOKUP(C24,Master!$J:$K,2,0),"") -> B1000 | C24: Top Management | D24: =_xlfn.IFNA(VLOOKUP(E24,Master!$J:$K,2,0),"") -> B1000 | E24: Top Management | F24: =_xlfn.IFNA(VLOOKUP(G24,Master!B:C,2,0),"") -> 7651102 | G24: Travel Expense-Domestic | H24: Parenbang daily fee [1N2D]_Aoki | I24: =_xlfn.IFNA(VLOOKUP(E24,Master!$J:$M,4,0),"") -> ADM | J24: =_xlfn.IFNA(VLOOKUP($E24,Master!$J:$M,3,0),"") -> SGA | T24: 700000 | Y24: 700000 | AC24: =SUM(K24:P24) -> 0 | AD24: =SUM(Q24:AB24) -> 1400000 | AE24: 700000 | AF24: 700000 | AG24: A
A25: BEX | B25: =_xlfn.IFNA(VLOOKUP(C25,Master!$J:$K,2,0),"") -> B1000 | C25: Top Management | D25: =_xlfn.IFNA(VLOOKUP(E25,Master!$J:$K,2,0),"") -> B1000 | E25: Top Management | F25: =_xlfn.IFNA(VLOOKUP(G25,Master!B:C,2,0),"") -> 7651102 | G25: Travel Expense-Domestic | H25: Karimantan fright [1N2D]_Aoki | I25: =_xlfn.IFNA(VLOOKUP(E25,Master!$J:$M,4,0),"") -> ADM | J25: =_xlfn.IFNA(VLOOKUP($E25,Master!$J:$M,3,0),"") -> SGA | U25: 1092000 | AA25: 1092000 | AC25: =SUM(K25:P25) -> 0 | AD25: =SUM(Q25:AB25) -> 2184000 | AE25: 1092000 | AF25: 1092000 | AG25: A
A26: BEX | B26: =_xlfn.IFNA(VLOOKUP(C26,Master!$J:$K,2,0),"") -> B1000 | C26: Top Management | D26: =_xlfn.IFNA(VLOOKUP(E26,Master!$J:$K,2,0),"") -> B1000 | E26: Top Management | F26: =_xlfn.IFNA(VLOOKUP(G26,Master!B:C,2,0),"") -> 7651102 | G26: Travel Expense-Domestic | H26: Karimantan hotel [1N2D]_Aoki | I26: =_xlfn.IFNA(VLOOKUP(E26,Master!$J:$M,4,0),"") -> ADM | J26: =_xlfn.IFNA(VLOOKUP($E26,Master!$J:$M,3,0),"") -> SGA | U26: 900000 | AA26: 900000 | AC26: =SUM(K26:P26) -> 0 | AD26: =SUM(Q26:AB26) -> 1800000 | AE26: 900000 | AF26: 900000 | AG26: A
A27: BEX | B27: =_xlfn.IFNA(VLOOKUP(C27,Master!$J:$K,2,0),"") -> B1000 | C27: Top Management | D27: =_xlfn.IFNA(VLOOKUP(E27,Master!$J:$K,2,0),"") -> B1000 | E27: Top Management | F27: =_xlfn.IFNA(VLOOKUP(G27,Master!B:C,2,0),"") -> 7651102 | G27: Travel Expense-Domestic | H27: Karimantan daily fee [1N2D]_Aoki | I27: =_xlfn.IFNA(VLOOKUP(E27,Master!$J:$M,4,0),"") -> ADM | J27: =_xlfn.IFNA(VLOOKUP($E27,Master!$J:$M,3,0),"") -> SGA | U27: 700000 | AA27: 700000 | AC27: =SUM(K27:P27) -> 0 | AD27: =SUM(Q27:AB27) -> 1400000 | AE27: 700000 | AF27: 700000 | AG27: A
A28: BEX | B28: =_xlfn.IFNA(VLOOKUP(C28,Master!$J:$K,2,0),"") -> B1000 | C28: Top Management | D28: =_xlfn.IFNA(VLOOKUP(E28,Master!$J:$K,2,0),"") -> B1000 | E28: Top Management | F28: =_xlfn.IFNA(VLOOKUP(G28,Master!B:C,2,0),"") -> 7651102 | G28: Travel Expense-Domestic | H28: Bundun hotel [1N2D]_Aoki | I28: =_xlfn.IFNA(VLOOKUP(E28,Master!$J:$M,4,0),"") -> ADM | J28: =_xlfn.IFNA(VLOOKUP($E28,Master!$J:$M,3,0),"") -> SGA | V28: 900000 | AB28: 900000 | AC28: =SUM(K28:P28) -> 0 | AD28: =SUM(Q28:AB28) -> 1800000 | AE28: 900000 | AF28: 900000 | AG28: A
A29: BEX | B29: =_xlfn.IFNA(VLOOKUP(C29,Master!$J:$K,2,0),"") -> B1000 | C29: Top Management | D29: =_xlfn.IFNA(VLOOKUP(E29,Master!$J:$K,2,0),"") -> B1000 | E29: Top Management | F29: =_xlfn.IFNA(VLOOKUP(G29,Master!B:C,2,0),"") -> 7651102 | G29: Travel Expense-Domestic | H29: Bundun daily fee [1N2D]_Aoki | I29: =_xlfn.IFNA(VLOOKUP(E29,Master!$J:$M,4,0),"") -> ADM | J29: =_xlfn.IFNA(VLOOKUP($E29,Master!$J:$M,3,0),"") -> SGA | V29: =300000*2+50000*2 -> 700000 | AB29: =300000*2+50000*2 -> 700000 | AC29: =SUM(K29:P29) -> 0 | AD29: =SUM(Q29:AB29) -> 1400000 | AE29: 700000 | AF29: 700000 | AG29: A
A30: BEX | B30: =_xlfn.IFNA(VLOOKUP(C30,Master!$J:$K,2,0),"") -> B1000 | C30: Top Management | D30: =_xlfn.IFNA(VLOOKUP(E30,Master!$J:$K,2,0),"") -> B1000 | E30: Top Management | F30: =_xlfn.IFNA(VLOOKUP(G30,Master!B:C,2,0),"") -> 7651101 | G30: Transportation Fee for employee | H30: Toll&Parking_Aoki | I30: =_xlfn.IFNA(VLOOKUP(E30,Master!$J:$M,4,0),"") -> ADM | J30: =_xlfn.IFNA(VLOOKUP($E30,Master!$J:$M,3,0),"") -> SGA | K30: 2000000 | L30: 2000000 | M30: 2000000 | N30: 2000000 | O30: 2000000 | P30: 2000000 | Q30: 2000000 | R30: 2000000 | S30: 2000000 | T30: 2000000 | U30: 2000000 | V30: 2000000 | W30: 2000000 | X30: 2000000 | Y30: 2000000 | Z30: 2000000 | AA30: 2000000 | AB30: 2000000 | AC30: =SUM(K30:P30) -> 12000000 | AD30: =SUM(Q30:AB30) -> 24000000 | AE30: 24000000 | AF30: 24000000 | AG30: A
A31: BEX | B31: =_xlfn.IFNA(VLOOKUP(C31,Master!$J:$K,2,0),"") -> B1000 | C31: Top Management | D31: =_xlfn.IFNA(VLOOKUP(E31,Master!$J:$K,2,0),"") -> B1000 | E31: Top Management | F31: =_xlfn.IFNA(VLOOKUP(G31,Master!B:C,2,0),"") -> 7651101 | G31: Transportation Fee for employee | H31: Gasoline_Aoki | I31: =_xlfn.IFNA(VLOOKUP(E31,Master!$J:$M,4,0),"") -> ADM | J31: =_xlfn.IFNA(VLOOKUP($E31,Master!$J:$M,3,0),"") -> SGA | K31: 2000000 | L31: 2000000 | M31: 2000000 | N31: 2000000 | O31: 2000000 | P31: 2000000 | Q31: 2000000 | R31: 2000000 | S31: 2000000 | T31: 2000000 | U31: 2000000 | V31: 2000000 | W31: 2000000 | X31: 2000000 | Y31: 2000000 | Z31: 2000000 | AA31: 2000000 | AB31: 2000000 | AC31: =SUM(K31:P31) -> 12000000 | AD31: =SUM(Q31:AB31) -> 24000000 | AE31: 24000000 | AF31: 24000000 | AG31: A
A32: BEX | B32: =_xlfn.IFNA(VLOOKUP(C32,Master!$J:$K,2,0),"") -> B1000 | C32: Top Management | D32: =_xlfn.IFNA(VLOOKUP(E32,Master!$J:$K,2,0),"") -> B1000 | E32: Top Management | F32: =_xlfn.IFNA(VLOOKUP(G32,Master!B:C,2,0),"") -> 7781103 | G32: Publishing Expense | H32: NNA Daily for BOD | I32: =_xlfn.IFNA(VLOOKUP(E32,Master!$J:$M,4,0),"") -> ADM | J32: =_xlfn.IFNA(VLOOKUP($E32,Master!$J:$M,3,0),"") -> SGA | K32: 2160000 | L32: 2160000 | M32: 2160000 | N32: 2160000 | O32: 2160000 | P32: 2160000 | Q32: 2160000 | R32: 2160000 | S32: 2160000 | T32: 2160000 | U32: 2160000 | V32: 2160000 | W32: 2160000 | X32: 2160000 | Y32: 2160000 | Z32: 2160000 | AA32: 2160000 | AB32: 2160000 | AC32: =SUM(K32:P32) -> 12960000 | AD32: =SUM(Q32:AB32) -> 25920000 | AE32: 25920000 | AF32: 25920000 | AG32: A
A33: BEX | B33: =_xlfn.IFNA(VLOOKUP(C33,Master!$J:$K,2,0),"") -> B1000 | C33: Top Management | D33: =_xlfn.IFNA(VLOOKUP(E33,Master!$J:$K,2,0),"") -> B1000 | E33: Top Management | F33: =_xlfn.IFNA(VLOOKUP(G33,Master!B:C,2,0),"") -> 7781103 | G33: Publishing Expense | H33: The Daily Jakarta Shimbun | I33: =_xlfn.IFNA(VLOOKUP(E33,Master!$J:$M,4,0),"") -> ADM | J33: =_xlfn.IFNA(VLOOKUP($E33,Master!$J:$M,3,0),"") -> SGA | K33: 300000 | L33: 300000 | M33: 300000 | N33: 300000 | O33: 300000 | P33: 300000 | Q33: 300000 | R33: 300000 | S33: 300000 | T33: 300000 | U33: 300000 | V33: 300000 | W33: 300000 | X33: 300000 | Y33: 300000 | Z33: 300000 | AA33: 300000 | AB33: 300000 | AC33: =SUM(K33:P33) -> 1800000 | AD33: =SUM(Q33:AB33) -> 3600000 | AE33: 3600000 | AF33: 3600000 | AG33: A
A34: BEX | B34: =_xlfn.IFNA(VLOOKUP(C34,Master!$J:$K,2,0),"") -> B1000 | C34: Top Management | D34: =_xlfn.IFNA(VLOOKUP(E34,Master!$J:$K,2,0),"") -> B1000 | E34: Top Management | F34: =_xlfn.IFNA(VLOOKUP(G34,Master!B:C,2,0),"") -> 7781103 | G34: Publishing Expense | H34: Annual corporate member fee JJC | I34: =_xlfn.IFNA(VLOOKUP(E34,Master!$J:$M,4,0),"") -> ADM | J34: =_xlfn.IFNA(VLOOKUP($E34,Master!$J:$M,3,0),"") -> SGA | K34: 4000000 | L34: 4000000 | M34: 4000000 | N34: 4000000 | O34: 4000000 | P34: 4000000 | Q34: 4000000 | R34: 4000000 | S34: 4000000 | T34: 4000000 | U34: 4000000 | V34: 4000000 | W34: 4000000 | X34: 4000000 | Y34: 4000000 | Z34: 4000000 | AA34: 4000000 | AB34: 4000000 | AC34: =SUM(K34:P34) -> 24000000 | AD34: =SUM(Q34:AB34) -> 48000000 | AE34: 48000000 | AF34: 48000000 | AG34: A
A35: BEX | B35: =_xlfn.IFNA(VLOOKUP(C35,Master!$J:$K,2,0),"") -> B1000 | C35: Top Management | D35: =_xlfn.IFNA(VLOOKUP(E35,Master!$J:$K,2,0),"") -> B1000 | E35: Top Management | F35: =_xlfn.IFNA(VLOOKUP(G35,Master!B:C,2,0),"") -> 7781103 | G35: Publishing Expense | H35: Annual fee for The Japanese School | I35: =_xlfn.IFNA(VLOOKUP(E35,Master!$J:$M,4,0),"") -> ADM | J35: =_xlfn.IFNA(VLOOKUP($E35,Master!$J:$M,3,0),"") -> SGA | K35: 330000 | L35: 330000 | M35: 330000 | N35: 330000 | O35: 330000 | P35: 330000 | Q35: 330000 | R35: 330000 | S35: 330000 | T35: 330000 | U35: 330000 | V35: 330000 | W35: 330000 | X35: 330000 | Y35: 330000 | Z35: 330000 | AA35: 330000 | AB35: 330000 | AC35: =SUM(K35:P35) -> 1980000 | AD35: =SUM(Q35:AB35) -> 3960000 | AE35: 3960000 | AF35: 3960000 | AG35: A
A36: BEX | B36: =_xlfn.IFNA(VLOOKUP(C36,Master!$J:$K,2,0),"") -> B1000 | C36: Top Management | D36: =_xlfn.IFNA(VLOOKUP(E36,Master!$J:$K,2,0),"") -> B1000 | E36: Top Management | F36: =_xlfn.IFNA(VLOOKUP(G36,Master!B:C,2,0),"") -> 7781103 | G36: Publishing Expense | H36: Membership Bogor Raya Golf_Aoki | I36: =_xlfn.IFNA(VLOOKUP(E36,Master!$J:$M,4,0),"") -> ADM | J36: =_xlfn.IFNA(VLOOKUP($E36,Master!$J:$M,3,0),"") -> SGA | K36: 2100000 | L36: 2100000 | M36: 2100000 | N36: 2100000 | O36: 2100000 | P36: 2100000 | Q36: 2100000 | R36: 2100000 | S36: 2100000 | T36: 2100000 | U36: 2100000 | V36: 2100000 | W36: 2100000 | X36: 2100000 | Y36: 2100000 | Z36: 2100000 | AA36: 2100000 | AB36: 2100000 | AC36: =SUM(K36:P36) -> 12600000 | AD36: =SUM(Q36:AB36) -> 25200000 | AE36: 25200000 | AF36: 25200000 | AG36: A
A37: BEX | B37: =_xlfn.IFNA(VLOOKUP(C37,Master!$J:$K,2,0),"") -> B1000 | C37: Top Management | D37: =_xlfn.IFNA(VLOOKUP(E37,Master!$J:$K,2,0),"") -> B1000 | E37: Top Management | F37: =_xlfn.IFNA(VLOOKUP(G37,Master!B:C,2,0),"") -> 7781103 | G37: Publishing Expense | H37: ADM supplier club 2022 | I37: =_xlfn.IFNA(VLOOKUP(E37,Master!$J:$M,4,0),"") -> ADM | J37: =_xlfn.IFNA(VLOOKUP($E37,Master!$J:$M,3,0),"") -> SGA | Q37: 1500000 | AC37: =SUM(K37:P37) -> 0 | AD37: =SUM(Q37:AB37) -> 1500000 | AE37: 1500000 | AF37: 1500000 | AG37: A
A38: BEX | B38: =_xlfn.IFNA(VLOOKUP(C38,Master!$J:$K,2,0),"") -> B1000 | C38: Top Management | D38: =_xlfn.IFNA(VLOOKUP(E38,Master!$J:$K,2,0),"") -> B1000 | E38: Top Management | F38: =_xlfn.IFNA(VLOOKUP(G38,Master!B:C,2,0),"") -> 7781112 | G38: Expatriate expenses exclude labor cost | H38: KITAS renewal exppense_Aoki | I38: =_xlfn.IFNA(VLOOKUP(E38,Master!$J:$M,4,0),"") -> ADM | J38: =_xlfn.IFNA(VLOOKUP($E38,Master!$J:$M,3,0),"") -> SGA | AB38: =9400000*3 -> 28200000 | AC38: =SUM(K38:P38) -> 0 | AD38: =SUM(Q38:AB38) -> 28200000 | AE38: 28200000 | AF38: 28200000 | AG38: A
A39: BEX | B39: =_xlfn.IFNA(VLOOKUP(C39,Master!$J:$K,2,0),"") -> B1000 | C39: Top Management | D39: =_xlfn.IFNA(VLOOKUP(E39,Master!$J:$K,2,0),"") -> B1000 | E39: Top Management | F39: =_xlfn.IFNA(VLOOKUP(G39,Master!B:C,2,0),"") -> 7781112 | G39: Expatriate expenses exclude labor cost | H39: DPKK_Aoki | I39: =_xlfn.IFNA(VLOOKUP(E39,Master!$J:$M,4,0),"") -> ADM | J39: =_xlfn.IFNA(VLOOKUP($E39,Master!$J:$M,3,0),"") -> SGA | K39: 1417720 | L39: 1417720 | M39: 1417720 | N39: 1417720 | O39: 1417720 | P39: 1417720 | Q39: 1417720 | R39: 1417720 | S39: 1417720 | T39: 1417720 | U39: 1417720 | V39: 1417720 | W39: 1417720 | X39: 1417720 | Y39: 1417720 | Z39: 1417720 | AA39: 1417720 | AB39: 1417720 | AC39: =SUM(K39:P39) -> 8506320 | AD39: =SUM(Q39:AB39) -> 17012640 | AE39: 17012640 | AF39: 17012640 | AG39: A
A40: BEX | B40: =_xlfn.IFNA(VLOOKUP(C40,Master!$J:$K,2,0),"") -> B1000 | C40: Top Management | D40: =_xlfn.IFNA(VLOOKUP(E40,Master!$J:$K,2,0),"") -> B1000 | E40: Top Management | F40: =_xlfn.IFNA(VLOOKUP(G40,Master!B:C,2,0),"") -> 7781103 | G40: Publishing Expense | H40: Cooperate card annual fee_BNI_Aoki | I40: =_xlfn.IFNA(VLOOKUP(E40,Master!$J:$M,4,0),"") -> ADM | J40: =_xlfn.IFNA(VLOOKUP($E40,Master!$J:$M,3,0),"") -> SGA | Q40: 600000 | AC40: =SUM(K40:P40) -> 0 | AD40: =SUM(Q40:AB40) -> 600000 | AE40: 600000 | AF40: 600000 | AG40: A
...

Sheet Master
A1: COA AX | B1: Name COA AX | C1: COA AX | D1: COA AX | E1: Group Cost | F1: UNIQ | G1: COA Budget | H1: Description | J1: Name | K1: BNGK | L1: GROUP COST | M1: GROUP SECTION | N1: Name | P1: Code | Q1: Name | S1: Priority Code | T1: Priority Name | U1: Description
A2: 7511101 | B2: Salary for Commissioner | C2: 7511101 | D2: 7511101 | E2: SGA | F2: SGA-7511101 | G2: A502 | H2: Salary for Commissioner | J2: Top Management | K2: B1000 | L2: SGA | M2: ADM | N2: Top Management | P2: 53450 | Q2: NGK BUSI INDONESIA | S2: A | T2: Must | U2: If this is not done, the company or our team cannot continue its business.
A3: 7511102 | B3: Salary for Director | C3: 7511102 | D3: 7511102 | E3: SGA | F3: SGA-7511102 | G3: A502 | H3: Salary for Director & Expat | J3: Commissioner | K3: B1001 | L3: SGA | M3: ADM | N3: Commissioner | S3: B | T3: Want to | U3: We want to do it as a team this term. we need it.
A4: 7511103 | B4: Staff Labor - Baslc Salary | C4: 7511103 | D4: 7511103 | E4: SGA | F4: SGA-7511103 | G4: A501 | H4: Basic Salary of permanent employee | J4: Admin & HR | K4: B2200 | L4: SGA | M4: ADM | N4: Admin & HR | S4: C | T4: Challenge | U4: We want to do it for this term or the future. But it doesn't matter if it's not this term.
A5: 7511111 | B5: Staff Labor - Allowance | C5: 7511111 | D5: 7511111 | E5: SGA | F5: SGA-7511111 | G5: A501 | H5: Employee allowance | J5: General Affair | K5: B2210 | L5: SGA | M5: ADM | N5: General Affair
A6: 7511112 | B6: Staff Labor - Tax allowance (art.21) | C6: 7511112 | D6: 7511112 | E6: SGA | F6: SGA-7511112 | G6: A501 | H6: Empployee Tax allowance | J6: Human Resource | K6: B2220 | L6: SGA | M6: ADM | N6: Human Resource | P6: BEX
A7: 7511121 | B7: Staff Labor - BPJS JK & JKK (1.19%) | C7: 7511121 | D7: 7511121 | E7: SGA | F7: SGA-7511121 | G7: A501 | H7: BPJS JK & JKK (death warrant, Accident Insurance) | J7: Health, Safety & Environment | K7: B2230 | L7: SGA | M7: ADM | N7: Health, Safety & Environment | P7: BEL
A8: 7511122 | B8: Staff Labor - BPJS Kesehatan (4%) | C8: 7511122 | D8: 7511122 | E8: SGA | F8: SGA-7511122 | G8: A501 | H8: BPJS health insurance | J8: Accounting & Finance | K8: B2300 | L8: SGA | M8: ADM | N8: Accounting & Finance
A9: 7511201 | B9: Staff Overtime | C9: 7511201 | D9: 7511201 | E9: SGA | F9: SGA-7511201 | G9: A503 | H9: Overtime permanent employee | J9: Information Technology | K9: B2400 | L9: SGA | M9: ADM | N9: Information Technology
A10: 7512111 | B10: Staff Welfare - BPJS Dana pensiun (2%) | C10: 7512111 | D10: 7512111 | E10: SGA | F10: SGA-7512111 | G10: A504 | H10: BPJS pension fund | J10: Sales & MKTG Dept.- Automotive | K10: B3100 | L10: SGA | M10: ADM | N10: Sales & MKTG Dept.- Automotive
A11: 7512112 | B11: Staff Welfare - BPJS JHT (3.7%) | C11: 7512112 | D11: 7512112 | E11: SGA | F11: SGA-7512112 | G11: A504 | H11: BPJS Pension plan | J11: Marketing | K11: B3160 | L11: SGA | M11: ADM | N11: Marketing
A12: 7514101 | B12: Staff Bonus / TAT | C12: 7514101 | D12: 7514101 | E12: SGA | F12: SGA-7514101 | G12: A501 | H12: Year-end allowance & Alpha | J12: Sales - OEM | K12: B3110 | L12: SGA | M12: ADM | N12: Sales - OEM
A13: 7514102 | B13: Staff Ramadhan / THR | C13: 7514102 | D13: 7514102 | E13: SGA | F13: SGA-7514102 | G13: A501 | H13: Lebaran bonus | J13: Sales - OES | K13: B3120 | L13: SGA | M13: ADM | N13: Sales - OES
A14: 7515401 | B14: Staff Welfare - Outpatient (Medical) | C14: 7515401 | D14: 7515401 | E14: SGA | F14: SGA-7515401 | G14: A504 | H14: outpatient treatment costs | J14: Sales - IAM | K14: B3130 | L14: SGA | M14: ADM | N14: Sales - IAM
A15: 7515402 | B15: Staff Welfare - Hospitalization | C15: 7515402 | D15: 7515402 | E15: SGA | F15: SGA-7515402 | G15: A504 | H15: hospitalization costs | J15: SP PD- CF | K15: B4101 | L15: MFG | M15: DIR | N15: SP PD- CF
A16: 7515403 | B16: Staff Welfare - Glasses | C16: 7515403 | D16: 7515403 | E16: SGA | F16: SGA-7515403 | G16: A504 | H16: glasses costs | J16: SP PD- CM | K16: B4102 | L16: MFG | M16: DIR | N16: SP PD- CM
A17: 7515404 | B17: Staff Welfare - Dental | C17: 7515404 | D17: 7515404 | E17: SGA | F17: SGA-7515404 | G17: A504 | H17: dental costs | J17: SP PD- WT | K17: B4103 | L17: MFG | M17: DIR | N17: SP PD- WT
A18: 7515405 | B18: Staff Welfare - Medical Check Up | C18: 7515405 | D18: 7515405 | E18: SGA | F18: SGA-7515405 | G18: A504 | H18: Medical Check Up cost | J18: SP PD- Plating | K18: B4105 | L18: MFG | M18: DIR | N18: SP PD- Plating
A19: 7515406 | B19: Staff Welfare - Uniform | C19: 7515406 | D19: 7515406 | E19: SGA | F19: SGA-7515406 | G19: A504 | H19: uniform costs | J19: SP PD- MS Insp. | K19: B4109 | L19: MFG | M19: DIR | N19: SP PD- MS Insp.
A20: 7515407 | B20: Staff Welfare - Safety Shoes | C20: 7515407 | D20: 7515407 | E20: SGA | F20: SGA-7515407 | G20: A504 | J20: SP PD- Insulator Sealing | K20: B4106 | L20: MFG | M20: DIR | N20: SP PD- Insulator Sealing
A21: 7515408 | B21: Staff Welfare - Family Gathering / Anniversary | C21: 7515408 | D21: 7515408 | E21: SGA | F21: SGA-7515408 | G21: A504 | H21: Family Gathering / Anniversary | J21: SP PD- Assy | K21: B4110 | L21: MFG | M21: DIR | N21: SP PD- Assy
A22: 7515409 | B22: Staff Welfare - Meals of canteen & other meals | C22: 7515409 | D22: 7515409 | E22: SGA | F22: SGA-7515409 | G22: A504 | H22: Meals of canteen & other meals cost | J22: SP-PD-Assy-Auto Assembly | K22: B4115 | L22: MFG | M22: DIR | N22: SP-PD-Assy-Auto Assembly
A23: 7515410 | B23: Staff Welfare - Kaizen & QCC reward | C23: 7515410 | D23: 7515410 | E23: SGA | F23: SGA-7515410 | G23: A504 | H23: an expense, arising from Kaizen and QCC acitivity | J23: SP PD- Bending | K23: B4114 | L23: MFG | M23: DIR | N23: SP PD- Bending
A24: 7515499 | B24: Staff Welfare - Welfare Others | C24: 7515499 | D24: 7515499 | E24: SGA | F24: SGA-7515499 | G24: A504 | H24: an other welfare expense, arising besides the above welfare expense | J24: SP PD- Final Inspection | K24: B4120 | L24: MFG | M24: DIR | N24: SP PD- Final Inspection
A25: 7516102 | B25: Retirement Allowance | C25: 7516102 | D25: 7516102 | E25: SGA | F25: SGA-7516102 | G25: A505 | H25: employee retirement provission costs | J25: SP PD- QC - OEM | K25: B4121 | L25: MFG | M25: DIR | N25: SP PD- QC - OEM
A26: 7519101 | B26: House Rent Allowance | C26: 7519101 | D26: 7519101 | E26: SGA | F26: SGA-7519101 | G26: A502 | H26: House Rent Allowance for expat | J26: PC PD- Injection | K26: B4410 | L26: MFG | M26: DIR | N26: PC PD- Injection
A27: 7521101 | B27: Casual Staff Labor - Basic Salary | C27: 7521101 | D27: 7521101 | E27: SGA | F27: SGA-7521101 | G27: A501 | H27: All benefit for temporary worker | J27: PC PD- Assy | K27: B4430 | L27: MFG | M27: DIR | N27: PC PD- Assy
A28: 7521102 | B28: Casual Staff Labor - Overtime | C28: 7521102 | D28: 7521102 | E28: SGA | F28: SGA-7521102 | G28: A503 | H28: Overtime temporary worker | J28: PC PD- QC | K28: B4440 | L28: MFG | M28: DIR | N28: PC PD- QC
A29: 7571101 | B29: Personnel expense transferred | C29: 7571101 | D29: 7571101 | E29: SGA | F29: SGA-7571101 | G29: A506 | H29: Transfer Labor cost from one section into another section | J29: Plant Operation (Indirect Mfg) | K29: B5000 | L29: MFG | M29: IND | N29: Plant Operation (Indirect Mfg)
A30: 7611100 | B30: Depreciation-Building | C30: 7611100 | D30: 7611100 | E30: SGA | F30: SGA-7611100 | G30: A601 | H30: the amount of depreciation of tangible assets for building | J30: Production Office | K30: B5100 | L30: MFG | M30: IND | N30: Production Office
A31: 7611300 | B31: Depreciation-Machiney & equipment | C31: 7611300 | D31: 7611300 | E31: SGA | F31: SGA-7611300 | G31: A601 | H31: the amount of depreciation of tangible assets for machinery & factory equipment | J31: Production Office (SP) | K31: B5101 | L31: MFG | M31: IND | N31: Production Office (SP)
A32: 7611400 | B32: Depreciation-Lease Machinery & equipment | C32: 7611400 | D32: 7611400 | E32: SGA | F32: SGA-7611400 | G32: A601 | H32: the amount of depreciation of tangible assets for machinery & factory equipment (Leases) | J32: Production Office (PC) | K32: B5104 | L32: MFG | M32: IND | N32: Production Office (PC)
... A41: 7641101 | B41: Repair Building | C41: 7641101 | D41: 7641101 | E41: SGA | F41: SGA-7641101 | G41: A1002 | H41: expenses for repair and maintenance asset building | J41: Continuous Improvement | K41: B5007 | L41: MFG | M41: IND | N41: Continuous Improvement
A42: 7641102 | B42: Repair of Equipment | C42: 7641102 | D42: 7641102 | E42: SGA | F42: SGA-7641102 | G42: A1002 | H42: expenses for repair and maintenance tangible assets, intangible assets and other assets beside building | J42: All | K42: B0000 | N42: All
A43: 7641103 | B43: Factory Supply Expense | C43: 7641103 | D43: 7641103 | E43: SGA | F43: SGA-7641103 | G43: A1099 | H43: All cost that arrising to support factory acitivity
A44: 7641104 | B44: Calibration Cost | C44: 7641104 | D44: 7641104 | E44: SGA | F44: SGA-7641104 | G44: A1099 | H44: Cost of calibration for tools and equipment of factory and others
A45: 7651101 | B45: Transportation Fee for employee | C45: 7651101 | D45: 7651101 | E45: SGA | F45: SGA-7651101 | G45: A801 | H45: Gasoline of company cars & expense for Local transportation
A46: 7651102 | B46: Travel Expense-Domestic | C46: 7651102 | D46: 7651102 | E46: SGA | F46: SGA-7651102 | G46: A801 | H46: expenses for business trip, including allowance for business trip to an employee only for domestic travel
A47: 7651103 | B47: Travel Expense-Oversea | C47: 7651103 | D47: 7651103 | E47: SGA | F47: SGA-7651103 | G47: A801 | H47: expenses for business trip, including allowance for business trip to an employee only for overseas travel
A48: 7661101 | B48: Entertainment | C48: 7661101 | D48: 7661101 | E48: SGA | F48: SGA-7661101 | G48: A1001 | H48: the amount of expenses for the act of entertaining the business partner
...
