Workbook
Name _j102: #REF!
Name aa: #REF!
Name AB: #REF!
Name ai: #REF!
Name as: #REF!
Name assit: #REF!
Name b: #REF!
Name BC: #REF!
Name BI: #REF!
Name BO: #REF!
Name cc: #REF!
Name CH: #REF!
Name CI: #REF!
Name Ck_for: #REF!
Name Ck_in: #REF!
Name Ck_out: #REF!
Name d: #REF!
Name dd: #REF!
Name DF: #REF!
Name e: #REF!
Name ee: #REF!
Name eXCRATE: #REF!
Name exrate: #REF!
Name F: #REF!
Name fcb: #REF!
Name FG: #REF!
Name g: #REF!
Name gg: #REF!
Name HF: #REF!
Name kissa: #REF!
Name kissakei: #REF!
Name kk: #REF!
Name kkk: #REF!
Name kkkk: #REF!
Name l: #REF!
Name L_01: #REF!
Name LIA: #REF!
Name LILI: #REF!
Name LINA: #REF!
Name m: #REF!
Name Manufacturing: #REF!
Name MR: #REF!
Name nittk: #REF!
Name nittk_ok: #REF!
Name nittoukei: #REF!
Name Print_Area_MI: #REF!
Name ry: #REF!
Name ryohikei: #REF!
Name S: #REF!
Name sais: #REF!
Name saisyuu: #REF!
Name se: #REF!
Name sett: #REF!
Name setta: #REF!
Name settaihikei: #REF!
Name settaikousai: #REF!
Name SEX: #REF!
Name shu: #REF!
Name shukuhakukei: #REF!
Name so: #REF!

Sheet Data
A1: Budget Type | B1: Section From (Code) | C1: Section From (Name) | D1: To Section (Code) | E1: To Section (Name) | F1: Coa ID | G1: Coa Name | H1: Asset Name | I1: Group Section | J1: Group Cost | K1: Acquisition Value | L1: Useful Life | M1: Allocation % | N1: Depre Start | O1: Priority Code | P1: Budget_Period | Q1: Budget Allocation
A2: BIP | B2: B2400 | C2: Information Technology | D2: B2400 | E2: Information Technology | F2: 2141000 | G2: Tools, furniture & office equipment | H2: 2 Unit AC Cassette Panasonic / Daikin for Server Room | I2: SGA | J2: ADM | K2: 90000000 | L2: 60 | M2: 1 | N2: 45658 | O2: A | P2: FY125 | Q2: 90000000 | R2: BIP26-2400-2400-001
A3: BIP | B3: B2400 | C3: Information Technology | D3: B2400 | E3: Information Technology | F3: 2141000 | G3: Tools, furniture & office equipment | H3: Additional Storage for NGK Busi Server - 10 TB | I3: SGA | J3: ADM | K3: 90000000 | L3: 60 | M3: 1 | N3: 45809 | O3: B | P3: FY126 | Q3: 90000000 | R3: BIP26-2400-2400-002
A4: BIP | B4: B2400 | C4: Information Technology | D4: B2400 | E4: Information Technology | F4: 2141000 | G4: Tools, furniture & office equipment | H4: Fortianalyzer Log Collector (Request by GHQ) Implementation | I4: SGA | J4: ADM | K4: 210000000 | L4: 60 | M4: 1 | N4: 45658 | O4: A | P4: FY125 | Q4: 250000000 | R4: BIP26-2400-2400-003
A5: BIP | B5: B2400 | C5: Information Technology | D5: B2400 | E5: Information Technology | F5: 2141000 | G5: Tools, furniture & office equipment | H5: Managed Switch VLAN 16 Port Switch ( AT-GS950/16) | I5: SGA | J5: ADM | K5: 48000000 | L5: 60 | M5: 1 | N5: 45809 | O5: B | P5: FY126 | Q5: 48000000 | R5: BIP26-2400-2400-004
A6: BIP | B6: B2400 | C6: Information Technology | D6: B2400 | E6: Information Technology | F6: 2141000 | G6: Tools, furniture & office equipment | H6: Notebook Replacement IT | I6: SGA | J6: ADM | K6: 15000000 | L6: 60 | M6: 1 | N6: 45748 | O6: B | P6: FY126 | Q6: 15000000 | R6: BIP26-2400-2400-005
A7: BIP | B7: B2400 | C7: Information Technology | D7: B2400 | E7: Information Technology | F7: 2221101 | G7: Software | H7: Project of Replacement Firewall Machine - Fortigate 601F | I7: SGA | J7: ADM | K7: 400000000 | L7: 60 | M7: 1 | N7: 45627 | O7: A | P7: FY125 | Q7: 400000000 | R7: BIP26-2400-2400-006
B8: =_xlfn.IFNA(VLOOKUP(C8,Master_Section!$H:$I,2,FALSE),"") | D8: =_xlfn.IFNA(VLOOKUP(E8,Master_Section!$H:$I,2,FALSE),"") | F8: =_xlfn.IFNA(VLOOKUP(G8,Master!AE:AF,2,FALSE),"") | I8: =_xlfn.IFNA(VLOOKUP(D8,Master_Section!$I:$K,2,FALSE),"") | J8: =_xlfn.IFNA(VLOOKUP(D8,Master_Section!$I:$K,3,FALSE),"") | L8: =IF(A8<>"CFA",_xlfn.IFNA(VLOOKUP($G8,Master!$AE:$AI,5,0),""),"") | P8: =IF(N8<>"",IF(MONTH(N8)>=4,"FY1"&RIGHT(YEAR(N8)+1,2),"FY1"&RIGHT(YEAR(N8),2)),"") | Q8: =IF(K8>0&M8>0,K8*M8,"")
B9: =_xlfn.IFNA(VLOOKUP(C9,Master_Section!$H:$I,2,FALSE),"") | D9: =_xlfn.IFNA(VLOOKUP(E9,Master_Section!$H:$I,2,FALSE),"") | F9: =_xlfn.IFNA(VLOOKUP(G9,Master!AE:AF,2,FALSE),"") | I9: =_xlfn.IFNA(VLOOKUP(D9,Master_Section!$I:$K,2,FALSE),"") | J9: =_xlfn.IFNA(VLOOKUP(D9,Master_Section!$I:$K,3,FALSE),"") | L9: =IF(A9<>"CFA",_xlfn.IFNA(VLOOKUP($G9,Master!$AE:$AI,5,0),""),"") | P9: =IF(N9<>"",IF(MONTH(N9)>=4,"FY1"&RIGHT(YEAR(N9)+1,2),"FY1"&RIGHT(YEAR(N9),2)),"") | Q9: =IF(K9>0&M9>0,K9*M9,"")
B10: =_xlfn.IFNA(VLOOKUP(C10,Master_Section!$H:$I,2,FALSE),"") | D10: =_xlfn.IFNA(VLOOKUP(E10,Master_Section!$H:$I,2,FALSE),"") | F10: =_xlfn.IFNA(VLOOKUP(G10,Master!AE:AF,2,FALSE),"") | I10: =_xlfn.IFNA(VLOOKUP(D10,Master_Section!$I:$K,2,FALSE),"") | J10: =_xlfn.IFNA(VLOOKUP(D10,Master_Section!$I:$K,3,FALSE),"") | L10: =IF(A10<>"CFA",_xlfn.IFNA(VLOOKUP($G10,Master!$AE:$AI,5,0),""),"") | P10: =IF(N10<>"",IF(MONTH(N10)>=4,"FY1"&RIGHT(YEAR(N10)+1,2),"FY1"&RIGHT(YEAR(N10),2)),"") | Q10: =IF(K10>0&M10>0,K10*M10,"")
B11: =_xlfn.IFNA(VLOOKUP(C11,Master_Section!$H:$I,2,FALSE),"") | D11: =_xlfn.IFNA(VLOOKUP(E11,Master_Section!$H:$I,2,FALSE),"") | F11: =_xlfn.IFNA(VLOOKUP(G11,Master!AE:AF,2,FALSE),"") | I11: =_xlfn.IFNA(VLOOKUP(D11,Master_Section!$I:$K,2,FALSE),"") | J11: =_xlfn.IFNA(VLOOKUP(D11,Master_Section!$I:$K,3,FALSE),"") | L11: =IF(A11<>"CFA",_xlfn.IFNA(VLOOKUP($G11,Master!$AE:$AI,5,0),""),"") | P11: =IF(N11<>"",IF(MONTH(N11)>=4,"FY1"&RIGHT(YEAR(N11)+1,2),"FY1"&RIGHT(YEAR(N11),2)),"") | Q11: =IF(K11>0&M11>0,K11*M11,"")
B12: =_xlfn.IFNA(VLOOKUP(C12,Master_Section!$H:$I,2,FALSE),"") | D12: =_xlfn.IFNA(VLOOKUP(E12,Master_Section!$H:$I,2,FALSE),"") | F12: =_xlfn.IFNA(VLOOKUP(G12,Master!AE:AF,2,FALSE),"") | I12: =_xlfn.IFNA(VLOOKUP(D12,Master_Section!$I:$K,2,FALSE),"") | J12: =_xlfn.IFNA(VLOOKUP(D12,Master_Section!$I:$K,3,FALSE),"") | L12: =IF(A12<>"CFA",_xlfn.IFNA(VLOOKUP($G12,Master!$AE:$AI,5,0),""),"") | P12: =IF(N12<>"",IF(MONTH(N12)>=4,"FY1"&RIGHT(YEAR(N12)+1,2),"FY1"&RIGHT(YEAR(N12),2)),"") | Q12: =IF(K12>0&M12>0,K12*M12,"")
B13: =_xlfn.IFNA(VLOOKUP(C13,Master_Section!$H:$I,2,FALSE),"") | D13: =_xlfn.IFNA(VLOOKUP(E13,Master_Section!$H:$I,2,FALSE),"") | F13: =_xlfn.IFNA(VLOOKUP(G13,Master!AE:AF,2,FALSE),"") | I13: =_xlfn.IFNA(VLOOKUP(D13,Master_Section!$I:$K,2,FALSE),"") | J13: =_xlfn.IFNA(VLOOKUP(D13,Master_Section!$I:$K,3,FALSE),"") | L13: =IF(A13<>"CFA",_xlfn.IFNA(VLOOKUP($G13,Master!$AE:$AI,5,0),""),"") | P13: =IF(N13<>"",IF(MONTH(N13)>=4,"FY1"&RIGHT(YEAR(N13)+1,2),"FY1"&RIGHT(YEAR(N13),2)),"") | Q13: =IF(K13>0&M13>0,K13*M13,"")
B14: =_xlfn.IFNA(VLOOKUP(C14,Master_Section!$H:$I,2,FALSE),"") | D14: =_xlfn.IFNA(VLOOKUP(E14,Master_Section!$H:$I,2,FALSE),"") | F14: =_xlfn.IFNA(VLOOKUP(G14,Master!AE:AF,2,FALSE),"") | I14: =_xlfn.IFNA(VLOOKUP(D14,Master_Section!$I:$K,2,FALSE),"") | J14: =_xlfn.IFNA(VLOOKUP(D14,Master_Section!$I:$K,3,FALSE),"") | L14: =IF(A14<>"CFA",_xlfn.IFNA(VLOOKUP($G14,Master!$AE:$AI,5,0),""),"") | P14: =IF(N14<>"",IF(MONTH(N14)>=4,"FY1"&RIGHT(YEAR(N14)+1,2),"FY1"&RIGHT(YEAR(N14),2)),"") | Q14: =IF(K14>0&M14>0,K14*M14,"")
B15: =_xlfn.IFNA(VLOOKUP(C15,Master_Section!$H:$I,2,FALSE),"") | D15: =_xlfn.IFNA(VLOOKUP(E15,Master_Section!$H:$I,2,FALSE),"") | F15: =_xlfn.IFNA(VLOOKUP(G15,Master!AE:AF,2,FALSE),"") | I15: =_xlfn.IFNA(VLOOKUP(D15,Master_Section!$I:$K,2,FALSE),"") | J15: =_xlfn.IFNA(VLOOKUP(D15,Master_Section!$I:$K,3,FALSE),"") | L15: =IF(A15<>"CFA",_xlfn.IFNA(VLOOKUP($G15,Master!$AE:$AI,5,0),""),"") | P15: =IF(N15<>"",IF(MONTH(N15)>=4,"FY1"&RIGHT(YEAR(N15)+1,2),"FY1"&RIGHT(YEAR(N15),2)),"") | Q15: =IF(K15>0&M15>0,K15*M15,"")
B16: =_xlfn.IFNA(VLOOKUP(C16,Master_Section!$H:$I,2,FALSE),"") | D16: =_xlfn.IFNA(VLOOKUP(E16,Master_Section!$H:$I,2,FALSE),"") | F16: =_xlfn.IFNA(VLOOKUP(G16,Master!AE:AF,2,FALSE),"") | I16: =_xlfn.IFNA(VLOOKUP(D16,Master_Section!$I:$K,2,FALSE),"") | J16: =_xlfn.IFNA(VLOOKUP(D16,Master_Section!$I:$K,3,FALSE),"") | L16: =IF(A16<>"CFA",_xlfn.IFNA(VLOOKUP($G16,Master!$AE:$AI,5,0),""),"") | P16: =IF(N16<>"",IF(MONTH(N16)>=4,"FY1"&RIGHT(YEAR(N16)+1,2),"FY1"&RIGHT(YEAR(N16),2)),"") | Q16: =IF(K16>0&M16>0,K16*M16,"")
B17: =_xlfn.IFNA(VLOOKUP(C17,Master_Section!$H:$I,2,FALSE),"") | D17: =_xlfn.IFNA(VLOOKUP(E17,Master_Section!$H:$I,2,FALSE),"") | F17: =_xlfn.IFNA(VLOOKUP(G17,Master!AE:AF,2,FALSE),"") | I17: =_xlfn.IFNA(VLOOKUP(D17,Master_Section!$I:$K,2,FALSE),"") | J17: =_xlfn.IFNA(VLOOKUP(D17,Master_Section!$I:$K,3,FALSE),"") | L17: =IF(A17<>"CFA",_xlfn.IFNA(VLOOKUP($G17,Master!$AE:$AI,5,0),""),"") | P17: =IF(N17<>"",IF(MONTH(N17)>=4,"FY1"&RIGHT(YEAR(N17)+1,2),"FY1"&RIGHT(YEAR(N17),2)),"") | Q17: =IF(K17>0&M17>0,K17*M17,"")
B18: =_xlfn.IFNA(VLOOKUP(C18,Master_Section!$H:$I,2,FALSE),"") | D18: =_xlfn.IFNA(VLOOKUP(E18,Master_Section!$H:$I,2,FALSE),"") | F18: =_xlfn.IFNA(VLOOKUP(G18,Master!AE:AF,2,FALSE),"") | I18: =_xlfn.IFNA(VLOOKUP(D18,Master_Section!$I:$K,2,FALSE),"") | J18: =_xlfn.IFNA(VLOOKUP(D18,Master_Section!$I:$K,3,FALSE),"") | L18: =IF(A18<>"CFA",_xlfn.IFNA(VLOOKUP($G18,Master!$AE:$AI,5,0),""),"") | P18: =IF(N18<>"",IF(MONTH(N18)>=4,"FY1"&RIGHT(YEAR(N18)+1,2),"FY1"&RIGHT(YEAR(N18),2)),"") | Q18: =IF(K18>0&M18>0,K18*M18,"")
B19: =_xlfn.IFNA(VLOOKUP(C19,Master_Section!$H:$I,2,FALSE),"") | D19: =_xlfn.IFNA(VLOOKUP(E19,Master_Section!$H:$I,2,FALSE),"") | F19: =_xlfn.IFNA(VLOOKUP(G19,Master!AE:AF,2,FALSE),"") | I19: =_xlfn.IFNA(VLOOKUP(D19,Master_Section!$I:$K,2,FALSE),"") | J19: =_xlfn.IFNA(VLOOKUP(D19,Master_Section!$I:$K,3,FALSE),"") | L19: =IF(A19<>"CFA",_xlfn.IFNA(VLOOKUP($G19,Master!$AE:$AI,5,0),""),"") | P19: =IF(N19<>"",IF(MONTH(N19)>=4,"FY1"&RIGHT(YEAR(N19)+1,2),"FY1"&RIGHT(YEAR(N19),2)),"") | Q19: =IF(K19>0&M19>0,K19*M19,"")
... B342: =_xlfn.IFNA(VLOOKUP(C342,Master_Section!$H:$I,2,FALSE),"") | D342: =_xlfn.IFNA(VLOOKUP(E342,Master_Section!$H:$I,2,FALSE),"") | F342: =_xlfn.IFNA(VLOOKUP(G342,Master!AE:AF,2,FALSE),"") | I342: =_xlfn.IFNA(VLOOKUP(D342,Master_Section!$I:$K,2,FALSE),"") | J342: =_xlfn.IFNA(VLOOKUP(D342,Master_Section!$I:$K,3,FALSE),"") | L342: =IF(A342<>"CFA",_xlfn.IFNA(VLOOKUP($G342,Master!$AE:$AI,5,0),""),"") | P342: =IF(N342<>"",IF(MONTH(N342)>=4,"FY1"&RIGHT(YEAR(N342)+1,2),"FY1"&RIGHT(YEAR(N342),2)),"") | Q342: =IF(K342>0&M342>0,K342*M342,"")
B343: =_xlfn.IFNA(VLOOKUP(C343,Master_Section!$H:$I,2,FALSE),"") | F343: =_xlfn.IFNA(VLOOKUP(G343,Master!AE:AF,2,FALSE),"") | I343: =_xlfn.IFNA(VLOOKUP(D343,Master_Section!$I:$K,2,FALSE),"") | J343: =_xlfn.IFNA(VLOOKUP(D343,Master_Section!$I:$K,3,FALSE),"") | L343: =IF(A343<>"CFA",_xlfn.IFNA(VLOOKUP($G343,Master!$AE:$AI,5,0),""),"") | P343: =IF(N343<>"",IF(MONTH(N343)>=4,"FY1"&RIGHT(YEAR(N343)+1,2),"FY1"&RIGHT(YEAR(N343),2)),"") | Q343: =IF(K343>0&M343>0,K343*M343,"")
B344: =_xlfn.IFNA(VLOOKUP(C344,Master_Section!$H:$I,2,FALSE),"") | F344: =_xlfn.IFNA(VLOOKUP(G344,Master!AE:AF,2,FALSE),"") | I344: =_xlfn.IFNA(VLOOKUP(D344,Master_Section!$I:$K,2,FALSE),"") | J344: =_xlfn.IFNA(VLOOKUP(D344,Master_Section!$I:$K,3,FALSE),"") | L344: =IF(A344<>"CFA",_xlfn.IFNA(VLOOKUP($G344,Master!$AE:$AI,5,0),""),"") | P344: =IF(N344<>"",IF(MONTH(N344)>=4,"FY1"&RIGHT(YEAR(N344)+1,2),"FY1"&RIGHT(YEAR(N344),2)),"") | Q344: =IF(K344>0&M344>0,K344*M344,"")
B345: =_xlfn.IFNA(VLOOKUP(C345,Master_Section!$H:$I,2,FALSE),"") | F345: =_xlfn.IFNA(VLOOKUP(G345,Master!AE:AF,2,FALSE),"") | I345: =_xlfn.IFNA(VLOOKUP(D345,Master_Section!$I:$K,2,FALSE),"") | J345: =_xlfn.IFNA(VLOOKUP(D345,Master_Section!$I:$K,3,FALSE),"") | L345: =IF(A345<>"CFA",_xlfn.IFNA(VLOOKUP($G345,Master!$AE:$AI,5,0),""),"") | P345: =IF(N345<>"",IF(MONTH(N345)>=4,"FY1"&RIGHT(YEAR(N345)+1,2),"FY1"&RIGHT(YEAR(N345),2)),"") | Q345: =IF(K345>0&M345>0,K345*M345,"")
B346: =_xlfn.IFNA(VLOOKUP(C346,Master_Section!$H:$I,2,FALSE),"") | F346: =_xlfn.IFNA(VLOOKUP(G346,Master!AE:AF,2,FALSE),"") | I346: =_xlfn.IFNA(VLOOKUP(D346,Master_Section!$I:$K,2,FALSE),"") | J346: =_xlfn.IFNA(VLOOKUP(D346,Master_Section!$I:$K,3,FALSE),"") | L346: =IF(A346<>"CFA",_xlfn.IFNA(VLOOKUP($G346,Master!$AE:$AI,5,0),""),"") | P346: =IF(N346<>"",IF(MONTH(N346)>=4,"FY1"&RIGHT(YEAR(N346)+1,2),"FY1"&RIGHT(YEAR(N346),2)),"") | Q346: =IF(K346>0&M346>0,K346*M346,"")
B347: =_xlfn.IFNA(VLOOKUP(C347,Master_Section!$H:$I,2,FALSE),"") | F347: =_xlfn.IFNA(VLOOKUP(G347,Master!AE:AF,2,FALSE),"") | I347: =_xlfn.IFNA(VLOOKUP(D347,Master_Section!$I:$K,2,FALSE),"") | J347: =_xlfn.IFNA(VLOOKUP(D347,Master_Section!$I:$K,3,FALSE),"") | L347: =IF(A347<>"CFA",_xlfn.IFNA(VLOOKUP($G347,Master!$AE:$AI,5,0),""),"") | P347: =IF(N347<>"",IF(MONTH(N347)>=4,"FY1"&RIGHT(YEAR(N347)+1,2),"FY1"&RIGHT(YEAR(N347),2)),"") | Q347: =IF(K347>0&M347>0,K347*M347,"")
B348: =_xlfn.IFNA(VLOOKUP(C348,Master_Section!$H:$I,2,FALSE),"") | F348: =_xlfn.IFNA(VLOOKUP(G348,Master!AE:AF,2,FALSE),"") | I348: =_xlfn.IFNA(VLOOKUP(D348,Master_Section!$I:$K,2,FALSE),"") | J348: =_xlfn.IFNA(VLOOKUP(D348,Master_Section!$I:$K,3,FALSE),"") | L348: =IF(A348<>"CFA",_xlfn.IFNA(VLOOKUP($G348,Master!$AE:$AI,5,0),""),"") | P348: =IF(N348<>"",IF(MONTH(N348)>=4,"FY1"&RIGHT(YEAR(N348)+1,2),"FY1"&RIGHT(YEAR(N348),2)),"") | Q348: =IF(K348>0&M348>0,K348*M348,"")
B349: =_xlfn.IFNA(VLOOKUP(C349,Master_Section!$H:$I,2,FALSE),"") | F349: =_xlfn.IFNA(VLOOKUP(G349,Master!AE:AF,2,FALSE),"") | I349: =_xlfn.IFNA(VLOOKUP(D349,Master_Section!$I:$K,2,FALSE),"") | J349: =_xlfn.IFNA(VLOOKUP(D349,Master_Section!$I:$K,3,FALSE),"") | L349: =IF(A349<>"CFA",_xlfn.IFNA(VLOOKUP($G349,Master!$AE:$AI,5,0),""),"") | P349: =IF(N349<>"",IF(MONTH(N349)>=4,"FY1"&RIGHT(YEAR(N349)+1,2),"FY1"&RIGHT(YEAR(N349),2)),"") | Q349: =IF(K349>0&M349>0,K349*M349,"")
B350: =_xlfn.IFNA(VLOOKUP(C350,Master_Section!$H:$I,2,FALSE),"") | F350: =_xlfn.IFNA(VLOOKUP(G350,Master!AE:AF,2,FALSE),"") | I350: =_xlfn.IFNA(VLOOKUP(D350,Master_Section!$I:$K,2,FALSE),"") | J350: =_xlfn.IFNA(VLOOKUP(D350,Master_Section!$I:$K,3,FALSE),"") | L350: =IF(A350<>"CFA",_xlfn.IFNA(VLOOKUP($G350,Master!$AE:$AI,5,0),""),"") | P350: =IF(N350<>"",IF(MONTH(N350)>=4,"FY1"&RIGHT(YEAR(N350)+1,2),"FY1"&RIGHT(YEAR(N350),2)),"") | Q350: =IF(K350>0&M350>0,K350*M350,"")
B351: =_xlfn.IFNA(VLOOKUP(C351,Master_Section!$H:$I,2,FALSE),"") | F351: =_xlfn.IFNA(VLOOKUP(G351,Master!AE:AF,2,FALSE),"") | I351: =_xlfn.IFNA(VLOOKUP(D351,Master_Section!$I:$K,2,FALSE),"") | J351: =_xlfn.IFNA(VLOOKUP(D351,Master_Section!$I:$K,3,FALSE),"") | L351: =IF(A351<>"CFA",_xlfn.IFNA(VLOOKUP($G351,Master!$AE:$AI,5,0),""),"") | P351: =IF(N351<>"",IF(MONTH(N351)>=4,"FY1"&RIGHT(YEAR(N351)+1,2),"FY1"&RIGHT(YEAR(N351),2)),"") | Q351: =IF(K351>0&M351>0,K351*M351,"")
B352: =_xlfn.IFNA(VLOOKUP(C352,Master_Section!$H:$I,2,FALSE),"") | F352: =_xlfn.IFNA(VLOOKUP(G352,Master!AE:AF,2,FALSE),"") | I352: =_xlfn.IFNA(VLOOKUP(D352,Master_Section!$I:$K,2,FALSE),"") | J352: =_xlfn.IFNA(VLOOKUP(D352,Master_Section!$I:$K,3,FALSE),"") | L352: =IF(A352<>"CFA",_xlfn.IFNA(VLOOKUP($G352,Master!$AE:$AI,5,0),""),"") | P352: =IF(N352<>"",IF(MONTH(N352)>=4,"FY1"&RIGHT(YEAR(N352)+1,2),"FY1"&RIGHT(YEAR(N352),2)),"") | Q352: =IF(K352>0&M352>0,K352*M352,"")
B353: =_xlfn.IFNA(VLOOKUP(C353,Master_Section!$H:$I,2,FALSE),"") | F353: =_xlfn.IFNA(VLOOKUP(G353,Master!AE:AF,2,FALSE),"") | I353: =_xlfn.IFNA(VLOOKUP(D353,Master_Section!$I:$K,2,FALSE),"") | J353: =_xlfn.IFNA(VLOOKUP(D353,Master_Section!$I:$K,3,FALSE),"") | L353: =IF(A353<>"CFA",_xlfn.IFNA(VLOOKUP($G353,Master!$AE:$AI,5,0),""),"") | P353: =IF(N353<>"",IF(MONTH(N353)>=4,"FY1"&RIGHT(YEAR(N353)+1,2),"FY1"&RIGHT(YEAR(N353),2)),"") | Q353: =IF(K353>0&M353>0,K353*M353,"")
B354: =_xlfn.IFNA(VLOOKUP(C354,Master_Section!$H:$I,2,FALSE),"") | F354: =_xlfn.IFNA(VLOOKUP(G354,Master!AE:AF,2,FALSE),"") | I354: =_xlfn.IFNA(VLOOKUP(D354,Master_Section!$I:$K,2,FALSE),"") | J354: =_xlfn.IFNA(VLOOKUP(D354,Master_Section!$I:$K,3,FALSE),"") | L354: =IF(A354<>"CFA",_xlfn.IFNA(VLOOKUP($G354,Master!$AE:$AI,5,0),""),"") | P354: =IF(N354<>"",IF(MONTH(N354)>=4,"FY1"&RIGHT(YEAR(N354)+1,2),"FY1"&RIGHT(YEAR(N354),2)),"") | Q354: =IF(K354>0&M354>0,K354*M354,"")
... B382: =_xlfn.IFNA(VLOOKUP(C382,Master_Section!$H:$I,2,FALSE),"") | F382: =_xlfn.IFNA(VLOOKUP(G382,Master!AE:AF,2,FALSE),"") | I382: =_xlfn.IFNA(VLOOKUP(D382,Master_Section!$I:$K,2,FALSE),"") | J382: =_xlfn.IFNA(VLOOKUP(D382,Master_Section!$I:$K,3,FALSE),"") | L382: =IF(A382<>"CFA",_xlfn.IFNA(VLOOKUP($G382,Master!$AE:$AI,5,0),""),"") | P382: =IF(N382<>"",IF(MONTH(N382)>=4,"FY1"&RIGHT(YEAR(N382)+1,2),"FY1"&RIGHT(YEAR(N382),2)),"") | Q382: =IF(K382>0&M382>0,K382*M382,"")
F383: =_xlfn.IFNA(VLOOKUP(G383,Master!AE:AF,2,FALSE),"") | I383: =_xlfn.IFNA(VLOOKUP(D383,Master_Section!$I:$K,2,FALSE),"") | J383: =_xlfn.IFNA(VLOOKUP(D383,Master_Section!$I:$K,3,FALSE),"") | L383: =IF(A383<>"CFA",_xlfn.IFNA(VLOOKUP($G383,Master!$AE:$AI,5,0),""),"") | P383: =IF(N383<>"",IF(MONTH(N383)>=4,"FY1"&RIGHT(YEAR(N383)+1,2),"FY1"&RIGHT(YEAR(N383),2)),"") | Q383: =IF(K383>0&M383>0,K383*M383,"")
F384: =_xlfn.IFNA(VLOOKUP(G384,Master!AE:AF,2,FALSE),"") | I384: =_xlfn.IFNA(VLOOKUP(D384,Master_Section!$I:$K,2,FALSE),"") | J384: =_xlfn.IFNA(VLOOKUP(D384,Master_Section!$I:$K,3,FALSE),"") | L384: =IF(A384<>"CFA",_xlfn.IFNA(VLOOKUP($G384,Master!$AE:$AI,5,0),""),"") | P384: =IF(N384<>"",IF(MONTH(N384)>=4,"FY1"&RIGHT(YEAR(N384)+1,2),"FY1"&RIGHT(YEAR(N384),2)),"") | Q384: =IF(K384>0&M384>0,K384*M384,"")
L385: =IF(A385<>"CFA",_xlfn.IFNA(VLOOKUP($G385,Master!$AE:$AI,5,0),""),"") | P385: =IF(N385<>"",IF(MONTH(N385)>=4,"FY1"&RIGHT(YEAR(N385)+1,2),"FY1"&RIGHT(YEAR(N385),2)),"") | Q385: =IF(K385>0&M385>0,K385*M385,"")
L386: =IF(A386<>"CFA",_xlfn.IFNA(VLOOKUP($G386,Master!$AE:$AI,5,0),""),"") | P386: =IF(N386<>"",IF(MONTH(N386)>=4,"FY1"&RIGHT(YEAR(N386)+1,2),"FY1"&RIGHT(YEAR(N386),2)),"") | Q386: =IF(K386>0&M386>0,K386*M386,"")
L387: =IF(A387<>"CFA",_xlfn.IFNA(VLOOKUP($G387,Master!$AE:$AI,5,0),""),"") | Q387: =IF(K387>0&M387>0,K387*M387,"")
L388: =IF(A388<>"CFA",_xlfn.IFNA(VLOOKUP($G388,Master!$AE:$AI,5,0),""),"") | Q388: =IF(K388>0&M388>0,K388*M388,"")
L389: =IF(A389<>"CFA",_xlfn.IFNA(VLOOKUP($G389,Master!$AE:$AI,5,0),""),"") | Q389: =IF(K389>0&M389>0,K389*M389,"")
...

Sheet V1
A1: This is used for version checking on portal, do not delete!.

Sheet Master
A1: Name | B1: BNGK | C1: GROUP COST | D1: GROUP SECTION | E1: Name | G1: Code | H1: Name | J1: Name COA AX | K1: COA AX | L1: Group Cost | M1: UNIQ | N1: COA Budget | O1: Description | Q1: Name | R1: BNGK | S1: GROUP COST | T1: GROUP SECTION | U1: Name | W1: Code | X1: Name | Z1: Priority Code | AA1: Priority Name | AB1: Description | AD1: COA Assets | AE1: Name of Asset | AF1: COA Assets | AG1: COA Depre | AH1: Name of Depre | AI1: Useful Life | AJ1: Value | AK1: Description | AM1: Priority Code | AN1: Priority Name | AO1: Description
A2: Top Management | B2: B1000 | C2: SGA | D2: ADM | E2: =A2 | G2: 53450 | H2: NGK BUSI INDONESIA | J2: Salary for Commissioner | K2: 7511101 | L2: SGA | M2: =L2&"-"&K2 | N2: A502 | O2: Salary for Commissioner | Q2: Top Management | R2: B1000 | S2: SGA | T2: ADM | U2: =Q2 | W2: 53450 | X2: NGK BUSI INDONESIA | Z2: A | AA2: Must | AB2: If this is not done, the company or our team cannot continue its business. | AD2: 2111100 | AE2: Building | AF2: 2111100 | AG2: 7611100 | AH2: Depreciation-Building | AI2: 240 | AK2: a construction such as a factory that has a roof and walls and Structure a construction fixed on land other than a building. | AM2: A | AN2: Must | AO2: If this is not done, the company or our team cannot continue its business.
A3: Commissioner | B3: B1001 | C3: SGA | D3: ADM | E3: =A3 | J3: Salary for Director | K3: 7511102 | L3: SGA | M3: =L3&"-"&K3 | N3: A502 | O3: Salary for Director & Expat | Q3: Commissioner | R3: B1001 | S3: SGA | T3: ADM | U3: =Q3 | Z3: B | AA3: Want to | AB3: We want to do it as a team this term. we need it. | AD3: 2121000 | AE3: Machinery & Equipment - New | AF3: 2121000 | AG3: 7611300 | AH3: Depreciation-Machiney & equipment | AI3: 120 | AK3: Devices that used for production, such as cold forming equipment, an assembly machine, and All Factory Equiptment (new) | AM3: B | AN3: Want to | AO3: We want to do it as a team this term. we need it.
A4: Admin & HR | B4: B2200 | C4: SGA | D4: ADM | E4: =A4 | J4: Staff Labor - Baslc Salary | K4: 7511103 | L4: SGA | M4: =L4&"-"&K4 | N4: A501 | O4: Basic Salary of permanent employee | Q4: Admin & HR | R4: B2200 | S4: SGA | T4: ADM | U4: =Q4 | Z4: C | AA4: Challenge | AB4: We want to do it for this term or the future. But it doesn't matter if it's not this term. | AD4: 2121000 | AE4: Machinery & Equipment - Second | AF4: 2121000 | AG4: 7611300 | AH4: Depreciation-Machiney & equipment | AI4: 84 | AK4: Devices that used for production, such as cold forming equipment, an assembly machine, and All Factory Equiptment (second) | AM4: C | AN4: Challenge | AO4: We want to do it for this term or the future. But it doesn't matter if it's not this term.
A5: General Affair | B5: B2210 | C5: SGA | D5: ADM | E5: =A5 | J5: Staff Labor - Allowance | K5: 7511111 | L5: SGA | M5: =L5&"-"&K5 | N5: A501 | O5: Employee allowance | Q5: General Affair | R5: B2210 | S5: SGA | T5: ADM | U5: =Q5 | AD5: 2131000 | AE5: Vehicles | AF5: 2131000 | AG5: 7611500 | AH5: Depreciation-Vehicles | AI5: 60 | AK5: things that used for surface-transporting people or goods, such as cars, trucks and forklifts.
A6: Human Resource | B6: B2220 | C6: SGA | D6: ADM | E6: =A6 | G6: BIP | J6: Staff Labor - Tax allowance (art.21) | K6: 7511112 | L6: SGA | M6: =L6&"-"&K6 | N6: A501 | O6: Empployee Tax allowance | Q6: Human Resource | R6: B2220 | S6: SGA | T6: ADM | U6: =Q6 | AD6: 2141000 | AE6: Tools, furniture & office equipment | AF6: 2141000 | AG6: 7611600 | AH6: Depreciation-Tools, furniture & office equipment | AI6: 60 | AJ6: > 5.000.000 | AK6: furniture that we used in office and factory, and Office equipment, such as fax machine, printer, komputer, note book, etc
A7: Health, Safety & Environment | B7: B2230 | C7: SGA | D7: ADM | E7: =A7 | G7: CIP | J7: Staff Labor - BPJS JK & JKK (1.19%) | K7: 7511121 | L7: SGA | M7: =L7&"-"&K7 | N7: A501 | O7: BPJS JK & JKK (death warrant, Accident Insurance) | Q7: Health, Safety & Environment | R7: B2230 | S7: SGA | T7: ADM | U7: =Q7 | AD7: 2221101 | AE7: Software | AF7: 2221101 | AG7: 7611700 | AH7: Depreciation-Software | AI7: 60
A8: Accounting & Finance | B8: B2300 | C8: SGA | D8: ADM | E8: =A8 | G8: CFA | J8: Staff Labor - BPJS Kesehatan (4%) | K8: 7511122 | L8: SGA | M8: =L8&"-"&K8 | N8: A501 | O8: BPJS health insurance | Q8: Accounting & Finance | R8: B2300 | S8: SGA | T8: ADM | U8: =Q8
A9: Information Technology | B9: B2400 | C9: SGA | D9: ADM | E9: =A9 | J9: Staff Overtime | K9: 7511201 | L9: SGA | M9: =L9&"-"&K9 | N9: A503 | O9: Overtime permanent employee | Q9: Information Technology | R9: B2400 | S9: SGA | T9: ADM | U9: =Q9
A10: Sales & MKTG Dept.- Automotive | B10: B3100 | C10: SGA | D10: ADM | E10: =A10 | J10: Staff Welfare - BPJS Dana pensiun (2%) | K10: 7512111 | L10: SGA | M10: =L10&"-"&K10 | N10: A504 | O10: BPJS pension fund | Q10: Sales & MKTG Dept.- Automotive | R10: B3100 | S10: SGA | T10: ADM | U10: =Q10
A11: Marketing | B11: B3160 | C11: SGA | D11: ADM | E11: =A11 | J11: Staff Welfare - BPJS JHT (3.7%) | K11: 7512112 | L11: SGA | M11: =L11&"-"&K11 | N11: A504 | O11: BPJS Pension plan | Q11: Marketing | R11: B3160 | S11: SGA | T11: ADM | U11: =Q11
A12: Sales - OEM | B12: B3110 | C12: SGA | D12: ADM | E12: =A12 | J12: Staff Bonus / TAT | K12: 7514101 | L12: SGA | M12: =L12&"-"&K12 | N12: A501 | O12: Year-end allowance & Alpha | Q12: Sales - OEM | R12: B3110 | S12: SGA | T12: ADM | U12: =Q12
A13: Sales - OES | B13: B3120 | C13: SGA | D13: ADM | E13: =A13 | J13: Staff Ramadhan / THR | K13: 7514102 | L13: SGA | M13: =L13&"-"&K13 | N13: A501 | O13: Lebaran bonus | Q13: Sales - OES | R13: B3120 | S13: SGA | T13: ADM | U13: =Q13
A14: Sales - IAM | B14: B3130 | C14: SGA | D14: ADM | E14: =A14 | J14: Staff Welfare - Outpatient (Medical) | K14: 7515401 | L14: SGA | M14: =L14&"-"&K14 | N14: A504 | O14: outpatient treatment costs | Q14: Sales - IAM | R14: B3130 | S14: SGA | T14: ADM | U14: =Q14
A15: SP PD- CF | B15: B4101 | C15: MFG | D15: DIR | E15: =A15 | J15: Staff Welfare - Hospitalization | K15: 7515402 | L15: SGA | M15: =L15&"-"&K15 | N15: A504 | O15: hospitalization costs | Q15: SP PD- CF | R15: B4101 | S15: MFG | T15: DIR | U15: =Q15
A16: SP PD- CM | B16: B4102 | C16: MFG | D16: DIR | E16: =A16 | J16: Staff Welfare - Glasses | K16: 7515403 | L16: SGA | M16: =L16&"-"&K16 | N16: A504 | O16: glasses costs | Q16: SP PD- CM | R16: B4102 | S16: MFG | T16: DIR | U16: =Q16
A17: SP PD- WT | B17: B4103 | C17: MFG | D17: DIR | E17: =A17 | J17: Staff Welfare - Dental | K17: 7515404 | L17: SGA | M17: =L17&"-"&K17 | N17: A504 | O17: dental costs | Q17: SP PD- WT | R17: B4103 | S17: MFG | T17: DIR | U17: =Q17
A18: SP PD- Plating | B18: B4105 | C18: MFG | D18: DIR | E18: =A18 | J18: Staff Welfare - Medical Check Up | K18: 7515405 | L18: SGA | M18: =L18&"-"&K18 | N18: A504 | O18: Medical Check Up cost | Q18: SP PD- Plating | R18: B4105 | S18: MFG | T18: DIR | U18: =Q18
A19: SP PD- MS Insp. | B19: B4109 | C19: MFG | D19: DIR | E19: =A19 | J19: Staff Welfare - Uniform | K19: 7515406 | L19: SGA | M19: =L19&"-"&K19 | N19: A504 | O19: uniform costs | Q19: SP PD- MS Insp. | R19: B4109 | S19: MFG | T19: DIR | U19: =Q19
A20: SP PD- Insulator Sealing | B20: B4106 | C20: MFG | D20: DIR | E20: =A20 | J20: Staff Welfare - Safety Shoes | K20: 7515407 | L20: SGA | M20: =L20&"-"&K20 | N20: A504
A21: SP PD- Assy | B21: B4110 | C21: MFG | D21: DIR | E21: =A21 | J21: Staff Welfare - Family Gathering / Anniversary | K21: 7515408 | L21: SGA | M21: =L21&"-"&K21 | N21: A504 | O21: Family Gathering / Anniversary | Q21: SP PD- Insulator Sealing | R21: B4106 | S21: MFG | T21: DIR | U21: =Q21
A22: SP-PD-Assy-Auto Assembly | B22: B4115 | C22: MFG | D22: DIR | E22: =A22 | J22: Staff Welfare - Meals of canteen & other meals | K22: 7515409 | L22: SGA | M22: =L22&"-"&K22 | N22: A504 | O22: Meals of canteen & other meals cost | Q22: SP PD- Assy | R22: B4110 | S22: MFG | T22: DIR | U22: =Q22
A23: SP PD- Bending | B23: B4114 | C23: MFG | D23: DIR | E23: =A23 | J23: Staff Welfare - Kaizen & QCC reward | K23: 7515410 | L23: SGA | M23: =L23&"-"&K23 | N23: A504 | O23: an expense, arising from Kaizen and QCC acitivity | Q23: SP-PD-Assy-Auto Assembly | R23: B4115 | S23: MFG | T23: DIR | U23: =Q23
A24: SP PD- Final Inspection | B24: B4120 | C24: MFG | D24: DIR | E24: =A24 | J24: Staff Welfare - Welfare Others | K24: 7515499 | L24: SGA | M24: =L24&"-"&K24 | N24: A504 | O24: an other welfare expense, arising besides the above welfare expense | Q24: SP PD- Bending | R24: B4114 | S24: MFG | T24: DIR | U24: =Q24
A25: SP PD- QC - OEM | B25: B4121 | C25: MFG | D25: DIR | E25: =A25 | J25: Retirement Allowance | K25: 7516102 | L25: SGA | M25: =L25&"-"&K25 | N25: A505 | O25: employee retirement provission costs | Q25: SP PD- Final Inspection | R25: B4120 | S25: MFG | T25: DIR | U25: =Q25
A26: PC PD- Injection | B26: B4410 | C26: MFG | D26: DIR | E26: =A26 | J26: House Rent Allowance | K26: 7519101 | L26: SGA | M26: =L26&"-"&K26 | N26: A502 | O26: House Rent Allowance for expat | Q26: SP PD- QC - OEM | R26: B4121 | S26: MFG | T26: DIR | U26: =Q26
A27: PC PD- Assy | B27: B4430 | C27: MFG | D27: DIR | E27: =A27 | J27: Casual Staff Labor - Basic Salary | K27: 7521101 | L27: SGA | M27: =L27&"-"&K27 | N27: A501 | O27: All benefit for temporary worker | Q27: PC PD- Injection | R27: B4410 | S27: MFG | T27: DIR | U27: =Q27
A28: PC PD- QC | B28: B4440 | C28: MFG | D28: DIR | E28: =A28 | J28: Casual Staff Labor - Overtime | K28: 7521102 | L28: SGA | M28: =L28&"-"&K28 | N28: A503 | O28: Overtime temporary worker | Q28: PC PD- Assy | R28: B4430 | S28: MFG | T28: DIR | U28: =Q28
A29: Plant Operation (Indirect Mfg) | B29: B5000 | C29: MFG | D29: IND | E29: =A29 | J29: Personnel expense transferred | K29: 7571101 | L29: SGA | M29: =L29&"-"&K29 | N29: A506 | O29: Transfer Labor cost from one section into another section | Q29: PC PD- QC | R29: B4440 | S29: MFG | T29: DIR | U29: =Q29
A30: Production Office | B30: B5100 | C30: MFG | D30: IND | E30: =A30 | J30: Depreciation-Building | K30: 7611100 | L30: SGA | M30: =L30&"-"&K30 | N30: A601 | O30: the amount of depreciation of tangible assets for building | Q30: Plant Operation (Indirect Mfg) | R30: B5000 | S30: MFG | T30: IND | U30: =Q30
A31: Production Office (SP) | B31: B5101 | C31: MFG | D31: IND | E31: =A31 | J31: Depreciation-Machiney & equipment | K31: 7611300 | L31: SGA | M31: =L31&"-"&K31 | N31: A601 | O31: the amount of depreciation of tangible assets for machinery & factory equipment | Q31: Production Office | R31: B5100 | S31: MFG | T31: IND | U31: =Q31
A32: Production Office (PC) | B32: B5104 | C32: MFG | D32: IND | E32: =A32 | J32: Depreciation-Lease Machinery & equipment | K32: 7611400 | L32: SGA | M32: =L32&"-"&K32 | N32: A601 | O32: the amount of depreciation of tangible assets for machinery & factory equipment (Leases) | Q32: Production Office (SP) | R32: B5101 | S32: MFG | T32: IND | U32: =Q32
... A42: WH Dept.- KD & RM | B42: B5710 | C42: MFG | D42: IND | E42: =A42 | J42: Repair of Equipment | K42: 7641102 | L42: SGA | M42: =L42&"-"&K42 | N42: A1002 | O42: expenses for repair and maintenance tangible assets, intangible assets and other assets beside building | Q42: Continuous Improvement | R42: B5007 | S42: MFG | T42: IND | U42: =Q42
A43: Continuous Improvement | B43: B5007 | C43: MFG | D43: IND | E43: =A43 | J43: Factory Supply Expense | K43: 7641103 | L43: SGA | M43: =L43&"-"&K43 | N43: A1099 | O43: All cost that arrising to support factory acitivity | Q43: All | R43: B0000 | U43: =Q43
J44: Calibration Cost | K44: 7641104 | L44: SGA | M44: =L44&"-"&K44 | N44: A1099 | O44: Cost of calibration for tools and equipment of factory and others
J45: Transportation Fee for employee | K45: 7651101 | L45: SGA | M45: =L45&"-"&K45 | N45: A801 | O45: Gasoline of company cars & expense for Local transportation
J46: Travel Expense-Domestic | K46: 7651102 | L46: SGA | M46: =L46&"-"&K46 | N46: A801 | O46: expenses for business trip, including allowance for business trip to an employee only for domestic travel
J47: Travel Expense-Oversea | K47: 7651103 | L47: SGA | M47: =L47&"-"&K47 | N47: A801 | O47: expenses for business trip, including allowance for business trip to an employee only for overseas travel
J48: Entertainment | K48: 7661101 | L48: SGA | M48: =L48&"-"&K48 | N48: A1001 | O48: the amount of expenses for the act of entertaining the business partner
J49: Amortization of Land & Building tax (PBB) | K49: 7671102 | L49: SGA | M49: =L49&"-"&K49 | N49: A1099 | O49: the amount of depreciation of intangible of Land & Building Tax (PBB)
...

Sheet Master_Section
A1: Name COA AX | B1: COA AX | C1: Group Cost | D1: UNIQ | E1: COA Budget | F1: Description | H1: Name | I1: BNGK | J1: GROUP COST | K1: GROUP SECTION | L1: Name | N1: Code | O1: Name | Q1: Priority Code | R1: Priority Name | S1: Description
A2: Salary for Commissioner | B2: 7511101 | C2: SGA | D2: =C2&"-"&B2 | E2: A502 | F2: Salary for Commissioner | H2: Top Management | I2: B1000 | J2: SGA | K2: ADM | L2: =H2 | N2: 53450 | O2: NGK BUSI INDONESIA | Q2: A | R2: Must | S2: If this is not done, the company or our team cannot continue its business.
A3: Salary for Director | B3: 7511102 | C3: SGA | D3: =C3&"-"&B3 | E3: A502 | F3: Salary for Director & Expat | H3: Commissioner | I3: B1001 | J3: SGA | K3: ADM | L3: =H3 | Q3: B | R3: Want to | S3: We want to do it as a team this term. we need it.
A4: Staff Labor - Baslc Salary | B4: 7511103 | C4: SGA | D4: =C4&"-"&B4 | E4: A501 | F4: Basic Salary of permanent employee | H4: Admin & HR | I4: B2200 | J4: SGA | K4: ADM | L4: =H4 | Q4: C | R4: Challenge | S4: We want to do it for this term or the future. But it doesn't matter if it's not this term.
A5: Staff Labor - Allowance | B5: 7511111 | C5: SGA | D5: =C5&"-"&B5 | E5: A501 | F5: Employee allowance | H5: General Affair | I5: B2210 | J5: SGA | K5: ADM | L5: =H5
A6: Staff Labor - Tax allowance (art.21) | B6: 7511112 | C6: SGA | D6: =C6&"-"&B6 | E6: A501 | F6: Empployee Tax allowance | H6: Human Resource | I6: B2220 | J6: SGA | K6: ADM | L6: =H6
A7: Staff Labor - BPJS JK & JKK (1.19%) | B7: 7511121 | C7: SGA | D7: =C7&"-"&B7 | E7: A501 | F7: BPJS JK & JKK (death warrant, Accident Insurance) | H7: Health, Safety & Environment | I7: B2230 | J7: SGA | K7: ADM | L7: =H7
A8: Staff Labor - BPJS Kesehatan (4%) | B8: 7511122 | C8: SGA | D8: =C8&"-"&B8 | E8: A501 | F8: BPJS health insurance | H8: Accounting & Finance | I8: B2300 | J8: SGA | K8: ADM | L8: =H8
A9: Staff Overtime | B9: 7511201 | C9: SGA | D9: =C9&"-"&B9 | E9: A503 | F9: Overtime permanent employee | H9: Information Technology | I9: B2400 | J9: SGA | K9: ADM | L9: =H9
A10: Staff Welfare - BPJS Dana pensiun (2%) | B10: 7512111 | C10: SGA | D10: =C10&"-"&B10 | E10: A504 | F10: BPJS pension fund | H10: Sales & MKTG Dept.- Automotive | I10: B3100 | J10: SGA | K10: ADM | L10: =H10
A11: Staff Welfare - BPJS JHT (3.7%) | B11: 7512112 | C11: SGA | D11: =C11&"-"&B11 | E11: A504 | F11: BPJS Pension plan | H11: Marketing | I11: B3160 | J11: SGA | K11: ADM | L11: =H11
A12: Staff Bonus / TAT | B12: 7514101 | C12: SGA | D12: =C12&"-"&B12 | E12: A501 | F12: Year-end allowance & Alpha | H12: Sales - OEM | I12: B3110 | J12: SGA | K12: ADM | L12: =H12
A13: Staff Ramadhan / THR | B13: 7514102 | C13: SGA | D13: =C13&"-"&B13 | E13: A501 | F13: Lebaran bonus | H13: Sales - OES | I13: B3120 | J13: SGA | K13: ADM | L13: =H13
A14: Staff Welfare - Outpatient (Medical) | B14: 7515401 | C14: SGA | D14: =C14&"-"&B14 | E14: A504 | F14: outpatient treatment costs | H14: Sales - IAM | I14: B3130 | J14: SGA | K14: ADM | L14: =H14
A15: Staff Welfare - Hospitalization | B15: 7515402 | C15: SGA | D15: =C15&"-"&B15 | E15: A504 | F15: hospitalization costs | H15: Sales & MKTG Dept.- DID Chain | I15: B3172 | J15: SGA | K15: ADM | L15: Sales & MKTG Dept.- DID Chain
A16: Staff Welfare - Glasses | B16: 7515403 | C16: SGA | D16: =C16&"-"&B16 | E16: A504 | F16: glasses costs | H16: SP PD- CF | I16: B4101 | J16: MFG | K16: DIR | L16: =H16
A17: Staff Welfare - Dental | B17: 7515404 | C17: SGA | D17: =C17&"-"&B17 | E17: A504 | F17: dental costs | H17: SP PD- CM | I17: B4102 | J17: MFG | K17: DIR | L17: =H17
A18: Staff Welfare - Medical Check Up | B18: 7515405 | C18: SGA | D18: =C18&"-"&B18 | E18: A504 | F18: Medical Check Up cost | H18: SP PD- WT | I18: B4103 | J18: MFG | K18: DIR | L18: =H18
A19: Staff Welfare - Uniform | B19: 7515406 | C19: SGA | D19: =C19&"-"&B19 | E19: A504 | F19: uniform costs | H19: SP PD- Plating | I19: B4105 | J19: MFG | K19: DIR | L19: =H19
A20: Staff Welfare - Safety Shoes | B20: 7515407 | C20: SGA | D20: =C20&"-"&B20 | E20: A504 | H20: SP PD- MS Insp. | I20: B4109 | J20: MFG | K20: DIR | L20: =H20
A21: Staff Welfare - Family Gathering / Anniversary | B21: 7515408 | C21: SGA | D21: =C21&"-"&B21 | E21: A504 | F21: Family Gathering / Anniversary | H21: SP PD- Insulator Sealing | I21: B4130 | J21: MFG | K21: DIR | L21: =H21
A22: Staff Welfare - Meals of canteen & other meals | B22: 7515409 | C22: SGA | D22: =C22&"-"&B22 | E22: A504 | F22: Meals of canteen & other meals cost | H22: SP PD- Assy | I22: B4110 | J22: MFG | K22: DIR | L22: =H22
A23: Staff Welfare - Kaizen & QCC reward | B23: 7515410 | C23: SGA | D23: =C23&"-"&B23 | E23: A504 | F23: an expense, arising from Kaizen and QCC acitivity | H23: SP-PD-Assy-Auto Assembly | I23: B4115 | J23: MFG | K23: DIR | L23: =H23
A24: Staff Welfare - Welfare Others | B24: 7515499 | C24: SGA | D24: =C24&"-"&B24 | E24: A504 | F24: an other welfare expense, arising besides the above welfare expense | H24: SP PD- Bending | I24: B4114 | J24: MFG | K24: DIR | L24: =H24
A25: Retirement Allowance | B25: 7516102 | C25: SGA | D25: =C25&"-"&B25 | E25: A505 | F25: employee retirement provission costs | H25: SP PD- Final Inspection | I25: B4120 | J25: MFG | K25: DIR | L25: =H25
A26: House Rent Allowance | B26: 7519101 | C26: SGA | D26: =C26&"-"&B26 | E26: A502 | F26: House Rent Allowance for expat | H26: SP PD- QC - OEM | I26: B4121 | J26: MFG | K26: DIR | L26: =H26
A27: Casual Staff Labor - Basic Salary | B27: 7521101 | C27: SGA | D27: =C27&"-"&B27 | E27: A501 | F27: All benefit for temporary worker | H27: PC PD- Injection | I27: B4410 | J27: MFG | K27: DIR | L27: =H27
A28: Casual Staff Labor - Overtime | B28: 7521102 | C28: SGA | D28: =C28&"-"&B28 | E28: A503 | F28: Overtime temporary worker | H28: PC PD- Assy | I28: B4430 | J28: MFG | K28: DIR | L28: =H28
A29: Personnel expense transferred | B29: 7571101 | C29: SGA | D29: =C29&"-"&B29 | E29: A506 | F29: Transfer Labor cost from one section into another section | H29: PC PD- QC | I29: B4440 | J29: MFG | K29: DIR | L29: =H29
A30: Depreciation-Building | B30: 7611100 | C30: SGA | D30: =C30&"-"&B30 | E30: A601 | F30: the amount of depreciation of tangible assets for building | H30: Plant Operation (Indirect Mfg) | I30: B5000 | J30: MFG | K30: IND | L30: =H30
A31: Depreciation-Machiney & equipment | B31: 7611300 | C31: SGA | D31: =C31&"-"&B31 | E31: A601 | F31: the amount of depreciation of tangible assets for machinery & factory equipment | H31: Production Office | I31: B5100 | J31: MFG | K31: IND | L31: =H31
A32: Depreciation-Lease Machinery & equipment | B32: 7611400 | C32: SGA | D32: =C32&"-"&B32 | E32: A601 | F32: the amount of depreciation of tangible assets for machinery & factory equipment (Leases) | H32: Production Office (SP) | I32: B5101 | J32: MFG | K32: IND | L32: =H32
... A42: Repair of Equipment | B42: 7641102 | C42: SGA | D42: =C42&"-"&B42 | E42: A1002 | F42: expenses for repair and maintenance tangible assets, intangible assets and other assets beside building | H42: Continuous Improvement | I42: B5007 | J42: MFG | K42: IND | L42: =H42
A43: Factory Supply Expense | B43: 7641103 | C43: SGA | D43: =C43&"-"&B43 | E43: A1099 | F43: All cost that arrising to support factory acitivity | H43: All | I43: B0000 | L43: =H43
A44: Calibration Cost | B44: 7641104 | C44: SGA | D44: =C44&"-"&B44 | E44: A1099 | F44: Cost of calibration for tools and equipment of factory and others
A45: Transportation Fee for employee | B45: 7651101 | C45: SGA | D45: =C45&"-"&B45 | E45: A801 | F45: Gasoline of company cars & expense for Local transportation
A46: Travel Expense-Domestic | B46: 7651102 | C46: SGA | D46: =C46&"-"&B46 | E46: A801 | F46: expenses for business trip, including allowance for business trip to an employee only for domestic travel
A47: Travel Expense-Oversea | B47: 7651103 | C47: SGA | D47: =C47&"-"&B47 | E47: A801 | F47: expenses for business trip, including allowance for business trip to an employee only for overseas travel
A48: Entertainment | B48: 7661101 | C48: SGA | D48: =C48&"-"&B48 | E48: A1001 | F48: the amount of expenses for the act of entertaining the business partner
A49: Amortization of Land & Building tax (PBB) | B49: 7671102 | C49: SGA | D49: =C49&"-"&B49 | E49: A1099 | F49: the amount of depreciation of intangible of Land & Building Tax (PBB)
...

Sheet COA
A1: Name | B1: COA AX | C1: Group Cost | D1: UNIQ | E1: COA Budget | F1: Description
A2: Salary for Commissioner | B2: 7511101 | C2: SGA | D2: =C2&"-"&B2 | E2: A502 | F2: Salary for Commissioner
A3: Salary for Director | B3: 7511102 | C3: SGA | D3: =C3&"-"&B3 | E3: A502 | F3: Salary for Director & Expat
A4: Staff Labor - Baslc Salary | B4: 7511103 | C4: SGA | D4: =C4&"-"&B4 | E4: A501 | F4: Basic Salary of permanent employee
A5: Staff Labor - Allowance | B5: 7511111 | C5: SGA | D5: =C5&"-"&B5 | E5: A501 | F5: Employee allowance
A6: Staff Labor - Tax allowance (art.21) | B6: 7511112 | C6: SGA | D6: =C6&"-"&B6 | E6: A501 | F6: Empployee Tax allowance
A7: Staff Labor - BPJS JK & JKK (1.19%) | B7: 7511121 | C7: SGA | D7: =C7&"-"&B7 | E7: A501 | F7: BPJS JK & JKK (death warrant, Accident Insurance)
A8: Staff Labor - BPJS Kesehatan (4%) | B8: 7511122 | C8: SGA | D8: =C8&"-"&B8 | E8: A501 | F8: BPJS health insurance
A9: Staff Overtime | B9: 7511201 | C9: SGA | D9: =C9&"-"&B9 | E9: A503 | F9: Overtime permanent employee
A10: Staff Welfare - BPJS Dana pensiun (2%) | B10: 7512111 | C10: SGA | D10: =C10&"-"&B10 | E10: A504 | F10: BPJS pension fund
A11: Staff Welfare - BPJS JHT (3.7%) | B11: 7512112 | C11: SGA | D11: =C11&"-"&B11 | E11: A504 | F11: BPJS Pension plan
A12: Staff Bonus / TAT | B12: 7514101 | C12: SGA | D12: =C12&"-"&B12 | E12: A501 | F12: Year-end allowance & Alpha
A13: Staff Ramadhan / THR | B13: 7514102 | C13: SGA | D13: =C13&"-"&B13 | E13: A501 | F13: Lebaran bonus
... A70: Cost of Samples | B70: 7461101 | C70: SGA | D70: =C70&"-"&B70 | E70: A499 | F70: Sample expense
A71: Sales - Insurance of Delivery or Shipment | B71: 7411105 | C71: SGA | D71: =C71&"-"&B71 | E71: A299
A72: Sales - Insurance of AR (Credit Insurance) | B72: 7471201 | C72: SGA | D72: =C72&"-"&B72 | E72: A299
A73: Sales - Royalty to NGK Group | B73: 7751101 | C73: SGA | D73: =C73&"-"&B73
A74: Sales - Royalty to Independence Party | B74: 7751102 | C74: SGA | D74: =C74&"-"&B74
A75: Import Duty-purchased FG from NGK group | B75: 7111211 | C75: MFG | D75: =C75&"-"&B75
A76: Import Duty-purchased KD&RM from NGK Japan | B76: 7111221 | C76: MFG | D76: =C76&"-"&B76
A77: Import Duty-purchased KD&RM from NGK Group(Not fromJP) | B77: 7111222 | C77: MFG | D77: =C77&"-"&B77
A78: Import Duty-purchased Comp Parts&RM from outside supplier | B78: 7111223 | C78: MFG | D78: =C78&"-"&B78
A79: Import Expense-purchased FG from NGK group | B79: 7111311 | C79: MFG | D79: =C79&"-"&B79
A80: Import Expense-purchased KD&RM from NGK Japan | B80: 7111321 | C80: MFG | D80: =C80&"-"&B80
A81: Import Expense-purchased KD&RM from NGK Group(Not fromJP) | B81: 7111322 | C81: MFG | D81: =C81&"-"&B81
A82: Import Expense-purchased Comp Parts&RM from outside supplier | B82: 7111323 | C82: MFG | D82: =C82&"-"&B82
A83: Cost of Factory Supply | B83: 7211101 | C83: MFG | D83: =C83&"-"&B83
A84: Cost of Chemical | B84: 7211102 | C84: MFG | D84: =C84&"-"&B84 | E84: 901 | F84: The expenses of Chemicals consumption
A85: Cost of Packaging | B85: 7211103 | C85: MFG | D85: =C85&"-"&B85
A86: Cost of Tooling | B86: 7221101 | C86: MFG | D86: =C86&"-"&B86 | E86: 302 | F86: The expenses of Tooling consumption
A87: Cost of Machinery parts | B87: 7221102 | C87: MFG | D87: =C87&"-"&B87 | E87: 301 | F87: The expenses of Spare Parts consumption
A88: Salary for Commissioner | B88: 7511101 | C88: MFG | D88: =C88&"-"&B88 | E88: 602 | F88: Salary for Commissioner
A89: Salary for Director | B89: 7511102 | C89: MFG | D89: =C89&"-"&B89 | E89: 602 | F89: Salary for Director & Expat
A90: Staff Labor - Baslc Salary | B90: 7511103 | C90: MFG | D90: =C90&"-"&B90 | E90: 601 | F90: Basic Salary of permanent employee
A91: Staff Labor - Allowance | B91: 7511111 | C91: MFG | D91: =C91&"-"&B91 | E91: 601 | F91: Employee allowance
A92: Staff Labor - Tax allowance (art.21) | B92: 7511112 | C92: MFG | D92: =C92&"-"&B92 | E92: 601 | F92: Empployee Tax allowance
A93: Staff Labor - BPJS JK & JKK (1.19%) | B93: 7511121 | C93: MFG | D93: =C93&"-"&B93 | E93: 601 | F93: BPJS JK & JKK (death warrant, Accident Insurance)
A94: Staff Labor - BPJS Kesehatan (4%) | B94: 7511122 | C94: MFG | D94: =C94&"-"&B94 | E94: 601 | F94: BPJS health insurance
A95: Staff Overtime | B95: 7511201 | C95: MFG | D95: =C95&"-"&B95 | E95: 603 | F95: Overtime permanent employee
A96: Staff Welfare - BPJS Dana pensiun (2%) | B96: 7512111 | C96: MFG | D96: =C96&"-"&B96 | E96: 604 | F96: BPJS pension fund
...

Sheet Password
A1: Password protect sheet = budget

Sheet Priority
A1: Priority Code | B1: Priority Name | C1: Description
A2: A | B2: Must | C2: If this is not done, the company or our team cannot continue its business.
A3: B | B3: Want to | C3: We want to do it as a team this term. we need it.
A4: C | B4: Challenge | C4: We want to do it for this term or the future. But it doesn't matter if it's not this term.
