Workbook
Name __j102: #REF!
Name _j102: #REF!
Name PRINT_AREA_MI: #REF!
Name Tgl: #REF!
Name tgll: #REF!
Name tr: #REF!
Name ﾃﾞｰﾀ海市: #REF!
Name ルピア: #REF!
Name 予算ﾚｰﾄ: #REF!
Name 今: #REF!
Name 印刷領域: #REF!
Name 品種別実績: #REF!
Name 実績レート: #REF!
Name 対象日数: #REF!
Name 技術開発経費181: #REF!
Name 日数: #REF!
Name 期: #REF!
Name 決算期区分: #REF!
Name 為替: #REF!
Name 為替レートEU: #REF!
Name 補助部門比率: #REF!
Name 補助部門費_設計以外181: #REF!
Name 補助部門費_設計以外182: #REF!
Name __j102: #REF!
Name _j102: #REF!
Name aa: #REF!
Name AB: #REF!
Name kissa: #REF!
Name kissakei: #REF!
Name kk: #REF!
Name Print_Area_MI: #REF!
Name PRINT_TITLES_MI: #REF!
Name ry: #REF!
Name Tgl: #REF!
Name tgll: #REF!
Name tr: #REF!
Name ﾃﾞｰﾀ海市: #REF!
Name ルピア: #REF!
Name 予算ﾚｰﾄ: #REF!
Name 今: #REF!
Name 出発: [6]支援計画・０４!$G$4:$G$171
Name 到着: [6]支援計画・０４!$F$4:$F$171
Name 印刷領域: #REF!
Name 品種別実績: #REF!
Name 商品群: [8]テーブル!$B$2:$B$7
Name 実績レート: #REF!
Name 対象日数: #REF!
Name 技術開発経費181: #REF!
Name 担当者: [8]テーブル!$F$2:$F$24
Name 日付: [6]支援計画・０４!$J$4:$CW$4
Name 日数: #REF!
Name 期: #REF!
Name 機能分類リスト: [12]開発計画品番リスト!#REF!
Name 比率: [13]調達計画!#REF!
Name 決算期区分: #REF!
Name 為替: #REF!
Name 為替レートEU: #REF!
Name 生産拠点: [8]テーブル!$C$2:$C$6
Name 立上年: [8]テーブル!$A$2:$A$11
Name 立上月: [8]テーブル!$D$2:$D$13

Sheet Data
A1: BUDGET TYPE | B1: Section Code (From) | C1: Section Name (From/Who Prepare) | D1: Section Code (To) | E1: Section Name (To/Who Use The Cost) | F1: COA-ID | G1: COA NAME | H1: DESCRIPTION | I1: GROUP SECTION | J1: GROUP COST | K1: 2024_10 | L1: 2024_11 | M1: 2024_12 | N1: 2025_01 | O1: 2025_02 | P1: 2025_03 | Q1: 2025_04 | R1: 2025_05 | S1: 2025_06 | T1: 2025_07 | U1: 2025_08 | V1: 2025_09 | W1: 2025_10 | X1: 2025_11 | Y1: 2025_12 | Z1: 2026_01 | AA1: 2026_02 | AB1: 2026_03 | AC1: TOTAL FY125 | AD1: TOTAL FY126 | AE1: TOTAL FY127 | AF1: TOTAL FY128 | AG1: Priority Category | AH1: BUDGET NO.
A2: BEX | B2: B2400 | C2: Information Technology | D2: B2400 | E2: Information Technology | F2: 7515401 | G2: Staff Welfare - Outpatient (Medical) | H2: Outpatient / Medical Expense | I2: ADM | J2: SGA | N2: 750000 | P2: 750000 | R2: 1500000 | T2: 750000 | V2: 750000 | X2: 750000 | Z2: 1500000 | AB2: 750000 | AC2: 1500000 | AD2: 6000000 | AE2: 6000000 | AF2: 6000000 | AG2: A | AH2: BEX26-2400-2400-001
A3: BEX | B3: B2400 | C3: Information Technology | D3: B2400 | E3: Information Technology | F3: 7515402 | G3: Staff Welfare - Hospitalization | H3: Hospitalization Expense | I3: ADM | J3: SGA | Q3: 25000000 | U3: 15000000 | Z3: 15000000 | AD3: 55000000 | AE3: 20000000 | AF3: 20000000 | AG3: A | AH3: BEX26-2400-2400-002
A4: BEX | B4: B2400 | C4: Information Technology | D4: B2400 | E4: Information Technology | F4: 7515404 | G4: Staff Welfare - Dental | H4: Dental Expense | I4: ADM | J4: SGA | N4: 4200000 | Q4: 500000 | S4: 500000 | V4: 1000000 | Y4: 500000 | AB4: 1000000 | AC4: 4200000 | AD4: 3500000 | AE4: 3500000 | AF4: 3500000 | AG4: A | AH4: BEX26-2400-2400-003
A5: BEX | B5: B2400 | C5: Information Technology | D5: B5800 | E5: Quality Assurance | F5: 7671103 | G5: License fee | H5: Google Apps License | I5: IND | J5: MFG | M5: 1941981 | N5: 1941981 | O5: 1941981 | P5: 1941981 | Q5: 2373532 | R5: 2373532 | S5: 2373532 | T5: 2373532 | U5: 2373532 | V5: 2373532 | W5: 2373532 | X5: 2373532 | Y5: 2373532 | Z5: 2373532 | AA5: 2373532 | AB5: 2373532 | AC5: 7767924 | AD5: 28482384 | AE5: 28482382 | AF5: 28482382 | AG5: A | AH5: BEX26-2400-5800-004
A6: BEX | B6: B2400 | C6: Information Technology | D6: B4105 | E6: SP PD- Plating | F6: 7671103 | G6: License fee | H6: Google Apps License | I6: DIR | J6: MFG | M6: 431551 | N6: 431551 | O6: 431551 | P6: 431551 | Q6: 431551 | R6: 431551 | S6: 431551 | T6: 431551 | U6: 431551 | V6: 431551 | W6: 431551 | X6: 431551 | Y6: 431551 | Z6: 431551 | AA6: 431551 | AB6: 431551 | AC6: 1726204 | AD6: 5178612 | AE6: 5178615 | AF6: 5178615 | AG6: A | AH6: BEX26-2400-4105-004
A7: BEX | B7: B2400 | C7: Information Technology | D7: B5130 | E7: Supply Procurement | F7: 7671103 | G7: License fee | H7: Google Apps License | I7: IND | J7: MFG | M7: 2589307 | N7: 2589307 | O7: 2589307 | P7: 2589307 | Q7: 2589307 | R7: 2589307 | S7: 2589307 | T7: 2589307 | U7: 2589307 | V7: 2589307 | W7: 2589307 | X7: 2589307 | Y7: 2589307 | Z7: 2589307 | AA7: 2589307 | AB7: 2589307 | AC7: 10357228 | AD7: 31071684 | AE7: 31071689 | AF7: 31071689 | AG7: A | AH7: BEX26-2400-5130-004
A8: BEX | B8: B2400 | C8: Information Technology | D8: B5500 | E8: Maintenance | F8: 7671103 | G8: License fee | H8: Google Apps License | I8: IND | J8: MFG | M8: 1941981 | N8: 1941981 | O8: 1941981 | P8: 1941981 | Q8: 1941981 | R8: 1941981 | S8: 1941981 | T8: 1941981 | U8: 1941981 | V8: 1941981 | W8: 1941981 | X8: 1941981 | Y8: 1941981 | Z8: 1941981 | AA8: 1941981 | AB8: 1941981 | AC8: 7767924 | AD8: 23303772 | AE8: 23303767 | AF8: 23303767 | AG8: A | AH8: BEX26-2400-5500-004
A9: BEX | B9: B2400 | C9: Information Technology | D9: B3100 | E9: Sales & MKTG Dept.- Automotive | F9: 7671103 | G9: License fee | H9: Google Apps License | I9: ADM | J9: SGA | M9: 431551 | N9: 431551 | O9: 431551 | P9: 431551 | Q9: 431551 | R9: 431551 | S9: 431551 | T9: 431551 | U9: 431551 | V9: 431551 | W9: 431551 | X9: 431551 | Y9: 431551 | Z9: 431551 | AA9: 431551 | AB9: 431551 | AC9: 1726204 | AD9: 5178612 | AE9: 5178615 | AF9: 5178615 | AG9: A | AH9: BEX26-2400-3100-004
A10: BEX | B10: B2400 | C10: Information Technology | D10: B3120 | E10: Sales - OES | F10: 7671103 | G10: License fee | H10: Google Apps License | I10: ADM | J10: SGA | M10: 431551 | N10: 431551 | O10: 431551 | P10: 431551 | Q10: 431551 | R10: 431551 | S10: 431551 | T10: 431551 | U10: 431551 | V10: 431551 | W10: 431551 | X10: 431551 | Y10: 431551 | Z10: 431551 | AA10: 431551 | AB10: 431551 | AC10: 1726204 | AD10: 5178612 | AE10: 5178615 | AF10: 5178615 | AG10: A | AH10: BEX26-2400-3120-004
A11: BEX | B11: B2400 | C11: Information Technology | D11: B3110 | E11: Sales - OEM | F11: 7671103 | G11: License fee | H11: Google Apps License | I11: ADM | J11: SGA | M11: 2589307 | N11: 2589307 | O11: 2589307 | P11: 2589307 | Q11: 2589307 | R11: 2589307 | S11: 2589307 | T11: 2589307 | U11: 2589307 | V11: 2589307 | W11: 2589307 | X11: 2589307 | Y11: 2589307 | Z11: 2589307 | AA11: 2589307 | AB11: 2589307 | AC11: 10357228 | AD11: 31071684 | AE11: 31071689 | AF11: 31071689 | AG11: A | AH11: BEX26-2400-3110-004
A12: BEX | B12: B2400 | C12: Information Technology | D12: B3130 | E12: Sales - IAM | F12: 7671103 | G12: License fee | H12: Google Apps License | I12: ADM | J12: SGA | M12: 3020859 | N12: 3020859 | O12: 3020859 | P12: 3020859 | Q12: 3020859 | R12: 3020859 | S12: 3020859 | T12: 3020859 | U12: 3020859 | V12: 3020859 | W12: 3020859 | X12: 3020859 | Y12: 3020859 | Z12: 3020859 | AA12: 3020859 | AB12: 3020859 | AC12: 12083436 | AD12: 36250308 | AE12: 36250304 | AF12: 36250304 | AG12: A | AH12: BEX26-2400-3130-004
A13: BEX | B13: B2400 | C13: Information Technology | D13: B5007 | E13: Continuous Improvement | F13: 7671103 | G13: License fee | H13: Google Apps License | I13: IND | J13: MFG | M13: 431551 | N13: 431551 | O13: 431551 | P13: 431551 | AC13: 1726204 | AG13: A | AH13: BEX26-2400-5007-004
A14: BEX | B14: B2400 | C14: Information Technology | D14: B5710 | E14: WH Dept.- KD & RM | F14: 7671103 | G14: License fee | H14: Google Apps License | I14: IND | J14: MFG | M14: 863102 | N14: 863102 | O14: 863102 | P14: 863102 | Q14: 863102 | R14: 863102 | S14: 863102 | T14: 863102 | U14: 863102 | V14: 863102 | W14: 863102 | X14: 863102 | Y14: 863102 | Z14: 863102 | AA14: 863102 | AB14: 863102 | AC14: 3452408 | AD14: 10357224 | AE14: 10357230 | AF14: 10357230 | AG14: A | AH14: BEX26-2400-5710-004
A15: BEX | B15: B2400 | C15: Information Technology | D15: B5100 | E15: Production Office | F15: 7671103 | G15: License fee | H15: Google Apps License | I15: IND | J15: MFG | M15: 1726205 | N15: 1726205 | O15: 1726205 | P15: 1726205 | Q15: 1726205 | R15: 1726205 | S15: 1726205 | T15: 1726205 | U15: 1726205 | V15: 1726205 | W15: 1726205 | X15: 1726205 | Y15: 1726205 | Z15: 1726205 | AA15: 1726205 | AB15: 1726205 | AC15: 6904820 | AD15: 20714460 | AE15: 20714460 | AF15: 20714460 | AG15: A | AH15: BEX26-2400-5100-004
A16: BEX | B16: B2400 | C16: Information Technology | D16: B2400 | E16: Information Technology | F16: 7671103 | G16: License fee | H16: Google Apps License | I16: ADM | J16: SGA | M16: 1294654 | N16: 1294654 | O16: 1294654 | P16: 1294654 | Q16: 1294654 | R16: 1294654 | S16: 1294654 | T16: 1294654 | U16: 1294654 | V16: 1294654 | W16: 1294654 | X16: 1294654 | Y16: 1294654 | Z16: 1294654 | AA16: 1294654 | AB16: 1294654 | AC16: 5178616 | AD16: 15535848 | AE16: 15535845 | AF16: 15535845 | AG16: A | AH16: BEX26-2400-2400-004
A17: BEX | B17: B2400 | C17: Information Technology | D17: B2230 | E17: Health, Safety & Environment | F17: 7671103 | G17: License fee | H17: Google Apps License | I17: ADM | J17: SGA | M17: 863102 | N17: 863102 | O17: 863102 | P17: 863102 | Q17: 863102 | R17: 863102 | S17: 863102 | T17: 863102 | U17: 863102 | V17: 863102 | W17: 863102 | X17: 863102 | Y17: 863102 | Z17: 863102 | AA17: 863102 | AB17: 863102 | AC17: 3452408 | AD17: 10357224 | AE17: 10357230 | AF17: 10357230 | AG17: A | AH17: BEX26-2400-2230-004
A18: BEX | B18: B2400 | C18: Information Technology | D18: B5900 | E18: Quality Control | F18: 7671103 | G18: License fee | H18: Google Apps License | I18: IND | J18: MFG | M18: 1078878 | N18: 1078878 | O18: 1078878 | P18: 1078878 | Q18: 1078878 | R18: 1078878 | S18: 1078878 | T18: 1078878 | U18: 1078878 | V18: 1078878 | W18: 1078878 | X18: 1078878 | Y18: 1078878 | Z18: 1078878 | AA18: 1078878 | AB18: 1078878 | AC18: 4315512 | AD18: 12946536 | AE18: 12946537 | AF18: 12946537 | AG18: A | AH18: BEX26-2400-5900-004
A19: BEX | B19: B2400 | C19: Information Technology | D19: B4102 | E19: SP PD- CM | F19: 7671103 | G19: License fee | H19: Google Apps License | I19: DIR | J19: MFG | M19: 647327 | N19: 647327 | O19: 647327 | P19: 647327 | Q19: 647327 | R19: 647327 | S19: 647327 | T19: 647327 | U19: 647327 | V19: 647327 | W19: 647327 | X19: 647327 | Y19: 647327 | Z19: 647327 | AA19: 647327 | AB19: 647327 | AC19: 2589308 | AD19: 7767924 | AE19: 7767922 | AF19: 7767922 | AG19: A | AH19: BEX26-2400-4102-004
A20: BEX | B20: B2400 | C20: Information Technology | D20: B5000 | E20: Plant Operation (Indirect Mfg) | F20: 7671103 | G20: License fee | H20: Google Apps License | I20: IND | J20: MFG | M20: 431551 | N20: 431551 | O20: 431551 | P20: 431551 | Q20: 431551 | R20: 431551 | S20: 431551 | T20: 431551 | U20: 431551 | V20: 431551 | W20: 431551 | X20: 431551 | Y20: 431551 | Z20: 431551 | AA20: 431551 | AB20: 431551 | AC20: 1726204 | AD20: 5178612 | AE20: 5178615 | AF20: 5178615 | AG20: A | AH20: BEX26-2400-5000-004
A21: BEX | B21: B2400 | C21: Information Technology | D21: B4410 | E21: PC PD- Injection | F21: 7671103 | G21: License fee | H21: Google Apps License | I21: DIR | J21: MFG | M21: 215776 | N21: 215776 | O21: 215776 | P21: 215776 | Q21: 215776 | R21: 215776 | S21: 215776 | T21: 215776 | U21: 215776 | V21: 215776 | W21: 215776 | X21: 215776 | Y21: 215776 | AC21: 863104 | AD21: 1941984 | AG21: A | AH21: BEX26-2400-4410-004
A22: BEX | B22: B2400 | C22: Information Technology | D22: B4130 | E22: SP PD- Insulator Sealing | F22: 7671103 | G22: License fee | H22: Google Apps License | I22: DIR | J22: MFG | M22: 215776 | N22: 215776 | O22: 215776 | P22: 215776 | Q22: 215776 | R22: 215776 | S22: 215776 | T22: 215776 | U22: 215776 | V22: 215776 | W22: 215776 | X22: 215776 | Y22: 215776 | Z22: 215776 | AA22: 215776 | AB22: 215776 | AC22: 863104 | AD22: 2589312 | AE22: 2589307 | AF22: 2589307 | AG22: A | AH22: BEX26-2400-4130-004
A23: BEX | B23: B2400 | C23: Information Technology | D23: B4121 | E23: SP PD- QC - OEM | F23: 7671103 | G23: License fee | H23: Google Apps License | I23: DIR | J23: MFG | M23: 215776 | N23: 215776 | O23: 215776 | P23: 215776 | AC23: 863104 | AG23: A | AH23: BEX26-2400-4121-004
A24: BEX | B24: B2400 | C24: Information Technology | D24: B5600 | E24: Production Engineering | F24: 7671103 | G24: License fee | H24: Google Apps License | I24: IND | J24: MFG | M24: 2373532 | N24: 2373532 | O24: 2373532 | P24: 2373532 | Q24: 2373532 | R24: 2373532 | S24: 2373532 | T24: 2373532 | U24: 2373532 | V24: 2373532 | W24: 2373532 | X24: 2373532 | Y24: 2373532 | Z24: 2373532 | AA24: 2373532 | AB24: 2373532 | AC24: 9494128 | AD24: 28482384 | AE24: 28482382 | AF24: 28482382 | AG24: A | AH24: BEX26-2400-5600-004
A25: BEX | B25: B2400 | C25: Information Technology | D25: B4110 | E25: SP PD- Assy | F25: 7671103 | G25: License fee | H25: Google Apps License | I25: DIR | J25: MFG | M25: 647327 | N25: 647327 | O25: 647327 | P25: 647327 | Q25: 647327 | R25: 647327 | S25: 647327 | T25: 647327 | U25: 647327 | V25: 647327 | W25: 647327 | X25: 647327 | Y25: 647327 | Z25: 647327 | AA25: 647327 | AB25: 647327 | AC25: 2589308 | AD25: 7767924 | AE25: 7767922 | AF25: 7767922 | AG25: A | AH25: BEX26-2400-4110-004
A26: BEX | B26: B2400 | C26: Information Technology | D26: B5104 | E26: Production Office (PC) | F26: 7671103 | G26: License fee | H26: Google Apps License | I26: IND | J26: MFG | M26: 431551 | N26: 431551 | O26: 431551 | P26: 431551 | Q26: 431551 | R26: 431551 | S26: 431551 | T26: 431551 | U26: 431551 | V26: 431551 | W26: 431551 | X26: 431551 | Y26: 431551 | Z26: 431551 | AA26: 431551 | AB26: 431551 | AC26: 1726204 | AD26: 5178612 | AE26: 5178615 | AF26: 5178615 | AG26: A | AH26: BEX26-2400-5104-004
A27: BEX | B27: B2400 | C27: Information Technology | D27: B1000 | E27: Top Management | F27: 7671103 | G27: License fee | H27: Google Apps License | I27: ADM | J27: SGA | M27: 431551 | N27: 431551 | O27: 431551 | P27: 431551 | Q27: 431551 | R27: 431551 | S27: 431551 | T27: 431551 | U27: 431551 | V27: 431551 | W27: 431551 | X27: 431551 | Y27: 431551 | Z27: 431551 | AA27: 431551 | AB27: 431551 | AC27: 1726204 | AD27: 5178612 | AE27: 5178615 | AF27: 5178615 | AG27: A | AH27: BEX26-2400-1000-004
A28: BEX | B28: B2400 | C28: Information Technology | D28: B2220 | E28: Human Resource | F28: 7671103 | G28: License fee | H28: Google Apps License | I28: ADM | J28: SGA | M28: 2373532 | N28: 2373532 | O28: 2373532 | P28: 2373532 | Q28: 2373532 | R28: 2373532 | S28: 2373532 | T28: 2373532 | U28: 2373532 | V28: 2373532 | W28: 2373532 | X28: 2373532 | Y28: 2373532 | Z28: 2373532 | AA28: 2373532 | AB28: 2373532 | AC28: 9494128 | AD28: 28482384 | AE28: 28482382 | AF28: 28482382 | AG28: A | AH28: BEX26-2400-2220-004
A29: BEX | B29: B2400 | C29: Information Technology | D29: B2210 | E29: General Affair | F29: 7671103 | G29: License fee | H29: Google Apps License | I29: ADM | J29: SGA | M29: 1510429 | N29: 1510429 | O29: 1510429 | P29: 1510429 | Q29: 1510429 | R29: 1510429 | S29: 1510429 | T29: 1510429 | U29: 1510429 | V29: 1510429 | W29: 1510429 | X29: 1510429 | Y29: 1510429 | Z29: 1510429 | AA29: 1510429 | AB29: 1510429 | AC29: 6041716 | AD29: 18125148 | AE29: 18125152 | AF29: 18125152 | AG29: A | AH29: BEX26-2400-2210-004
A30: BEX | B30: B2400 | C30: Information Technology | D30: B2300 | E30: Accounting & Finance | F30: 7671103 | G30: License fee | H30: Google Apps License | I30: ADM | J30: SGA | M30: 2373532 | N30: 2373532 | O30: 2373532 | P30: 2373532 | Q30: 2373532 | R30: 2373532 | S30: 2373532 | T30: 2373532 | U30: 2373532 | V30: 2373532 | W30: 2373532 | X30: 2373532 | Y30: 2373532 | Z30: 2373532 | AA30: 2373532 | AB30: 2373532 | AC30: 9494128 | AD30: 28482384 | AE30: 28482382 | AF30: 28482382 | AG30: A | AH30: BEX26-2400-2300-004
A31: BEX | B31: B2400 | C31: Information Technology | D31: B5101 | E31: Production Office (SP) | F31: 7671103 | G31: License fee | H31: Google Apps License | I31: IND | J31: MFG | M31: 431551 | N31: 431551 | O31: 431551 | P31: 431551 | Q31: 431551 | R31: 431551 | S31: 431551 | T31: 431551 | U31: 431551 | V31: 431551 | W31: 431551 | X31: 431551 | Y31: 431551 | Z31: 431551 | AA31: 431551 | AB31: 431551 | AC31: 1726204 | AD31: 5178612 | AE31: 5178615 | AF31: 5178615 | AG31: A | AH31: BEX26-2400-5101-004
A32: BEX | B32: B2400 | C32: Information Technology | D32: B3150 | E32: SCM - FG WH | F32: 7671103 | G32: License fee | H32: Google Apps License | I32: ADM | J32: SGA | M32: 1294654 | N32: 1294654 | O32: 1294654 | P32: 1294654 | Q32: 1294654 | R32: 1294654 | S32: 1294654 | T32: 1294654 | U32: 1294654 | V32: 1294654 | W32: 1294654 | X32: 1294654 | Y32: 1294654 | Z32: 1294654 | AA32: 1294654 | AB32: 1294654 | AC32: 5178616 | AD32: 15535848 | AE32: 15535845 | AF32: 15535845 | AG32: A | AH32: BEX26-2400-3150-004
A33: BEX | B33: B2400 | C33: Information Technology | D33: B4120 | E33: SP PD- Final Inspection | F33: 7671103 | G33: License fee | H33: Google Apps License | I33: DIR | J33: MFG | M33: 431551 | N33: 431551 | O33: 431551 | P33: 431551 | Q33: 647327 | R33: 647327 | S33: 647327 | T33: 647327 | U33: 647327 | V33: 647327 | W33: 647327 | X33: 647327 | Y33: 647327 | Z33: 647327 | AA33: 647327 | AB33: 647327 | AC33: 1726204 | AD33: 7767924 | AE33: 7767922 | AF33: 7767922 | AG33: A | AH33: BEX26-2400-4120-004
A34: BEX | B34: B2400 | C34: Information Technology | D34: B3160 | E34: Marketing | F34: 7671103 | G34: License fee | H34: Google Apps License | I34: ADM | J34: SGA | M34: 1510429 | N34: 1510429 | O34: 1510429 | P34: 1510429 | Q34: 1510429 | R34: 1510429 | S34: 1510429 | T34: 1510429 | U34: 1510429 | V34: 1510429 | W34: 1510429 | X34: 1510429 | Y34: 1510429 | Z34: 1510429 | AA34: 1510429 | AB34: 1510429 | AC34: 6041716 | AD34: 18125148 | AE34: 18125152 | AF34: 18125152 | AG34: A | AH34: BEX26-2400-3160-004
A35: BEX | B35: B2400 | C35: Information Technology | D35: B2400 | E35: Information Technology | F35: 7671103 | G35: License fee | H35: New License - 5 Microsoft License Windows 11 | I35: ADM | J35: SGA | Q35: 16000000 | AD35: 16000000 | AE35: 16000000 | AF35: 16000000 | AG35: C | AH35: BEX26-2400-2400-005
A36: BEX | B36: B2400 | C36: Information Technology | D36: B2400 | E36: Information Technology | F36: 7671103 | G36: License fee | H36: New License - Google Developer License Fee | I36: ADM | J36: SGA | Q36: 375000 | AD36: 375000 | AE36: 375000 | AF36: 375000 | AG36: A | AH36: BEX26-2400-2400-006
A37: BEX | B37: B2400 | C37: Information Technology | D37: B2400 | E37: Information Technology | F37: 7671103 | G37: License fee | H37: New License - IOS Developer Membership Fee | I37: ADM | J37: SGA | Q37: 123750 | R37: 123750 | S37: 123750 | T37: 123750 | U37: 123750 | V37: 123750 | W37: 123750 | X37: 123750 | Y37: 123750 | Z37: 123750 | AA37: 123750 | AB37: 123750 | AD37: 1485000 | AE37: 1485000 | AF37: 1485000 | AG37: A | AH37: BEX26-2400-2400-007
A38: BEX | B38: B2400 | C38: Information Technology | D38: B2400 | E38: Information Technology | F38: 7671103 | G38: License fee | H38: New License - Nitro PDF Pro | I38: ADM | J38: SGA | Q38: 350000 | R38: 350000 | S38: 350000 | T38: 350000 | U38: 350000 | V38: 350000 | W38: 350000 | X38: 350000 | Y38: 350000 | Z38: 350000 | AA38: 350000 | AB38: 350000 | AD38: 4200000 | AE38: 4200000 | AF38: 4200000 | AG38: B | AH38: BEX26-2400-2400-008
A39: BEX | B39: B2400 | C39: Information Technology | D39: B3110 | E39: Sales - OEM | F39: 7671103 | G39: License fee | H39: Nrimo Usage License | I39: ADM | J39: SGA | M39: 504217 | N39: 504217 | O39: 504217 | P39: 504217 | Q39: 504217 | R39: 504217 | S39: 504217 | T39: 504217 | U39: 504217 | V39: 504217 | W39: 504217 | X39: 504217 | Y39: 504217 | Z39: 504217 | AA39: 504217 | AB39: 504217 | AC39: 2016868 | AD39: 6050604 | AE39: 6050606 | AF39: 6050606 | AG39: A | AH39: BEX26-2400-3110-009
A40: BEX | B40: B2400 | C40: Information Technology | D40: B3160 | E40: Marketing | F40: 7671103 | G40: License fee | H40: Nrimo Usage License | I40: ADM | J40: SGA | M40: 252109 | N40: 252109 | O40: 252109 | P40: 252109 | Q40: 252109 | R40: 252109 | S40: 252109 | T40: 252109 | U40: 252109 | V40: 252109 | W40: 252109 | X40: 252109 | Y40: 252109 | Z40: 252109 | AA40: 252109 | AB40: 252109 | AC40: 1008436 | AD40: 3025308 | AE40: 3025303 | AF40: 3025303 | AG40: A | AH40: BEX26-2400-3160-009
...

Sheet V1
A1: This sheet is used for version checking, do not delete

Sheet Master
A1: COA AX | B1: Name COA AX | C1: COA AX | D1: COA AX | E1: Group Cost | F1: UNIQ | G1: COA Budget | H1: Description | J1: Name | K1: BNGK | L1: GROUP COST | M1: GROUP SECTION | N1: Name | P1: Code | Q1: Name | S1: Priority Code | T1: Priority Name | U1: Description
A2: 7511101 | B2: Salary for Commissioner | C2: 7511101 | D2: 7511101 | E2: SGA | F2: SGA-7511101 | G2: A502 | H2: Salary for Commissioner | J2: Top Management | K2: B1000 | L2: SGA | M2: ADM | N2: Top Management | P2: 53450 | Q2: NGK BUSI INDONESIA | S2: A | T2: Must | U2: If this is not done, the company or our team cannot continue its business.
A3: 7511102 | B3: Salary for Director | C3: 7511102 | D3: 7511102 | E3: SGA | F3: SGA-7511102 | G3: A502 | H3: Salary for Director & Expat | J3: Commissioner | K3: B1001 | L3: SGA | M3: ADM | N3: Commissioner | S3: B | T3: Want to | U3: We want to do it as a team this term. we need it.
A4: 7511103 | B4: Staff Labor - Baslc Salary | C4: 7511103 | D4: 7511103 | E4: SGA | F4: SGA-7511103 | G4: A501 | H4: Basic Salary of permanent employee | J4: Admin & HR | K4: B2200 | L4: SGA | M4: ADM | N4: Admin & HR | S4: C | T4: Challenge | U4: We want to do it for this term or the future. But it doesn't matter if it's not this term.
A5: 7511111 | B5: Staff Labor - Allowance | C5: 7511111 | D5: 7511111 | E5: SGA | F5: SGA-7511111 | G5: A501 | H5: Employee allowance | J5: General Affair | K5: B2210 | L5: SGA | M5: ADM | N5: General Affair
A6: 7511112 | B6: Staff Labor - Tax allowance (art.21) | C6: 7511112 | D6: 7511112 | E6: SGA | F6: SGA-7511112 | G6: A501 | H6: Empployee Tax allowance | J6: Human Resource | K6: B2220 | L6: SGA | M6: ADM | N6: Human Resource | P6: BEX
A7: 7511121 | B7: Staff Labor - BPJS JK & JKK (1.19%) | C7: 7511121 | D7: 7511121 | E7: SGA | F7: SGA-7511121 | G7: A501 | H7: BPJS JK & JKK (death warrant, Accident Insurance) | J7: Health, Safety & Environment | K7: B2230 | L7: SGA | M7: ADM | N7: Health, Safety & Environment | P7: BEL
A8: 7511122 | B8: Staff Labor - BPJS Kesehatan (4%) | C8: 7511122 | D8: 7511122 | E8: SGA | F8: SGA-7511122 | G8: A501 | H8: BPJS health insurance | J8: Accounting & Finance | K8: B2300 | L8: SGA | M8: ADM | N8: Accounting & Finance
A9: 7511201 | B9: Staff Overtime | C9: 7511201 | D9: 7511201 | E9: SGA | F9: SGA-7511201 | G9: A503 | H9: Overtime permanent employee | J9: Information Technology | K9: B2400 | L9: SGA | M9: ADM | N9: Information Technology
A10: 7512111 | B10: Staff Welfare - BPJS Dana pensiun (2%) | C10: 7512111 | D10: 7512111 | E10: SGA | F10: SGA-7512111 | G10: A504 | H10: BPJS pension fund | J10: Sales & MKTG Dept.- Automotive | K10: B3100 | L10: SGA | M10: ADM | N10: Sales & MKTG Dept.- Automotive
A11: 7512112 | B11: Staff Welfare - BPJS JHT (3.7%) | C11: 7512112 | D11: 7512112 | E11: SGA | F11: SGA-7512112 | G11: A504 | H11: BPJS Pension plan | J11: Marketing | K11: B3160 | L11: SGA | M11: ADM | N11: Marketing
A12: 7514101 | B12: Staff Bonus / TAT | C12: 7514101 | D12: 7514101 | E12: SGA | F12: SGA-7514101 | G12: A501 | H12: Year-end allowance & Alpha | J12: Sales - OEM | K12: B3110 | L12: SGA | M12: ADM | N12: Sales - OEM
A13: 7514102 | B13: Staff Ramadhan / THR | C13: 7514102 | D13: 7514102 | E13: SGA | F13: SGA-7514102 | G13: A501 | H13: Lebaran bonus | J13: Sales - OES | K13: B3120 | L13: SGA | M13: ADM | N13: Sales - OES
A14: 7515401 | B14: Staff Welfare - Outpatient (Medical) | C14: 7515401 | D14: 7515401 | E14: SGA | F14: SGA-7515401 | G14: A504 | H14: outpatient treatment costs | J14: Sales - IAM | K14: B3130 | L14: SGA | M14: ADM | N14: Sales - IAM
A15: 7515402 | B15: Staff Welfare - Hospitalization | C15: 7515402 | D15: 7515402 | E15: SGA | F15: SGA-7515402 | G15: A504 | H15: hospitalization costs | J15: Sales & MKTG Dept.- DID Chain | K15: B3172 | L15: SGA | M15: ADM | N15: Sales & MKTG Dept.- DID Chain
A16: 7515403 | B16: Staff Welfare - Glasses | C16: 7515403 | D16: 7515403 | E16: SGA | F16: SGA-7515403 | G16: A504 | H16: glasses costs | J16: SP PD- CF | K16: B4101 | L16: MFG | M16: DIR | N16: SP PD- CF
A17: 7515404 | B17: Staff Welfare - Dental | C17: 7515404 | D17: 7515404 | E17: SGA | F17: SGA-7515404 | G17: A504 | H17: dental costs | J17: SP PD- CM | K17: B4102 | L17: MFG | M17: DIR | N17: SP PD- CM
A18: 7515405 | B18: Staff Welfare - Medical Check Up | C18: 7515405 | D18: 7515405 | E18: SGA | F18: SGA-7515405 | G18: A504 | H18: Medical Check Up cost | J18: SP PD- WT | K18: B4103 | L18: MFG | M18: DIR | N18: SP PD- WT
A19: 7515406 | B19: Staff Welfare - Uniform | C19: 7515406 | D19: 7515406 | E19: SGA | F19: SGA-7515406 | G19: A504 | H19: uniform costs | J19: SP PD- Plating | K19: B4105 | L19: MFG | M19: DIR | N19: SP PD- Plating
A20: 7515407 | B20: Staff Welfare - Safety Shoes | C20: 7515407 | D20: 7515407 | E20: SGA | F20: SGA-7515407 | G20: A504 | J20: SP PD- MS Insp. | K20: B4109 | L20: MFG | M20: DIR | N20: SP PD- MS Insp.
A21: 7515408 | B21: Staff Welfare - Family Gathering / Anniversary | C21: 7515408 | D21: 7515408 | E21: SGA | F21: SGA-7515408 | G21: A504 | H21: Family Gathering / Anniversary | J21: SP PD- Insulator Sealing | K21: B4130 | L21: MFG | M21: DIR | N21: SP PD- Insulator Sealing
A22: 7515409 | B22: Staff Welfare - Meals of canteen & other meals | C22: 7515409 | D22: 7515409 | E22: SGA | F22: SGA-7515409 | G22: A504 | H22: Meals of canteen & other meals cost | J22: SP PD- Assy | K22: B4110 | L22: MFG | M22: DIR | N22: SP PD- Assy
A23: 7515410 | B23: Staff Welfare - Kaizen & QCC reward | C23: 7515410 | D23: 7515410 | E23: SGA | F23: SGA-7515410 | G23: A504 | H23: an expense, arising from Kaizen and QCC acitivity | J23: SP-PD-Assy-Auto Assembly | K23: B4115 | L23: MFG | M23: DIR | N23: SP-PD-Assy-Auto Assembly
A24: 7515499 | B24: Staff Welfare - Welfare Others | C24: 7515499 | D24: 7515499 | E24: SGA | F24: SGA-7515499 | G24: A504 | H24: an other welfare expense, arising besides the above welfare expense | J24: SP PD- Bending | K24: B4114 | L24: MFG | M24: DIR | N24: SP PD- Bending
A25: 7516102 | B25: Retirement Allowance | C25: 7516102 | D25: 7516102 | E25: SGA | F25: SGA-7516102 | G25: A505 | H25: employee retirement provission costs | J25: SP PD- Final Inspection | K25: B4120 | L25: MFG | M25: DIR | N25: SP PD- Final Inspection
A26: 7519101 | B26: House Rent Allowance | C26: 7519101 | D26: 7519101 | E26: SGA | F26: SGA-7519101 | G26: A502 | H26: House Rent Allowance for expat | J26: SP PD- QC - OEM | K26: B4121 | L26: MFG | M26: DIR | N26: SP PD- QC - OEM
A27: 7521101 | B27: Casual Staff Labor - Basic Salary | C27: 7521101 | D27: 7521101 | E27: SGA | F27: SGA-7521101 | G27: A501 | H27: All benefit for temporary worker | J27: PC PD- Injection | K27: B4410 | L27: MFG | M27: DIR | N27: PC PD- Injection
A28: 7521102 | B28: Casual Staff Labor - Overtime | C28: 7521102 | D28: 7521102 | E28: SGA | F28: SGA-7521102 | G28: A503 | H28: Overtime temporary worker | J28: PC PD- Assy | K28: B4430 | L28: MFG | M28: DIR | N28: PC PD- Assy
A29: 7571101 | B29: Personnel expense transferred | C29: 7571101 | D29: 7571101 | E29: SGA | F29: SGA-7571101 | G29: A506 | H29: Transfer Labor cost from one section into another section | J29: PC PD- QC | K29: B4440 | L29: MFG | M29: DIR | N29: PC PD- QC
A30: 7611100 | B30: Depreciation-Building | C30: 7611100 | D30: 7611100 | E30: SGA | F30: SGA-7611100 | G30: A601 | H30: the amount of depreciation of tangible assets for building | J30: Plant Operation (Indirect Mfg) | K30: B5000 | L30: MFG | M30: IND | N30: Plant Operation (Indirect Mfg)
A31: 7611300 | B31: Depreciation-Machiney & equipment | C31: 7611300 | D31: 7611300 | E31: SGA | F31: SGA-7611300 | G31: A601 | H31: the amount of depreciation of tangible assets for machinery & factory equipment | J31: Production Office | K31: B5100 | L31: MFG | M31: IND | N31: Production Office
A32: 7611400 | B32: Depreciation-Lease Machinery & equipment | C32: 7611400 | D32: 7611400 | E32: SGA | F32: SGA-7611400 | G32: A601 | H32: the amount of depreciation of tangible assets for machinery & factory equipment (Leases) | J32: Production Office (SP) | K32: B5101 | L32: MFG | M32: IND | N32: Production Office (SP)
... A42: 7641102 | B42: Repair of Equipment | C42: 7641102 | D42: 7641102 | E42: SGA | F42: SGA-7641102 | G42: A1002 | H42: expenses for repair and maintenance tangible assets, intangible assets and other assets beside building | J42: Continuous Improvement | K42: B5007 | L42: MFG | M42: IND | N42: Continuous Improvement
A43: 7641103 | B43: Factory Supply Expense | C43: 7641103 | D43: 7641103 | E43: SGA | F43: SGA-7641103 | G43: A1099 | H43: All cost that arrising to support factory acitivity | J43: All | K43: B0000 | N43: All
A44: 7641104 | B44: Calibration Cost | C44: 7641104 | D44: 7641104 | E44: SGA | F44: SGA-7641104 | G44: A1099 | H44: Cost of calibration for tools and equipment of factory and others
A45: 7651101 | B45: Transportation Fee for employee | C45: 7651101 | D45: 7651101 | E45: SGA | F45: SGA-7651101 | G45: A801 | H45: Gasoline of company cars & expense for Local transportation
A46: 7651102 | B46: Travel Expense-Domestic | C46: 7651102 | D46: 7651102 | E46: SGA | F46: SGA-7651102 | G46: A801 | H46: expenses for business trip, including allowance for business trip to an employee only for domestic travel
A47: 7651103 | B47: Travel Expense-Oversea | C47: 7651103 | D47: 7651103 | E47: SGA | F47: SGA-7651103 | G47: A801 | H47: expenses for business trip, including allowance for business trip to an employee only for overseas travel
A48: 7661101 | B48: Entertainment | C48: 7661101 | D48: 7661101 | E48: SGA | F48: SGA-7661101 | G48: A1001 | H48: the amount of expenses for the act of entertaining the business partner
A49: 7671102 | B49: Amortization of Land & Building tax (PBB) | C49: 7671102 | D49: 7671102 | E49: SGA | F49: SGA-7671102 | G49: A1099 | H49: the amount of depreciation of intangible of Land & Building Tax (PBB)
...

Sheet Priority
A1: Priority Code | B1: Priority Name | C1: Description
A2: A | B2: Must | C2: If this is not done, the company or our team cannot continue its business.
A3: B | B3: Want to | C3: We want to do it as a team this term. we need it.
A4: C | B4: Challenge | C4: We want to do it for this term or the future. But it doesn't matter if it's not this term.

Sheet Password
A1: Password protect sheet = budget
