Workbook
Name __j102: #REF!
Name __j102: #REF!
Name _1: #N/A
Name _j102: #REF!
Name _j102: #REF!
Name aa: #REF!
Name AB: #REF!
Name ai: #REF!
Name as: #REF!
Name assit: #REF!
Name b: #REF!
Name BC: #REF!
Name BI: #REF!
Name BO: #REF!
Name cc: #REF!
Name CH: #REF!
Name CI: #REF!
Name Ck_for: #REF!
Name Ck_in: #REF!
Name Ck_out: #REF!
Name d: #REF!
Name dd: #REF!
Name DF: #REF!
Name e: #REF!
Name ee: #REF!
Name eXCRATE: #REF!
Name exrate: #REF!
Name F: #REF!
Name fcb: #REF!
Name FG: #REF!
Name g: #REF!
Name gg: #REF!
Name HF: #REF!
Name kissa: #REF!
Name kissakei: #REF!
Name kk: #REF!
Name kkk: #REF!
Name kkkk: #REF!
Name l: #REF!
Name L_01: #REF!
Name LIA: #REF!
Name LILI: #REF!
Name LINA: #REF!
Name m: #REF!
Name Manufacturing: #REF!
Name MR: #REF!
Name nittk: #REF!
Name nittk_ok: #REF!
Name nittoukei: #REF!
Name PRINT_AREA_MI: #REF!
Name PRINT_AREA_MI: #REF!
Name PRINT_TITLES_MI: #REF!
Name ry: #REF!
Name ryohikei: #REF!
Name S: #REF!
Name sais: #REF!
Name saisyuu: #REF!
Name se: #REF!
Name sett: #REF!
Name setta: #REF!

Sheet Data
A1: BUDGET TYPE | B1: Section Code (From) | C1: Section Name (From/Who Prepare) | D1: Section Code (To) | E1: Section Name (To/Who Use The Cost) | F1: COA-ID | G1: COA NAME | H1: DESCRIPTION | I1: GROUP SECTION | J1: GROUP COST | K1: 2022_10 | L1: 2022_11 | M1: 2022_12 | N1: 2023_01 | O1: 2023_02 | P1: 2023_03 | Q1: 2023_04 | R1: 2023_05 | S1: 2023_06 | T1: 2023_07 | U1: 2023_08 | V1: 2023_09 | W1: 2023_10 | X1: 2023_11 | Y1: 2023_12 | Z1: 2024_01 | AA1: 2024_02 | AB1: 2024_03 | AC1: TOTAL FY123 | AD1: TOTAL FY124 | AE1: TOTAL FY125 | AF1: TOTAL FY126 | AG1: Priority Category | AH1: BUDGET NO.
A2: BEX | B2: =_xlfn.IFNA(VLOOKUP(C2,Master!$J:$K,2,0),"") -> B5710 | C2: WH Dept.- KD & RM | D2: =_xlfn.IFNA(VLOOKUP(E2,Master!$J:$K,2,0),"") -> B5710 | E2: WH Dept.- KD & RM | F2: =_xlfn.IFNA(VLOOKUP(G2,Master!B:C,2,0),"") -> 7111211 | G2: Import Duty-purchased FG from NGK group | H2: Import Duty-purchased FG from NGK group | I2: =_xlfn.IFNA(VLOOKUP(E2,Master!$J:$M,4,0),"") -> IND | J2: =_xlfn.IFNA(VLOOKUP($E2,Master!$J:$M,3,0),"") -> MFG | M2: 3535693 | N2: 14288218 | O2: 20231958 | P2: 10038555 | Q2: 9867717 | R2: 2397052 | S2: 2253200 | T2: 2574627 | U2: 2413914 | V2: 2253200 | W2: 3217480 | X2: 3522045 | Y2: 2413914 | Z2: 2735340 | AA2: 3378194 | AB2: 2896054 | AC2: =SUM(K2:P2) -> 48094424 | AD2: =SUM(Q2:AB2) -> 39922737 | AE2: 31986795 | AF2: 33926233
A3: BEX | B3: =_xlfn.IFNA(VLOOKUP(C3,Master!$J:$K,2,0),"") -> B5710 | C3: WH Dept.- KD & RM | D3: =_xlfn.IFNA(VLOOKUP(E3,Master!$J:$K,2,0),"") -> B5710 | E3: WH Dept.- KD & RM | F3: =_xlfn.IFNA(VLOOKUP(G3,Master!B:C,2,0),"") -> 7111212 | G3: Import Duty-purchased FG from outside supplier | H3: Import Duty-purchased FG from outside supplier | I3: =_xlfn.IFNA(VLOOKUP(E3,Master!$J:$M,4,0),"") -> IND | J3: =_xlfn.IFNA(VLOOKUP($E3,Master!$J:$M,3,0),"") -> MFG | M3: 3535693 | N3: 14288218 | O3: 20231958 | P3: 10038555 | Q3: 9867717 | R3: 2397052 | S3: 2253200 | T3: 2574627 | U3: 2413914 | V3: 2253200 | W3: 3217480 | X3: 3522045 | Y3: 2413914 | Z3: 2735340 | AA3: 3378194 | AB3: 2896054 | AC3: =SUM(K3:P3) -> 48094424 | AD3: =SUM(Q3:AB3) -> 39922737 | AE3: 31986795 | AF3: 33926233
A4: BEX | B4: =_xlfn.IFNA(VLOOKUP(C4,Master!$J:$K,2,0),"") -> B5710 | C4: WH Dept.- KD & RM | D4: =_xlfn.IFNA(VLOOKUP(E4,Master!$J:$K,2,0),"") -> B5710 | E4: WH Dept.- KD & RM | F4: =_xlfn.IFNA(VLOOKUP(G4,Master!B:C,2,0),"") -> 7111221 | G4: Import Duty-purchased KD&RM from NGK Japan | H4: Import Duty-purchased KD&RM from NGK Japan | I4: =_xlfn.IFNA(VLOOKUP(E4,Master!$J:$M,4,0),"") -> IND | J4: =_xlfn.IFNA(VLOOKUP($E4,Master!$J:$M,3,0),"") -> MFG | M4: 3535693 | N4: 14288218 | O4: 20231958 | P4: 10038555 | Q4: 9867717 | R4: 2397052 | S4: 2253200 | T4: 2574627 | U4: 2413914 | V4: 2253200 | W4: 3217480 | X4: 3522045 | Y4: 2413914 | Z4: 2735340 | AA4: 3378194 | AB4: 2896054 | AC4: =SUM(K4:P4) -> 48094424 | AD4: =SUM(Q4:AB4) -> 39922737 | AE4: 31986795 | AF4: 33926233
A5: BEX | B5: =_xlfn.IFNA(VLOOKUP(C5,Master!$J:$K,2,0),"") -> B5710 | C5: WH Dept.- KD & RM | D5: =_xlfn.IFNA(VLOOKUP(E5,Master!$J:$K,2,0),"") -> B5710 | E5: WH Dept.- KD & RM | F5: =_xlfn.IFNA(VLOOKUP(G5,Master!B:C,2,0),"") -> 7111222 | G5: Import Duty-purchased KD&RM from NGK Group(Not fromJP) | H5: Import Duty-purchased KD&RM from NGK Group(Not fromJP) | I5: =_xlfn.IFNA(VLOOKUP(E5,Master!$J:$M,4,0),"") -> IND | J5: =_xlfn.IFNA(VLOOKUP($E5,Master!$J:$M,3,0),"") -> MFG | M5: 3535693 | N5: 14288218 | O5: 20231958 | P5: 10038555 | Q5: 9867717 | R5: 2397052 | S5: 2253200 | T5: 2574627 | U5: 2413914 | V5: 2253200 | W5: 3217480 | X5: 3522045 | Y5: 2413914 | Z5: 2735340 | AA5: 3378194 | AB5: 2896054 | AC5: =SUM(K5:P5) -> 48094424 | AD5: =SUM(Q5:AB5) -> 39922737 | AE5: 31986795 | AF5: 33926233
A6: BEX | B6: =_xlfn.IFNA(VLOOKUP(C6,Master!$J:$K,2,0),"") -> B5710 | C6: WH Dept.- KD & RM | D6: =_xlfn.IFNA(VLOOKUP(E6,Master!$J:$K,2,0),"") -> B5710 | E6: WH Dept.- KD & RM | F6: =_xlfn.IFNA(VLOOKUP(G6,Master!B:C,2,0),"") -> 7111223 | G6: Import Duty-purchased Comp Parts&RM from outside supplier | H6: Import Duty-purchased Comp Parts&RM from outside supplier | I6: =_xlfn.IFNA(VLOOKUP(E6,Master!$J:$M,4,0),"") -> IND | J6: =_xlfn.IFNA(VLOOKUP($E6,Master!$J:$M,3,0),"") -> MFG | M6: 3535693 | N6: 14288218 | O6: 20231958 | P6: 10038555 | Q6: 9867717 | R6: 2397052 | S6: 2253200 | T6: 2574627 | U6: 2413914 | V6: 2253200 | W6: 3217480 | X6: 3522045 | Y6: 2413914 | Z6: 2735340 | AA6: 3378194 | AB6: 2896054 | AC6: =SUM(K6:P6) -> 48094424 | AD6: =SUM(Q6:AB6) -> 39922737 | AE6: 31986795 | AF6: 33926233
B7: =_xlfn.IFNA(VLOOKUP(C7,Master!$J:$K,2,0),"") | D7: =_xlfn.IFNA(VLOOKUP(E7,Master!$J:$K,2,0),"") | F7: =_xlfn.IFNA(VLOOKUP(G7,Master!B:C,2,0),"") | I7: =_xlfn.IFNA(VLOOKUP(E7,Master!$J:$M,4,0),"") | J7: =_xlfn.IFNA(VLOOKUP($E7,Master!$J:$M,3,0),"") | AC7: =SUM(K7:P7) -> 0 | AD7: =SUM(Q7:AB7) -> 0
B8: =_xlfn.IFNA(VLOOKUP(C8,Master!$J:$K,2,0),"") | D8: =_xlfn.IFNA(VLOOKUP(E8,Master!$J:$K,2,0),"") | F8: =_xlfn.IFNA(VLOOKUP(G8,Master!B:C,2,0),"") | I8: =_xlfn.IFNA(VLOOKUP(E8,Master!$J:$M,4,0),"") | J8: =_xlfn.IFNA(VLOOKUP($E8,Master!$J:$M,3,0),"") | AC8: =SUM(K8:P8) -> 0 | AD8: =SUM(Q8:AB8) -> 0
B9: =_xlfn.IFNA(VLOOKUP(C9,Master!$J:$K,2,0),"") | D9: =_xlfn.IFNA(VLOOKUP(E9,Master!$J:$K,2,0),"") | F9: =_xlfn.IFNA(VLOOKUP(G9,Master!B:C,2,0),"") | I9: =_xlfn.IFNA(VLOOKUP(E9,Master!$J:$M,4,0),"") | J9: =_xlfn.IFNA(VLOOKUP($E9,Master!$J:$M,3,0),"") | AC9: =SUM(K9:P9) -> 0 | AD9: =SUM(Q9:AB9) -> 0
B10: =_xlfn.IFNA(VLOOKUP(C10,Master!$J:$K,2,0),"") | D10: =_xlfn.IFNA(VLOOKUP(E10,Master!$J:$K,2,0),"") | F10: =_xlfn.IFNA(VLOOKUP(G10,Master!B:C,2,0),"") | I10: =_xlfn.IFNA(VLOOKUP(E10,Master!$J:$M,4,0),"") | J10: =_xlfn.IFNA(VLOOKUP($E10,Master!$J:$M,3,0),"") | AC10: =SUM(K10:P10) -> 0 | AD10: =SUM(Q10:AB10) -> 0
B11: =_xlfn.IFNA(VLOOKUP(C11,Master!$J:$K,2,0),"") | D11: =_xlfn.IFNA(VLOOKUP(E11,Master!$J:$K,2,0),"") | F11: =_xlfn.IFNA(VLOOKUP(G11,Master!B:C,2,0),"") | I11: =_xlfn.IFNA(VLOOKUP(E11,Master!$J:$M,4,0),"") | J11: =_xlfn.IFNA(VLOOKUP($E11,Master!$J:$M,3,0),"") | AC11: =SUM(K11:P11) -> 0 | AD11: =SUM(Q11:AB11) -> 0
B12: =_xlfn.IFNA(VLOOKUP(C12,Master!$J:$K,2,0),"") | D12: =_xlfn.IFNA(VLOOKUP(E12,Master!$J:$K,2,0),"") | F12: =_xlfn.IFNA(VLOOKUP(G12,Master!B:C,2,0),"") | I12: =_xlfn.IFNA(VLOOKUP(E12,Master!$J:$M,4,0),"") | J12: =_xlfn.IFNA(VLOOKUP($E12,Master!$J:$M,3,0),"") | AC12: =SUM(K12:P12) -> 0 | AD12: =SUM(Q12:AB12) -> 0
B13: =_xlfn.IFNA(VLOOKUP(C13,Master!$J:$K,2,0),"") | D13: =_xlfn.IFNA(VLOOKUP(E13,Master!$J:$K,2,0),"") | F13: =_xlfn.IFNA(VLOOKUP(G13,Master!B:C,2,0),"") | I13: =_xlfn.IFNA(VLOOKUP(E13,Master!$J:$M,4,0),"") | J13: =_xlfn.IFNA(VLOOKUP($E13,Master!$J:$M,3,0),"") | AC13: =SUM(K13:P13) -> 0 | AD13: =SUM(Q13:AB13) -> 0
B14: =_xlfn.IFNA(VLOOKUP(C14,Master!$J:$K,2,0),"") | D14: =_xlfn.IFNA(VLOOKUP(E14,Master!$J:$K,2,0),"") | F14: =_xlfn.IFNA(VLOOKUP(G14,Master!B:C,2,0),"") | I14: =_xlfn.IFNA(VLOOKUP(E14,Master!$J:$M,4,0),"") | J14: =_xlfn.IFNA(VLOOKUP($E14,Master!$J:$M,3,0),"") | AC14: =SUM(K14:P14) -> 0 | AD14: =SUM(Q14:AB14) -> 0
B15: =_xlfn.IFNA(VLOOKUP(C15,Master!$J:$K,2,0),"") | D15: =_xlfn.IFNA(VLOOKUP(E15,Master!$J:$K,2,0),"") | F15: =_xlfn.IFNA(VLOOKUP(G15,Master!B:C,2,0),"") | I15: =_xlfn.IFNA(VLOOKUP(E15,Master!$J:$M,4,0),"") | J15: =_xlfn.IFNA(VLOOKUP($E15,Master!$J:$M,3,0),"") | AC15: =SUM(K15:P15) -> 0 | AD15: =SUM(Q15:AB15) -> 0
B16: =_xlfn.IFNA(VLOOKUP(C16,Master!$J:$K,2,0),"") | D16: =_xlfn.IFNA(VLOOKUP(E16,Master!$J:$K,2,0),"") | F16: =_xlfn.IFNA(VLOOKUP(G16,Master!B:C,2,0),"") | I16: =_xlfn.IFNA(VLOOKUP(E16,Master!$J:$M,4,0),"") | J16: =_xlfn.IFNA(VLOOKUP($E16,Master!$J:$M,3,0),"") | AC16: =SUM(K16:P16) -> 0 | AD16: =SUM(Q16:AB16) -> 0
B17: =_xlfn.IFNA(VLOOKUP(C17,Master!$J:$K,2,0),"") | D17: =_xlfn.IFNA(VLOOKUP(E17,Master!$J:$K,2,0),"") | F17: =_xlfn.IFNA(VLOOKUP(G17,Master!B:C,2,0),"") | I17: =_xlfn.IFNA(VLOOKUP(E17,Master!$J:$M,4,0),"") | J17: =_xlfn.IFNA(VLOOKUP($E17,Master!$J:$M,3,0),"") | AC17: =SUM(K17:P17) -> 0 | AD17: =SUM(Q17:AB17) -> 0
B18: =_xlfn.IFNA(VLOOKUP(C18,Master!$J:$K,2,0),"") | D18: =_xlfn.IFNA(VLOOKUP(E18,Master!$J:$K,2,0),"") | F18: =_xlfn.IFNA(VLOOKUP(G18,Master!B:C,2,0),"") | I18: =_xlfn.IFNA(VLOOKUP(E18,Master!$J:$M,4,0),"") | J18: =_xlfn.IFNA(VLOOKUP($E18,Master!$J:$M,3,0),"") | AC18: =SUM(K18:P18) -> 0 | AD18: =SUM(Q18:AB18) -> 0
... B451: =_xlfn.IFNA(VLOOKUP(C451,Master!$J:$K,2,0),"") | D451: =_xlfn.IFNA(VLOOKUP(E451,Master!$J:$K,2,0),"") | F451: =_xlfn.IFNA(VLOOKUP(G451,Master!B:C,2,0),"") | I451: =_xlfn.IFNA(VLOOKUP(E451,Master!$J:$M,4,0),"") | J451: =_xlfn.IFNA(VLOOKUP($E451,Master!$J:$M,3,0),"") | AC451: =SUM(K451:P451) -> 0 | AD451: =SUM(Q451:AB451) -> 0
B452: =_xlfn.IFNA(VLOOKUP(C452,Master!$J:$K,2,0),"") | F452: =_xlfn.IFNA(VLOOKUP(G452,Master!B:C,2,0),"") | I452: =_xlfn.IFNA(VLOOKUP(E452,Master!$J:$M,4,0),"") | J452: =_xlfn.IFNA(VLOOKUP($E452,Master!$J:$M,3,0),"") | AC452: =SUM(K452:P452) -> 0 | AD452: =SUM(Q452:AB452) -> 0
B453: =_xlfn.IFNA(VLOOKUP(C453,Master!$J:$K,2,0),"") | F453: =_xlfn.IFNA(VLOOKUP(G453,Master!B:C,2,0),"") | I453: =_xlfn.IFNA(VLOOKUP(E453,Master!$J:$M,4,0),"") | J453: =_xlfn.IFNA(VLOOKUP($E453,Master!$J:$M,3,0),"") | AC453: =SUM(K453:P453) -> 0 | AD453: =SUM(Q453:AB453) -> 0
B454: =_xlfn.IFNA(VLOOKUP(C454,Master!$J:$K,2,0),"") | F454: =_xlfn.IFNA(VLOOKUP(G454,Master!B:C,2,0),"") | I454: =_xlfn.IFNA(VLOOKUP(E454,Master!$J:$M,4,0),"") | J454: =_xlfn.IFNA(VLOOKUP($E454,Master!$J:$M,3,0),"") | AC454: =SUM(K454:P454) -> 0 | AD454: =SUM(Q454:AB454) -> 0
B455: =_xlfn.IFNA(VLOOKUP(C455,Master!$J:$K,2,0),"") | F455: =_xlfn.IFNA(VLOOKUP(G455,Master!B:C,2,0),"") | I455: =_xlfn.IFNA(VLOOKUP(E455,Master!$J:$M,4,0),"") | J455: =_xlfn.IFNA(VLOOKUP($E455,Master!$J:$M,3,0),"") | AC455: =SUM(K455:P455) -> 0 | AD455: =SUM(Q455:AB455) -> 0
B456: =_xlfn.IFNA(VLOOKUP(C456,Master!$J:$K,2,0),"") | F456: =_xlfn.IFNA(VLOOKUP(G456,Master!B:C,2,0),"") | I456: =_xlfn.IFNA(VLOOKUP(E456,Master!$J:$M,4,0),"") | J456: =_xlfn.IFNA(VLOOKUP($E456,Master!$J:$M,3,0),"") | AC456: =SUM(K456:P456) -> 0 | AD456: =SUM(Q456:AB456) -> 0
B457: =_xlfn.IFNA(VLOOKUP(C457,Master!$J:$K,2,0),"") | F457: =_xlfn.IFNA(VLOOKUP(G457,Master!B:C,2,0),"") | I457: =_xlfn.IFNA(VLOOKUP(E457,Master!$J:$M,4,0),"") | J457: =_xlfn.IFNA(VLOOKUP($E457,Master!$J:$M,3,0),"") | AC457: =SUM(K457:P457) -> 0 | AD457: =SUM(Q457:AB457) -> 0
B458: =_xlfn.IFNA(VLOOKUP(C458,Master!$J:$K,2,0),"") | F458: =_xlfn.IFNA(VLOOKUP(G458,Master!B:C,2,0),"") | I458: =_xlfn.IFNA(VLOOKUP(E458,Master!$J:$M,4,0),"") | J458: =_xlfn.IFNA(VLOOKUP($E458,Master!$J:$M,3,0),"") | AC458: =SUM(K458:P458) -> 0 | AD458: =SUM(Q458:AB458) -> 0
B459: =_xlfn.IFNA(VLOOKUP(C459,Master!$J:$K,2,0),"") | F459: =_xlfn.IFNA(VLOOKUP(G459,Master!B:C,2,0),"") | I459: =_xlfn.IFNA(VLOOKUP(E459,Master!$J:$M,4,0),"") | J459: =_xlfn.IFNA(VLOOKUP($E459,Master!$J:$M,3,0),"") | AC459: =SUM(K459:P459) -> 0 | AD459: =SUM(Q459:AB459) -> 0
B460: =_xlfn.IFNA(VLOOKUP(C460,Master!$J:$K,2,0),"") | F460: =_xlfn.IFNA(VLOOKUP(G460,Master!B:C,2,0),"") | I460: =_xlfn.IFNA(VLOOKUP(E460,Master!$J:$M,4,0),"") | J460: =_xlfn.IFNA(VLOOKUP($E460,Master!$J:$M,3,0),"") | AC460: =SUM(K460:P460) -> 0 | AD460: =SUM(Q460:AB460) -> 0
B461: =_xlfn.IFNA(VLOOKUP(C461,Master!$J:$K,2,0),"") | F461: =_xlfn.IFNA(VLOOKUP(G461,Master!B:C,2,0),"") | I461: =_xlfn.IFNA(VLOOKUP(E461,Master!$J:$M,4,0),"") | J461: =_xlfn.IFNA(VLOOKUP($E461,Master!$J:$M,3,0),"") | AC461: =SUM(K461:P461) -> 0 | AD461: =SUM(Q461:AB461) -> 0
B462: =_xlfn.IFNA(VLOOKUP(C462,Master!$J:$K,2,0),"") | F462: =_xlfn.IFNA(VLOOKUP(G462,Master!B:C,2,0),"") | I462: =_xlfn.IFNA(VLOOKUP(E462,Master!$J:$M,4,0),"") | J462: =_xlfn.IFNA(VLOOKUP($E462,Master!$J:$M,3,0),"") | AC462: =SUM(K462:P462) -> 0 | AD462: =SUM(Q462:AB462) -> 0
B463: =_xlfn.IFNA(VLOOKUP(C463,Master!$J:$K,2,0),"") | F463: =_xlfn.IFNA(VLOOKUP(G463,Master!B:C,2,0),"") | I463: =_xlfn.IFNA(VLOOKUP(E463,Master!$J:$M,4,0),"") | J463: =_xlfn.IFNA(VLOOKUP($E463,Master!$J:$M,3,0),"") | AC463: =SUM(K463:P463) -> 0 | AD463: =SUM(Q463:AB463) -> 0
... B513: =_xlfn.IFNA(VLOOKUP(C513,Master!$J:$K,2,0),"") | F513: =_xlfn.IFNA(VLOOKUP(G513,Master!B:C,2,0),"") | I513: =_xlfn.IFNA(VLOOKUP(E513,Master!$J:$M,4,0),"") | J513: =_xlfn.IFNA(VLOOKUP($E513,Master!$J:$M,3,0),"") | AC513: =SUM(K513:P513) -> 0 | AD513: =SUM(Q513:AB513) -> 0
B514: =_xlfn.IFNA(VLOOKUP(C514,Master!$J:$K,2,0),"") | F514: =_xlfn.IFNA(VLOOKUP(G514,Master!B:C,2,0),"") | AC514: =SUM(K514:P514) -> 0 | AD514: =SUM(Q514:AB514) -> 0
B515: =_xlfn.IFNA(VLOOKUP(C515,Master!$J:$K,2,0),"") | F515: =_xlfn.IFNA(VLOOKUP(G515,Master!B:C,2,0),"") | AC515: =SUM(K515:P515) -> 0 | AD515: =SUM(Q515:AB515) -> 0
B516: =_xlfn.IFNA(VLOOKUP(C516,Master!$J:$K,2,0),"") | F516: =_xlfn.IFNA(VLOOKUP(G516,Master!B:C,2,0),"") | AC516: =SUM(K516:P516) -> 0 | AD516: =SUM(Q516:AB516) -> 0
B517: =_xlfn.IFNA(VLOOKUP(C517,Master!$J:$K,2,0),"") | F517: =_xlfn.IFNA(VLOOKUP(G517,Master!B:C,2,0),"") | AC517: =SUM(K517:P517) -> 0 | AD517: =SUM(Q517:AB517) -> 0
B518: =_xlfn.IFNA(VLOOKUP(C518,Master!$J:$K,2,0),"") | F518: =_xlfn.IFNA(VLOOKUP(G518,Master!B:C,2,0),"") | AC518: =SUM(K518:P518) -> 0 | AD518: =SUM(Q518:AB518) -> 0
B519: =_xlfn.IFNA(VLOOKUP(C519,Master!$J:$K,2,0),"") | F519: =_xlfn.IFNA(VLOOKUP(G519,Master!B:C,2,0),"") | AC519: =SUM(K519:P519) -> 0 | AD519: =SUM(Q519:AB519) -> 0
B520: =_xlfn.IFNA(VLOOKUP(C520,Master!$J:$K,2,0),"") | F520: =_xlfn.IFNA(VLOOKUP(G520,Master!B:C,2,0),"") | AC520: =SUM(K520:P520) -> 0 | AD520: =SUM(Q520:AB520) -> 0
B521: =_xlfn.IFNA(VLOOKUP(C521,Master!$J:$K,2,0),"") | F521: =_xlfn.IFNA(VLOOKUP(G521,Master!B:C,2,0),"") | AC521: =SUM(K521:P521) -> 0 | AD521: =SUM(Q521:AB521) -> 0
...

Sheet Master
A1: COA AX | B1: Name COA AX | C1: COA AX | D1: COA AX | E1: Group Cost | F1: UNIQ | G1: COA Budget | H1: Description | J1: Name | K1: BNGK | L1: GROUP COST | M1: GROUP SECTION | N1: Name | P1: Code | Q1: Name | S1: Priority Code | T1: Priority Name | U1: Description
A2: 7511101 | B2: Salary for Commissioner | C2: 7511101 | D2: 7511101 | E2: SGA | F2: SGA-7511101 | G2: A502 | H2: Salary for Commissioner | J2: Top Management | K2: B1000 | L2: SGA | M2: ADM | N2: Top Management | P2: 53450 | Q2: NGK BUSI INDONESIA | S2: A | T2: Must | U2: If this is not done, the company or our team cannot continue its business.
A3: 7511102 | B3: Salary for Director | C3: 7511102 | D3: 7511102 | E3: SGA | F3: SGA-7511102 | G3: A502 | H3: Salary for Director & Expat | J3: Commissioner | K3: B1001 | L3: SGA | M3: ADM | N3: Commissioner | S3: B | T3: Want to | U3: We want to do it as a team this term. we need it.
A4: 7511103 | B4: Staff Labor - Baslc Salary | C4: 7511103 | D4: 7511103 | E4: SGA | F4: SGA-7511103 | G4: A501 | H4: Basic Salary of permanent employee | J4: Admin & HR | K4: B2200 | L4: SGA | M4: ADM | N4: Admin & HR | S4: C | T4: Challenge | U4: We want to do it for this term or the future. But it doesn't matter if it's not this term.
A5: 7511111 | B5: Staff Labor - Allowance | C5: 7511111 | D5: 7511111 | E5: SGA | F5: SGA-7511111 | G5: A501 | H5: Employee allowance | J5: General Affair | K5: B2210 | L5: SGA | M5: ADM | N5: General Affair
A6: 7511112 | B6: Staff Labor - Tax allowance (art.21) | C6: 7511112 | D6: 7511112 | E6: SGA | F6: SGA-7511112 | G6: A501 | H6: Empployee Tax allowance | J6: Human Resource | K6: B2220 | L6: SGA | M6: ADM | N6: Human Resource | P6: BEX
A7: 7511121 | B7: Staff Labor - BPJS JK & JKK (1.19%) | C7: 7511121 | D7: 7511121 | E7: SGA | F7: SGA-7511121 | G7: A501 | H7: BPJS JK & JKK (death warrant, Accident Insurance) | J7: Health, Safety & Environment | K7: B2230 | L7: SGA | M7: ADM | N7: Health, Safety & Environment | P7: BEL
A8: 7511122 | B8: Staff Labor - BPJS Kesehatan (4%) | C8: 7511122 | D8: 7511122 | E8: SGA | F8: SGA-7511122 | G8: A501 | H8: BPJS health insurance | J8: Accounting & Finance | K8: B2300 | L8: SGA | M8: ADM | N8: Accounting & Finance
A9: 7511201 | B9: Staff Overtime | C9: 7511201 | D9: 7511201 | E9: SGA | F9: SGA-7511201 | G9: A503 | H9: Overtime permanent employee | J9: Information Technology | K9: B2400 | L9: SGA | M9: ADM | N9: Information Technology
A10: 7512111 | B10: Staff Welfare - BPJS Dana pensiun (2%) | C10: 7512111 | D10: 7512111 | E10: SGA | F10: SGA-7512111 | G10: A504 | H10: BPJS pension fund | J10: Sales & MKTG Dept.- Automotive | K10: B3100 | L10: SGA | M10: ADM | N10: Sales & MKTG Dept.- Automotive
A11: 7512112 | B11: Staff Welfare - BPJS JHT (3.7%) | C11: 7512112 | D11: 7512112 | E11: SGA | F11: SGA-7512112 | G11: A504 | H11: BPJS Pension plan | J11: Marketing | K11: B3160 | L11: SGA | M11: ADM | N11: Marketing
A12: 7514101 | B12: Staff Bonus / TAT | C12: 7514101 | D12: 7514101 | E12: SGA | F12: SGA-7514101 | G12: A501 | H12: Year-end allowance & Alpha | J12: Sales - OEM | K12: B3110 | L12: SGA | M12: ADM | N12: Sales - OEM
A13: 7514102 | B13: Staff Ramadhan / THR | C13: 7514102 | D13: 7514102 | E13: SGA | F13: SGA-7514102 | G13: A501 | H13: Lebaran bonus | J13: Sales - OES | K13: B3120 | L13: SGA | M13: ADM | N13: Sales - OES
A14: 7515401 | B14: Staff Welfare - Outpatient (Medical) | C14: 7515401 | D14: 7515401 | E14: SGA | F14: SGA-7515401 | G14: A504 | H14: outpatient treatment costs | J14: Sales - IAM | K14: B3130 | L14: SGA | M14: ADM | N14: Sales - IAM
A15: 7515402 | B15: Staff Welfare - Hospitalization | C15: 7515402 | D15: 7515402 | E15: SGA | F15: SGA-7515402 | G15: A504 | H15: hospitalization costs | J15: SP PD- CF | K15: B4101 | L15: MFG | M15: DIR | N15: SP PD- CF
A16: 7515403 | B16: Staff Welfare - Glasses | C16: 7515403 | D16: 7515403 | E16: SGA | F16: SGA-7515403 | G16: A504 | H16: glasses costs | J16: SP PD- CM | K16: B4102 | L16: MFG | M16: DIR | N16: SP PD- CM
A17: 7515404 | B17: Staff Welfare - Dental | C17: 7515404 | D17: 7515404 | E17: SGA | F17: SGA-7515404 | G17: A504 | H17: dental costs | J17: SP PD- WT | K17: B4103 | L17: MFG | M17: DIR | N17: SP PD- WT
A18: 7515405 | B18: Staff Welfare - Medical Check Up | C18: 7515405 | D18: 7515405 | E18: SGA | F18: SGA-7515405 | G18: A504 | H18: Medical Check Up cost | J18: SP PD- Plating | K18: B4105 | L18: MFG | M18: DIR | N18: SP PD- Plating
A19: 7515406 | B19: Staff Welfare - Uniform | C19: 7515406 | D19: 7515406 | E19: SGA | F19: SGA-7515406 | G19: A504 | H19: uniform costs | J19: SP PD- MS Insp. | K19: B4109 | L19: MFG | M19: DIR | N19: SP PD- MS Insp.
A20: 7515407 | B20: Staff Welfare - Safety Shoes | C20: 7515407 | D20: 7515407 | E20: SGA | F20: SGA-7515407 | G20: A504 | J20: SP PD- Insulator Sealing | K20: B4106 | L20: MFG | M20: DIR | N20: SP PD- Insulator Sealing
A21: 7515408 | B21: Staff Welfare - Family Gathering / Anniversary | C21: 7515408 | D21: 7515408 | E21: SGA | F21: SGA-7515408 | G21: A504 | H21: Family Gathering / Anniversary | J21: SP PD- Assy | K21: B4110 | L21: MFG | M21: DIR | N21: SP PD- Assy
A22: 7515409 | B22: Staff Welfare - Meals of canteen & other meals | C22: 7515409 | D22: 7515409 | E22: SGA | F22: SGA-7515409 | G22: A504 | H22: Meals of canteen & other meals cost | J22: SP-PD-Assy-Auto Assembly | K22: B4115 | L22: MFG | M22: DIR | N22: SP-PD-Assy-Auto Assembly
A23: 7515410 | B23: Staff Welfare - Kaizen & QCC reward | C23: 7515410 | D23: 7515410 | E23: SGA | F23: SGA-7515410 | G23: A504 | H23: an expense, arising from Kaizen and QCC acitivity | J23: SP PD- Bending | K23: B4114 | L23: MFG | M23: DIR | N23: SP PD- Bending
A24: 7515499 | B24: Staff Welfare - Welfare Others | C24: 7515499 | D24: 7515499 | E24: SGA | F24: SGA-7515499 | G24: A504 | H24: an other welfare expense, arising besides the above welfare expense | J24: SP PD- Final Inspection | K24: B4120 | L24: MFG | M24: DIR | N24: SP PD- Final Inspection
A25: 7516102 | B25: Retirement Allowance | C25: 7516102 | D25: 7516102 | E25: SGA | F25: SGA-7516102 | G25: A505 | H25: employee retirement provission costs | J25: SP PD- QC - OEM | K25: B4121 | L25: MFG | M25: DIR | N25: SP PD- QC - OEM
A26: 7519101 | B26: House Rent Allowance | C26: 7519101 | D26: 7519101 | E26: SGA | F26: SGA-7519101 | G26: A502 | H26: House Rent Allowance for expat | J26: PC PD- Injection | K26: B4410 | L26: MFG | M26: DIR | N26: PC PD- Injection
A27: 7521101 | B27: Casual Staff Labor - Basic Salary | C27: 7521101 | D27: 7521101 | E27: SGA | F27: SGA-7521101 | G27: A501 | H27: All benefit for temporary worker | J27: PC PD- Assy | K27: B4430 | L27: MFG | M27: DIR | N27: PC PD- Assy
A28: 7521102 | B28: Casual Staff Labor - Overtime | C28: 7521102 | D28: 7521102 | E28: SGA | F28: SGA-7521102 | G28: A503 | H28: Overtime temporary worker | J28: PC PD- QC | K28: B4440 | L28: MFG | M28: DIR | N28: PC PD- QC
A29: 7571101 | B29: Personnel expense transferred | C29: 7571101 | D29: 7571101 | E29: SGA | F29: SGA-7571101 | G29: A506 | H29: Transfer Labor cost from one section into another section | J29: Plant Operation (Indirect Mfg) | K29: B5000 | L29: MFG | M29: IND | N29: Plant Operation (Indirect Mfg)
A30: 7611100 | B30: Depreciation-Building | C30: 7611100 | D30: 7611100 | E30: SGA | F30: SGA-7611100 | G30: A601 | H30: the amount of depreciation of tangible assets for building | J30: Production Office | K30: B5100 | L30: MFG | M30: IND | N30: Production Office
A31: 7611300 | B31: Depreciation-Machiney & equipment | C31: 7611300 | D31: 7611300 | E31: SGA | F31: SGA-7611300 | G31: A601 | H31: the amount of depreciation of tangible assets for machinery & factory equipment | J31: Production Office (SP) | K31: B5101 | L31: MFG | M31: IND | N31: Production Office (SP)
A32: 7611400 | B32: Depreciation-Lease Machinery & equipment | C32: 7611400 | D32: 7611400 | E32: SGA | F32: SGA-7611400 | G32: A601 | H32: the amount of depreciation of tangible assets for machinery & factory equipment (Leases) | J32: Production Office (PC) | K32: B5104 | L32: MFG | M32: IND | N32: Production Office (PC)
... A41: 7641101 | B41: Repair Building | C41: 7641101 | D41: 7641101 | E41: SGA | F41: SGA-7641101 | G41: A1002 | H41: expenses for repair and maintenance asset building | J41: Continuous Improvement | K41: B5007 | L41: MFG | M41: IND | N41: Continuous Improvement
A42: 7641102 | B42: Repair of Equipment | C42: 7641102 | D42: 7641102 | E42: SGA | F42: SGA-7641102 | G42: A1002 | H42: expenses for repair and maintenance tangible assets, intangible assets and other assets beside building | J42: All | K42: B0000 | N42: All
A43: 7641103 | B43: Factory Supply Expense | C43: 7641103 | D43: 7641103 | E43: SGA | F43: SGA-7641103 | G43: A1099 | H43: All cost that arrising to support factory acitivity
A44: 7641104 | B44: Calibration Cost | C44: 7641104 | D44: 7641104 | E44: SGA | F44: SGA-7641104 | G44: A1099 | H44: Cost of calibration for tools and equipment of factory and others
A45: 7651101 | B45: Transportation Fee for employee | C45: 7651101 | D45: 7651101 | E45: SGA | F45: SGA-7651101 | G45: A801 | H45: Gasoline of company cars & expense for Local transportation
A46: 7651102 | B46: Travel Expense-Domestic | C46: 7651102 | D46: 7651102 | E46: SGA | F46: SGA-7651102 | G46: A801 | H46: expenses for business trip, including allowance for business trip to an employee only for domestic travel
A47: 7651103 | B47: Travel Expense-Oversea | C47: 7651103 | D47: 7651103 | E47: SGA | F47: SGA-7651103 | G47: A801 | H47: expenses for business trip, including allowance for business trip to an employee only for overseas travel
A48: 7661101 | B48: Entertainment | C48: 7661101 | D48: 7661101 | E48: SGA | F48: SGA-7661101 | G48: A1001 | H48: the amount of expenses for the act of entertaining the business partner
...
