Workbook
Name \z: #REF!
Name __j102: #REF!
Name __j102: #REF!
Name _1: #N/A
Name _j102: #REF!
Name _j102: #REF!
Name _j102: #REF!
Name _j102: #REF!
Name _JIS2: #REF!
Name _JIS3: #REF!
Name a: #REF!
Name aa: #REF!
Name aa: #REF!
Name aa: #REF!
Name AAA: '[5]3300-00'!$K$86:$K$91,'[5]3300-00'!$K$81:$K$84,'[5]3300-00'!$K$68:$K$78,'[5]3300-00'!$K$64,'[5]3300-00'!$K$59:$K$62,'[5]3300-00'!$K$41:$K$57,'[5]3300-00'!$K$35:$K$39,'[5]3300-00'!$K$29:$K$33
Name AB: #REF!
Name AB: #REF!
Name AB: #REF!
Name ai: #REF!
Name ai: #REF!
Name ai: #REF!
Name ALL_CHART: [6]Sheet2!$A$3:$N$48
Name APC: #REF!
Name APPLICATIONS: #REF!
Name APQP9: [7]!APQP9
Name as: #REF!
Name as: #REF!
Name as: #REF!
Name asgd: #REF!
Name assit: #REF!
Name assit: #REF!
Name assit: #REF!
Name AVERAGE: #REF!
Name b: #REF!
Name b: #REF!
Name b: #REF!
Name baru: #REF!
Name BC: #REF!
Name BC: #REF!
Name BC: #REF!
Name BDTime_Freq_1999: #REF!
Name BeginSel: #REF!
Name BI: #REF!
Name BI: #REF!
Name BI: #REF!
Name biaya: [8]Feb!$B$4
Name BO: #REF!
Name BO: #REF!
Name BO: #REF!
Name BOX: #REF!
Name CATDET2: '[9]2002'!#REF!
Name cc: #REF!
Name cc: #REF!
Name cc: #REF!
Name cccc: #REF!
Name CH: #REF!
Name CH: #REF!
Name CH: #REF!
Name CHART1: [6]Sheet2!$A$3:$N$46
Name CHART2: [6]Sheet2!$A$48:$N$48

Sheet Data
A1: Budget Type | B1: Section From (Code) | C1: Section From (Name) | D1: To Section (Code) | E1: To Section (Name) | F1: Coa ID | G1: Coa Name | H1: Asset Name | I1: Group Section | J1: Group Cost | K1: Acquisition Value | L1: Useful Life | M1: Allocation % | N1: Depre Start | O1: Priority Code | P1: Budget_Period | Q1: Budget Allocation
A2: BIP | B2: =_xlfn.IFNA(VLOOKUP(C2,Master_Section!$H:$I,2,FALSE),"") -> B5500 | C2: Maintenance | D2: =_xlfn.IFNA(VLOOKUP(E2,Master_Section!$H:$I,2,FALSE),"") -> B5500 | E2: Maintenance | F2: =_xlfn.IFNA(VLOOKUP(G2,Master!AE:AF,2,FALSE),"") -> 2111100 | G2: Building | H2: Replace panel SDP front office + Replace wiring front office | I2: =_xlfn.IFNA(VLOOKUP(D2,Master_Section!$I:$K,2,FALSE),"") -> MFG | J2: =_xlfn.IFNA(VLOOKUP(D2,Master_Section!$I:$K,3,FALSE),"") -> IND | K2: 276000000 | L2: 60 | M2: 1 | N2: 45292 | O2: A | P2: =IF(N2<>"",IF(MONTH(N2)>=4,"FY1"&RIGHT(YEAR(N2)+1,2),"FY1"&RIGHT(YEAR(N2),2)),"") -> FY124 | Q2: =IF(K2>0&M2>0,K2*M2,"") -> 276000000
A3: BIP | B3: =_xlfn.IFNA(VLOOKUP(C3,Master_Section!$H:$I,2,FALSE),"") -> B5500 | C3: Maintenance | D3: =_xlfn.IFNA(VLOOKUP(E3,Master_Section!$H:$I,2,FALSE),"") -> B5500 | E3: Maintenance | F3: =_xlfn.IFNA(VLOOKUP(G3,Master!AE:AF,2,FALSE),"") -> 2111100 | G3: Building | H3: Replace panel SDP TPS scrap room | I3: =_xlfn.IFNA(VLOOKUP(D3,Master_Section!$I:$K,2,FALSE),"") -> MFG | J3: =_xlfn.IFNA(VLOOKUP(D3,Master_Section!$I:$K,3,FALSE),"") -> IND | K3: 68000000 | L3: 60 | M3: 1 | N3: 45292 | O3: B | P3: =IF(N3<>"",IF(MONTH(N3)>=4,"FY1"&RIGHT(YEAR(N3)+1,2),"FY1"&RIGHT(YEAR(N3),2)),"") -> FY124 | Q3: =IF(K3>0&M3>0,K3*M3,"") -> 68000000
A4: BIP | B4: =_xlfn.IFNA(VLOOKUP(C4,Master_Section!$H:$I,2,FALSE),"") -> B5500 | C4: Maintenance | D4: =_xlfn.IFNA(VLOOKUP(E4,Master_Section!$H:$I,2,FALSE),"") -> B4105 | E4: SP PD- Plating | F4: =_xlfn.IFNA(VLOOKUP(G4,Master!AE:AF,2,FALSE),"") -> 2121000 | G4: Machinery & Equipment | H4: Replace chiller plating | I4: =_xlfn.IFNA(VLOOKUP(D4,Master_Section!$I:$K,2,FALSE),"") -> MFG | J4: =_xlfn.IFNA(VLOOKUP(D4,Master_Section!$I:$K,3,FALSE),"") -> DIR | K4: 480000000 | L4: 60 | M4: 1 | N4: 45139 | O4: A | P4: =IF(N4<>"",IF(MONTH(N4)>=4,"FY1"&RIGHT(YEAR(N4)+1,2),"FY1"&RIGHT(YEAR(N4),2)),"") -> FY124 | Q4: =IF(K4>0&M4>0,K4*M4,"") -> 480000000
A5: BIP | B5: =_xlfn.IFNA(VLOOKUP(C5,Master_Section!$H:$I,2,FALSE),"") -> B5500 | C5: Maintenance | D5: =_xlfn.IFNA(VLOOKUP(E5,Master_Section!$H:$I,2,FALSE),"") -> B5500 | E5: Maintenance | F5: =_xlfn.IFNA(VLOOKUP(G5,Master!AE:AF,2,FALSE),"") -> 2111100 | G5: Building | H5: Replace cable 20 KV from gardu induk PLN to cubicle at panel room (est 200 mtr) | I5: =_xlfn.IFNA(VLOOKUP(D5,Master_Section!$I:$K,2,FALSE),"") -> MFG | J5: =_xlfn.IFNA(VLOOKUP(D5,Master_Section!$I:$K,3,FALSE),"") -> IND | K5: 10000 | L5: 120 | M5: 1 | N5: 45017 | O5: B | P5: =IF(N5<>"",IF(MONTH(N5)>=4,"FY1"&RIGHT(YEAR(N5)+1,2),"FY1"&RIGHT(YEAR(N5),2)),"") -> FY124 | Q5: =IF(K5>0&M5>0,K5*M5,"") -> 10000
A6: BIP | B6: =_xlfn.IFNA(VLOOKUP(C6,Master_Section!$H:$I,2,FALSE),"") -> B5500 | C6: Maintenance | D6: =_xlfn.IFNA(VLOOKUP(E6,Master_Section!$H:$I,2,FALSE),"") -> B5500 | E6: Maintenance | F6: =_xlfn.IFNA(VLOOKUP(G6,Master!AE:AF,2,FALSE),"") -> 2111100 | G6: Building | H6: Replace AC CFC become NON CFC ( ceiling mounted 5 unit, wall mounted 5 unit ) | I6: =_xlfn.IFNA(VLOOKUP(D6,Master_Section!$I:$K,2,FALSE),"") -> MFG | J6: =_xlfn.IFNA(VLOOKUP(D6,Master_Section!$I:$K,3,FALSE),"") -> IND | K6: 265000000 | L6: 60 | M6: 1 | N6: 45170 | O6: A | P6: =IF(N6<>"",IF(MONTH(N6)>=4,"FY1"&RIGHT(YEAR(N6)+1,2),"FY1"&RIGHT(YEAR(N6),2)),"") -> FY124 | Q6: =IF(K6>0&M6>0,K6*M6,"") -> 265000000
A7: BIP | B7: =_xlfn.IFNA(VLOOKUP(C7,Master_Section!$H:$I,2,FALSE),"") -> B5500 | C7: Maintenance | D7: =_xlfn.IFNA(VLOOKUP(E7,Master_Section!$H:$I,2,FALSE),"") -> B2230 | E7: Health, Safety & Environment | F7: =_xlfn.IFNA(VLOOKUP(G7,Master!AE:AF,2,FALSE),"") -> 2111100 | G7: Building | H7: Replace panel SDP deep water pump | I7: =_xlfn.IFNA(VLOOKUP(D7,Master_Section!$I:$K,2,FALSE),"") -> SGA | J7: =_xlfn.IFNA(VLOOKUP(D7,Master_Section!$I:$K,3,FALSE),"") -> ADM | K7: 37000000 | L7: 60 | M7: 1 | N7: 45108 | O7: B | P7: =IF(N7<>"",IF(MONTH(N7)>=4,"FY1"&RIGHT(YEAR(N7)+1,2),"FY1"&RIGHT(YEAR(N7),2)),"") -> FY124 | Q7: =IF(K7>0&M7>0,K7*M7,"") -> 37000000
A8: BIP | B8: =_xlfn.IFNA(VLOOKUP(C8,Master_Section!$H:$I,2,FALSE),"") -> B5500 | C8: Maintenance | D8: =_xlfn.IFNA(VLOOKUP(E8,Master_Section!$H:$I,2,FALSE),"") -> B5500 | E8: Maintenance | F8: =_xlfn.IFNA(VLOOKUP(G8,Master!AE:AF,2,FALSE),"") -> 2111100 | G8: Building | H8: Replace AC canteen standing type 5PK (4 unit) become split type 2.5 PK (6 unit) | I8: =_xlfn.IFNA(VLOOKUP(D8,Master_Section!$I:$K,2,FALSE),"") -> MFG | J8: =_xlfn.IFNA(VLOOKUP(D8,Master_Section!$I:$K,3,FALSE),"") -> IND | K8: 246000000 | L8: 60 | M8: 1 | N8: 45078 | O8: B | P8: =IF(N8<>"",IF(MONTH(N8)>=4,"FY1"&RIGHT(YEAR(N8)+1,2),"FY1"&RIGHT(YEAR(N8),2)),"") -> FY124 | Q8: =IF(K8>0&M8>0,K8*M8,"") -> 246000000
A9: BIP | B9: =_xlfn.IFNA(VLOOKUP(C9,Master_Section!$H:$I,2,FALSE),"") -> B5500 | C9: Maintenance | D9: =_xlfn.IFNA(VLOOKUP(E9,Master_Section!$H:$I,2,FALSE),"") -> B3150 | E9: SCM - FG WH | F9: =_xlfn.IFNA(VLOOKUP(G9,Master!AE:AF,2,FALSE),"") -> 2121000 | G9: Machinery & Equipment | H9: Automatic guide vehicle (AGV) | I9: =_xlfn.IFNA(VLOOKUP(D9,Master_Section!$I:$K,2,FALSE),"") -> SGA | J9: =_xlfn.IFNA(VLOOKUP(D9,Master_Section!$I:$K,3,FALSE),"") -> ADM | K9: 380000000 | L9: 60 | M9: 1 | N9: 45200 | O9: B | P9: =IF(N9<>"",IF(MONTH(N9)>=4,"FY1"&RIGHT(YEAR(N9)+1,2),"FY1"&RIGHT(YEAR(N9),2)),"") -> FY124 | Q9: =IF(K9>0&M9>0,K9*M9,"") -> 380000000
A10: BIP | B10: =_xlfn.IFNA(VLOOKUP(C10,Master_Section!$H:$I,2,FALSE),"") -> B5500 | C10: Maintenance | D10: =_xlfn.IFNA(VLOOKUP(E10,Master_Section!$H:$I,2,FALSE),"") -> B4105 | E10: SP PD- Plating | F10: =_xlfn.IFNA(VLOOKUP(G10,Master!AE:AF,2,FALSE),"") -> 2121000 | G10: Machinery & Equipment | H10: FS replace scrubber plating | I10: =_xlfn.IFNA(VLOOKUP(D10,Master_Section!$I:$K,2,FALSE),"") -> MFG | J10: =_xlfn.IFNA(VLOOKUP(D10,Master_Section!$I:$K,3,FALSE),"") -> DIR | K10: 15000000 | L10: 60 | M10: 1 | N10: 45139 | O10: B | P10: =IF(N10<>"",IF(MONTH(N10)>=4,"FY1"&RIGHT(YEAR(N10)+1,2),"FY1"&RIGHT(YEAR(N10),2)),"") -> FY124 | Q10: =IF(K10>0&M10>0,K10*M10,"") -> 15000000
A11: BIP | B11: =_xlfn.IFNA(VLOOKUP(C11,Master_Section!$H:$I,2,FALSE),"") -> B5500 | C11: Maintenance | D11: =_xlfn.IFNA(VLOOKUP(E11,Master_Section!$H:$I,2,FALSE),"") -> B5500 | E11: Maintenance | F11: =_xlfn.IFNA(VLOOKUP(G11,Master!AE:AF,2,FALSE),"") -> 2121000 | G11: Machinery & Equipment | H11: Renewal WWT | I11: =_xlfn.IFNA(VLOOKUP(D11,Master_Section!$I:$K,2,FALSE),"") -> MFG | J11: =_xlfn.IFNA(VLOOKUP(D11,Master_Section!$I:$K,3,FALSE),"") -> IND | K11: 2280000000 | L11: 120 | M11: 1 | N11: 45658 | O11: B | P11: =IF(N11<>"",IF(MONTH(N11)>=4,"FY1"&RIGHT(YEAR(N11)+1,2),"FY1"&RIGHT(YEAR(N11),2)),"") -> FY125 | Q11: =IF(K11>0&M11>0,K11*M11,"") -> 2280000000
A12: BIP | B12: =_xlfn.IFNA(VLOOKUP(C12,Master_Section!$H:$I,2,FALSE),"") -> B5500 | C12: Maintenance | D12: =_xlfn.IFNA(VLOOKUP(E12,Master_Section!$H:$I,2,FALSE),"") -> B5500 | E12: Maintenance | F12: =_xlfn.IFNA(VLOOKUP(G12,Master!AE:AF,2,FALSE),"") -> 2121000 | G12: Machinery & Equipment | H12: Renewal RO | I12: =_xlfn.IFNA(VLOOKUP(D12,Master_Section!$I:$K,2,FALSE),"") -> MFG | J12: =_xlfn.IFNA(VLOOKUP(D12,Master_Section!$I:$K,3,FALSE),"") -> IND | K12: 320000000 | L12: 120 | M12: 1 | N12: 45658 | O12: B | P12: =IF(N12<>"",IF(MONTH(N12)>=4,"FY1"&RIGHT(YEAR(N12)+1,2),"FY1"&RIGHT(YEAR(N12),2)),"") -> FY125 | Q12: =IF(K12>0&M12>0,K12*M12,"") -> 320000000
A13: BIP | B13: =_xlfn.IFNA(VLOOKUP(C13,Master_Section!$H:$I,2,FALSE),"") -> B5500 | C13: Maintenance | D13: =_xlfn.IFNA(VLOOKUP(E13,Master_Section!$H:$I,2,FALSE),"") -> B4102 | E13: SP PD- CM | F13: =_xlfn.IFNA(VLOOKUP(G13,Master!AE:AF,2,FALSE),"") -> 2121000 | G13: Machinery & Equipment | H13: Replace pipe cooling tower CM | I13: =_xlfn.IFNA(VLOOKUP(D13,Master_Section!$I:$K,2,FALSE),"") -> MFG | J13: =_xlfn.IFNA(VLOOKUP(D13,Master_Section!$I:$K,3,FALSE),"") -> DIR | K13: 128000000 | L13: 60 | M13: 1 | N13: 45170 | O13: A | P13: =IF(N13<>"",IF(MONTH(N13)>=4,"FY1"&RIGHT(YEAR(N13)+1,2),"FY1"&RIGHT(YEAR(N13),2)),"") -> FY124 | Q13: =IF(K13>0&M13>0,K13*M13,"") -> 128000000
... A23: BIP | B23: =_xlfn.IFNA(VLOOKUP(C23,Master_Section!$H:$I,2,FALSE),"") -> B5500 | C23: Maintenance | D23: =_xlfn.IFNA(VLOOKUP(E23,Master_Section!$H:$I,2,FALSE),"") -> B2230 | E23: Health, Safety & Environment | F23: =_xlfn.IFNA(VLOOKUP(G23,Master!AE:AF,2,FALSE),"") -> 2111100 | G23: Building | H23: Container for PPE warehouse | I23: =_xlfn.IFNA(VLOOKUP(D23,Master_Section!$I:$K,2,FALSE),"") -> SGA | J23: =_xlfn.IFNA(VLOOKUP(D23,Master_Section!$I:$K,3,FALSE),"") -> ADM | K23: 135000000 | L23: 120 | M23: 1 | N23: 45352 | O23: B | P23: =IF(N23<>"",IF(MONTH(N23)>=4,"FY1"&RIGHT(YEAR(N23)+1,2),"FY1"&RIGHT(YEAR(N23),2)),"") -> FY124 | Q23: =IF(K23>0&M23>0,K23*M23,"") -> 135000000
A24: BIP | B24: =_xlfn.IFNA(VLOOKUP(C24,Master_Section!$H:$I,2,FALSE),"") -> B5500 | C24: Maintenance | D24: =_xlfn.IFNA(VLOOKUP(E24,Master_Section!$H:$I,2,FALSE),"") -> B2210 | E24: General Affair | F24: =_xlfn.IFNA(VLOOKUP(G24,Master!AE:AF,2,FALSE),"") -> 2111100 | G24: Building | H24: Roof Plant | I24: =_xlfn.IFNA(VLOOKUP(D24,Master_Section!$I:$K,2,FALSE),"") -> SGA | J24: =_xlfn.IFNA(VLOOKUP(D24,Master_Section!$I:$K,3,FALSE),"") -> ADM | K24: 4400000000 | L24: 120 | M24: 1 | N24: 45352 | O24: A | P24: =IF(N24<>"",IF(MONTH(N24)>=4,"FY1"&RIGHT(YEAR(N24)+1,2),"FY1"&RIGHT(YEAR(N24),2)),"") -> FY124 | Q24: =IF(K24>0&M24>0,K24*M24,"") -> 4400000000 | R24: Pay Timing October 2023
A25: BIP | B25: =_xlfn.IFNA(VLOOKUP(C25,Master_Section!$H:$I,2,FALSE),"") -> B5500 | C25: Maintenance | D25: =_xlfn.IFNA(VLOOKUP(E25,Master_Section!$H:$I,2,FALSE),"") -> B5500 | E25: Maintenance | F25: =_xlfn.IFNA(VLOOKUP(G25,Master!AE:AF,2,FALSE),"") -> 2141000 | G25: Tools, furniture & office equipment | H25: Laptop For Sigit A | I25: =_xlfn.IFNA(VLOOKUP(D25,Master_Section!$I:$K,2,FALSE),"") -> MFG | J25: =_xlfn.IFNA(VLOOKUP(D25,Master_Section!$I:$K,3,FALSE),"") -> IND | K25: 13000000 | L25: 60 | M25: 1 | N25: 45017 | O25: A | P25: =IF(N25<>"",IF(MONTH(N25)>=4,"FY1"&RIGHT(YEAR(N25)+1,2),"FY1"&RIGHT(YEAR(N25),2)),"") -> FY124 | Q25: =IF(K25>0&M25>0,K25*M25,"") -> 13000000
A26: BIP | B26: =_xlfn.IFNA(VLOOKUP(C26,Master_Section!$H:$I,2,FALSE),"") -> B5500 | C26: Maintenance | D26: =_xlfn.IFNA(VLOOKUP(E26,Master_Section!$H:$I,2,FALSE),"") -> B5500 | E26: Maintenance | F26: =_xlfn.IFNA(VLOOKUP(G26,Master!AE:AF,2,FALSE),"") -> 2141000 | G26: Tools, furniture & office equipment | H26: Laptop For Unggul P | I26: =_xlfn.IFNA(VLOOKUP(D26,Master_Section!$I:$K,2,FALSE),"") -> MFG | J26: =_xlfn.IFNA(VLOOKUP(D26,Master_Section!$I:$K,3,FALSE),"") -> IND | K26: 10000000 | L26: 60 | M26: 1 | N26: 45017 | O26: A | P26: =IF(N26<>"",IF(MONTH(N26)>=4,"FY1"&RIGHT(YEAR(N26)+1,2),"FY1"&RIGHT(YEAR(N26),2)),"") -> FY124 | Q26: =IF(K26>0&M26>0,K26*M26,"") -> 10000000
A27: BIP | B27: =_xlfn.IFNA(VLOOKUP(C27,Master_Section!$H:$I,2,FALSE),"") -> B5500 | C27: Maintenance | D27: =_xlfn.IFNA(VLOOKUP(E27,Master_Section!$H:$I,2,FALSE),"") -> B5500 | E27: Maintenance | F27: =_xlfn.IFNA(VLOOKUP(G27,Master!AE:AF,2,FALSE),"") -> 2141000 | G27: Tools, furniture & office equipment | H27: Bearing Heater (TMBH 1 SKF) | I27: =_xlfn.IFNA(VLOOKUP(D27,Master_Section!$I:$K,2,FALSE),"") -> MFG | J27: =_xlfn.IFNA(VLOOKUP(D27,Master_Section!$I:$K,3,FALSE),"") -> IND | K27: 60000000 | L27: 60 | M27: 1 | N27: 45108 | O27: B | P27: =IF(N27<>"",IF(MONTH(N27)>=4,"FY1"&RIGHT(YEAR(N27)+1,2),"FY1"&RIGHT(YEAR(N27),2)),"") -> FY124 | Q27: =IF(K27>0&M27>0,K27*M27,"") -> 60000000
B28: =_xlfn.IFNA(VLOOKUP(C28,Master_Section!$H:$I,2,FALSE),"") | D28: =_xlfn.IFNA(VLOOKUP(E28,Master_Section!$H:$I,2,FALSE),"") | F28: =_xlfn.IFNA(VLOOKUP(G28,Master!AE:AF,2,FALSE),"") | I28: =_xlfn.IFNA(VLOOKUP(D28,Master_Section!$I:$K,2,FALSE),"") | P28: =IF(N28<>"",IF(MONTH(N28)>=4,"FY1"&RIGHT(YEAR(N28)+1,2),"FY1"&RIGHT(YEAR(N28),2)),"") | Q28: =IF(K28>0&M28>0,K28*M28,"") -> 0
B29: =_xlfn.IFNA(VLOOKUP(C29,Master_Section!$H:$I,2,FALSE),"") | D29: =_xlfn.IFNA(VLOOKUP(E29,Master_Section!$H:$I,2,FALSE),"") | F29: =_xlfn.IFNA(VLOOKUP(G29,Master!AE:AF,2,FALSE),"") | I29: =_xlfn.IFNA(VLOOKUP(D29,Master_Section!$I:$K,2,FALSE),"") | J29: =_xlfn.IFNA(VLOOKUP(D29,Master_Section!$I:$K,3,FALSE),"") | P29: =IF(N29<>"",IF(MONTH(N29)>=4,"FY1"&RIGHT(YEAR(N29)+1,2),"FY1"&RIGHT(YEAR(N29),2)),"") | Q29: =IF(K29>0&M29>0,K29*M29,"") -> 0
B30: =_xlfn.IFNA(VLOOKUP(C30,Master_Section!$H:$I,2,FALSE),"") | D30: =_xlfn.IFNA(VLOOKUP(E30,Master_Section!$H:$I,2,FALSE),"") | F30: =_xlfn.IFNA(VLOOKUP(G30,Master!AE:AF,2,FALSE),"") | I30: =_xlfn.IFNA(VLOOKUP(D30,Master_Section!$I:$K,2,FALSE),"") | J30: =_xlfn.IFNA(VLOOKUP(D30,Master_Section!$I:$K,3,FALSE),"") | P30: =IF(N30<>"",IF(MONTH(N30)>=4,"FY1"&RIGHT(YEAR(N30)+1,2),"FY1"&RIGHT(YEAR(N30),2)),"") | Q30: =IF(K30>0&M30>0,K30*M30,"") -> 0
B31: =_xlfn.IFNA(VLOOKUP(C31,Master_Section!$H:$I,2,FALSE),"") | D31: =_xlfn.IFNA(VLOOKUP(E31,Master_Section!$H:$I,2,FALSE),"") | F31: =_xlfn.IFNA(VLOOKUP(G31,Master!AE:AF,2,FALSE),"") | I31: =_xlfn.IFNA(VLOOKUP(D31,Master_Section!$I:$K,2,FALSE),"") | J31: =_xlfn.IFNA(VLOOKUP(D31,Master_Section!$I:$K,3,FALSE),"") | P31: =IF(N31<>"",IF(MONTH(N31)>=4,"FY1"&RIGHT(YEAR(N31)+1,2),"FY1"&RIGHT(YEAR(N31),2)),"") | Q31: =IF(K31>0&M31>0,K31*M31,"") -> 0
B32: =_xlfn.IFNA(VLOOKUP(C32,Master_Section!$H:$I,2,FALSE),"") | D32: =_xlfn.IFNA(VLOOKUP(E32,Master_Section!$H:$I,2,FALSE),"") | F32: =_xlfn.IFNA(VLOOKUP(G32,Master!AE:AF,2,FALSE),"") | I32: =_xlfn.IFNA(VLOOKUP(D32,Master_Section!$I:$K,2,FALSE),"") | J32: =_xlfn.IFNA(VLOOKUP(D32,Master_Section!$I:$K,3,FALSE),"") | P32: =IF(N32<>"",IF(MONTH(N32)>=4,"FY1"&RIGHT(YEAR(N32)+1,2),"FY1"&RIGHT(YEAR(N32),2)),"") | Q32: =IF(K32>0&M32>0,K32*M32,"") -> 0
B33: =_xlfn.IFNA(VLOOKUP(C33,Master_Section!$H:$I,2,FALSE),"") | D33: =_xlfn.IFNA(VLOOKUP(E33,Master_Section!$H:$I,2,FALSE),"") | F33: =_xlfn.IFNA(VLOOKUP(G33,Master!AE:AF,2,FALSE),"") | I33: =_xlfn.IFNA(VLOOKUP(D33,Master_Section!$I:$K,2,FALSE),"") | J33: =_xlfn.IFNA(VLOOKUP(D33,Master_Section!$I:$K,3,FALSE),"") | P33: =IF(N33<>"",IF(MONTH(N33)>=4,"FY1"&RIGHT(YEAR(N33)+1,2),"FY1"&RIGHT(YEAR(N33),2)),"") | Q33: =IF(K33>0&M33>0,K33*M33,"") -> 0
B34: =_xlfn.IFNA(VLOOKUP(C34,Master_Section!$H:$I,2,FALSE),"") | D34: =_xlfn.IFNA(VLOOKUP(E34,Master_Section!$H:$I,2,FALSE),"") | F34: =_xlfn.IFNA(VLOOKUP(G34,Master!AE:AF,2,FALSE),"") | I34: =_xlfn.IFNA(VLOOKUP(D34,Master_Section!$I:$K,2,FALSE),"") | J34: =_xlfn.IFNA(VLOOKUP(D34,Master_Section!$I:$K,3,FALSE),"") | P34: =IF(N34<>"",IF(MONTH(N34)>=4,"FY1"&RIGHT(YEAR(N34)+1,2),"FY1"&RIGHT(YEAR(N34),2)),"") | Q34: =IF(K34>0&M34>0,K34*M34,"") -> 0
B35: =_xlfn.IFNA(VLOOKUP(C35,Master_Section!$H:$I,2,FALSE),"") | D35: =_xlfn.IFNA(VLOOKUP(E35,Master_Section!$H:$I,2,FALSE),"") | F35: =_xlfn.IFNA(VLOOKUP(G35,Master!AE:AF,2,FALSE),"") | I35: =_xlfn.IFNA(VLOOKUP(D35,Master_Section!$I:$K,2,FALSE),"") | J35: =_xlfn.IFNA(VLOOKUP(D35,Master_Section!$I:$K,3,FALSE),"") | P35: =IF(N35<>"",IF(MONTH(N35)>=4,"FY1"&RIGHT(YEAR(N35)+1,2),"FY1"&RIGHT(YEAR(N35),2)),"") | Q35: =IF(K35>0&M35>0,K35*M35,"") -> 0
B36: =_xlfn.IFNA(VLOOKUP(C36,Master_Section!$H:$I,2,FALSE),"") | D36: =_xlfn.IFNA(VLOOKUP(E36,Master_Section!$H:$I,2,FALSE),"") | F36: =_xlfn.IFNA(VLOOKUP(G36,Master!AE:AF,2,FALSE),"") | I36: =_xlfn.IFNA(VLOOKUP(D36,Master_Section!$I:$K,2,FALSE),"") | J36: =_xlfn.IFNA(VLOOKUP(D36,Master_Section!$I:$K,3,FALSE),"") | P36: =IF(N36<>"",IF(MONTH(N36)>=4,"FY1"&RIGHT(YEAR(N36)+1,2),"FY1"&RIGHT(YEAR(N36),2)),"") | Q36: =IF(K36>0&M36>0,K36*M36,"") -> 0
B37: =_xlfn.IFNA(VLOOKUP(C37,Master_Section!$H:$I,2,FALSE),"") | D37: =_xlfn.IFNA(VLOOKUP(E37,Master_Section!$H:$I,2,FALSE),"") | F37: =_xlfn.IFNA(VLOOKUP(G37,Master!AE:AF,2,FALSE),"") | I37: =_xlfn.IFNA(VLOOKUP(D37,Master_Section!$I:$K,2,FALSE),"") | J37: =_xlfn.IFNA(VLOOKUP(D37,Master_Section!$I:$K,3,FALSE),"") | P37: =IF(N37<>"",IF(MONTH(N37)>=4,"FY1"&RIGHT(YEAR(N37)+1,2),"FY1"&RIGHT(YEAR(N37),2)),"") | Q37: =IF(K37>0&M37>0,K37*M37,"") -> 0
B38: =_xlfn.IFNA(VLOOKUP(C38,Master_Section!$H:$I,2,FALSE),"") | D38: =_xlfn.IFNA(VLOOKUP(E38,Master_Section!$H:$I,2,FALSE),"") | F38: =_xlfn.IFNA(VLOOKUP(G38,Master!AE:AF,2,FALSE),"") | I38: =_xlfn.IFNA(VLOOKUP(D38,Master_Section!$I:$K,2,FALSE),"") | J38: =_xlfn.IFNA(VLOOKUP(D38,Master_Section!$I:$K,3,FALSE),"") | P38: =IF(N38<>"",IF(MONTH(N38)>=4,"FY1"&RIGHT(YEAR(N38)+1,2),"FY1"&RIGHT(YEAR(N38),2)),"") | Q38: =IF(K38>0&M38>0,K38*M38,"") -> 0
B39: =_xlfn.IFNA(VLOOKUP(C39,Master_Section!$H:$I,2,FALSE),"") | D39: =_xlfn.IFNA(VLOOKUP(E39,Master_Section!$H:$I,2,FALSE),"") | F39: =_xlfn.IFNA(VLOOKUP(G39,Master!AE:AF,2,FALSE),"") | I39: =_xlfn.IFNA(VLOOKUP(D39,Master_Section!$I:$K,2,FALSE),"") | J39: =_xlfn.IFNA(VLOOKUP(D39,Master_Section!$I:$K,3,FALSE),"") | P39: =IF(N39<>"",IF(MONTH(N39)>=4,"FY1"&RIGHT(YEAR(N39)+1,2),"FY1"&RIGHT(YEAR(N39),2)),"") | Q39: =IF(K39>0&M39>0,K39*M39,"") -> 0
B40: =_xlfn.IFNA(VLOOKUP(C40,Master_Section!$H:$I,2,FALSE),"") | D40: =_xlfn.IFNA(VLOOKUP(E40,Master_Section!$H:$I,2,FALSE),"") | F40: =_xlfn.IFNA(VLOOKUP(G40,Master!AE:AF,2,FALSE),"") | I40: =_xlfn.IFNA(VLOOKUP(D40,Master_Section!$I:$K,2,FALSE),"") | J40: =_xlfn.IFNA(VLOOKUP(D40,Master_Section!$I:$K,3,FALSE),"") | P40: =IF(N40<>"",IF(MONTH(N40)>=4,"FY1"&RIGHT(YEAR(N40)+1,2),"FY1"&RIGHT(YEAR(N40),2)),"") | Q40: =IF(K40>0&M40>0,K40*M40,"") -> 0
... B342: =_xlfn.IFNA(VLOOKUP(C342,Master_Section!$H:$I,2,FALSE),"") | D342: =_xlfn.IFNA(VLOOKUP(E342,Master_Section!$H:$I,2,FALSE),"") | F342: =_xlfn.IFNA(VLOOKUP(G342,Master!AE:AF,2,FALSE),"") | I342: =_xlfn.IFNA(VLOOKUP(D342,Master_Section!$I:$K,2,FALSE),"") | J342: =_xlfn.IFNA(VLOOKUP(D342,Master_Section!$I:$K,3,FALSE),"") | P342: =IF(N342<>"",IF(MONTH(N342)>=4,"FY1"&RIGHT(YEAR(N342)+1,2),"FY1"&RIGHT(YEAR(N342),2)),"") | Q342: =IF(K342>0&M342>0,K342*M342,"") -> 0
B343: =_xlfn.IFNA(VLOOKUP(C343,Master_Section!$H:$I,2,FALSE),"") | F343: =_xlfn.IFNA(VLOOKUP(G343,Master!AE:AF,2,FALSE),"") | I343: =_xlfn.IFNA(VLOOKUP(D343,Master_Section!$I:$K,2,FALSE),"") | J343: =_xlfn.IFNA(VLOOKUP(D343,Master_Section!$I:$K,3,FALSE),"") | P343: =IF(N343<>"",IF(MONTH(N343)>=4,"FY1"&RIGHT(YEAR(N343)+1,2),"FY1"&RIGHT(YEAR(N343),2)),"") | Q343: =IF(K343>0&M343>0,K343*M343,"") -> 0
B344: =_xlfn.IFNA(VLOOKUP(C344,Master_Section!$H:$I,2,FALSE),"") | F344: =_xlfn.IFNA(VLOOKUP(G344,Master!AE:AF,2,FALSE),"") | I344: =_xlfn.IFNA(VLOOKUP(D344,Master_Section!$I:$K,2,FALSE),"") | J344: =_xlfn.IFNA(VLOOKUP(D344,Master_Section!$I:$K,3,FALSE),"") | P344: =IF(N344<>"",IF(MONTH(N344)>=4,"FY1"&RIGHT(YEAR(N344)+1,2),"FY1"&RIGHT(YEAR(N344),2)),"") | Q344: =IF(K344>0&M344>0,K344*M344,"") -> 0
B345: =_xlfn.IFNA(VLOOKUP(C345,Master_Section!$H:$I,2,FALSE),"") | F345: =_xlfn.IFNA(VLOOKUP(G345,Master!AE:AF,2,FALSE),"") | I345: =_xlfn.IFNA(VLOOKUP(D345,Master_Section!$I:$K,2,FALSE),"") | J345: =_xlfn.IFNA(VLOOKUP(D345,Master_Section!$I:$K,3,FALSE),"") | P345: =IF(N345<>"",IF(MONTH(N345)>=4,"FY1"&RIGHT(YEAR(N345)+1,2),"FY1"&RIGHT(YEAR(N345),2)),"") | Q345: =IF(K345>0&M345>0,K345*M345,"") -> 0
B346: =_xlfn.IFNA(VLOOKUP(C346,Master_Section!$H:$I,2,FALSE),"") | F346: =_xlfn.IFNA(VLOOKUP(G346,Master!AE:AF,2,FALSE),"") | I346: =_xlfn.IFNA(VLOOKUP(D346,Master_Section!$I:$K,2,FALSE),"") | J346: =_xlfn.IFNA(VLOOKUP(D346,Master_Section!$I:$K,3,FALSE),"") | P346: =IF(N346<>"",IF(MONTH(N346)>=4,"FY1"&RIGHT(YEAR(N346)+1,2),"FY1"&RIGHT(YEAR(N346),2)),"") | Q346: =IF(K346>0&M346>0,K346*M346,"") -> 0
B347: =_xlfn.IFNA(VLOOKUP(C347,Master_Section!$H:$I,2,FALSE),"") | F347: =_xlfn.IFNA(VLOOKUP(G347,Master!AE:AF,2,FALSE),"") | I347: =_xlfn.IFNA(VLOOKUP(D347,Master_Section!$I:$K,2,FALSE),"") | J347: =_xlfn.IFNA(VLOOKUP(D347,Master_Section!$I:$K,3,FALSE),"") | P347: =IF(N347<>"",IF(MONTH(N347)>=4,"FY1"&RIGHT(YEAR(N347)+1,2),"FY1"&RIGHT(YEAR(N347),2)),"") | Q347: =IF(K347>0&M347>0,K347*M347,"") -> 0
B348: =_xlfn.IFNA(VLOOKUP(C348,Master_Section!$H:$I,2,FALSE),"") | F348: =_xlfn.IFNA(VLOOKUP(G348,Master!AE:AF,2,FALSE),"") | I348: =_xlfn.IFNA(VLOOKUP(D348,Master_Section!$I:$K,2,FALSE),"") | J348: =_xlfn.IFNA(VLOOKUP(D348,Master_Section!$I:$K,3,FALSE),"") | P348: =IF(N348<>"",IF(MONTH(N348)>=4,"FY1"&RIGHT(YEAR(N348)+1,2),"FY1"&RIGHT(YEAR(N348),2)),"") | Q348: =IF(K348>0&M348>0,K348*M348,"") -> 0
B349: =_xlfn.IFNA(VLOOKUP(C349,Master_Section!$H:$I,2,FALSE),"") | F349: =_xlfn.IFNA(VLOOKUP(G349,Master!AE:AF,2,FALSE),"") | I349: =_xlfn.IFNA(VLOOKUP(D349,Master_Section!$I:$K,2,FALSE),"") | J349: =_xlfn.IFNA(VLOOKUP(D349,Master_Section!$I:$K,3,FALSE),"") | P349: =IF(N349<>"",IF(MONTH(N349)>=4,"FY1"&RIGHT(YEAR(N349)+1,2),"FY1"&RIGHT(YEAR(N349),2)),"") | Q349: =IF(K349>0&M349>0,K349*M349,"") -> 0
B350: =_xlfn.IFNA(VLOOKUP(C350,Master_Section!$H:$I,2,FALSE),"") | F350: =_xlfn.IFNA(VLOOKUP(G350,Master!AE:AF,2,FALSE),"") | I350: =_xlfn.IFNA(VLOOKUP(D350,Master_Section!$I:$K,2,FALSE),"") | J350: =_xlfn.IFNA(VLOOKUP(D350,Master_Section!$I:$K,3,FALSE),"") | P350: =IF(N350<>"",IF(MONTH(N350)>=4,"FY1"&RIGHT(YEAR(N350)+1,2),"FY1"&RIGHT(YEAR(N350),2)),"") | Q350: =IF(K350>0&M350>0,K350*M350,"") -> 0
...

Sheet Form HSE
A1: Investment Plan FY 122 - 124
A3: (Machinery, Production Equipment, Production Facility)
A4: No | B4: Section | C4: Item Investment | D4: Quantity | E4: Background | F4: Target Investment | G4: Plan Start to Use
G5: Month | H5: FY
A6: 1 | B6: HSE | C6: Tank for WWT domestic | D6: 1 | E6: Final Tank water (Damage,bubble tank) | F6: replacement with new ones | G6: JUN'23 | H6: FY124
C7: Pump for blower wwt tank | D7: 1 | E7: Pump for bower tank was damage (it can't operate)
A8: 2 | B8: HSE | C8: Emergency exit door | D8: 2 | E8: 1.For SP2 room 2.For QM room As regulation in case fire accident in that room for directly acces | F8: Have emergency exit | G8: OCT'23 | H8: FY124
A9: 3 | B9: HSE | C9: Container used for PPE Warehouse (20 fit) | D9: 1 | E9: Current condition PPE Warehouse still mix with Document warehouse and access not proper | F9: Have PPE Warehouse proper | G9: DEC'23 | H9: FY124

Sheet Supporting data HSE
A5: NO | B5: Investment Name | C5: Current Condition | F5: Future Condition
C6: TYPE | D6: PURPOSE | E6: CURRENT CONDITION | F6: TYPE | G6: SPECIFICATION | H6: PRICE ESTIMATION
A7: 1 | B7: Final water tank & Pump Blower for WWT Domestic | C7: Penguin 2000 liter capacity | D7: Final tank | E7: Water tank is Damage due to soil squeze | F7: Penguin 2000 liter capacity | G7: Install new water tank same capacity | H7: 120000000
D8: End collection water tank | G8: Install concrate square on final tank for protection the soil squeze
D9: WWT domestic process | G9: Install piping and tools supporting final tank process
D11: Normal operational 24 hours
C25: Root Blower Showfou pump (small capacity) | D25: Blow oxygen for activing aerobic bacteri in aerob tank | E25: Blower Pump is Damage due to deterotation | F25: Root Blower Showfou pump (Big capacity), same with new install blower pump | G25: Install new Blower pump with big capacity
D26: Normal operational 24 hours | G26: Install piping and supporting tool Blower pump
A41: 2 | B41: Emergency Exit Door | C41: NO | D41: Emergency exit at second Floor room at QM office and SP2 Meeting area | E41: Not yet provide emergency exit door | F41: Crash Bar System / Panic Door | G41: Crash bar handle | H41: =143000000*2 -> 286000000
G42: Steel material, fire protection material | H42: Contoh di SCM Lt 2
D43: - REGULATION OF THE MINISTER OF PUBLIC WORKS, NUMBER: 26/PRT/M/2008 , ABOUT TECHNICAL REQUIREMENTS FIRE PROTECTION SYSTEM IN BUILDING AND ENVIRONMENT - Safety Regulation No 01 - 1970 year - Occupational safety and healthy management system, PP No 50 - 2012 year | G43: Install transparan window and door closer
G44: Install emergency lamp and exit sign
G45: Provide Stair walk access go to outside (grating material) and canopy in front of door outside
A67: 3 | B67: Container used for PPE Warehouse (20 fit) | C67: NO | D67: Special warehouse storage for PPE | E67: Mix with document warehouse & unsafe condition | F67: Container used | G67: Container 20 Fit renovation | H67: 100000000
G68: Provide Door access, Window and Locket access
G69: Install Lamp, Exhaust fan, Fan
G70: Install canopy roof for protection the sun directly
G71: Provide Racking for PPE storage
G72: Install in behind PC area

Sheet Form HC
A1: Investment Plan FY 124 - 126
A3: (Machinery, Production Equipment, Production Facility)
A4: No | B4: Section | C4: Item Investment | D4: Quantity | E4: Background | F4: Target Investment | G4: Plan Start to Use | I4: CATATAN
G5: Month | H5: FY
A6: 1 | B6: GENERAL AFFAIR | C6: Parking 4 Wheels Area | D6: 1 Set | E6: Parking lot reduce due to hand over the land in front of NGK area, and will be moved backward until 1,5 meter. | F6: a) Relayout current parking area b) Adding parking area in Volley ball court c) New aspalt or conblock (easy to absorb the water) d) Canopy for safety | G6: 45292 | H6: FY124 | I6: Konsultasi FS design FY124 Eksekusi FY125 Simultan dg pembangunan public facility
A7: 2 | B7: GENERAL AFFAIR | C7: Additional Rest Room/Toilet for Office (Temporary Building) | D7: 1 Set | E7: More staff office employee and queque claim in rest room | F7: a) Temporary building - no need permit b) Current rest room only for female, and additional for male rest room c) Rest room need 3 closet cubicles and 4 urinoir | G7: 45108 | H7: FY124 | I7: WC Container yg sudah jadi
A8: 3 | B8: GENERAL AFFAIR | C8: Automatic Entrance Door for Main Office | D8: 1 Set | E8: Current main office door is broken and can't closed/opened offently | F8: Renovate with the automatic entrance door | G8: 45078 | H8: FY124 | I8: Renov dg model saat ini (Expense)
A9: 4 | B9: GENERAL AFFAIR | C9: Company New Name and Logo | D9: 3 set | E9: Change the company name | F9: New company name & logo at: 1) Main gate 2) Lobby of Main office 3) Roof of SCM Building | G9: 45017 | H9: FY124 | I9: Expense
A10: 5 | B10: GENERAL AFFAIR | C10: Sport Center | D10: 1 Set | E10: Currently we rent outside for some of sport (badminton, futsal), and need cost. | F10: a) Build sport center at football court b) All at one court for Futsal, Volley ball, badminton & table tennis c) Supporting facilities; rest room d) Cost reduction, no rent outside e) Improve employee engagement | G10: 45566 | H10: FY125 | I10: Konsultasi FS design FY124 Eksekusi FY125 Cek KDB
A11: 6 | B11: GENERAL AFFAIR | C11: Build Public Facility | D11: 1 Set | E11: Fulfilment NGK obligation to the government (based on IPPR) | F11: a) New NGK fence b) Main gate | G11: 45383 | H11: FY125 | I11: Design pager sudah selesai bagian timur & selatan Design fasum timur menyusul (+/- 2 minggu)
A12: 7 | B12: GENERAL AFFAIR | C12: Build Public Facility | D12: 1 Set | E12: Fulfilment NGK obligation to the government (based on IPPR) | F12: a) New additional road in Jl Kiwi b) Supporting public facilities; pedistrian, lighting, gutter ect | G12: 45992 | H12: FY126 | I12: FS public facility area selatan (depan) FY124
A13: 8 | B13: GENERAL AFFAIR | C13: New Office | D13: 2 - 3 Floors | E13: a) Old building > 50 years b) Overcapacity c) Not centralize, lack of monitoring and controling | F13: a) New building with 2-3 floors | G13: 45992 | H13: FY126 | I13: Laporan assessement building office Nov 2022 (FY123) FS Konstruksi FY124
A14: 9 | B14: HRD | C14: Training Center | D14: 1 Set | E14: Improving the competency of plant employee which currently we don’t have specific training center | F14: a) New training center at production area b) Simulator of production process to practicing the skills before go to the production line | G14: 45261 | H14: FY124 | I14: Konfirmasi ke Production & PE terkait availibility area bawah quality atau depan PEM

Sheet Master
A1: Name | B1: BNGK | C1: GROUP COST | D1: GROUP SECTION | E1: Name | G1: Code | H1: Name | J1: Name COA AX | K1: COA AX | L1: Group Cost | M1: UNIQ | N1: COA Budget | O1: Description | Q1: Name | R1: BNGK | S1: GROUP COST | T1: GROUP SECTION | U1: Name | W1: Code | X1: Name | Z1: Priority Code | AA1: Priority Name | AB1: Description | AD1: COA Assets | AE1: Name of Asset | AF1: COA Assets | AG1: COA Depre | AH1: Name of Depre | AJ1: Priority Code | AK1: Priority Name | AL1: Description
A2: Top Management | B2: B1000 | C2: SGA | D2: ADM | E2: =A2 -> Top Management | G2: 53450 | H2: NGK BUSI INDONESIA | J2: Salary for Commissioner | K2: 7511101 | L2: SGA | M2: =L2&"-"&K2 -> SGA-7511101 | N2: A502 | O2: Salary for Commissioner | Q2: Top Management | R2: B1000 | S2: SGA | T2: ADM | U2: =Q2 -> Top Management | W2: 53450 | X2: NGK BUSI INDONESIA | Z2: A | AA2: Must | AB2: If this is not done, the company or our team cannot continue its business. | AD2: 2111100 | AE2: Building | AF2: 2111100 | AG2: 7611100 | AH2: Depreciation-Building | AJ2: A | AK2: Must | AL2: If this is not done, the company or our team cannot continue its business.
A3: Commissioner | B3: B1001 | C3: SGA | D3: ADM | E3: =A3 -> Commissioner | J3: Salary for Director | K3: 7511102 | L3: SGA | M3: =L3&"-"&K3 -> SGA-7511102 | N3: A502 | O3: Salary for Director & Expat | Q3: Commissioner | R3: B1001 | S3: SGA | T3: ADM | U3: =Q3 -> Commissioner | Z3: B | AA3: Want to | AB3: We want to do it as a team this term. we need it. | AD3: 2121000 | AE3: Machinery & Equipment | AF3: 2121000 | AG3: 7611300 | AH3: Depreciation-Machiney & equipment | AJ3: B | AK3: Want to | AL3: We want to do it as a team this term. we need it.
A4: Admin & HR | B4: B2200 | C4: SGA | D4: ADM | E4: =A4 -> Admin & HR | J4: Staff Labor - Baslc Salary | K4: 7511103 | L4: SGA | M4: =L4&"-"&K4 -> SGA-7511103 | N4: A501 | O4: Basic Salary of permanent employee | Q4: Admin & HR | R4: B2200 | S4: SGA | T4: ADM | U4: =Q4 -> Admin & HR | Z4: C | AA4: Challenge | AB4: We want to do it for this term or the future. But it doesn't matter if it's not this term. | AD4: 2131000 | AE4: Vehicles | AF4: 2131000 | AG4: 7611500 | AH4: Depreciation-Vehicles | AJ4: C | AK4: Challenge | AL4: We want to do it for this term or the future. But it doesn't matter if it's not this term.
A5: General Affair | B5: B2210 | C5: SGA | D5: ADM | E5: =A5 -> General Affair | J5: Staff Labor - Allowance | K5: 7511111 | L5: SGA | M5: =L5&"-"&K5 -> SGA-7511111 | N5: A501 | O5: Employee allowance | Q5: General Affair | R5: B2210 | S5: SGA | T5: ADM | U5: =Q5 -> General Affair | AD5: 2141000 | AE5: Tools, furniture & office equipment | AF5: 2141000 | AG5: 7611600 | AH5: Depreciation-Tools, furniture & office equipment
A6: Human Resource | B6: B2220 | C6: SGA | D6: ADM | E6: =A6 -> Human Resource | G6: BIP | J6: Staff Labor - Tax allowance (art.21) | K6: 7511112 | L6: SGA | M6: =L6&"-"&K6 -> SGA-7511112 | N6: A501 | O6: Empployee Tax allowance | Q6: Human Resource | R6: B2220 | S6: SGA | T6: ADM | U6: =Q6 -> Human Resource | AD6: 2221101 | AE6: Software | AF6: 2221101 | AG6: 7611700 | AH6: Depreciation-Software
A7: Health, Safety & Environment | B7: B2230 | C7: SGA | D7: ADM | E7: =A7 -> Health, Safety & Environment | G7: CIP | J7: Staff Labor - BPJS JK & JKK (1.19%) | K7: 7511121 | L7: SGA | M7: =L7&"-"&K7 -> SGA-7511121 | N7: A501 | O7: BPJS JK & JKK (death warrant, Accident Insurance) | Q7: Health, Safety & Environment | R7: B2230 | S7: SGA | T7: ADM | U7: =Q7 -> Health, Safety & Environment
A8: Accounting & Finance | B8: B2300 | C8: SGA | D8: ADM | E8: =A8 -> Accounting & Finance | G8: CFA | J8: Staff Labor - BPJS Kesehatan (4%) | K8: 7511122 | L8: SGA | M8: =L8&"-"&K8 -> SGA-7511122 | N8: A501 | O8: BPJS health insurance | Q8: Accounting & Finance | R8: B2300 | S8: SGA | T8: ADM | U8: =Q8 -> Accounting & Finance
A9: Information Technology | B9: B2400 | C9: SGA | D9: ADM | E9: =A9 -> Information Technology | J9: Staff Overtime | K9: 7511201 | L9: SGA | M9: =L9&"-"&K9 -> SGA-7511201 | N9: A503 | O9: Overtime permanent employee | Q9: Information Technology | R9: B2400 | S9: SGA | T9: ADM | U9: =Q9 -> Information Technology
A10: Sales & MKTG Dept.- Automotive | B10: B3100 | C10: SGA | D10: ADM | E10: =A10 -> Sales & MKTG Dept.- Automotive | J10: Staff Welfare - BPJS Dana pensiun (2%) | K10: 7512111 | L10: SGA | M10: =L10&"-"&K10 -> SGA-7512111 | N10: A504 | O10: BPJS pension fund | Q10: Sales & MKTG Dept.- Automotive | R10: B3100 | S10: SGA | T10: ADM | U10: =Q10 -> Sales & MKTG Dept.- Automotive
A11: Marketing | B11: B3160 | C11: SGA | D11: ADM | E11: =A11 -> Marketing | J11: Staff Welfare - BPJS JHT (3.7%) | K11: 7512112 | L11: SGA | M11: =L11&"-"&K11 -> SGA-7512112 | N11: A504 | O11: BPJS Pension plan | Q11: Marketing | R11: B3160 | S11: SGA | T11: ADM | U11: =Q11 -> Marketing
A12: Sales - OEM | B12: B3110 | C12: SGA | D12: ADM | E12: =A12 -> Sales - OEM | J12: Staff Bonus / TAT | K12: 7514101 | L12: SGA | M12: =L12&"-"&K12 -> SGA-7514101 | N12: A501 | O12: Year-end allowance & Alpha | Q12: Sales - OEM | R12: B3110 | S12: SGA | T12: ADM | U12: =Q12 -> Sales - OEM
A13: Sales - OES | B13: B3120 | C13: SGA | D13: ADM | E13: =A13 -> Sales - OES | J13: Staff Ramadhan / THR | K13: 7514102 | L13: SGA | M13: =L13&"-"&K13 -> SGA-7514102 | N13: A501 | O13: Lebaran bonus | Q13: Sales - OES | R13: B3120 | S13: SGA | T13: ADM | U13: =Q13 -> Sales - OES
A14: Sales - IAM | B14: B3130 | C14: SGA | D14: ADM | E14: =A14 -> Sales - IAM | J14: Staff Welfare - Outpatient (Medical) | K14: 7515401 | L14: SGA | M14: =L14&"-"&K14 -> SGA-7515401 | N14: A504 | O14: outpatient treatment costs | Q14: Sales - IAM | R14: B3130 | S14: SGA | T14: ADM | U14: =Q14 -> Sales - IAM
A15: SP PD- CF | B15: B4101 | C15: MFG | D15: DIR | E15: =A15 -> SP PD- CF | J15: Staff Welfare - Hospitalization | K15: 7515402 | L15: SGA | M15: =L15&"-"&K15 -> SGA-7515402 | N15: A504 | O15: hospitalization costs | Q15: SP PD- CF | R15: B4101 | S15: MFG | T15: DIR | U15: =Q15 -> SP PD- CF
A16: SP PD- CM | B16: B4102 | C16: MFG | D16: DIR | E16: =A16 -> SP PD- CM | J16: Staff Welfare - Glasses | K16: 7515403 | L16: SGA | M16: =L16&"-"&K16 -> SGA-7515403 | N16: A504 | O16: glasses costs | Q16: SP PD- CM | R16: B4102 | S16: MFG | T16: DIR | U16: =Q16 -> SP PD- CM
A17: SP PD- WT | B17: B4103 | C17: MFG | D17: DIR | E17: =A17 -> SP PD- WT | J17: Staff Welfare - Dental | K17: 7515404 | L17: SGA | M17: =L17&"-"&K17 -> SGA-7515404 | N17: A504 | O17: dental costs | Q17: SP PD- WT | R17: B4103 | S17: MFG | T17: DIR | U17: =Q17 -> SP PD- WT
A18: SP PD- Plating | B18: B4105 | C18: MFG | D18: DIR | E18: =A18 -> SP PD- Plating | J18: Staff Welfare - Medical Check Up | K18: 7515405 | L18: SGA | M18: =L18&"-"&K18 -> SGA-7515405 | N18: A504 | O18: Medical Check Up cost | Q18: SP PD- Plating | R18: B4105 | S18: MFG | T18: DIR | U18: =Q18 -> SP PD- Plating
A19: SP PD- MS Insp. | B19: B4109 | C19: MFG | D19: DIR | E19: =A19 -> SP PD- MS Insp. | J19: Staff Welfare - Uniform | K19: 7515406 | L19: SGA | M19: =L19&"-"&K19 -> SGA-7515406 | N19: A504 | O19: uniform costs | Q19: SP PD- MS Insp. | R19: B4109 | S19: MFG | T19: DIR | U19: =Q19 -> SP PD- MS Insp.
A20: SP PD- Insulator Sealing | B20: B4106 | C20: MFG | D20: DIR | E20: =A20 -> SP PD- Insulator Sealing | J20: Staff Welfare - Safety Shoes | K20: 7515407 | L20: SGA | M20: =L20&"-"&K20 -> SGA-7515407 | N20: A504
A21: SP PD- Assy | B21: B4110 | C21: MFG | D21: DIR | E21: =A21 -> SP PD- Assy | J21: Staff Welfare - Family Gathering / Anniversary | K21: 7515408 | L21: SGA | M21: =L21&"-"&K21 -> SGA-7515408 | N21: A504 | O21: Family Gathering / Anniversary | Q21: SP PD- Insulator Sealing | R21: B4106 | S21: MFG | T21: DIR | U21: =Q21 -> SP PD- Insulator Sealing
A22: SP-PD-Assy-Auto Assembly | B22: B4115 | C22: MFG | D22: DIR | E22: =A22 -> SP-PD-Assy-Auto Assembly | J22: Staff Welfare - Meals of canteen & other meals | K22: 7515409 | L22: SGA | M22: =L22&"-"&K22 -> SGA-7515409 | N22: A504 | O22: Meals of canteen & other meals cost | Q22: SP PD- Assy | R22: B4110 | S22: MFG | T22: DIR | U22: =Q22 -> SP PD- Assy
A23: SP PD- Bending | B23: B4114 | C23: MFG | D23: DIR | E23: =A23 -> SP PD- Bending | J23: Staff Welfare - Kaizen & QCC reward | K23: 7515410 | L23: SGA | M23: =L23&"-"&K23 -> SGA-7515410 | N23: A504 | O23: an expense, arising from Kaizen and QCC acitivity | Q23: SP-PD-Assy-Auto Assembly | R23: B4115 | S23: MFG | T23: DIR | U23: =Q23 -> SP-PD-Assy-Auto Assembly
A24: SP PD- Final Inspection | B24: B4120 | C24: MFG | D24: DIR | E24: =A24 -> SP PD- Final Inspection | J24: Staff Welfare - Welfare Others | K24: 7515499 | L24: SGA | M24: =L24&"-"&K24 -> SGA-7515499 | N24: A504 | O24: an other welfare expense, arising besides the above welfare expense | Q24: SP PD- Bending | R24: B4114 | S24: MFG | T24: DIR | U24: =Q24 -> SP PD- Bending
A25: SP PD- QC - OEM | B25: B4121 | C25: MFG | D25: DIR | E25: =A25 -> SP PD- QC - OEM | J25: Retirement Allowance | K25: 7516102 | L25: SGA | M25: =L25&"-"&K25 -> SGA-7516102 | N25: A505 | O25: employee retirement provission costs | Q25: SP PD- Final Inspection | R25: B4120 | S25: MFG | T25: DIR | U25: =Q25 -> SP PD- Final Inspection
A26: PC PD- Injection | B26: B4410 | C26: MFG | D26: DIR | E26: =A26 -> PC PD- Injection | J26: House Rent Allowance | K26: 7519101 | L26: SGA | M26: =L26&"-"&K26 -> SGA-7519101 | N26: A502 | O26: House Rent Allowance for expat | Q26: SP PD- QC - OEM | R26: B4121 | S26: MFG | T26: DIR | U26: =Q26 -> SP PD- QC - OEM
A27: PC PD- Assy | B27: B4430 | C27: MFG | D27: DIR | E27: =A27 -> PC PD- Assy | J27: Casual Staff Labor - Basic Salary | K27: 7521101 | L27: SGA | M27: =L27&"-"&K27 -> SGA-7521101 | N27: A501 | O27: All benefit for temporary worker | Q27: PC PD- Injection | R27: B4410 | S27: MFG | T27: DIR | U27: =Q27 -> PC PD- Injection
A28: PC PD- QC | B28: B4440 | C28: MFG | D28: DIR | E28: =A28 -> PC PD- QC | J28: Casual Staff Labor - Overtime | K28: 7521102 | L28: SGA | M28: =L28&"-"&K28 -> SGA-7521102 | N28: A503 | O28: Overtime temporary worker | Q28: PC PD- Assy | R28: B4430 | S28: MFG | T28: DIR | U28: =Q28 -> PC PD- Assy
A29: Plant Operation (Indirect Mfg) | B29: B5000 | C29: MFG | D29: IND | E29: =A29 -> Plant Operation (Indirect Mfg) | J29: Personnel expense transferred | K29: 7571101 | L29: SGA | M29: =L29&"-"&K29 -> SGA-7571101 | N29: A506 | O29: Transfer Labor cost from one section into another section | Q29: PC PD- QC | R29: B4440 | S29: MFG | T29: DIR | U29: =Q29 -> PC PD- QC
A30: Production Office | B30: B5100 | C30: MFG | D30: IND | E30: =A30 -> Production Office | J30: Depreciation-Building | K30: 7611100 | L30: SGA | M30: =L30&"-"&K30 -> SGA-7611100 | N30: A601 | O30: the amount of depreciation of tangible assets for building | Q30: Plant Operation (Indirect Mfg) | R30: B5000 | S30: MFG | T30: IND | U30: =Q30 -> Plant Operation (Indirect Mfg)
A31: Production Office (SP) | B31: B5101 | C31: MFG | D31: IND | E31: =A31 -> Production Office (SP) | J31: Depreciation-Machiney & equipment | K31: 7611300 | L31: SGA | M31: =L31&"-"&K31 -> SGA-7611300 | N31: A601 | O31: the amount of depreciation of tangible assets for machinery & factory equipment | Q31: Production Office | R31: B5100 | S31: MFG | T31: IND | U31: =Q31 -> Production Office
A32: Production Office (PC) | B32: B5104 | C32: MFG | D32: IND | E32: =A32 -> Production Office (PC) | J32: Depreciation-Lease Machinery & equipment | K32: 7611400 | L32: SGA | M32: =L32&"-"&K32 -> SGA-7611400 | N32: A601 | O32: the amount of depreciation of tangible assets for machinery & factory equipment (Leases) | Q32: Production Office (SP) | R32: B5101 | S32: MFG | T32: IND | U32: =Q32 -> Production Office (SP)
... A42: WH Dept.- KD & RM | B42: B5710 | C42: MFG | D42: IND | E42: =A42 -> WH Dept.- KD & RM | J42: Repair of Equipment | K42: 7641102 | L42: SGA | M42: =L42&"-"&K42 -> SGA-7641102 | N42: A1002 | O42: expenses for repair and maintenance tangible assets, intangible assets and other assets beside building | Q42: Continuous Improvement | R42: B5007 | S42: MFG | T42: IND | U42: =Q42 -> Continuous Improvement
A43: Continuous Improvement | B43: B5007 | C43: MFG | D43: IND | E43: =A43 -> Continuous Improvement | J43: Factory Supply Expense | K43: 7641103 | L43: SGA | M43: =L43&"-"&K43 -> SGA-7641103 | N43: A1099 | O43: All cost that arrising to support factory acitivity | Q43: All | R43: B0000 | U43: =Q43 -> All
J44: Calibration Cost | K44: 7641104 | L44: SGA | M44: =L44&"-"&K44 -> SGA-7641104 | N44: A1099 | O44: Cost of calibration for tools and equipment of factory and others
J45: Transportation Fee for employee | K45: 7651101 | L45: SGA | M45: =L45&"-"&K45 -> SGA-7651101 | N45: A801 | O45: Gasoline of company cars & expense for Local transportation
J46: Travel Expense-Domestic | K46: 7651102 | L46: SGA | M46: =L46&"-"&K46 -> SGA-7651102 | N46: A801 | O46: expenses for business trip, including allowance for business trip to an employee only for domestic travel
J47: Travel Expense-Oversea | K47: 7651103 | L47: SGA | M47: =L47&"-"&K47 -> SGA-7651103 | N47: A801 | O47: expenses for business trip, including allowance for business trip to an employee only for overseas travel
J48: Entertainment | K48: 7661101 | L48: SGA | M48: =L48&"-"&K48 -> SGA-7661101 | N48: A1001 | O48: the amount of expenses for the act of entertaining the business partner
J49: Amortization of Land & Building tax (PBB) | K49: 7671102 | L49: SGA | M49: =L49&"-"&K49 -> SGA-7671102 | N49: A1099 | O49: the amount of depreciation of intangible of Land & Building Tax (PBB)
...

Sheet Master_Section
A1: Name COA AX | B1: COA AX | C1: Group Cost | D1: UNIQ | E1: COA Budget | F1: Description | H1: Name | I1: BNGK | J1: GROUP COST | K1: GROUP SECTION | L1: Name | N1: Code | O1: Name | Q1: Priority Code | R1: Priority Name | S1: Description
A2: Salary for Commissioner | B2: 7511101 | C2: SGA | D2: =C2&"-"&B2 -> SGA-7511101 | E2: A502 | F2: Salary for Commissioner | H2: Top Management | I2: B1000 | J2: SGA | K2: ADM | L2: =H2 -> Top Management | N2: 53450 | O2: NGK BUSI INDONESIA | Q2: A | R2: Must | S2: If this is not done, the company or our team cannot continue its business.
A3: Salary for Director | B3: 7511102 | C3: SGA | D3: =C3&"-"&B3 -> SGA-7511102 | E3: A502 | F3: Salary for Director & Expat | H3: Commissioner | I3: B1001 | J3: SGA | K3: ADM | L3: =H3 -> Commissioner | Q3: B | R3: Want to | S3: We want to do it as a team this term. we need it.
A4: Staff Labor - Baslc Salary | B4: 7511103 | C4: SGA | D4: =C4&"-"&B4 -> SGA-7511103 | E4: A501 | F4: Basic Salary of permanent employee | H4: Admin & HR | I4: B2200 | J4: SGA | K4: ADM | L4: =H4 -> Admin & HR | Q4: C | R4: Challenge | S4: We want to do it for this term or the future. But it doesn't matter if it's not this term.
A5: Staff Labor - Allowance | B5: 7511111 | C5: SGA | D5: =C5&"-"&B5 -> SGA-7511111 | E5: A501 | F5: Employee allowance | H5: General Affair | I5: B2210 | J5: SGA | K5: ADM | L5: =H5 -> General Affair
A6: Staff Labor - Tax allowance (art.21) | B6: 7511112 | C6: SGA | D6: =C6&"-"&B6 -> SGA-7511112 | E6: A501 | F6: Empployee Tax allowance | H6: Human Resource | I6: B2220 | J6: SGA | K6: ADM | L6: =H6 -> Human Resource
A7: Staff Labor - BPJS JK & JKK (1.19%) | B7: 7511121 | C7: SGA | D7: =C7&"-"&B7 -> SGA-7511121 | E7: A501 | F7: BPJS JK & JKK (death warrant, Accident Insurance) | H7: Health, Safety & Environment | I7: B2230 | J7: SGA | K7: ADM | L7: =H7 -> Health, Safety & Environment
A8: Staff Labor - BPJS Kesehatan (4%) | B8: 7511122 | C8: SGA | D8: =C8&"-"&B8 -> SGA-7511122 | E8: A501 | F8: BPJS health insurance | H8: Accounting & Finance | I8: B2300 | J8: SGA | K8: ADM | L8: =H8 -> Accounting & Finance
A9: Staff Overtime | B9: 7511201 | C9: SGA | D9: =C9&"-"&B9 -> SGA-7511201 | E9: A503 | F9: Overtime permanent employee | H9: Information Technology | I9: B2400 | J9: SGA | K9: ADM | L9: =H9 -> Information Technology
A10: Staff Welfare - BPJS Dana pensiun (2%) | B10: 7512111 | C10: SGA | D10: =C10&"-"&B10 -> SGA-7512111 | E10: A504 | F10: BPJS pension fund | H10: Sales & MKTG Dept.- Automotive | I10: B3100 | J10: SGA | K10: ADM | L10: =H10 -> Sales & MKTG Dept.- Automotive
A11: Staff Welfare - BPJS JHT (3.7%) | B11: 7512112 | C11: SGA | D11: =C11&"-"&B11 -> SGA-7512112 | E11: A504 | F11: BPJS Pension plan | H11: Marketing | I11: B3160 | J11: SGA | K11: ADM | L11: =H11 -> Marketing
A12: Staff Bonus / TAT | B12: 7514101 | C12: SGA | D12: =C12&"-"&B12 -> SGA-7514101 | E12: A501 | F12: Year-end allowance & Alpha | H12: Sales - OEM | I12: B3110 | J12: SGA | K12: ADM | L12: =H12 -> Sales - OEM
A13: Staff Ramadhan / THR | B13: 7514102 | C13: SGA | D13: =C13&"-"&B13 -> SGA-7514102 | E13: A501 | F13: Lebaran bonus | H13: Sales - OES | I13: B3120 | J13: SGA | K13: ADM | L13: =H13 -> Sales - OES
A14: Staff Welfare - Outpatient (Medical) | B14: 7515401 | C14: SGA | D14: =C14&"-"&B14 -> SGA-7515401 | E14: A504 | F14: outpatient treatment costs | H14: Sales - IAM | I14: B3130 | J14: SGA | K14: ADM | L14: =H14 -> Sales - IAM
A15: Staff Welfare - Hospitalization | B15: 7515402 | C15: SGA | D15: =C15&"-"&B15 -> SGA-7515402 | E15: A504 | F15: hospitalization costs | H15: SP PD- CF | I15: B4101 | J15: MFG | K15: DIR | L15: =H15 -> SP PD- CF
A16: Staff Welfare - Glasses | B16: 7515403 | C16: SGA | D16: =C16&"-"&B16 -> SGA-7515403 | E16: A504 | F16: glasses costs | H16: SP PD- CM | I16: B4102 | J16: MFG | K16: DIR | L16: =H16 -> SP PD- CM
... A19: Staff Welfare - Uniform | B19: 7515406 | C19: SGA | D19: =C19&"-"&B19 -> SGA-7515406 | E19: A504 | F19: uniform costs | H19: SP PD- MS Insp. | I19: B4109 | J19: MFG | K19: DIR | L19: =H19 -> SP PD- MS Insp.
A20: Staff Welfare - Safety Shoes | B20: 7515407 | C20: SGA | D20: =C20&"-"&B20 -> SGA-7515407 | E20: A504 | H20: SP PD- Insulator Sealing | I20: B4106 | J20: MFG | K20: DIR | L20: =H20 -> SP PD- Insulator Sealing
A21: Staff Welfare - Family Gathering / Anniversary | B21: 7515408 | C21: SGA | D21: =C21&"-"&B21 -> SGA-7515408 | E21: A504 | F21: Family Gathering / Anniversary | H21: SP PD- Assy | I21: B4110 | J21: MFG | K21: DIR | L21: =H21 -> SP PD- Assy
A22: Staff Welfare - Meals of canteen & other meals | B22: 7515409 | C22: SGA | D22: =C22&"-"&B22 -> SGA-7515409 | E22: A504 | F22: Meals of canteen & other meals cost | H22: SP-PD-Assy-Auto Assembly | I22: B4115 | J22: MFG | K22: DIR | L22: =H22 -> SP-PD-Assy-Auto Assembly
A23: Staff Welfare - Kaizen & QCC reward | B23: 7515410 | C23: SGA | D23: =C23&"-"&B23 -> SGA-7515410 | E23: A504 | F23: an expense, arising from Kaizen and QCC acitivity | H23: SP PD- Bending | I23: B4114 | J23: MFG | K23: DIR | L23: =H23 -> SP PD- Bending
A24: Staff Welfare - Welfare Others | B24: 7515499 | C24: SGA | D24: =C24&"-"&B24 -> SGA-7515499 | E24: A504 | F24: an other welfare expense, arising besides the above welfare expense | H24: SP PD- Final Inspection | I24: B4120 | J24: MFG | K24: DIR | L24: =H24 -> SP PD- Final Inspection
A25: Retirement Allowance | B25: 7516102 | C25: SGA | D25: =C25&"-"&B25 -> SGA-7516102 | E25: A505 | F25: employee retirement provission costs | H25: SP PD- QC - OEM | I25: B4121 | J25: MFG | K25: DIR | L25: =H25 -> SP PD- QC - OEM
A26: House Rent Allowance | B26: 7519101 | C26: SGA | D26: =C26&"-"&B26 -> SGA-7519101 | E26: A502 | F26: House Rent Allowance for expat | H26: PC PD- Injection | I26: B4410 | J26: MFG | K26: DIR | L26: =H26 -> PC PD- Injection
A27: Casual Staff Labor - Basic Salary | B27: 7521101 | C27: SGA | D27: =C27&"-"&B27 -> SGA-7521101 | E27: A501 | F27: All benefit for temporary worker | H27: PC PD- Assy | I27: B4430 | J27: MFG | K27: DIR | L27: =H27 -> PC PD- Assy
A28: Casual Staff Labor - Overtime | B28: 7521102 | C28: SGA | D28: =C28&"-"&B28 -> SGA-7521102 | E28: A503 | F28: Overtime temporary worker | H28: PC PD- QC | I28: B4440 | J28: MFG | K28: DIR | L28: =H28 -> PC PD- QC
A29: Personnel expense transferred | B29: 7571101 | C29: SGA | D29: =C29&"-"&B29 -> SGA-7571101 | E29: A506 | F29: Transfer Labor cost from one section into another section | H29: Plant Operation (Indirect Mfg) | I29: B5000 | J29: MFG | K29: IND | L29: =H29 -> Plant Operation (Indirect Mfg)
A30: Depreciation-Building | B30: 7611100 | C30: SGA | D30: =C30&"-"&B30 -> SGA-7611100 | E30: A601 | F30: the amount of depreciation of tangible assets for building | H30: Production Office | I30: B5100 | J30: MFG | K30: IND | L30: =H30 -> Production Office
A31: Depreciation-Machiney & equipment | B31: 7611300 | C31: SGA | D31: =C31&"-"&B31 -> SGA-7611300 | E31: A601 | F31: the amount of depreciation of tangible assets for machinery & factory equipment | H31: Production Office (SP) | I31: B5101 | J31: MFG | K31: IND | L31: =H31 -> Production Office (SP)
A32: Depreciation-Lease Machinery & equipment | B32: 7611400 | C32: SGA | D32: =C32&"-"&B32 -> SGA-7611400 | E32: A601 | F32: the amount of depreciation of tangible assets for machinery & factory equipment (Leases) | H32: Production Office (PC) | I32: B5104 | J32: MFG | K32: IND | L32: =H32 -> Production Office (PC)
... A41: Repair Building | B41: 7641101 | C41: SGA | D41: =C41&"-"&B41 -> SGA-7641101 | E41: A1002 | F41: expenses for repair and maintenance asset building | H41: Continuous Improvement | I41: B5007 | J41: MFG | K41: IND | L41: =H41 -> Continuous Improvement
A42: Repair of Equipment | B42: 7641102 | C42: SGA | D42: =C42&"-"&B42 -> SGA-7641102 | E42: A1002 | F42: expenses for repair and maintenance tangible assets, intangible assets and other assets beside building | H42: All | I42: B0000 | L42: =H42 -> All
A43: Factory Supply Expense | B43: 7641103 | C43: SGA | D43: =C43&"-"&B43 -> SGA-7641103 | E43: A1099 | F43: All cost that arrising to support factory acitivity
A44: Calibration Cost | B44: 7641104 | C44: SGA | D44: =C44&"-"&B44 -> SGA-7641104 | E44: A1099 | F44: Cost of calibration for tools and equipment of factory and others
A45: Transportation Fee for employee | B45: 7651101 | C45: SGA | D45: =C45&"-"&B45 -> SGA-7651101 | E45: A801 | F45: Gasoline of company cars & expense for Local transportation
A46: Travel Expense-Domestic | B46: 7651102 | C46: SGA | D46: =C46&"-"&B46 -> SGA-7651102 | E46: A801 | F46: expenses for business trip, including allowance for business trip to an employee only for domestic travel
A47: Travel Expense-Oversea | B47: 7651103 | C47: SGA | D47: =C47&"-"&B47 -> SGA-7651103 | E47: A801 | F47: expenses for business trip, including allowance for business trip to an employee only for overseas travel
A48: Entertainment | B48: 7661101 | C48: SGA | D48: =C48&"-"&B48 -> SGA-7661101 | E48: A1001 | F48: the amount of expenses for the act of entertaining the business partner
A49: Amortization of Land & Building tax (PBB) | B49: 7671102 | C49: SGA | D49: =C49&"-"&B49 -> SGA-7671102 | E49: A1099 | F49: the amount of depreciation of intangible of Land & Building Tax (PBB)
A50: License fee | B50: 7671103 | C50: SGA | D50: =C50&"-"&B50 -> SGA-7671103 | E50: A1099 | F50: The expense related with the documentation process, such as : KIR, Car lisence, company lisence, etc.
...

Sheet COA
A1: Name | B1: COA AX | C1: Group Cost | D1: UNIQ | E1: COA Budget | F1: Description
A2: Salary for Commissioner | B2: 7511101 | C2: SGA | D2: =C2&"-"&B2 -> SGA-7511101 | E2: A502 | F2: Salary for Commissioner
A3: Salary for Director | B3: 7511102 | C3: SGA | D3: =C3&"-"&B3 -> SGA-7511102 | E3: A502 | F3: Salary for Director & Expat
A4: Staff Labor - Baslc Salary | B4: 7511103 | C4: SGA | D4: =C4&"-"&B4 -> SGA-7511103 | E4: A501 | F4: Basic Salary of permanent employee
A5: Staff Labor - Allowance | B5: 7511111 | C5: SGA | D5: =C5&"-"&B5 -> SGA-7511111 | E5: A501 | F5: Employee allowance
A6: Staff Labor - Tax allowance (art.21) | B6: 7511112 | C6: SGA | D6: =C6&"-"&B6 -> SGA-7511112 | E6: A501 | F6: Empployee Tax allowance
A7: Staff Labor - BPJS JK & JKK (1.19%) | B7: 7511121 | C7: SGA | D7: =C7&"-"&B7 -> SGA-7511121 | E7: A501 | F7: BPJS JK & JKK (death warrant, Accident Insurance)
A8: Staff Labor - BPJS Kesehatan (4%) | B8: 7511122 | C8: SGA | D8: =C8&"-"&B8 -> SGA-7511122 | E8: A501 | F8: BPJS health insurance
A9: Staff Overtime | B9: 7511201 | C9: SGA | D9: =C9&"-"&B9 -> SGA-7511201 | E9: A503 | F9: Overtime permanent employee
A10: Staff Welfare - BPJS Dana pensiun (2%) | B10: 7512111 | C10: SGA | D10: =C10&"-"&B10 -> SGA-7512111 | E10: A504 | F10: BPJS pension fund
A11: Staff Welfare - BPJS JHT (3.7%) | B11: 7512112 | C11: SGA | D11: =C11&"-"&B11 -> SGA-7512112 | E11: A504 | F11: BPJS Pension plan
A12: Staff Bonus / TAT | B12: 7514101 | C12: SGA | D12: =C12&"-"&B12 -> SGA-7514101 | E12: A501 | F12: Year-end allowance & Alpha
A13: Staff Ramadhan / THR | B13: 7514102 | C13: SGA | D13: =C13&"-"&B13 -> SGA-7514102 | E13: A501 | F13: Lebaran bonus
... A70: Cost of Samples | B70: 7461101 | C70: SGA | D70: =C70&"-"&B70 -> SGA-7461101 | E70: A499 | F70: Sample expense
A71: Sales - Insurance of Delivery or Shipment | B71: 7411105 | C71: SGA | D71: =C71&"-"&B71 -> SGA-7411105 | E71: A299
A72: Sales - Insurance of AR (Credit Insurance) | B72: 7471201 | C72: SGA | D72: =C72&"-"&B72 -> SGA-7471201 | E72: A299
A73: Sales - Royalty to NGK Group | B73: 7751101 | C73: SGA | D73: =C73&"-"&B73 -> SGA-7751101
A74: Sales - Royalty to Independence Party | B74: 7751102 | C74: SGA | D74: =C74&"-"&B74 -> SGA-7751102
A75: Import Duty-purchased FG from NGK group | B75: 7111211 | C75: MFG | D75: =C75&"-"&B75 -> MFG-7111211
A76: Import Duty-purchased KD&RM from NGK Japan | B76: 7111221 | C76: MFG | D76: =C76&"-"&B76 -> MFG-7111221
A77: Import Duty-purchased KD&RM from NGK Group(Not fromJP) | B77: 7111222 | C77: MFG | D77: =C77&"-"&B77 -> MFG-7111222
A78: Import Duty-purchased Comp Parts&RM from outside supplier | B78: 7111223 | C78: MFG | D78: =C78&"-"&B78 -> MFG-7111223
A79: Import Expense-purchased FG from NGK group | B79: 7111311 | C79: MFG | D79: =C79&"-"&B79 -> MFG-7111311
A80: Import Expense-purchased KD&RM from NGK Japan | B80: 7111321 | C80: MFG | D80: =C80&"-"&B80 -> MFG-7111321
A81: Import Expense-purchased KD&RM from NGK Group(Not fromJP) | B81: 7111322 | C81: MFG | D81: =C81&"-"&B81 -> MFG-7111322
A82: Import Expense-purchased Comp Parts&RM from outside supplier | B82: 7111323 | C82: MFG | D82: =C82&"-"&B82 -> MFG-7111323
A83: Cost of Factory Supply | B83: 7211101 | C83: MFG | D83: =C83&"-"&B83 -> MFG-7211101
A84: Cost of Chemical | B84: 7211102 | C84: MFG | D84: =C84&"-"&B84 -> MFG-7211102 | E84: 901 | F84: The expenses of Chemicals consumption
A85: Cost of Packaging | B85: 7211103 | C85: MFG | D85: =C85&"-"&B85 -> MFG-7211103
A86: Cost of Tooling | B86: 7221101 | C86: MFG | D86: =C86&"-"&B86 -> MFG-7221101 | E86: 302 | F86: The expenses of Tooling consumption
A87: Cost of Machinery parts | B87: 7221102 | C87: MFG | D87: =C87&"-"&B87 -> MFG-7221102 | E87: 301 | F87: The expenses of Spare Parts consumption
A88: Salary for Commissioner | B88: 7511101 | C88: MFG | D88: =C88&"-"&B88 -> MFG-7511101 | E88: 602 | F88: Salary for Commissioner
A89: Salary for Director | B89: 7511102 | C89: MFG | D89: =C89&"-"&B89 -> MFG-7511102 | E89: 602 | F89: Salary for Director & Expat
A90: Staff Labor - Baslc Salary | B90: 7511103 | C90: MFG | D90: =C90&"-"&B90 -> MFG-7511103 | E90: 601 | F90: Basic Salary of permanent employee
A91: Staff Labor - Allowance | B91: 7511111 | C91: MFG | D91: =C91&"-"&B91 -> MFG-7511111 | E91: 601 | F91: Employee allowance
A92: Staff Labor - Tax allowance (art.21) | B92: 7511112 | C92: MFG | D92: =C92&"-"&B92 -> MFG-7511112 | E92: 601 | F92: Empployee Tax allowance
A93: Staff Labor - BPJS JK & JKK (1.19%) | B93: 7511121 | C93: MFG | D93: =C93&"-"&B93 -> MFG-7511121 | E93: 601 | F93: BPJS JK & JKK (death warrant, Accident Insurance)
A94: Staff Labor - BPJS Kesehatan (4%) | B94: 7511122 | C94: MFG | D94: =C94&"-"&B94 -> MFG-7511122 | E94: 601 | F94: BPJS health insurance
A95: Staff Overtime | B95: 7511201 | C95: MFG | D95: =C95&"-"&B95 -> MFG-7511201 | E95: 603 | F95: Overtime permanent employee
A96: Staff Welfare - BPJS Dana pensiun (2%) | B96: 7512111 | C96: MFG | D96: =C96&"-"&B96 -> MFG-7512111 | E96: 604 | F96: BPJS pension fund
...
