Workbook
Name __j102: #REF!
Name __j102: #REF!
Name __j102: #REF!
Name _1: #N/A
Name _j102: #REF!
Name _j102: #REF!
Name _j102: #REF!
Name aa: #REF!
Name aa: #REF!
Name AB: #REF!
Name AB: #REF!
Name ai: #REF!
Name as: #REF!
Name assit: #REF!
Name b: #REF!
Name BC: #REF!
Name BI: #REF!
Name BO: #REF!
Name cc: #REF!
Name CH: #REF!
Name CI: #REF!
Name Ck_for: #REF!
Name Ck_in: #REF!
Name Ck_out: #REF!
Name d: #REF!
Name dd: #REF!
Name DF: #REF!
Name e: #REF!
Name edy: #REF!
Name ee: #REF!
Name eXCRATE: #REF!
Name exrate: #REF!
Name F: #REF!
Name fcb: #REF!
Name FG: #REF!
Name g: #REF!
Name gg: #REF!
Name HF: #REF!
Name kissa: #REF!
Name kissa: #REF!
Name kissakei: #REF!
Name kissakei: #REF!
Name kk: #REF!
Name kk: #REF!
Name kkk: #REF!
Name kkkk: #REF!
Name l: #REF!
Name L_01: #REF!
Name LIA: #REF!
Name LILI: #REF!
Name LINA: #REF!
Name m: #REF!
Name Manufacturing: #REF!
Name MR: #REF!
Name nittk: #REF!
Name nittk_ok: #REF!
Name nittoukei: #REF!
Name PRINT_AREA_MI: #REF!
Name Print_Area_MI: #REF!
Name PRINT_AREA_MI: #REF!

Sheet Data
A1: BUDGET TYPE | B1: Section Code (From) | C1: Section Name (From/Who Prepare) | D1: Section Code (To) | E1: Section Name (To/Who Use The Cost) | F1: COA-ID | G1: COA NAME | H1: DESCRIPTION | I1: GROUP SECTION | J1: GROUP COST | K1: 2023_10 | L1: 2023_11 | M1: 2023_12 | N1: 2024_01 | O1: 2024_02 | P1: 2024_03 | Q1: 2024_04 | R1: 2024_05 | S1: 2024_06 | T1: 2024_07 | U1: 2024_08 | V1: 2024_09 | W1: 2024_10 | X1: 2024_11 | Y1: 2024_12 | Z1: 2025_01 | AA1: 2025_02 | AB1: 2025_03 | AC1: TOTAL FY124 | AD1: TOTAL FY125 | AE1: TOTAL FY126 | AF1: TOTAL FY127 | AG1: Priority Category | AH1: BUDGET NO.
A2: BEL | B2: =_xlfn.IFNA(VLOOKUP(C2,Master!$J:$K,2,0),"") -> B2220 | C2: Human Resource | D2: =_xlfn.IFNA(VLOOKUP(E2,Master!$J:$K,2,0),"") -> B2210 | E2: General Affair | F2: =_xlfn.IFNA(VLOOKUP(G2,Master!B:C,2,0),"") -> 7511103 | G2: Staff Labor - Basic Salary | H2: Basic Salary | I2: =_xlfn.IFNA(VLOOKUP(E2,Master!$J:$M,4,0),"") -> ADM | J2: =_xlfn.IFNA(VLOOKUP($E2,Master!$J:$M,3,0),"") -> SGA | M2: 142400300 | N2: 152369000 | O2: 152369000 | P2: 152369000 | Q2: 154027000 | R2: 145699100 | S2: 145699100 | T2: 137465400 | U2: 137465400 | V2: 137465400 | W2: 138323700 | X2: 138323700 | Y2: 129563600 | Z2: 138633100 | AA2: 138633100 | AB2: 138633100 | AC2: =SUM(K2:P2) -> 599507300 | AD2: =SUM(Q2:AB2) -> 1679931700 | AE2: 1832502900 | AF2: 1652242900 | AG2: A
A3: BEL | B3: =_xlfn.IFNA(VLOOKUP(C3,Master!$J:$K,2,0),"") -> B2220 | C3: Human Resource | D3: =_xlfn.IFNA(VLOOKUP(E3,Master!$J:$K,2,0),"") -> B2220 | E3: Human Resource | F3: =_xlfn.IFNA(VLOOKUP(G3,Master!B:C,2,0),"") -> 7511103 | G3: Staff Labor - Basic Salary | H3: Basic Salary | I3: =_xlfn.IFNA(VLOOKUP(E3,Master!$J:$M,4,0),"") -> ADM | J3: =_xlfn.IFNA(VLOOKUP($E3,Master!$J:$M,3,0),"") -> SGA | M3: 57236200 | N3: 61242900 | O3: 82642900 | P3: 82642900 | Q3: 89490900 | R3: 89490900 | S3: 89490900 | T3: 89490900 | U3: 89490900 | V3: 89490900 | W3: 90281500 | X3: 90281500 | Y3: 90281500 | Z3: 96601300 | AA3: 96601300 | AB3: 96601300 | AC3: =SUM(K3:P3) -> 283764900 | AD3: =SUM(Q3:AB3) -> 1097593800 | AE3: 1179501900 | AF3: 1262067300 | AG3: A
A4: BEL | B4: =_xlfn.IFNA(VLOOKUP(C4,Master!$J:$K,2,0),"") -> B2220 | C4: Human Resource | D4: =_xlfn.IFNA(VLOOKUP(E4,Master!$J:$K,2,0),"") -> B2230 | E4: Health, Safety & Environment | F4: =_xlfn.IFNA(VLOOKUP(G4,Master!B:C,2,0),"") -> 7511103 | G4: Staff Labor - Basic Salary | H4: Basic Salary | I4: =_xlfn.IFNA(VLOOKUP(E4,Master!$J:$M,4,0),"") -> ADM | J4: =_xlfn.IFNA(VLOOKUP($E4,Master!$J:$M,3,0),"") -> SGA | M4: 44992000 | N4: 48141600 | O4: 48141600 | P4: 48141600 | Q4: 48141600 | R4: 48141600 | S4: 48141600 | T4: 48141600 | U4: 48141600 | V4: 48141600 | W4: 48141600 | X4: 48141600 | Y4: 48141600 | Z4: 51511500 | AA4: 51511500 | AB4: 51511500 | AC4: =SUM(K4:P4) -> 189416800 | AD4: =SUM(Q4:AB4) -> 587808900 | AE4: 628955400 | AF4: 685208100 | AG4: A
A5: BEL | B5: =_xlfn.IFNA(VLOOKUP(C5,Master!$J:$K,2,0),"") -> B2220 | C5: Human Resource | D5: =_xlfn.IFNA(VLOOKUP(E5,Master!$J:$K,2,0),"") -> B2300 | E5: Accounting & Finance | F5: =_xlfn.IFNA(VLOOKUP(G5,Master!B:C,2,0),"") -> 7511103 | G5: Staff Labor - Basic Salary | H5: Basic Salary | I5: =_xlfn.IFNA(VLOOKUP(E5,Master!$J:$M,4,0),"") -> ADM | J5: =_xlfn.IFNA(VLOOKUP($E5,Master!$J:$M,3,0),"") -> SGA | M5: 111751000 | N5: 119573700 | O5: 119573700 | P5: 119573700 | Q5: 119573700 | R5: 119573700 | S5: 119573700 | T5: 119573700 | U5: 119573700 | V5: 119573700 | W5: 119573700 | X5: 119573700 | Y5: 119573700 | Z5: 127944100 | AA5: 127944100 | AB5: 127944100 | AC5: =SUM(K5:P5) -> 470472100 | AD5: =SUM(Q5:AB5) -> 1459995600 | AE5: 1651664700 | AF5: 1767280800 | AG5: A
A6: BEL | B6: =_xlfn.IFNA(VLOOKUP(C6,Master!$J:$K,2,0),"") -> B2220 | C6: Human Resource | D6: =_xlfn.IFNA(VLOOKUP(E6,Master!$J:$K,2,0),"") -> B2400 | E6: Information Technology | F6: =_xlfn.IFNA(VLOOKUP(G6,Master!B:C,2,0),"") -> 7511103 | G6: Staff Labor - Basic Salary | H6: Basic Salary | I6: =_xlfn.IFNA(VLOOKUP(E6,Master!$J:$M,4,0),"") -> ADM | J6: =_xlfn.IFNA(VLOOKUP($E6,Master!$J:$M,3,0),"") -> SGA | M6: 48100000 | N6: 51467100 | O6: 51467100 | P6: 51467100 | Q6: 51467100 | R6: 51467100 | S6: 51467100 | T6: 51467100 | U6: 51467100 | V6: 51467100 | W6: 51467100 | X6: 51467100 | Y6: 51467100 | Z6: 55070000 | AA6: 55070000 | AB6: 55070000 | AC6: =SUM(K6:P6) -> 202501300 | AD6: =SUM(Q6:AB6) -> 628413900 | AE6: 672404400 | AF6: 719471400 | AG6: A
A7: BEL | B7: =_xlfn.IFNA(VLOOKUP(C7,Master!$J:$K,2,0),"") -> B2220 | C7: Human Resource | D7: =_xlfn.IFNA(VLOOKUP(E7,Master!$J:$K,2,0),"") -> B3110 | E7: Sales - OEM | F7: =_xlfn.IFNA(VLOOKUP(G7,Master!B:C,2,0),"") -> 7511103 | G7: Staff Labor - Basic Salary | H7: Basic Salary | I7: =_xlfn.IFNA(VLOOKUP(E7,Master!$J:$M,4,0),"") -> ADM | J7: =_xlfn.IFNA(VLOOKUP($E7,Master!$J:$M,3,0),"") -> SGA | M7: 72104100 | N7: 77151600 | O7: 77151600 | P7: 77151600 | Q7: 77968800 | R7: 77968800 | S7: 77968800 | T7: 77968800 | U7: 77968800 | V7: 77968800 | W7: 77968800 | X7: 77968800 | Y7: 77968800 | Z7: 83426800 | AA7: 83426800 | AB7: 83426800 | AC7: =SUM(K7:P7) -> 303558900 | AD7: =SUM(Q7:AB7) -> 951999600 | AE7: 1018641000 | AF7: 1089944700 | AG7: A
A8: BEL | B8: =_xlfn.IFNA(VLOOKUP(C8,Master!$J:$K,2,0),"") -> B2220 | C8: Human Resource | D8: =_xlfn.IFNA(VLOOKUP(E8,Master!$J:$K,2,0),"") -> B3120 | E8: Sales - OES | F8: =_xlfn.IFNA(VLOOKUP(G8,Master!B:C,2,0),"") -> 7511103 | G8: Staff Labor - Basic Salary | H8: Basic Salary | I8: =_xlfn.IFNA(VLOOKUP(E8,Master!$J:$M,4,0),"") -> ADM | J8: =_xlfn.IFNA(VLOOKUP($E8,Master!$J:$M,3,0),"") -> SGA | M8: 10789000 | N8: 11544300 | O8: 11544300 | P8: 11544300 | Q8: 11544300 | R8: 11544300 | S8: 11544300 | T8: 11544300 | U8: 11544300 | V8: 11544300 | W8: 11544300 | X8: 11544300 | Y8: 11544300 | Z8: 12352400 | AA8: 12352400 | AB8: 12352400 | AC8: =SUM(K8:P8) -> 45421900 | AD8: =SUM(Q8:AB8) -> 140955900 | AE8: 150822600 | AF8: 161379600 | AG8: A
A9: BEL | B9: =_xlfn.IFNA(VLOOKUP(C9,Master!$J:$K,2,0),"") -> B2220 | C9: Human Resource | D9: =_xlfn.IFNA(VLOOKUP(E9,Master!$J:$K,2,0),"") -> B3130 | E9: Sales - IAM | F9: =_xlfn.IFNA(VLOOKUP(G9,Master!B:C,2,0),"") -> 7511103 | G9: Staff Labor - Basic Salary | H9: Basic Salary | I9: =_xlfn.IFNA(VLOOKUP(E9,Master!$J:$M,4,0),"") -> ADM | J9: =_xlfn.IFNA(VLOOKUP($E9,Master!$J:$M,3,0),"") -> SGA | M9: 137330000 | N9: 146943600 | O9: 160639600 | P9: 160639600 | Q9: 175187900 | R9: 175187900 | S9: 175187900 | T9: 175187900 | U9: 175187900 | V9: 175187900 | W9: 175187900 | X9: 175187900 | Y9: 175187900 | Z9: 187451300 | AA9: 187451300 | AB9: 187451300 | AC9: =SUM(K9:P9) -> 605552800 | AD9: =SUM(Q9:AB9) -> 2139045000 | AE9: 2288779500 | AF9: 2448990900 | AG9: A
A10: BEL | B10: =_xlfn.IFNA(VLOOKUP(C10,Master!$J:$K,2,0),"") -> B2220 | C10: Human Resource | D10: =_xlfn.IFNA(VLOOKUP(E10,Master!$J:$K,2,0),"") -> B3150 | E10: SCM - FG WH | F10: =_xlfn.IFNA(VLOOKUP(G10,Master!B:C,2,0),"") -> 7511103 | G10: Staff Labor - Basic Salary | H10: Basic Salary | I10: =_xlfn.IFNA(VLOOKUP(E10,Master!$J:$M,4,0),"") -> ADM | J10: =_xlfn.IFNA(VLOOKUP($E10,Master!$J:$M,3,0),"") -> SGA | M10: 118432000 | N10: 115895200 | O10: 115895200 | P10: 115895200 | Q10: 117330200 | R10: 117330200 | S10: 117330200 | T10: 117330200 | U10: 117330200 | V10: 117330200 | W10: 118003300 | X10: 118003300 | Y10: 118003300 | Z10: 126263700 | AA10: 126263700 | AB10: 126263700 | AC10: =SUM(K10:P10) -> 466117600 | AD10: =SUM(Q10:AB10) -> 1436782200 | AE10: 1546165500 | AF10: 1659033900 | AG10: A
A11: BEL | B11: =_xlfn.IFNA(VLOOKUP(C11,Master!$J:$K,2,0),"") -> B2220 | C11: Human Resource | D11: =_xlfn.IFNA(VLOOKUP(E11,Master!$J:$K,2,0),"") -> B3160 | E11: Marketing | F11: =_xlfn.IFNA(VLOOKUP(G11,Master!B:C,2,0),"") -> 7511103 | G11: Staff Labor - Basic Salary | H11: Basic Salary | I11: =_xlfn.IFNA(VLOOKUP(E11,Master!$J:$M,4,0),"") -> ADM | J11: =_xlfn.IFNA(VLOOKUP($E11,Master!$J:$M,3,0),"") -> SGA | M11: 71196000 | N11: 76179800 | O11: 76179800 | P11: 76179800 | Q11: 76179800 | R11: 76179800 | S11: 76179800 | T11: 76179800 | U11: 76179800 | V11: 76179800 | W11: 76179800 | X11: 76179800 | Y11: 76179800 | Z11: 81512500 | AA11: 81512500 | AB11: 81512500 | AC11: =SUM(K11:P11) -> 299735400 | AD11: =SUM(Q11:AB11) -> 930155700 | AE11: 995268000 | AF11: 1064937600 | AG11: A
A12: BEL | B12: =_xlfn.IFNA(VLOOKUP(C12,Master!$J:$K,2,0),"") -> B2220 | C12: Human Resource | D12: =_xlfn.IFNA(VLOOKUP(E12,Master!$J:$K,2,0),"") -> B4101 | E12: SP PD- CF | F12: =_xlfn.IFNA(VLOOKUP(G12,Master!B:C,2,0),"") -> 7511103 | G12: Staff Labor - Basic Salary | H12: Basic Salary | I12: =_xlfn.IFNA(VLOOKUP(E12,Master!$J:$M,4,0),"") -> DIR | J12: =_xlfn.IFNA(VLOOKUP($E12,Master!$J:$M,3,0),"") -> MFG | M12: 47547000 | N12: 50875600 | O12: 50875600 | P12: 50875600 | Q12: 50875600 | R12: 50875600 | S12: 50875600 | T12: 50875600 | U12: 50875600 | V12: 50875600 | W12: 50875600 | X12: 50875600 | Y12: 50875600 | Z12: 54436800 | AA12: 54436800 | AB12: 54436800 | AC12: =SUM(K12:P12) -> 200173800 | AD12: =SUM(Q12:AB12) -> 621190800 | AE12: 664673400 | AF12: 622194500 | AG12: A
A13: BEL | B13: =_xlfn.IFNA(VLOOKUP(C13,Master!$J:$K,2,0),"") -> B2220 | C13: Human Resource | D13: =_xlfn.IFNA(VLOOKUP(E13,Master!$J:$K,2,0),"") -> B4102 | E13: SP PD- CM | F13: =_xlfn.IFNA(VLOOKUP(G13,Master!B:C,2,0),"") -> 7511103 | G13: Staff Labor - Basic Salary | H13: Basic Salary | I13: =_xlfn.IFNA(VLOOKUP(E13,Master!$J:$M,4,0),"") -> DIR | J13: =_xlfn.IFNA(VLOOKUP($E13,Master!$J:$M,3,0),"") -> MFG | M13: 117001000 | N13: 125191700 | O13: 125191700 | P13: 125191700 | Q13: 114178100 | R13: 114178100 | S13: 114178100 | T13: 114178100 | U13: 114178100 | V13: 114178100 | W13: 120794000 | X13: 120794000 | Y13: 120794000 | Z13: 129249800 | AA13: 129249800 | AB13: 129249800 | AC13: =SUM(K13:P13) -> 492576100 | AD13: =SUM(Q13:AB13) -> 1435200000 | AE13: 1551677100 | AF13: 1457714700 | AG13: A
... A19: BEL | B19: =_xlfn.IFNA(VLOOKUP(C19,Master!$J:$K,2,0),"") -> B2220 | C19: Human Resource | D19: =_xlfn.IFNA(VLOOKUP(E19,Master!$J:$K,2,0),"") -> B4120 | E19: SP PD- Final Inspection | F19: =_xlfn.IFNA(VLOOKUP(G19,Master!B:C,2,0),"") -> 7511103 | G19: Staff Labor - Basic Salary | H19: Basic Salary | I19: =_xlfn.IFNA(VLOOKUP(E19,Master!$J:$M,4,0),"") -> DIR | J19: =_xlfn.IFNA(VLOOKUP($E19,Master!$J:$M,3,0),"") -> MFG | M19: 234388000 | N19: 250796500 | O19: 239044600 | P19: 239044600 | Q19: 235385400 | R19: 223902100 | S19: 223902100 | T19: 200604900 | U19: 200604900 | V19: 200604900 | W19: 214868100 | X19: 214868100 | Y19: 214868100 | Z19: 229908800 | AA19: 229908800 | AB19: 229908800 | AC19: =SUM(K19:P19) -> 963273700 | AD19: =SUM(Q19:AB19) -> 2619335000 | AE19: 2529357100 | AF19: 2663080200 | AG19: A
A20: BEL | B20: =_xlfn.IFNA(VLOOKUP(C20,Master!$J:$K,2,0),"") -> B2220 | C20: Human Resource | D20: =_xlfn.IFNA(VLOOKUP(E20,Master!$J:$K,2,0),"") -> B4121 | E20: SP PD- QC - OEM | F20: =_xlfn.IFNA(VLOOKUP(G20,Master!B:C,2,0),"") -> 7511103 | G20: Staff Labor - Basic Salary | H20: Basic Salary | I20: =_xlfn.IFNA(VLOOKUP(E20,Master!$J:$M,4,0),"") -> DIR | J20: =_xlfn.IFNA(VLOOKUP($E20,Master!$J:$M,3,0),"") -> MFG | M20: 19971000 | N20: 21369200 | O20: 21369200 | P20: 21369200 | AC20: =SUM(K20:P20) -> 84078600 | AD20: =SUM(Q20:AB20) -> 0 | AG20: A
A21: BEL | B21: =_xlfn.IFNA(VLOOKUP(C21,Master!$J:$K,2,0),"") -> B2220 | C21: Human Resource | D21: =_xlfn.IFNA(VLOOKUP(E21,Master!$J:$K,2,0),"") -> B4130 | E21: SP PD- Insulator Sealing | F21: =_xlfn.IFNA(VLOOKUP(G21,Master!B:C,2,0),"") -> 7511103 | G21: Staff Labor - Basic Salary | H21: Basic Salary | I21: =_xlfn.IFNA(VLOOKUP(E21,Master!$J:$M,4,0),"") -> DIR | J21: =_xlfn.IFNA(VLOOKUP($E21,Master!$J:$M,3,0),"") -> MFG | M21: 49572000 | N21: 53042300 | O21: 53042300 | P21: 53042300 | Q21: 53042300 | R21: 53042300 | S21: 53042300 | T21: 53042300 | U21: 53042300 | V21: 53042300 | W21: 53042300 | X21: 53042300 | Y21: 53042300 | Z21: 56755300 | AA21: 56755300 | AB21: 56755300 | AC21: =SUM(K21:P21) -> 208698900 | AD21: =SUM(Q21:AB21) -> 647646600 | AE21: 616097600 | AF21: 602174100 | AG21: A
A22: BEL | B22: =_xlfn.IFNA(VLOOKUP(C22,Master!$J:$K,2,0),"") -> B2220 | C22: Human Resource | D22: =_xlfn.IFNA(VLOOKUP(E22,Master!$J:$K,2,0),"") -> B4410 | E22: PC PD- Injection | F22: =_xlfn.IFNA(VLOOKUP(G22,Master!B:C,2,0),"") -> 7511103 | G22: Staff Labor - Basic Salary | H22: Basic Salary | I22: =_xlfn.IFNA(VLOOKUP(E22,Master!$J:$M,4,0),"") -> DIR | J22: =_xlfn.IFNA(VLOOKUP($E22,Master!$J:$M,3,0),"") -> MFG | M22: 22297000 | N22: 23857900 | O22: 23857900 | P22: 23857900 | Q22: 23857900 | R22: 23857900 | S22: 23857900 | T22: 23857900 | U22: 23857900 | V22: 23857900 | W22: 23857900 | X22: 23857900 | Y22: 23857900 | AC22: =SUM(K22:P22) -> 93870700 | AD22: =SUM(Q22:AB22) -> 214721100 | AG22: A
A23: BEL | B23: =_xlfn.IFNA(VLOOKUP(C23,Master!$J:$K,2,0),"") -> B2220 | C23: Human Resource | D23: =_xlfn.IFNA(VLOOKUP(E23,Master!$J:$K,2,0),"") -> B4430 | E23: PC PD- Assy | F23: =_xlfn.IFNA(VLOOKUP(G23,Master!B:C,2,0),"") -> 7511103 | G23: Staff Labor - Basic Salary | H23: Basic Salary | I23: =_xlfn.IFNA(VLOOKUP(E23,Master!$J:$M,4,0),"") -> DIR | J23: =_xlfn.IFNA(VLOOKUP($E23,Master!$J:$M,3,0),"") -> MFG | M23: 38090000 | N23: 40756600 | O23: 40756600 | P23: 40756600 | Q23: 40756600 | R23: 40756600 | S23: 40756600 | T23: 40756600 | U23: 40756600 | V23: 40756600 | W23: 40756600 | X23: 40756600 | Y23: 40756600 | AC23: =SUM(K23:P23) -> 160359800 | AD23: =SUM(Q23:AB23) -> 366809400 | AG23: A
A24: BEL | B24: =_xlfn.IFNA(VLOOKUP(C24,Master!$J:$K,2,0),"") -> B2220 | C24: Human Resource | D24: =_xlfn.IFNA(VLOOKUP(E24,Master!$J:$K,2,0),"") -> B4440 | E24: PC PD- QC | F24: =_xlfn.IFNA(VLOOKUP(G24,Master!B:C,2,0),"") -> 7511103 | G24: Staff Labor - Basic Salary | H24: Basic Salary | I24: =_xlfn.IFNA(VLOOKUP(E24,Master!$J:$M,4,0),"") -> DIR | J24: =_xlfn.IFNA(VLOOKUP($E24,Master!$J:$M,3,0),"") -> MFG | M24: 41955000 | N24: 44892100 | O24: 32647000 | P24: 32647000 | Q24: 32647000 | R24: 32647000 | S24: 32647000 | T24: 32647000 | U24: 32647000 | V24: 32647000 | W24: 32647000 | X24: 32647000 | Y24: 21749000 | AC24: =SUM(K24:P24) -> 152141100 | AD24: =SUM(Q24:AB24) -> 282925000 | AG24: A
A25: BEL | B25: =_xlfn.IFNA(VLOOKUP(C25,Master!$J:$K,2,0),"") -> B2220 | C25: Human Resource | D25: =_xlfn.IFNA(VLOOKUP(E25,Master!$J:$K,2,0),"") -> B5100 | E25: Production Office | F25: =_xlfn.IFNA(VLOOKUP(G25,Master!B:C,2,0),"") -> 7511103 | G25: Staff Labor - Basic Salary | H25: Basic Salary | I25: =_xlfn.IFNA(VLOOKUP(E25,Master!$J:$M,4,0),"") -> IND | J25: =_xlfn.IFNA(VLOOKUP($E25,Master!$J:$M,3,0),"") -> MFG | M25: 115903000 | N25: 124016400 | O25: 124016400 | P25: 124016400 | Q25: 124016400 | R25: 124016400 | S25: 124016400 | T25: 124016400 | U25: 124016400 | V25: 124016400 | W25: 124016400 | X25: 124016400 | Y25: 124016400 | Z25: 132697500 | AA25: 132697500 | AB25: 132697500 | AC25: =SUM(K25:P25) -> 487952200 | AD25: =SUM(Q25:AB25) -> 1514240100 | AE25: 1620236700 | AF25: 1733653800 | AG25: A
A26: BEL | B26: =_xlfn.IFNA(VLOOKUP(C26,Master!$J:$K,2,0),"") -> B2220 | C26: Human Resource | D26: =_xlfn.IFNA(VLOOKUP(E26,Master!$J:$K,2,0),"") -> B5101 | E26: Production Office (SP) | F26: =_xlfn.IFNA(VLOOKUP(G26,Master!B:C,2,0),"") -> 7511103 | G26: Staff Labor - Basic Salary | H26: Basic Salary | I26: =_xlfn.IFNA(VLOOKUP(E26,Master!$J:$M,4,0),"") -> IND | J26: =_xlfn.IFNA(VLOOKUP($E26,Master!$J:$M,3,0),"") -> MFG | M26: 57936000 | N26: 61991800 | O26: 61991800 | P26: 61991800 | Q26: 60924900 | R26: 60924900 | S26: 60924900 | T26: 60924900 | U26: 60924900 | V26: 60924900 | W26: 61593400 | X26: 61593400 | Y26: 61593400 | Z26: 65904900 | AA26: 65904900 | AB26: 65904900 | AC26: =SUM(K26:P26) -> 243911400 | AD26: =SUM(Q26:AB26) -> 748044300 | AE26: 858662400 | AF26: 974557500 | AG26: A
A27: BEL | B27: =_xlfn.IFNA(VLOOKUP(C27,Master!$J:$K,2,0),"") -> B2220 | C27: Human Resource | D27: =_xlfn.IFNA(VLOOKUP(E27,Master!$J:$K,2,0),"") -> B5130 | E27: Supply Procurement | F27: =_xlfn.IFNA(VLOOKUP(G27,Master!B:C,2,0),"") -> 7511103 | G27: Staff Labor - Basic Salary | H27: Basic Salary | I27: =_xlfn.IFNA(VLOOKUP(E27,Master!$J:$M,4,0),"") -> IND | J27: =_xlfn.IFNA(VLOOKUP($E27,Master!$J:$M,3,0),"") -> MFG | M27: 128750000 | N27: 137763200 | O27: 137763200 | P27: 137763200 | Q27: 137763200 | R27: 137763200 | S27: 137763200 | T27: 137763200 | U27: 137763200 | V27: 137763200 | W27: 137763200 | X27: 137763200 | Y27: 137763200 | Z27: 136608700 | AA27: 136608700 | AB27: 136608700 | AC27: =SUM(K27:P27) -> 542039600 | AD27: =SUM(Q27:AB27) -> 1649694900 | AE27: 1636794300 | AF27: 1657776000 | AG27: A
A28: BEL | B28: =_xlfn.IFNA(VLOOKUP(C28,Master!$J:$K,2,0),"") -> B2220 | C28: Human Resource | D28: =_xlfn.IFNA(VLOOKUP(E28,Master!$J:$K,2,0),"") -> B5200 | E28: Inventory Control | F28: =_xlfn.IFNA(VLOOKUP(G28,Master!B:C,2,0),"") -> 7511103 | G28: Staff Labor - Basic Salary | H28: Basic Salary | I28: =_xlfn.IFNA(VLOOKUP(E28,Master!$J:$M,4,0),"") -> IND | J28: =_xlfn.IFNA(VLOOKUP($E28,Master!$J:$M,3,0),"") -> MFG | M28: 19722000 | N28: 21102700 | O28: 21102700 | P28: 21102700 | Q28: 21813400 | R28: 21813400 | S28: 21813400 | T28: 21813400 | U28: 21813400 | V28: 21813400 | W28: 21813400 | X28: 21813400 | Y28: 21813400 | Z28: 23340300 | AA28: 23340300 | AB28: 23340300 | AC28: =SUM(K28:P28) -> 83030100 | AD28: =SUM(Q28:AB28) -> 266341500 | AE28: 284985300 | AF28: 304935000 | AG28: A
A29: BEL | B29: =_xlfn.IFNA(VLOOKUP(C29,Master!$J:$K,2,0),"") -> B2220 | C29: Human Resource | D29: =_xlfn.IFNA(VLOOKUP(E29,Master!$J:$K,2,0),"") -> B5500 | E29: Maintenance | F29: =_xlfn.IFNA(VLOOKUP(G29,Master!B:C,2,0),"") -> 7511103 | G29: Staff Labor - Basic Salary | H29: Basic Salary | I29: =_xlfn.IFNA(VLOOKUP(E29,Master!$J:$M,4,0),"") -> IND | J29: =_xlfn.IFNA(VLOOKUP($E29,Master!$J:$M,3,0),"") -> MFG | M29: 79461600 | N29: 90267300 | O29: 90267300 | P29: 90267300 | Q29: 118732000 | R29: 118732000 | S29: 118732000 | T29: 118732000 | U29: 118732000 | V29: 118732000 | W29: 125819700 | X29: 125819700 | Y29: 125819700 | Z29: 134627500 | AA29: 134627500 | AB29: 134627500 | AC29: =SUM(K29:P29) -> 350263500 | AD29: =SUM(Q29:AB29) -> 1493733600 | AE29: 1608081300 | AF29: 1669928400 | AG29: A
A30: BEL | B30: =_xlfn.IFNA(VLOOKUP(C30,Master!$J:$K,2,0),"") -> B2220 | C30: Human Resource | D30: =_xlfn.IFNA(VLOOKUP(E30,Master!$J:$K,2,0),"") -> B5600 | E30: Production Engineering | F30: =_xlfn.IFNA(VLOOKUP(G30,Master!B:C,2,0),"") -> 7511103 | G30: Staff Labor - Basic Salary | H30: Basic Salary | I30: =_xlfn.IFNA(VLOOKUP(E30,Master!$J:$M,4,0),"") -> IND | J30: =_xlfn.IFNA(VLOOKUP($E30,Master!$J:$M,3,0),"") -> MFG | M30: 102763000 | N30: 109957000 | O30: 109957000 | P30: 109957000 | Q30: 111382100 | R30: 111382100 | S30: 111382100 | T30: 111382100 | U30: 111382100 | V30: 111382100 | W30: 111382100 | X30: 111382100 | Y30: 111382100 | Z30: 119178600 | AA30: 119178600 | AB30: 119178600 | AC30: =SUM(K30:P30) -> 432634000 | AD30: =SUM(Q30:AB30) -> 1359974700 | AE30: 1474053000 | AF30: 1600005600 | AG30: A
A31: BEL | B31: =_xlfn.IFNA(VLOOKUP(C31,Master!$J:$K,2,0),"") -> B2220 | C31: Human Resource | D31: =_xlfn.IFNA(VLOOKUP(E31,Master!$J:$K,2,0),"") -> B5710 | E31: WH Dept.- KD & RM | F31: =_xlfn.IFNA(VLOOKUP(G31,Master!B:C,2,0),"") -> 7511103 | G31: Staff Labor - Basic Salary | H31: Basic Salary | I31: =_xlfn.IFNA(VLOOKUP(E31,Master!$J:$M,4,0),"") -> IND | J31: =_xlfn.IFNA(VLOOKUP($E31,Master!$J:$M,3,0),"") -> MFG | M31: 49886000 | N31: 53378300 | O31: 53378300 | P31: 53378300 | Q31: 53378300 | R31: 53378300 | S31: 53378300 | T31: 53378300 | U31: 53378300 | V31: 53378300 | W31: 53378300 | X31: 53378300 | Y31: 53378300 | Z31: 67912400 | AA31: 67912400 | AB31: 67912400 | AC31: =SUM(K31:P31) -> 210020900 | AD31: =SUM(Q31:AB31) -> 684141900 | AE31: 726411300 | AF31: 741431400 | AG31: A
A32: BEL | B32: =_xlfn.IFNA(VLOOKUP(C32,Master!$J:$K,2,0),"") -> B2220 | C32: Human Resource | D32: =_xlfn.IFNA(VLOOKUP(E32,Master!$J:$K,2,0),"") -> B5800 | E32: Quality Assurance | F32: =_xlfn.IFNA(VLOOKUP(G32,Master!B:C,2,0),"") -> 7511103 | G32: Staff Labor - Basic Salary | H32: Basic Salary | I32: =_xlfn.IFNA(VLOOKUP(E32,Master!$J:$M,4,0),"") -> IND | J32: =_xlfn.IFNA(VLOOKUP($E32,Master!$J:$M,3,0),"") -> MFG | M32: 105115000 | N32: 112473300 | O32: 112473300 | P32: 112473300 | Q32: 113186800 | R32: 113186800 | S32: 113186800 | T32: 113186800 | U32: 113186800 | V32: 113186800 | W32: 113186800 | X32: 113186800 | Y32: 113186800 | Z32: 121110100 | AA32: 121110100 | AB32: 121110100 | AC32: =SUM(K32:P32) -> 442534900 | AD32: =SUM(Q32:AB32) -> 1382011500 | AE32: 1478754300 | AF32: 1461641600 | AG32: A
A33: BEL | B33: =_xlfn.IFNA(VLOOKUP(C33,Master!$J:$K,2,0),"") -> B2220 | C33: Human Resource | D33: =_xlfn.IFNA(VLOOKUP(E33,Master!$J:$K,2,0),"") -> B5900 | E33: Quality Control | F33: =_xlfn.IFNA(VLOOKUP(G33,Master!B:C,2,0),"") -> 7511103 | G33: Staff Labor - Basic Salary | H33: Basic Salary | I33: =_xlfn.IFNA(VLOOKUP(E33,Master!$J:$M,4,0),"") -> IND | J33: =_xlfn.IFNA(VLOOKUP($E33,Master!$J:$M,3,0),"") -> MFG | M33: 97042000 | N33: 103835500 | O33: 103835500 | P33: 103835500 | Q33: 103835500 | R33: 103835500 | S33: 103835500 | T33: 103835500 | U33: 103835500 | V33: 103835500 | W33: 103835500 | X33: 103835500 | Y33: 103835500 | Z33: 111104000 | AA33: 111104000 | AB33: 111104000 | AC33: =SUM(K33:P33) -> 408548500 | AD33: =SUM(Q33:AB33) -> 1267831500 | AE33: 1370765700 | AF33: 1343855100 | AG33: A
A34: BEL | B34: =_xlfn.IFNA(VLOOKUP(C34,Master!$J:$K,2,0),"") -> B2220 | C34: Human Resource | D34: =_xlfn.IFNA(VLOOKUP(E34,Master!$J:$K,2,0),"") -> B2210 | E34: General Affair | F34: =_xlfn.IFNA(VLOOKUP(G34,Master!B:C,2,0),"") -> 7511111 | G34: Staff Labor - Allowance | H34: ATM Allowance | I34: =_xlfn.IFNA(VLOOKUP(E34,Master!$J:$M,4,0),"") -> ADM | J34: =_xlfn.IFNA(VLOOKUP($E34,Master!$J:$M,3,0),"") -> SGA | M34: 76500 | N34: 76500 | O34: 76500 | P34: 76500 | Q34: 76500 | R34: 72000 | S34: 72000 | T34: 67500 | U34: 67500 | V34: 67500 | W34: 67500 | X34: 67500 | Y34: 63000 | Z34: 63000 | AA34: 63000 | AB34: 63000 | AC34: =SUM(K34:P34) -> 306000 | AD34: =SUM(Q34:AB34) -> 810000 | AE34: 810000 | AF34: 697500 | AG34: A
A35: BEL | B35: =_xlfn.IFNA(VLOOKUP(C35,Master!$J:$K,2,0),"") -> B2220 | C35: Human Resource | D35: =_xlfn.IFNA(VLOOKUP(E35,Master!$J:$K,2,0),"") -> B2210 | E35: General Affair | F35: =_xlfn.IFNA(VLOOKUP(G35,Master!B:C,2,0),"") -> 7511111 | G35: Staff Labor - Allowance | H35: Daily Transportation Allowance | I35: =_xlfn.IFNA(VLOOKUP(E35,Master!$J:$M,4,0),"") -> ADM | J35: =_xlfn.IFNA(VLOOKUP($E35,Master!$J:$M,3,0),"") -> SGA | M35: 7875200 | N35: 9162400 | O35: 8457600 | P35: 7400400 | Q35: 6343200 | R35: 7337000 | S35: 7003500 | T35: 7865000 | U35: 7550400 | V35: 6921200 | W35: 7865000 | X35: 7235800 | Y35: 6505400 | Z35: 7437600 | AA35: 6817800 | AB35: 5888100 | AC35: =SUM(K35:P35) -> 32895600 | AD35: =SUM(Q35:AB35) -> 84770000 | AE35: 85818400 | AF35: 74372100 | AG35: A
A36: BEL | B36: =_xlfn.IFNA(VLOOKUP(C36,Master!$J:$K,2,0),"") -> B2220 | C36: Human Resource | D36: =_xlfn.IFNA(VLOOKUP(E36,Master!$J:$K,2,0),"") -> B2210 | E36: General Affair | F36: =_xlfn.IFNA(VLOOKUP(G36,Master!B:C,2,0),"") -> 7511111 | G36: Staff Labor - Allowance | H36: Job Allowance | I36: =_xlfn.IFNA(VLOOKUP(E36,Master!$J:$M,4,0),"") -> ADM | J36: =_xlfn.IFNA(VLOOKUP($E36,Master!$J:$M,3,0),"") -> SGA | M36: 1550000 | N36: 1550000 | O36: 1550000 | P36: 1550000 | Q36: 1550000 | R36: 1550000 | S36: 1550000 | T36: 1550000 | U36: 1550000 | V36: 1550000 | W36: 1550000 | X36: 1550000 | Y36: 1550000 | Z36: 2950000 | AA36: 2950000 | AB36: 2950000 | AC36: =SUM(K36:P36) -> 6200000 | AD36: =SUM(Q36:AB36) -> 22800000 | AE36: 41400000 | AF36: 33900000 | AG36: A
A37: BEL | B37: =_xlfn.IFNA(VLOOKUP(C37,Master!$J:$K,2,0),"") -> B2220 | C37: Human Resource | D37: =_xlfn.IFNA(VLOOKUP(E37,Master!$J:$K,2,0),"") -> B2210 | E37: General Affair | F37: =_xlfn.IFNA(VLOOKUP(G37,Master!B:C,2,0),"") -> 7511111 | G37: Staff Labor - Allowance | H37: Meals Allowance | I37: =_xlfn.IFNA(VLOOKUP(E37,Master!$J:$M,4,0),"") -> ADM | J37: =_xlfn.IFNA(VLOOKUP($E37,Master!$J:$M,3,0),"") -> SGA | P37: 3128000 | Q37: 1564000 | AB37: 4032000 | AC37: =SUM(K37:P37) -> 3128000 | AD37: =SUM(Q37:AB37) -> 5596000 | AE37: 4500000 | AF37: 3432000 | AG37: A
A38: BEL | B38: =_xlfn.IFNA(VLOOKUP(C38,Master!$J:$K,2,0),"") -> B2220 | C38: Human Resource | D38: =_xlfn.IFNA(VLOOKUP(E38,Master!$J:$K,2,0),"") -> B2210 | E38: General Affair | F38: =_xlfn.IFNA(VLOOKUP(G38,Master!B:C,2,0),"") -> 7511111 | G38: Staff Labor - Allowance | H38: Medical Allowance | I38: =_xlfn.IFNA(VLOOKUP(E38,Master!$J:$M,4,0),"") -> ADM | J38: =_xlfn.IFNA(VLOOKUP($E38,Master!$J:$M,3,0),"") -> SGA | M38: 1000000 | N38: 1000000 | O38: 1000000 | P38: 1000000 | Q38: 1000000 | R38: 940000 | S38: 940000 | T38: 880000 | U38: 880000 | V38: 880000 | W38: 880000 | X38: 880000 | Y38: 820000 | Z38: 820000 | AA38: 820000 | AB38: 820000 | AC38: =SUM(K38:P38) -> 4000000 | AD38: =SUM(Q38:AB38) -> 10560000 | AE38: 10560000 | AF38: 9060000 | AG38: A
A39: BEL | B39: =_xlfn.IFNA(VLOOKUP(C39,Master!$J:$K,2,0),"") -> B2220 | C39: Human Resource | D39: =_xlfn.IFNA(VLOOKUP(E39,Master!$J:$K,2,0),"") -> B2210 | E39: General Affair | F39: =_xlfn.IFNA(VLOOKUP(G39,Master!B:C,2,0),"") -> 7511111 | G39: Staff Labor - Allowance | H39: Transportation (fixed) Allowance | I39: =_xlfn.IFNA(VLOOKUP(E39,Master!$J:$M,4,0),"") -> ADM | J39: =_xlfn.IFNA(VLOOKUP($E39,Master!$J:$M,3,0),"") -> SGA | M39: 5100000 | N39: 5100000 | O39: 5100000 | P39: 5100000 | Q39: 5100000 | R39: 4800000 | S39: 4800000 | T39: 4500000 | U39: 4500000 | V39: 4500000 | W39: 4500000 | X39: 4500000 | Y39: 4200000 | Z39: 4200000 | AA39: 4200000 | AB39: 4200000 | AC39: =SUM(K39:P39) -> 20400000 | AD39: =SUM(Q39:AB39) -> 54000000 | AE39: 54000000 | AF39: 46500000 | AG39: A
A40: BEL | B40: =_xlfn.IFNA(VLOOKUP(C40,Master!$J:$K,2,0),"") -> B2220 | C40: Human Resource | D40: =_xlfn.IFNA(VLOOKUP(E40,Master!$J:$K,2,0),"") -> B2220 | E40: Human Resource | F40: =_xlfn.IFNA(VLOOKUP(G40,Master!B:C,2,0),"") -> 7511111 | G40: Staff Labor - Allowance | H40: ATM Allowance | I40: =_xlfn.IFNA(VLOOKUP(E40,Master!$J:$M,4,0),"") -> ADM | J40: =_xlfn.IFNA(VLOOKUP($E40,Master!$J:$M,3,0),"") -> SGA | M40: 22500 | N40: 22500 | O40: 27000 | P40: 27000 | Q40: 31500 | R40: 31500 | S40: 31500 | T40: 31500 | U40: 31500 | V40: 31500 | W40: 31500 | X40: 31500 | Y40: 31500 | Z40: 31500 | AA40: 31500 | AB40: 31500 | AC40: =SUM(K40:P40) -> 99000 | AD40: =SUM(Q40:AB40) -> 378000 | AE40: 378000 | AF40: 378000 | AG40: A
A41: BEL | B41: =_xlfn.IFNA(VLOOKUP(C41,Master!$J:$K,2,0),"") -> B2220 | C41: Human Resource | D41: =_xlfn.IFNA(VLOOKUP(E41,Master!$J:$K,2,0),"") -> B2220 | E41: Human Resource | F41: =_xlfn.IFNA(VLOOKUP(G41,Master!B:C,2,0),"") -> 7511111 | G41: Staff Labor - Allowance | H41: Daily Transportation Allowance | I41: =_xlfn.IFNA(VLOOKUP(E41,Master!$J:$M,4,0),"") -> ADM | J41: =_xlfn.IFNA(VLOOKUP($E41,Master!$J:$M,3,0),"") -> SGA | M41: 12720650 | N41: 13010300 | O41: 16317200 | P41: 16027550 | Q41: 18696000 | R41: 19184000 | S41: 19062000 | T41: 19550000 | U41: 19428000 | V41: 19184000 | W41: 19550000 | X41: 19306000 | Y41: 19184000 | Z41: 19428000 | AA41: 19184000 | AB41: 18818000 | AC41: =SUM(K41:P41) -> 58075700 | AD41: =SUM(Q41:AB41) -> 230574000 | AE41: 231153000 | AF41: 233700000 | AG41: A
A42: BEL | B42: =_xlfn.IFNA(VLOOKUP(C42,Master!$J:$K,2,0),"") -> B2220 | C42: Human Resource | D42: =_xlfn.IFNA(VLOOKUP(E42,Master!$J:$K,2,0),"") -> B2220 | E42: Human Resource | F42: =_xlfn.IFNA(VLOOKUP(G42,Master!B:C,2,0),"") -> 7511111 | G42: Staff Labor - Allowance | H42: Job Allowance | I42: =_xlfn.IFNA(VLOOKUP(E42,Master!$J:$M,4,0),"") -> ADM | J42: =_xlfn.IFNA(VLOOKUP($E42,Master!$J:$M,3,0),"") -> SGA | M42: 4250000 | N42: 4250000 | O42: 5750000 | P42: 5750000 | Q42: 5750000 | R42: 5750000 | S42: 5750000 | T42: 5750000 | U42: 5750000 | V42: 5750000 | W42: 5750000 | X42: 5750000 | Y42: 5750000 | Z42: 7600000 | AA42: 7600000 | AB42: 7600000 | AC42: =SUM(K42:P42) -> 20000000 | AD42: =SUM(Q42:AB42) -> 74550000 | AE42: 91200000 | AF42: 91200000 | AG42: A
A43: BEL | B43: =_xlfn.IFNA(VLOOKUP(C43,Master!$J:$K,2,0),"") -> B2220 | C43: Human Resource | D43: =_xlfn.IFNA(VLOOKUP(E43,Master!$J:$K,2,0),"") -> B2220 | E43: Human Resource | F43: =_xlfn.IFNA(VLOOKUP(G43,Master!B:C,2,0),"") -> 7511111 | G43: Staff Labor - Allowance | H43: Meals Allowance | I43: =_xlfn.IFNA(VLOOKUP(E43,Master!$J:$M,4,0),"") -> ADM | J43: =_xlfn.IFNA(VLOOKUP($E43,Master!$J:$M,3,0),"") -> SGA | P43: 1104000 | Q43: 644000 | AB43: 2016000 | AC43: =SUM(K43:P43) -> 1104000 | AD43: =SUM(Q43:AB43) -> 2660000 | AE43: 2100000 | AF43: 2184000 | AG43: A
A44: BEL | B44: =_xlfn.IFNA(VLOOKUP(C44,Master!$J:$K,2,0),"") -> B2220 | C44: Human Resource | D44: =_xlfn.IFNA(VLOOKUP(E44,Master!$J:$K,2,0),"") -> B2220 | E44: Human Resource | F44: =_xlfn.IFNA(VLOOKUP(G44,Master!B:C,2,0),"") -> 7511111 | G44: Staff Labor - Allowance | H44: Medical Allowance | I44: =_xlfn.IFNA(VLOOKUP(E44,Master!$J:$M,4,0),"") -> ADM | J44: =_xlfn.IFNA(VLOOKUP($E44,Master!$J:$M,3,0),"") -> SGA | M44: 160000 | N44: 160000 | O44: 160000 | P44: 160000 | Q44: 220000 | R44: 220000 | S44: 220000 | T44: 220000 | U44: 220000 | V44: 220000 | W44: 220000 | X44: 220000 | Y44: 220000 | Z44: 220000 | AA44: 220000 | AB44: 220000 | AC44: =SUM(K44:P44) -> 640000 | AD44: =SUM(Q44:AB44) -> 2640000 | AE44: 2640000 | AF44: 2640000 | AG44: A
A45: BEL | B45: =_xlfn.IFNA(VLOOKUP(C45,Master!$J:$K,2,0),"") -> B2220 | C45: Human Resource | D45: =_xlfn.IFNA(VLOOKUP(E45,Master!$J:$K,2,0),"") -> B2220 | E45: Human Resource | F45: =_xlfn.IFNA(VLOOKUP(G45,Master!B:C,2,0),"") -> 7511111 | G45: Staff Labor - Allowance | H45: Transportation (fixed) Allowance | I45: =_xlfn.IFNA(VLOOKUP(E45,Master!$J:$M,4,0),"") -> ADM | J45: =_xlfn.IFNA(VLOOKUP($E45,Master!$J:$M,3,0),"") -> SGA | M45: 1200000 | N45: 1200000 | O45: 3200000 | P45: 3200000 | Q45: 3500000 | R45: 3500000 | S45: 3500000 | T45: 3500000 | U45: 3500000 | V45: 3500000 | W45: 3500000 | X45: 3500000 | Y45: 3500000 | Z45: 3500000 | AA45: 3500000 | AB45: 3500000 | AC45: =SUM(K45:P45) -> 8800000 | AD45: =SUM(Q45:AB45) -> 42000000 | AE45: 42000000 | AF45: 42000000 | AG45: A
...

Sheet Master
A1: COA AX | B1: Name COA AX | C1: COA AX | D1: COA AX | E1: Group Cost | F1: UNIQ | G1: COA Budget | H1: Description | J1: Name | K1: BNGK | L1: GROUP COST | M1: GROUP SECTION | N1: Name | P1: Code | Q1: Name | S1: Priority Code | T1: Priority Name | U1: Description
A2: 7511101 | B2: Salary for Commissioner | C2: 7511101 | D2: 7511101 | E2: SGA | F2: SGA-7511101 | G2: A502 | H2: Salary for Commissioner | J2: Top Management | K2: B1000 | L2: SGA | M2: ADM | N2: Top Management | P2: 53450 | Q2: NGK BUSI INDONESIA | S2: A | T2: Must | U2: If this is not done, the company or our team cannot continue its business.
A3: 7511102 | B3: Salary for Director | C3: 7511102 | D3: 7511102 | E3: SGA | F3: SGA-7511102 | G3: A502 | H3: Salary for Director & Expat | J3: Commissioner | K3: B1001 | L3: SGA | M3: ADM | N3: Commissioner | S3: B | T3: Want to | U3: We want to do it as a team this term. we need it.
A4: 7511103 | B4: Staff Labor - Baslc Salary | C4: 7511103 | D4: 7511103 | E4: SGA | F4: SGA-7511103 | G4: A501 | H4: Basic Salary of permanent employee | J4: Admin & HR | K4: B2200 | L4: SGA | M4: ADM | N4: Admin & HR | S4: C | T4: Challenge | U4: We want to do it for this term or the future. But it doesn't matter if it's not this term.
A5: 7511111 | B5: Staff Labor - Allowance | C5: 7511111 | D5: 7511111 | E5: SGA | F5: SGA-7511111 | G5: A501 | H5: Employee allowance | J5: General Affair | K5: B2210 | L5: SGA | M5: ADM | N5: General Affair
A6: 7511112 | B6: Staff Labor - Tax allowance (art.21) | C6: 7511112 | D6: 7511112 | E6: SGA | F6: SGA-7511112 | G6: A501 | H6: Empployee Tax allowance | J6: Human Resource | K6: B2220 | L6: SGA | M6: ADM | N6: Human Resource | P6: BEX
A7: 7511121 | B7: Staff Labor - BPJS JK & JKK (1.19%) | C7: 7511121 | D7: 7511121 | E7: SGA | F7: SGA-7511121 | G7: A501 | H7: BPJS JK & JKK (death warrant, Accident Insurance) | J7: Health, Safety & Environment | K7: B2230 | L7: SGA | M7: ADM | N7: Health, Safety & Environment | P7: BEL
A8: 7511122 | B8: Staff Labor - BPJS Kesehatan (4%) | C8: 7511122 | D8: 7511122 | E8: SGA | F8: SGA-7511122 | G8: A501 | H8: BPJS health insurance | J8: Accounting & Finance | K8: B2300 | L8: SGA | M8: ADM | N8: Accounting & Finance
A9: 7511201 | B9: Staff Overtime | C9: 7511201 | D9: 7511201 | E9: SGA | F9: SGA-7511201 | G9: A503 | H9: Overtime permanent employee | J9: Information Technology | K9: B2400 | L9: SGA | M9: ADM | N9: Information Technology
A10: 7512111 | B10: Staff Welfare - BPJS Dana pensiun (2%) | C10: 7512111 | D10: 7512111 | E10: SGA | F10: SGA-7512111 | G10: A504 | H10: BPJS pension fund | J10: Sales & MKTG Dept.- Automotive | K10: B3100 | L10: SGA | M10: ADM | N10: Sales & MKTG Dept.- Automotive
A11: 7512112 | B11: Staff Welfare - BPJS JHT (3.7%) | C11: 7512112 | D11: 7512112 | E11: SGA | F11: SGA-7512112 | G11: A504 | H11: BPJS Pension plan | J11: Marketing | K11: B3160 | L11: SGA | M11: ADM | N11: Marketing
A12: 7514101 | B12: Staff Bonus / TAT | C12: 7514101 | D12: 7514101 | E12: SGA | F12: SGA-7514101 | G12: A501 | H12: Year-end allowance & Alpha | J12: Sales - OEM | K12: B3110 | L12: SGA | M12: ADM | N12: Sales - OEM
A13: 7514102 | B13: Staff Ramadhan / THR | C13: 7514102 | D13: 7514102 | E13: SGA | F13: SGA-7514102 | G13: A501 | H13: Lebaran bonus | J13: Sales - OES | K13: B3120 | L13: SGA | M13: ADM | N13: Sales - OES
A14: 7515401 | B14: Staff Welfare - Outpatient (Medical) | C14: 7515401 | D14: 7515401 | E14: SGA | F14: SGA-7515401 | G14: A504 | H14: outpatient treatment costs | J14: Sales - IAM | K14: B3130 | L14: SGA | M14: ADM | N14: Sales - IAM
A15: 7515402 | B15: Staff Welfare - Hospitalization | C15: 7515402 | D15: 7515402 | E15: SGA | F15: SGA-7515402 | G15: A504 | H15: hospitalization costs | J15: Sales & MKTG Dept.- DID Chain | K15: B3172 | L15: SGA | M15: ADM | N15: Sales & MKTG Dept.- DID Chain
A16: 7515403 | B16: Staff Welfare - Glasses | C16: 7515403 | D16: 7515403 | E16: SGA | F16: SGA-7515403 | G16: A504 | H16: glasses costs | J16: SP PD- CF | K16: B4101 | L16: MFG | M16: DIR | N16: SP PD- CF
A17: 7515404 | B17: Staff Welfare - Dental | C17: 7515404 | D17: 7515404 | E17: SGA | F17: SGA-7515404 | G17: A504 | H17: dental costs | J17: SP PD- CM | K17: B4102 | L17: MFG | M17: DIR | N17: SP PD- CM
A18: 7515405 | B18: Staff Welfare - Medical Check Up | C18: 7515405 | D18: 7515405 | E18: SGA | F18: SGA-7515405 | G18: A504 | H18: Medical Check Up cost | J18: SP PD- WT | K18: B4103 | L18: MFG | M18: DIR | N18: SP PD- WT
A19: 7515406 | B19: Staff Welfare - Uniform | C19: 7515406 | D19: 7515406 | E19: SGA | F19: SGA-7515406 | G19: A504 | H19: uniform costs | J19: SP PD- Plating | K19: B4105 | L19: MFG | M19: DIR | N19: SP PD- Plating
A20: 7515407 | B20: Staff Welfare - Safety Shoes | C20: 7515407 | D20: 7515407 | E20: SGA | F20: SGA-7515407 | G20: A504 | J20: SP PD- MS Insp. | K20: B4109 | L20: MFG | M20: DIR | N20: SP PD- MS Insp.
A21: 7515408 | B21: Staff Welfare - Family Gathering / Anniversary | C21: 7515408 | D21: 7515408 | E21: SGA | F21: SGA-7515408 | G21: A504 | H21: Family Gathering / Anniversary | J21: SP PD- Insulator Sealing | K21: B4130 | L21: MFG | M21: DIR | N21: SP PD- Insulator Sealing
A22: 7515409 | B22: Staff Welfare - Meals of canteen & other meals | C22: 7515409 | D22: 7515409 | E22: SGA | F22: SGA-7515409 | G22: A504 | H22: Meals of canteen & other meals cost | J22: SP PD- Assy | K22: B4110 | L22: MFG | M22: DIR | N22: SP PD- Assy
A23: 7515410 | B23: Staff Welfare - Kaizen & QCC reward | C23: 7515410 | D23: 7515410 | E23: SGA | F23: SGA-7515410 | G23: A504 | H23: an expense, arising from Kaizen and QCC acitivity | J23: SP-PD-Assy-Auto Assembly | K23: B4115 | L23: MFG | M23: DIR | N23: SP-PD-Assy-Auto Assembly
A24: 7515499 | B24: Staff Welfare - Welfare Others | C24: 7515499 | D24: 7515499 | E24: SGA | F24: SGA-7515499 | G24: A504 | H24: an other welfare expense, arising besides the above welfare expense | J24: SP PD- Bending | K24: B4114 | L24: MFG | M24: DIR | N24: SP PD- Bending
A25: 7516102 | B25: Retirement Allowance | C25: 7516102 | D25: 7516102 | E25: SGA | F25: SGA-7516102 | G25: A505 | H25: employee retirement provission costs | J25: SP PD- Final Inspection | K25: B4120 | L25: MFG | M25: DIR | N25: SP PD- Final Inspection
A26: 7519101 | B26: House Rent Allowance | C26: 7519101 | D26: 7519101 | E26: SGA | F26: SGA-7519101 | G26: A502 | H26: House Rent Allowance for expat | J26: SP PD- QC - OEM | K26: B4121 | L26: MFG | M26: DIR | N26: SP PD- QC - OEM
A27: 7521101 | B27: Casual Staff Labor - Basic Salary | C27: 7521101 | D27: 7521101 | E27: SGA | F27: SGA-7521101 | G27: A501 | H27: All benefit for temporary worker | J27: PC PD- Injection | K27: B4410 | L27: MFG | M27: DIR | N27: PC PD- Injection
A28: 7521102 | B28: Casual Staff Labor - Overtime | C28: 7521102 | D28: 7521102 | E28: SGA | F28: SGA-7521102 | G28: A503 | H28: Overtime temporary worker | J28: PC PD- Assy | K28: B4430 | L28: MFG | M28: DIR | N28: PC PD- Assy
A29: 7571101 | B29: Personnel expense transferred | C29: 7571101 | D29: 7571101 | E29: SGA | F29: SGA-7571101 | G29: A506 | H29: Transfer Labor cost from one section into another section | J29: PC PD- QC | K29: B4440 | L29: MFG | M29: DIR | N29: PC PD- QC
A30: 7611100 | B30: Depreciation-Building | C30: 7611100 | D30: 7611100 | E30: SGA | F30: SGA-7611100 | G30: A601 | H30: the amount of depreciation of tangible assets for building | J30: Plant Operation (Indirect Mfg) | K30: B5000 | L30: MFG | M30: IND | N30: Plant Operation (Indirect Mfg)
A31: 7611300 | B31: Depreciation-Machiney & equipment | C31: 7611300 | D31: 7611300 | E31: SGA | F31: SGA-7611300 | G31: A601 | H31: the amount of depreciation of tangible assets for machinery & factory equipment | J31: Production Office | K31: B5100 | L31: MFG | M31: IND | N31: Production Office
A32: 7611400 | B32: Depreciation-Lease Machinery & equipment | C32: 7611400 | D32: 7611400 | E32: SGA | F32: SGA-7611400 | G32: A601 | H32: the amount of depreciation of tangible assets for machinery & factory equipment (Leases) | J32: Production Office (SP) | K32: B5101 | L32: MFG | M32: IND | N32: Production Office (SP)
... A42: 7641102 | B42: Repair of Equipment | C42: 7641102 | D42: 7641102 | E42: SGA | F42: SGA-7641102 | G42: A1002 | H42: expenses for repair and maintenance tangible assets, intangible assets and other assets beside building | J42: Continuous Improvement | K42: B5007 | L42: MFG | M42: IND | N42: Continuous Improvement
A43: 7641103 | B43: Factory Supply Expense | C43: 7641103 | D43: 7641103 | E43: SGA | F43: SGA-7641103 | G43: A1099 | H43: All cost that arrising to support factory acitivity | J43: All | K43: B0000 | N43: All
A44: 7641104 | B44: Calibration Cost | C44: 7641104 | D44: 7641104 | E44: SGA | F44: SGA-7641104 | G44: A1099 | H44: Cost of calibration for tools and equipment of factory and others
A45: 7651101 | B45: Transportation Fee for employee | C45: 7651101 | D45: 7651101 | E45: SGA | F45: SGA-7651101 | G45: A801 | H45: Gasoline of company cars & expense for Local transportation
A46: 7651102 | B46: Travel Expense-Domestic | C46: 7651102 | D46: 7651102 | E46: SGA | F46: SGA-7651102 | G46: A801 | H46: expenses for business trip, including allowance for business trip to an employee only for domestic travel
A47: 7651103 | B47: Travel Expense-Oversea | C47: 7651103 | D47: 7651103 | E47: SGA | F47: SGA-7651103 | G47: A801 | H47: expenses for business trip, including allowance for business trip to an employee only for overseas travel
A48: 7661101 | B48: Entertainment | C48: 7661101 | D48: 7661101 | E48: SGA | F48: SGA-7661101 | G48: A1001 | H48: the amount of expenses for the act of entertaining the business partner
A49: 7671102 | B49: Amortization of Land & Building tax (PBB) | C49: 7671102 | D49: 7671102 | E49: SGA | F49: SGA-7671102 | G49: A1099 | H49: the amount of depreciation of intangible of Land & Building Tax (PBB)
...

Sheet Priority
A1: Priority Code | B1: Priority Name | C1: Description
A2: A | B2: Must | C2: If this is not done, the company or our team cannot continue its business.
A3: B | B3: Want to | C3: We want to do it as a team this term. we need it.
A4: C | B4: Challenge | C4: We want to do it for this term or the future. But it doesn't matter if it's not this term.

Sheet Password
A1: Password protect sheet = budget
