Workbook
Name __j102: #REF!
Name __j102: #REF!
Name __j102: #REF!
Name _1: #N/A
Name _j102: #REF!
Name _j102: #REF!
Name _j102: #REF!
Name aa: #REF!
Name aa: #REF!
Name AB: #REF!
Name AB: #REF!
Name ai: #REF!
Name as: #REF!
Name assit: #REF!
Name b: #REF!
Name BC: #REF!
Name BI: #REF!
Name BO: #REF!
Name cc: #REF!
Name CH: #REF!
Name CI: #REF!
Name Ck_for: #REF!
Name Ck_in: #REF!
Name Ck_out: #REF!
Name d: #REF!
Name dd: #REF!
Name DF: #REF!
Name e: #REF!
Name edy: #REF!
Name ee: #REF!
Name eXCRATE: #REF!
Name exrate: #REF!
Name F: #REF!
Name fcb: #REF!
Name FG: #REF!
Name g: #REF!
Name gg: #REF!
Name HF: #REF!
Name kissa: #REF!
Name kissa: #REF!
Name kissakei: #REF!
Name kissakei: #REF!
Name kk: #REF!
Name kk: #REF!
Name kkk: #REF!
Name kkkk: #REF!
Name l: #REF!
Name L_01: #REF!
Name LIA: #REF!
Name LILI: #REF!
Name LINA: #REF!
Name m: #REF!
Name Manufacturing: #REF!
Name MR: #REF!
Name nittk: #REF!
Name nittk_ok: #REF!
Name nittoukei: #REF!
Name PRINT_AREA_MI: #REF!
Name Print_Area_MI: #REF!
Name PRINT_AREA_MI: #REF!

Sheet Data
A1: BUDGET TYPE | B1: Section Code (From) | C1: Section Name (From/Who Prepare) | D1: Section Code (To) | E1: Section Name (To/Who Use The Cost) | F1: COA-ID | G1: COA NAME | H1: DESCRIPTION | I1: GROUP SECTION | J1: GROUP COST | K1: 2024_10 | L1: 2024_11 | M1: 2024_12 | N1: 2025_01 | O1: 2025_02 | P1: 2025_03 | Q1: 2025_04 | R1: 2025_05 | S1: 2025_06 | T1: 2025_07 | U1: 2025_08 | V1: 2025_09 | W1: 2025_10 | X1: 2025_11 | Y1: 2025_12 | Z1: 2026_01 | AA1: 2026_02 | AB1: 2026_03 | AC1: TOTAL FY125 | AD1: TOTAL FY126 | AE1: TOTAL FY127 | AF1: TOTAL FY128 | AG1: Priority Category | AH1: BUDGET NO.
A2: BEX | B2: =IFERROR(VLOOKUP(C2,Master!$J:$K,2,0),"") -> B4410 | C2: PC PD- Injection | D2: =IFERROR(VLOOKUP(E2,Master!$J:$K,2,0),"") -> B4410 | E2: PC PD- Injection | F2: =IFERROR(VLOOKUP(G2,Master!B:C,2,0),"") -> 7515402 | G2: Staff Welfare - Hospitalization | H2: Potential maternity, sick ,etc | I2: =IFERROR(VLOOKUP(E2,Master!$J:$M,4,0),"") -> DIR | J2: =IFERROR(VLOOKUP($E2,Master!$J:$M,3,0),"") -> MFG | AC2: =SUM(K2:P2) -> 0 | AD2: =SUM(Q2:AB2) -> 0
A3: BEX | B3: =IFERROR(VLOOKUP(C3,Master!$J:$K,2,0),"") -> B4410 | C3: PC PD- Injection | D3: =IFERROR(VLOOKUP(E3,Master!$J:$K,2,0),"") -> B4410 | E3: PC PD- Injection | F3: =IFERROR(VLOOKUP(G3,Master!B:C,2,0),"") -> 7515403 | G3: Staff Welfare - Glasses | H3: For operator use glass and for potential operator (old ) | I3: =IFERROR(VLOOKUP(E3,Master!$J:$M,4,0),"") -> DIR | J3: =IFERROR(VLOOKUP($E3,Master!$J:$M,3,0),"") -> MFG | O3: 1000000 | W3: 1000000 | AC3: =SUM(K3:P3) -> 1000000 | AD3: =SUM(Q3:AB3) -> 1000000
A4: BEX | B4: =IFERROR(VLOOKUP(C4,Master!$J:$K,2,0),"") -> B4410 | C4: PC PD- Injection | D4: =IFERROR(VLOOKUP(E4,Master!$J:$K,2,0),"") -> B4410 | E4: PC PD- Injection | F4: =IFERROR(VLOOKUP(G4,Master!B:C,2,0),"") -> 7515404 | G4: Staff Welfare - Dental | H4: dentist claim for all operator | I4: =IFERROR(VLOOKUP(E4,Master!$J:$M,4,0),"") -> DIR | J4: =IFERROR(VLOOKUP($E4,Master!$J:$M,3,0),"") -> MFG | L4: 1000000 | R4: 1000000 | U4: 1000000 | Y4: 2000000 | AC4: =SUM(K4:P4) -> 1000000 | AD4: =SUM(Q4:AB4) -> 4000000
A5: BEX | B5: =IFERROR(VLOOKUP(C5,Master!$J:$K,2,0),"") -> B4410 | C5: PC PD- Injection | D5: =IFERROR(VLOOKUP(E5,Master!$J:$K,2,0),"") -> B4410 | E5: PC PD- Injection | F5: =IFERROR(VLOOKUP(G5,Master!B:C,2,0),"") -> 7641103 | G5: Factory Supply Expense | H5: Chemical for moldiing ( cleaner, release agent, lubricant,etc | I5: =IFERROR(VLOOKUP(E5,Master!$J:$M,4,0),"") -> DIR | J5: =IFERROR(VLOOKUP($E5,Master!$J:$M,3,0),"") -> MFG | K5: 3500000 | L5: 3500000 | M5: 3500000 | N5: 3500000 | O5: 3500000 | P5: 3500000 | Q5: 3500000 | R5: 3500000 | S5: 3500000 | T5: 3500000 | U5: 3500000 | V5: 3500000 | W5: 3500000 | X5: 3500000 | Y5: 3500000 | AC5: =SUM(K5:P5) -> 21000000 | AD5: =SUM(Q5:AB5) -> 31500000
A6: BEX | B6: =IFERROR(VLOOKUP(C6,Master!$J:$K,2,0),"") -> B4410 | C6: PC PD- Injection | D6: =IFERROR(VLOOKUP(E6,Master!$J:$K,2,0),"") -> B4410 | E6: PC PD- Injection | F6: =IFERROR(VLOOKUP(G6,Master!B:C,2,0),"") -> 7641103 | G6: Factory Supply Expense | H6: Tools For mold maintenance ( Copper bar, Hammer, diamond paste, felt bob ) | I6: =IFERROR(VLOOKUP(E6,Master!$J:$M,4,0),"") -> DIR | J6: =IFERROR(VLOOKUP($E6,Master!$J:$M,3,0),"") -> MFG | N6: 2000000 | S6: 2000000 | W6: 2000000 | AC6: =SUM(K6:P6) -> 2000000 | AD6: =SUM(Q6:AB6) -> 4000000
A7: BEX | B7: =IFERROR(VLOOKUP(C7,Master!$J:$K,2,0),"") -> B4410 | C7: PC PD- Injection | D7: =IFERROR(VLOOKUP(E7,Master!$J:$K,2,0),"") -> B4410 | E7: PC PD- Injection | F7: =IFERROR(VLOOKUP(G7,Master!B:C,2,0),"") -> 7641103 | G7: Factory Supply Expense | H7: Supporting Equipment ( wall fan ,etc ) | I7: =IFERROR(VLOOKUP(E7,Master!$J:$M,4,0),"") -> DIR | J7: =IFERROR(VLOOKUP($E7,Master!$J:$M,3,0),"") -> MFG | M7: 1000000 | O7: 2000000 | R7: 3000000 | X7: 3000000 | AC7: =SUM(K7:P7) -> 3000000 | AD7: =SUM(Q7:AB7) -> 6000000
A8: BEX | B8: =IFERROR(VLOOKUP(C8,Master!$J:$K,2,0),"") -> B4410 | C8: PC PD- Injection | D8: =IFERROR(VLOOKUP(E8,Master!$J:$K,2,0),"") -> B4410 | E8: PC PD- Injection | F8: =IFERROR(VLOOKUP(G8,Master!B:C,2,0),"") -> 7641103 | G8: Factory Supply Expense | H8: Equipment for Mold set up | I8: =IFERROR(VLOOKUP(E8,Master!$J:$M,4,0),"") -> DIR | J8: =IFERROR(VLOOKUP($E8,Master!$J:$M,3,0),"") -> MFG | M8: 1500000 | S8: 1000000 | W8: 500000 | AC8: =SUM(K8:P8) -> 1500000 | AD8: =SUM(Q8:AB8) -> 1500000
A9: BEX | B9: =IFERROR(VLOOKUP(C9,Master!$J:$K,2,0),"") -> B4410 | C9: PC PD- Injection | D9: =IFERROR(VLOOKUP(E9,Master!$J:$K,2,0),"") -> B4410 | E9: PC PD- Injection | F9: =IFERROR(VLOOKUP(G9,Master!B:C,2,0),"") -> 7641103 | G9: Factory Supply Expense | H9: Hand Tools for operational molding | I9: =IFERROR(VLOOKUP(E9,Master!$J:$M,4,0),"") -> DIR | J9: =IFERROR(VLOOKUP($E9,Master!$J:$M,3,0),"") -> MFG | N9: 1700000 | T9: 1000000 | X9: 1000000 | AC9: =SUM(K9:P9) -> 1700000 | AD9: =SUM(Q9:AB9) -> 2000000
A10: BEX | B10: =IFERROR(VLOOKUP(C10,Master!$J:$K,2,0),"") -> B4410 | C10: PC PD- Injection | D10: =IFERROR(VLOOKUP(E10,Master!$J:$K,2,0),"") -> B4410 | E10: PC PD- Injection | F10: =IFERROR(VLOOKUP(G10,Master!B:C,2,0),"") -> 7691000 | G10: Office supply & Stationary Expense | H10: Paper, stationary | I10: =IFERROR(VLOOKUP(E10,Master!$J:$M,4,0),"") -> DIR | J10: =IFERROR(VLOOKUP($E10,Master!$J:$M,3,0),"") -> MFG | M10: 100000 | P10: 100000 | S10: 200000 | V10: 200000 | Y10: 200000 | AC10: =SUM(K10:P10) -> 200000 | AD10: =SUM(Q10:AB10) -> 600000
A11: BEX | B11: =IFERROR(VLOOKUP(C11,Master!$J:$K,2,0),"") -> B4410 | C11: PC PD- Injection | D11: =IFERROR(VLOOKUP(E11,Master!$J:$K,2,0),"") -> B4410 | E11: PC PD- Injection | F11: =IFERROR(VLOOKUP(G11,Master!B:C,2,0),"") -> 7711102 | G11: IT Expense | H11: Renewal PC set | I11: =IFERROR(VLOOKUP(E11,Master!$J:$M,4,0),"") -> DIR | J11: =IFERROR(VLOOKUP($E11,Master!$J:$M,3,0),"") -> MFG | N11: 500000 | R11: 1000000 | AC11: =SUM(K11:P11) -> 500000 | AD11: =SUM(Q11:AB11) -> 1000000
A12: BEX | B12: =IFERROR(VLOOKUP(C12,Master!$J:$K,2,0),"") -> B4410 | C12: PC PD- Injection | D12: =IFERROR(VLOOKUP(E12,Master!$J:$K,2,0),"") -> B4410 | E12: PC PD- Injection | F12: =IFERROR(VLOOKUP(G12,Master!B:C,2,0),"") -> 7781101 | G12: Miscellaneous Expense | H12: Cleaning Tools, vacuum cleaner,Tape, paint, | I12: =IFERROR(VLOOKUP(E12,Master!$J:$M,4,0),"") -> DIR | J12: =IFERROR(VLOOKUP($E12,Master!$J:$M,3,0),"") -> MFG | M12: 3000000 | S12: 5000000 | W12: 4000000 | AC12: =SUM(K12:P12) -> 3000000 | AD12: =SUM(Q12:AB12) -> 9000000
A13: BEX | B13: =IFERROR(VLOOKUP(C13,Master!$J:$K,2,0),"") -> B4430 | C13: PC PD- Assy | D13: =IFERROR(VLOOKUP(E13,Master!$J:$K,2,0),"") -> B4430 | E13: PC PD- Assy | F13: =IFERROR(VLOOKUP(G13,Master!B:C,2,0),"") -> 7151101 | G13: Subcontracting Cost | H13: Terminal body from kyoeidenki | I13: =IFERROR(VLOOKUP(E13,Master!$J:$M,4,0),"") -> DIR | J13: =IFERROR(VLOOKUP($E13,Master!$J:$M,3,0),"") -> MFG | AC13: =SUM(K13:P13) -> 0 | AD13: =SUM(Q13:AB13) -> 0
A14: BEX | B14: =IFERROR(VLOOKUP(C14,Master!$J:$K,2,0),"") -> B4430 | C14: PC PD- Assy | D14: =IFERROR(VLOOKUP(E14,Master!$J:$K,2,0),"") -> B4430 | E14: PC PD- Assy | F14: =IFERROR(VLOOKUP(G14,Master!B:C,2,0),"") -> 7515402 | G14: Staff Welfare - Hospitalization | H14: Potential operator to be sick , maternity,etc | I14: =IFERROR(VLOOKUP(E14,Master!$J:$M,4,0),"") -> DIR | J14: =IFERROR(VLOOKUP($E14,Master!$J:$M,3,0),"") -> MFG | AC14: =SUM(K14:P14) -> 0 | AD14: =SUM(Q14:AB14) -> 0
A15: BEX | B15: =IFERROR(VLOOKUP(C15,Master!$J:$K,2,0),"") -> B4430 | C15: PC PD- Assy | D15: =IFERROR(VLOOKUP(E15,Master!$J:$K,2,0),"") -> B4430 | E15: PC PD- Assy | F15: =IFERROR(VLOOKUP(G15,Master!B:C,2,0),"") -> 7515403 | G15: Staff Welfare - Glasses | H15: operator use glasses + other potential | I15: =IFERROR(VLOOKUP(E15,Master!$J:$M,4,0),"") -> DIR | J15: =IFERROR(VLOOKUP($E15,Master!$J:$M,3,0),"") -> MFG | O15: 500000 | W15: 1200000 | AC15: =SUM(K15:P15) -> 500000 | AD15: =SUM(Q15:AB15) -> 1200000
A16: BEX | B16: =IFERROR(VLOOKUP(C16,Master!$J:$K,2,0),"") -> B4430 | C16: PC PD- Assy | D16: =IFERROR(VLOOKUP(E16,Master!$J:$K,2,0),"") -> B4430 | E16: PC PD- Assy | F16: =IFERROR(VLOOKUP(G16,Master!B:C,2,0),"") -> 7515404 | G16: Staff Welfare - Dental | H16: potential operator to dentist | I16: =IFERROR(VLOOKUP(E16,Master!$J:$M,4,0),"") -> DIR | J16: =IFERROR(VLOOKUP($E16,Master!$J:$M,3,0),"") -> MFG | P16: 1000000 | R16: 1000000 | T16: 1000000 | V16: 1000000 | X16: 2000000 | AC16: =SUM(K16:P16) -> 1000000 | AD16: =SUM(Q16:AB16) -> 5000000
A17: BEX | B17: =IFERROR(VLOOKUP(C17,Master!$J:$K,2,0),"") -> B4430 | C17: PC PD- Assy | D17: =IFERROR(VLOOKUP(E17,Master!$J:$K,2,0),"") -> B4430 | E17: PC PD- Assy | F17: =IFERROR(VLOOKUP(G17,Master!B:C,2,0),"") -> 7641103 | G17: Factory Supply Expense | H17: every TR ( lubricant for install rubber ) | I17: =IFERROR(VLOOKUP(E17,Master!$J:$M,4,0),"") -> DIR | J17: =IFERROR(VLOOKUP($E17,Master!$J:$M,3,0),"") -> MFG | K17: 7600000 | L17: 7600000 | M17: 7600000 | N17: 7600000 | O17: 7600000 | P17: 7600000 | Q17: 8000000 | R17: 8000000 | S17: 8000000 | T17: 8000000 | U17: 8000000 | V17: 8000000 | W17: 8000000 | X17: 8000000 | Y17: 8000000 | Z17: 8000000 | AC17: =SUM(K17:P17) -> 45600000 | AD17: =SUM(Q17:AB17) -> 80000000
A18: BEX | B18: =IFERROR(VLOOKUP(C18,Master!$J:$K,2,0),"") -> B4430 | C18: PC PD- Assy | D18: =IFERROR(VLOOKUP(E18,Master!$J:$K,2,0),"") -> B4430 | E18: PC PD- Assy | F18: =IFERROR(VLOOKUP(G18,Master!B:C,2,0),"") -> 7641103 | G18: Factory Supply Expense | H18: plastic wrapping | I18: =IFERROR(VLOOKUP(E18,Master!$J:$M,4,0),"") -> DIR | J18: =IFERROR(VLOOKUP($E18,Master!$J:$M,3,0),"") -> MFG | K18: 760000 | L18: 760000 | M18: 760000 | N18: 760000 | O18: 760000 | P18: 760000 | Q18: 1000000 | R18: 1000000 | S18: 1000000 | T18: 1000000 | U18: 1000000 | V18: 1000000 | W18: 1000000 | X18: 1000000 | Y18: 800000 | Z18: 800000 | AC18: =SUM(K18:P18) -> 4560000 | AD18: =SUM(Q18:AB18) -> 9600000
A19: BEX | B19: =IFERROR(VLOOKUP(C19,Master!$J:$K,2,0),"") -> B4430 | C19: PC PD- Assy | D19: =IFERROR(VLOOKUP(E19,Master!$J:$K,2,0),"") -> B4430 | E19: PC PD- Assy | F19: =IFERROR(VLOOKUP(G19,Master!B:C,2,0),"") -> 7641103 | G19: Factory Supply Expense | H19: supporting equipment ( vacuum cleaner, wall fan,etc ) | I19: =IFERROR(VLOOKUP(E19,Master!$J:$M,4,0),"") -> DIR | J19: =IFERROR(VLOOKUP($E19,Master!$J:$M,3,0),"") -> MFG | M19: 2000000 | O19: 1000000 | R19: 6000000 | V19: 6000000 | AC19: =SUM(K19:P19) -> 3000000 | AD19: =SUM(Q19:AB19) -> 12000000
A20: BEX | B20: =IFERROR(VLOOKUP(C20,Master!$J:$K,2,0),"") -> B4430 | C20: PC PD- Assy | D20: =IFERROR(VLOOKUP(E20,Master!$J:$K,2,0),"") -> B4430 | E20: PC PD- Assy | F20: =IFERROR(VLOOKUP(G20,Master!B:C,2,0),"") -> 7691000 | G20: Office supply & Stationary Expense | H20: Paper , pen, board marker, etc | I20: =IFERROR(VLOOKUP(E20,Master!$J:$M,4,0),"") -> DIR | J20: =IFERROR(VLOOKUP($E20,Master!$J:$M,3,0),"") -> MFG | K20: 50000 | L20: 50000 | M20: 50000 | N20: 50000 | O20: 50000 | P20: 50000 | Q20: 200000 | R20: 200000 | S20: 200000 | T20: 200000 | U20: 200000 | V20: 200000 | W20: 200000 | X20: 200000 | Y20: 200000 | Z20: 200000 | AC20: =SUM(K20:P20) -> 300000 | AD20: =SUM(Q20:AB20) -> 2000000
A21: BEX | B21: =IFERROR(VLOOKUP(C21,Master!$J:$K,2,0),"") -> B4430 | C21: PC PD- Assy | D21: =IFERROR(VLOOKUP(E21,Master!$J:$K,2,0),"") -> B4430 | E21: PC PD- Assy | F21: =IFERROR(VLOOKUP(G21,Master!B:C,2,0),"") -> 7711102 | G21: IT Expense | H21: service PC, upgrading, change equipment | I21: =IFERROR(VLOOKUP(E21,Master!$J:$M,4,0),"") -> DIR | J21: =IFERROR(VLOOKUP($E21,Master!$J:$M,3,0),"") -> MFG | O21: 800000 | T21: 1000000 | X21: 600000 | AC21: =SUM(K21:P21) -> 800000 | AD21: =SUM(Q21:AB21) -> 1600000
A22: BEX | B22: =IFERROR(VLOOKUP(C22,Master!$J:$K,2,0),"") -> B4430 | C22: PC PD- Assy | D22: =IFERROR(VLOOKUP(E22,Master!$J:$K,2,0),"") -> B4430 | E22: PC PD- Assy | F22: =IFERROR(VLOOKUP(G22,Master!B:C,2,0),"") -> 7781101 | G22: Miscellaneous Expense | H22: cleaning tools , vacuum cleaner ,tape,paint,chair | I22: =IFERROR(VLOOKUP(E22,Master!$J:$M,4,0),"") -> DIR | J22: =IFERROR(VLOOKUP($E22,Master!$J:$M,3,0),"") -> MFG | M22: 5000000 | R22: 6000000 | V22: 6000000 | AC22: =SUM(K22:P22) -> 5000000 | AD22: =SUM(Q22:AB22) -> 12000000
A23: BEX | B23: =IFERROR(VLOOKUP(C23,Master!$J:$K,2,0),"") -> B4430 | C23: PC PD- Assy | D23: =IFERROR(VLOOKUP(E23,Master!$J:$K,2,0),"") -> B4430 | E23: PC PD- Assy | F23: =IFERROR(VLOOKUP(G23,Master!B:C,2,0),"") -> 7781101 | G23: Miscellaneous Expense | H23: Upgrading Rest Area ( Dispencer, Carpet,fan,etc) | I23: =IFERROR(VLOOKUP(E23,Master!$J:$M,4,0),"") -> DIR | J23: =IFERROR(VLOOKUP($E23,Master!$J:$M,3,0),"") -> MFG | N23: 1200000 | Q23: 7000000 | AC23: =SUM(K23:P23) -> 1200000 | AD23: =SUM(Q23:AB23) -> 7000000
A24: BEX | B24: =IFERROR(VLOOKUP(C24,Master!$J:$K,2,0),"") -> B4440 | C24: PC PD- QC | D24: =IFERROR(VLOOKUP(E24,Master!$J:$K,2,0),"") -> B4440 | E24: PC PD- QC | F24: =IFERROR(VLOOKUP(G24,Master!B:C,2,0),"") -> 7211103 | G24: Cost of Packaging | H24: packaging material base on BOM | I24: =IFERROR(VLOOKUP(E24,Master!$J:$M,4,0),"") -> DIR | J24: =IFERROR(VLOOKUP($E24,Master!$J:$M,3,0),"") -> MFG | AC24: =SUM(K24:P24) -> 0 | AD24: =SUM(Q24:AB24) -> 0
A25: BEX | B25: =IFERROR(VLOOKUP(C25,Master!$J:$K,2,0),"") -> B4440 | C25: PC PD- QC | D25: =IFERROR(VLOOKUP(E25,Master!$J:$K,2,0),"") -> B4440 | E25: PC PD- QC | F25: =IFERROR(VLOOKUP(G25,Master!B:C,2,0),"") -> 7515403 | G25: Staff Welfare - Glasses | H25: operator use glasses + other potential | I25: =IFERROR(VLOOKUP(E25,Master!$J:$M,4,0),"") -> DIR | J25: =IFERROR(VLOOKUP($E25,Master!$J:$M,3,0),"") -> MFG | M25: 1000000 | S25: 1000000 | Y25: 1000000 | AC25: =SUM(K25:P25) -> 1000000 | AD25: =SUM(Q25:AB25) -> 2000000
A26: BEX | B26: =IFERROR(VLOOKUP(C26,Master!$J:$K,2,0),"") -> B4440 | C26: PC PD- QC | D26: =IFERROR(VLOOKUP(E26,Master!$J:$K,2,0),"") -> B4440 | E26: PC PD- QC | F26: =IFERROR(VLOOKUP(G26,Master!B:C,2,0),"") -> 7515404 | G26: Staff Welfare - Dental | H26: potential operator to dentist | I26: =IFERROR(VLOOKUP(E26,Master!$J:$M,4,0),"") -> DIR | J26: =IFERROR(VLOOKUP($E26,Master!$J:$M,3,0),"") -> MFG | N26: 1000000 | S26: 1500000 | V26: 1500000 | Y26: 1500000 | AC26: =SUM(K26:P26) -> 1000000 | AD26: =SUM(Q26:AB26) -> 4500000
A27: BEX | B27: =IFERROR(VLOOKUP(C27,Master!$J:$K,2,0),"") -> B4440 | C27: PC PD- QC | D27: =IFERROR(VLOOKUP(E27,Master!$J:$K,2,0),"") -> B4440 | E27: PC PD- QC | F27: =IFERROR(VLOOKUP(G27,Master!B:C,2,0),"") -> 7641103 | G27: Factory Supply Expense | H27: supporting equipment ( wall fan, chair) | I27: =IFERROR(VLOOKUP(E27,Master!$J:$M,4,0),"") -> DIR | J27: =IFERROR(VLOOKUP($E27,Master!$J:$M,3,0),"") -> MFG | M27: 500000 | U27: 2000000 | AC27: =SUM(K27:P27) -> 500000 | AD27: =SUM(Q27:AB27) -> 2000000
A28: BEX | B28: =IFERROR(VLOOKUP(C28,Master!$J:$K,2,0),"") -> B4440 | C28: PC PD- QC | D28: =IFERROR(VLOOKUP(E28,Master!$J:$K,2,0),"") -> B4440 | E28: PC PD- QC | F28: =IFERROR(VLOOKUP(G28,Master!B:C,2,0),"") -> 7691000 | G28: Office supply & Stationary Expense | H28: Paper , pen, board marker, etc | I28: =IFERROR(VLOOKUP(E28,Master!$J:$M,4,0),"") -> DIR | J28: =IFERROR(VLOOKUP($E28,Master!$J:$M,3,0),"") -> MFG | N28: 100000 | R28: 200000 | X28: 200000 | AC28: =SUM(K28:P28) -> 100000 | AD28: =SUM(Q28:AB28) -> 400000
A29: BEX | B29: =IFERROR(VLOOKUP(C29,Master!$J:$K,2,0),"") -> B4440 | C29: PC PD- QC | D29: =IFERROR(VLOOKUP(E29,Master!$J:$K,2,0),"") -> B4440 | E29: PC PD- QC | F29: =IFERROR(VLOOKUP(G29,Master!B:C,2,0),"") -> 7781101 | G29: Miscellaneous Expense | H29: cleaning tools , vacuum, tape , pilox, paint | I29: =IFERROR(VLOOKUP(E29,Master!$J:$M,4,0),"") -> DIR | J29: =IFERROR(VLOOKUP($E29,Master!$J:$M,3,0),"") -> MFG | M29: 1000000 | S29: 2000000 | AC29: =SUM(K29:P29) -> 1000000 | AD29: =SUM(Q29:AB29) -> 2000000
A30: BEX | B30: =IFERROR(VLOOKUP(C30,Master!$J:$K,2,0),"") -> B4440 | C30: PC PD- QC | D30: =IFERROR(VLOOKUP(E30,Master!$J:$K,2,0),"") -> B4440 | E30: PC PD- QC | F30: =IFERROR(VLOOKUP(G30,Master!B:C,2,0),"") -> 7641103 | G30: Factory Supply Expense | H30: Sealer Machine , wall Fan | I30: =IFERROR(VLOOKUP(E30,Master!$J:$M,4,0),"") -> DIR | J30: =IFERROR(VLOOKUP($E30,Master!$J:$M,3,0),"") -> MFG | N30: 700000 | R30: 1500000 | X30: 1500000 | AC30: =SUM(K30:P30) -> 700000 | AD30: =SUM(Q30:AB30) -> 3000000
B31: =IFERROR(VLOOKUP(C31,Master!$J:$K,2,0),"") | D31: =IFERROR(VLOOKUP(E31,Master!$J:$K,2,0),"") | F31: =IFERROR(VLOOKUP(G31,Master!B:C,2,0),"") | I31: =IFERROR(VLOOKUP(E31,Master!$J:$M,4,0),"") | J31: =IFERROR(VLOOKUP($E31,Master!$J:$M,3,0),"") | AC31: =SUM(K31:P31) -> 0 | AD31: =SUM(Q31:AB31) -> 0
B32: =IFERROR(VLOOKUP(C32,Master!$J:$K,2,0),"") | D32: =IFERROR(VLOOKUP(E32,Master!$J:$K,2,0),"") | F32: =IFERROR(VLOOKUP(G32,Master!B:C,2,0),"") | I32: =IFERROR(VLOOKUP(E32,Master!$J:$M,4,0),"") | J32: =IFERROR(VLOOKUP($E32,Master!$J:$M,3,0),"") | AC32: =SUM(K32:P32) -> 0 | AD32: =SUM(Q32:AB32) -> 0
B33: =IFERROR(VLOOKUP(C33,Master!$J:$K,2,0),"") | D33: =IFERROR(VLOOKUP(E33,Master!$J:$K,2,0),"") | F33: =IFERROR(VLOOKUP(G33,Master!B:C,2,0),"") | I33: =IFERROR(VLOOKUP(E33,Master!$J:$M,4,0),"") | J33: =IFERROR(VLOOKUP($E33,Master!$J:$M,3,0),"") | AC33: =SUM(K33:P33) -> 0 | AD33: =SUM(Q33:AB33) -> 0
B34: =IFERROR(VLOOKUP(C34,Master!$J:$K,2,0),"") | D34: =IFERROR(VLOOKUP(E34,Master!$J:$K,2,0),"") | F34: =IFERROR(VLOOKUP(G34,Master!B:C,2,0),"") | I34: =IFERROR(VLOOKUP(E34,Master!$J:$M,4,0),"") | J34: =IFERROR(VLOOKUP($E34,Master!$J:$M,3,0),"") | AC34: =SUM(K34:P34) -> 0 | AD34: =SUM(Q34:AB34) -> 0
B35: =IFERROR(VLOOKUP(C35,Master!$J:$K,2,0),"") | D35: =IFERROR(VLOOKUP(E35,Master!$J:$K,2,0),"") | F35: =IFERROR(VLOOKUP(G35,Master!B:C,2,0),"") | I35: =IFERROR(VLOOKUP(E35,Master!$J:$M,4,0),"") | J35: =IFERROR(VLOOKUP($E35,Master!$J:$M,3,0),"") | AC35: =SUM(K35:P35) -> 0 | AD35: =SUM(Q35:AB35) -> 0
B36: =IFERROR(VLOOKUP(C36,Master!$J:$K,2,0),"") | D36: =IFERROR(VLOOKUP(E36,Master!$J:$K,2,0),"") | F36: =IFERROR(VLOOKUP(G36,Master!B:C,2,0),"") | I36: =IFERROR(VLOOKUP(E36,Master!$J:$M,4,0),"") | J36: =IFERROR(VLOOKUP($E36,Master!$J:$M,3,0),"") | AC36: =SUM(K36:P36) -> 0 | AD36: =SUM(Q36:AB36) -> 0
B37: =IFERROR(VLOOKUP(C37,Master!$J:$K,2,0),"") | D37: =IFERROR(VLOOKUP(E37,Master!$J:$K,2,0),"") | F37: =IFERROR(VLOOKUP(G37,Master!B:C,2,0),"") | I37: =IFERROR(VLOOKUP(E37,Master!$J:$M,4,0),"") | J37: =IFERROR(VLOOKUP($E37,Master!$J:$M,3,0),"") | AC37: =SUM(K37:P37) -> 0 | AD37: =SUM(Q37:AB37) -> 0
B38: =IFERROR(VLOOKUP(C38,Master!$J:$K,2,0),"") | D38: =IFERROR(VLOOKUP(E38,Master!$J:$K,2,0),"") | F38: =IFERROR(VLOOKUP(G38,Master!B:C,2,0),"") | I38: =IFERROR(VLOOKUP(E38,Master!$J:$M,4,0),"") | J38: =IFERROR(VLOOKUP($E38,Master!$J:$M,3,0),"") | AC38: =SUM(K38:P38) -> 0 | AD38: =SUM(Q38:AB38) -> 0
B39: =IFERROR(VLOOKUP(C39,Master!$J:$K,2,0),"") | D39: =IFERROR(VLOOKUP(E39,Master!$J:$K,2,0),"") | F39: =IFERROR(VLOOKUP(G39,Master!B:C,2,0),"") | I39: =IFERROR(VLOOKUP(E39,Master!$J:$M,4,0),"") | J39: =IFERROR(VLOOKUP($E39,Master!$J:$M,3,0),"") | AC39: =SUM(K39:P39) -> 0 | AD39: =SUM(Q39:AB39) -> 0
B40: =IFERROR(VLOOKUP(C40,Master!$J:$K,2,0),"") | D40: =IFERROR(VLOOKUP(E40,Master!$J:$K,2,0),"") | F40: =IFERROR(VLOOKUP(G40,Master!B:C,2,0),"") | I40: =IFERROR(VLOOKUP(E40,Master!$J:$M,4,0),"") | J40: =IFERROR(VLOOKUP($E40,Master!$J:$M,3,0),"") | AC40: =SUM(K40:P40) -> 0 | AD40: =SUM(Q40:AB40) -> 0
...

Sheet Master
A1: COA AX | B1: Name COA AX | C1: COA AX | D1: COA AX | E1: Group Cost | F1: UNIQ | G1: COA Budget | H1: Description | J1: Name | K1: BNGK | L1: GROUP COST | M1: GROUP SECTION | N1: Name | P1: Code | Q1: Name | S1: Priority Code | T1: Priority Name | U1: Description
A2: 7511101 | B2: Salary for Commissioner | C2: 7511101 | D2: 7511101 | E2: SGA | F2: SGA-7511101 | G2: A502 | H2: Salary for Commissioner | J2: Top Management | K2: B1000 | L2: SGA | M2: ADM | N2: Top Management | P2: 53450 | Q2: NGK BUSI INDONESIA | S2: A | T2: Must | U2: If this is not done, the company or our team cannot continue its business.
A3: 7511102 | B3: Salary for Director | C3: 7511102 | D3: 7511102 | E3: SGA | F3: SGA-7511102 | G3: A502 | H3: Salary for Director & Expat | J3: Commissioner | K3: B1001 | L3: SGA | M3: ADM | N3: Commissioner | S3: B | T3: Want to | U3: We want to do it as a team this term. we need it.
A4: 7511103 | B4: Staff Labor - Baslc Salary | C4: 7511103 | D4: 7511103 | E4: SGA | F4: SGA-7511103 | G4: A501 | H4: Basic Salary of permanent employee | J4: Admin & HR | K4: B2200 | L4: SGA | M4: ADM | N4: Admin & HR | S4: C | T4: Challenge | U4: We want to do it for this term or the future. But it doesn't matter if it's not this term.
A5: 7511111 | B5: Staff Labor - Allowance | C5: 7511111 | D5: 7511111 | E5: SGA | F5: SGA-7511111 | G5: A501 | H5: Employee allowance | J5: General Affair | K5: B2210 | L5: SGA | M5: ADM | N5: General Affair
A6: 7511112 | B6: Staff Labor - Tax allowance (art.21) | C6: 7511112 | D6: 7511112 | E6: SGA | F6: SGA-7511112 | G6: A501 | H6: Empployee Tax allowance | J6: Human Resource | K6: B2220 | L6: SGA | M6: ADM | N6: Human Resource | P6: BEX
A7: 7511121 | B7: Staff Labor - BPJS JK & JKK (1.19%) | C7: 7511121 | D7: 7511121 | E7: SGA | F7: SGA-7511121 | G7: A501 | H7: BPJS JK & JKK (death warrant, Accident Insurance) | J7: Health, Safety & Environment | K7: B2230 | L7: SGA | M7: ADM | N7: Health, Safety & Environment | P7: BEL
A8: 7511122 | B8: Staff Labor - BPJS Kesehatan (4%) | C8: 7511122 | D8: 7511122 | E8: SGA | F8: SGA-7511122 | G8: A501 | H8: BPJS health insurance | J8: Accounting & Finance | K8: B2300 | L8: SGA | M8: ADM | N8: Accounting & Finance
A9: 7511201 | B9: Staff Overtime | C9: 7511201 | D9: 7511201 | E9: SGA | F9: SGA-7511201 | G9: A503 | H9: Overtime permanent employee | J9: Information Technology | K9: B2400 | L9: SGA | M9: ADM | N9: Information Technology
A10: 7512111 | B10: Staff Welfare - BPJS Dana pensiun (2%) | C10: 7512111 | D10: 7512111 | E10: SGA | F10: SGA-7512111 | G10: A504 | H10: BPJS pension fund | J10: Sales & MKTG Dept.- Automotive | K10: B3100 | L10: SGA | M10: ADM | N10: Sales & MKTG Dept.- Automotive
A11: 7512112 | B11: Staff Welfare - BPJS JHT (3.7%) | C11: 7512112 | D11: 7512112 | E11: SGA | F11: SGA-7512112 | G11: A504 | H11: BPJS Pension plan | J11: Marketing | K11: B3160 | L11: SGA | M11: ADM | N11: Marketing
A12: 7514101 | B12: Staff Bonus / TAT | C12: 7514101 | D12: 7514101 | E12: SGA | F12: SGA-7514101 | G12: A501 | H12: Year-end allowance & Alpha | J12: Sales - OEM | K12: B3110 | L12: SGA | M12: ADM | N12: Sales - OEM
A13: 7514102 | B13: Staff Ramadhan / THR | C13: 7514102 | D13: 7514102 | E13: SGA | F13: SGA-7514102 | G13: A501 | H13: Lebaran bonus | J13: Sales - OES | K13: B3120 | L13: SGA | M13: ADM | N13: Sales - OES
A14: 7515401 | B14: Staff Welfare - Outpatient (Medical) | C14: 7515401 | D14: 7515401 | E14: SGA | F14: SGA-7515401 | G14: A504 | H14: outpatient treatment costs | J14: Sales - IAM | K14: B3130 | L14: SGA | M14: ADM | N14: Sales - IAM
A15: 7515402 | B15: Staff Welfare - Hospitalization | C15: 7515402 | D15: 7515402 | E15: SGA | F15: SGA-7515402 | G15: A504 | H15: hospitalization costs | J15: Sales & MKTG Dept.- DID Chain | K15: B3172 | L15: SGA | M15: ADM | N15: Sales & MKTG Dept.- DID Chain
A16: 7515403 | B16: Staff Welfare - Glasses | C16: 7515403 | D16: 7515403 | E16: SGA | F16: SGA-7515403 | G16: A504 | H16: glasses costs | J16: SP PD- CF | K16: B4101 | L16: MFG | M16: DIR | N16: SP PD- CF
A17: 7515404 | B17: Staff Welfare - Dental | C17: 7515404 | D17: 7515404 | E17: SGA | F17: SGA-7515404 | G17: A504 | H17: dental costs | J17: SP PD- CM | K17: B4102 | L17: MFG | M17: DIR | N17: SP PD- CM
A18: 7515405 | B18: Staff Welfare - Medical Check Up | C18: 7515405 | D18: 7515405 | E18: SGA | F18: SGA-7515405 | G18: A504 | H18: Medical Check Up cost | J18: SP PD- WT | K18: B4103 | L18: MFG | M18: DIR | N18: SP PD- WT
A19: 7515406 | B19: Staff Welfare - Uniform | C19: 7515406 | D19: 7515406 | E19: SGA | F19: SGA-7515406 | G19: A504 | H19: uniform costs | J19: SP PD- Plating | K19: B4105 | L19: MFG | M19: DIR | N19: SP PD- Plating
A20: 7515407 | B20: Staff Welfare - Safety Shoes | C20: 7515407 | D20: 7515407 | E20: SGA | F20: SGA-7515407 | G20: A504 | J20: SP PD- MS Insp. | K20: B4109 | L20: MFG | M20: DIR | N20: SP PD- MS Insp.
A21: 7515408 | B21: Staff Welfare - Family Gathering / Anniversary | C21: 7515408 | D21: 7515408 | E21: SGA | F21: SGA-7515408 | G21: A504 | H21: Family Gathering / Anniversary | J21: SP PD - Insulator Sealing | K21: B4130 | L21: MFG | M21: DIR | N21: SP PD - Insulator Sealing
A22: 7515409 | B22: Staff Welfare - Meals of canteen & other meals | C22: 7515409 | D22: 7515409 | E22: SGA | F22: SGA-7515409 | G22: A504 | H22: Meals of canteen & other meals cost | J22: SP PD- Assy | K22: B4110 | L22: MFG | M22: DIR | N22: SP PD- Assy
A23: 7515410 | B23: Staff Welfare - Kaizen & QCC reward | C23: 7515410 | D23: 7515410 | E23: SGA | F23: SGA-7515410 | G23: A504 | H23: an expense, arising from Kaizen and QCC acitivity | J23: SP-PD-Assy-Auto Assembly | K23: B4115 | L23: MFG | M23: DIR | N23: SP-PD-Assy-Auto Assembly
A24: 7515499 | B24: Staff Welfare - Welfare Others | C24: 7515499 | D24: 7515499 | E24: SGA | F24: SGA-7515499 | G24: A504 | H24: an other welfare expense, arising besides the above welfare expense | J24: SP PD- Bending | K24: B4114 | L24: MFG | M24: DIR | N24: SP PD- Bending
A25: 7516102 | B25: Retirement Allowance | C25: 7516102 | D25: 7516102 | E25: SGA | F25: SGA-7516102 | G25: A505 | H25: employee retirement provission costs | J25: SP PD- Final Inspection | K25: B4120 | L25: MFG | M25: DIR | N25: SP PD- Final Inspection
A26: 7519101 | B26: House Rent Allowance | C26: 7519101 | D26: 7519101 | E26: SGA | F26: SGA-7519101 | G26: A502 | H26: House Rent Allowance for expat | J26: SP PD- QC - OEM | K26: B4121 | L26: MFG | M26: DIR | N26: SP PD- QC - OEM
A27: 7521101 | B27: Casual Staff Labor - Basic Salary | C27: 7521101 | D27: 7521101 | E27: SGA | F27: SGA-7521101 | G27: A501 | H27: All benefit for temporary worker | J27: PC PD- Injection | K27: B4410 | L27: MFG | M27: DIR | N27: PC PD- Injection
A28: 7521102 | B28: Casual Staff Labor - Overtime | C28: 7521102 | D28: 7521102 | E28: SGA | F28: SGA-7521102 | G28: A503 | H28: Overtime temporary worker | J28: PC PD- Assy | K28: B4430 | L28: MFG | M28: DIR | N28: PC PD- Assy
A29: 7571101 | B29: Personnel expense transferred | C29: 7571101 | D29: 7571101 | E29: SGA | F29: SGA-7571101 | G29: A506 | H29: Transfer Labor cost from one section into another section | J29: PC PD- QC | K29: B4440 | L29: MFG | M29: DIR | N29: PC PD- QC
A30: 7611100 | B30: Depreciation-Building | C30: 7611100 | D30: 7611100 | E30: SGA | F30: SGA-7611100 | G30: A601 | H30: the amount of depreciation of tangible assets for building | J30: Plant Operation (Indirect Mfg) | K30: B5000 | L30: MFG | M30: IND | N30: Plant Operation (Indirect Mfg)
A31: 7611300 | B31: Depreciation-Machiney & equipment | C31: 7611300 | D31: 7611300 | E31: SGA | F31: SGA-7611300 | G31: A601 | H31: the amount of depreciation of tangible assets for machinery & factory equipment | J31: Production Office | K31: B5100 | L31: MFG | M31: IND | N31: Production Office
A32: 7611400 | B32: Depreciation-Lease Machinery & equipment | C32: 7611400 | D32: 7611400 | E32: SGA | F32: SGA-7611400 | G32: A601 | H32: the amount of depreciation of tangible assets for machinery & factory equipment (Leases) | J32: Production Office (SP) | K32: B5101 | L32: MFG | M32: IND | N32: Production Office (SP)
... A42: 7641102 | B42: Repair of Equipment | C42: 7641102 | D42: 7641102 | E42: SGA | F42: SGA-7641102 | G42: A1002 | H42: expenses for repair and maintenance tangible assets, intangible assets and other assets beside building | J42: Continuous Improvement | K42: B5007 | L42: MFG | M42: IND | N42: Continuous Improvement
A43: 7641103 | B43: Factory Supply Expense | C43: 7641103 | D43: 7641103 | E43: SGA | F43: SGA-7641103 | G43: A1099 | H43: All cost that arrising to support factory acitivity | J43: All | K43: B0000 | N43: All
A44: 7641104 | B44: Calibration Cost | C44: 7641104 | D44: 7641104 | E44: SGA | F44: SGA-7641104 | G44: A1099 | H44: Cost of calibration for tools and equipment of factory and others
A45: 7651101 | B45: Transportation Fee for employee | C45: 7651101 | D45: 7651101 | E45: SGA | F45: SGA-7651101 | G45: A801 | H45: Gasoline of company cars & expense for Local transportation
A46: 7651102 | B46: Travel Expense-Domestic | C46: 7651102 | D46: 7651102 | E46: SGA | F46: SGA-7651102 | G46: A801 | H46: expenses for business trip, including allowance for business trip to an employee only for domestic travel
A47: 7651103 | B47: Travel Expense-Oversea | C47: 7651103 | D47: 7651103 | E47: SGA | F47: SGA-7651103 | G47: A801 | H47: expenses for business trip, including allowance for business trip to an employee only for overseas travel
A48: 7661101 | B48: Entertainment | C48: 7661101 | D48: 7661101 | E48: SGA | F48: SGA-7661101 | G48: A1001 | H48: the amount of expenses for the act of entertaining the business partner
A49: 7671102 | B49: Amortization of Land & Building tax (PBB) | C49: 7671102 | D49: 7671102 | E49: SGA | F49: SGA-7671102 | G49: A1099 | H49: the amount of depreciation of intangible of Land & Building Tax (PBB)
...

Sheet Priority
A1: Priority Code | B1: Priority Name | C1: Description
A2: A | B2: Must | C2: If this is not done, the company or our team cannot continue its business.
A3: B | B3: Want to | C3: We want to do it as a team this term. we need it.
A4: C | B4: Challenge | C4: We want to do it for this term or the future. But it doesn't matter if it's not this term.

Sheet V1
A1: This is used for version checking on portal, do not delete!.

Sheet Password
A1: Password protect sheet = budget
