Workbook
Name __j102: #REF!
Name __j102: #REF!
Name __j102: #REF!
Name __j102: #REF!
Name _1: #N/A
Name _j102: #REF!
Name _j102: #REF!
Name _j102: #REF!
Name _j102: #REF!
Name _j102: #REF!
Name _j102: #REF!
Name aa: #REF!
Name aa: #REF!
Name aa: #REF!
Name aa: #REF!
Name aa: #REF!
Name AB: #REF!
Name AB: #REF!
Name AB: #REF!
Name AB: #REF!
Name AB: #REF!
Name ai: #REF!
Name ai: #REF!
Name ai: #REF!
Name ai: #REF!
Name ai: #REF!
Name as: #REF!
Name as: #REF!
Name as: #REF!
Name as: #REF!
Name as: #REF!
Name assit: #REF!
Name assit: #REF!
Name assit: #REF!
Name assit: #REF!
Name assit: #REF!
Name b: #REF!
Name b: #REF!
Name b: #REF!
Name b: #REF!
Name b: #REF!
Name BC: #REF!
Name BC: #REF!
Name BC: #REF!
Name BC: #REF!
Name BC: #REF!
Name BI: #REF!
Name BI: #REF!
Name BI: #REF!
Name BI: #REF!
Name BI: #REF!
Name BO: #REF!
Name BO: #REF!
Name BO: #REF!
Name BO: #REF!
Name BO: #REF!
Name cc: #REF!
Name cc: #REF!
Name cc: #REF!
Name cc: #REF!

Sheet COA
A1: Name | B1: COA AX | C1: Group Cost | D1: UNIQ | E1: COA Budget | F1: Description
A2: Salary for Commissioner | B2: 7511101 | C2: SGA | D2: =C2&"-"&B2 -> SGA-7511101 | E2: A502 | F2: Salary for Commissioner
A3: Salary for Director | B3: 7511102 | C3: SGA | D3: =C3&"-"&B3 -> SGA-7511102 | E3: A502 | F3: Salary for Director & Expat
A4: Staff Labor - Baslc Salary | B4: 7511103 | C4: SGA | D4: =C4&"-"&B4 -> SGA-7511103 | E4: A501 | F4: Basic Salary of permanent employee
A5: Staff Labor - Allowance | B5: 7511111 | C5: SGA | D5: =C5&"-"&B5 -> SGA-7511111 | E5: A501 | F5: Employee allowance
A6: Staff Labor - Tax allowance (art.21) | B6: 7511112 | C6: SGA | D6: =C6&"-"&B6 -> SGA-7511112 | E6: A501 | F6: Empployee Tax allowance
A7: Staff Labor - BPJS JK & JKK (1.19%) | B7: 7511121 | C7: SGA | D7: =C7&"-"&B7 -> SGA-7511121 | E7: A501 | F7: BPJS JK & JKK (death warrant, Accident Insurance)
A8: Staff Labor - BPJS Kesehatan (4%) | B8: 7511122 | C8: SGA | D8: =C8&"-"&B8 -> SGA-7511122 | E8: A501 | F8: BPJS health insurance
A9: Staff Overtime | B9: 7511201 | C9: SGA | D9: =C9&"-"&B9 -> SGA-7511201 | E9: A503 | F9: Overtime permanent employee
A10: Staff Welfare - BPJS Dana pensiun (2%) | B10: 7512111 | C10: SGA | D10: =C10&"-"&B10 -> SGA-7512111 | E10: A504 | F10: BPJS pension fund
A11: Staff Welfare - BPJS JHT (3.7%) | B11: 7512112 | C11: SGA | D11: =C11&"-"&B11 -> SGA-7512112 | E11: A504 | F11: BPJS Pension plan
A12: Staff Bonus / TAT | B12: 7514101 | C12: SGA | D12: =C12&"-"&B12 -> SGA-7514101 | E12: A501 | F12: Year-end allowance & Alpha
A13: Staff Ramadhan / THR | B13: 7514102 | C13: SGA | D13: =C13&"-"&B13 -> SGA-7514102 | E13: A501 | F13: Lebaran bonus
... A70: Cost of Samples | B70: 7461101 | C70: SGA | D70: =C70&"-"&B70 -> SGA-7461101 | E70: A499 | F70: Sample expense
A71: Sales - Insurance of Delivery or Shipment | B71: 7411105 | C71: SGA | D71: =C71&"-"&B71 -> SGA-7411105 | E71: A299
A72: Sales - Insurance of AR (Credit Insurance) | B72: 7471201 | C72: SGA | D72: =C72&"-"&B72 -> SGA-7471201 | E72: A299
A73: Sales - Royalty to NGK Group | B73: 7751101 | C73: SGA | D73: =C73&"-"&B73 -> SGA-7751101
A74: Sales - Royalty to Independence Party | B74: 7751102 | C74: SGA | D74: =C74&"-"&B74 -> SGA-7751102
A75: Import Duty-purchased FG from NGK group | B75: 7111211 | C75: MFG | D75: =C75&"-"&B75 -> MFG-7111211
A76: Import Duty-purchased KD&RM from NGK Japan | B76: 7111221 | C76: MFG | D76: =C76&"-"&B76 -> MFG-7111221
A77: Import Duty-purchased KD&RM from NGK Group(Not fromJP) | B77: 7111222 | C77: MFG | D77: =C77&"-"&B77 -> MFG-7111222
A78: Import Duty-purchased Comp Parts&RM from outside supplier | B78: 7111223 | C78: MFG | D78: =C78&"-"&B78 -> MFG-7111223
A79: Import Expense-purchased FG from NGK group | B79: 7111311 | C79: MFG | D79: =C79&"-"&B79 -> MFG-7111311
A80: Import Expense-purchased KD&RM from NGK Japan | B80: 7111321 | C80: MFG | D80: =C80&"-"&B80 -> MFG-7111321
A81: Import Expense-purchased KD&RM from NGK Group(Not fromJP) | B81: 7111322 | C81: MFG | D81: =C81&"-"&B81 -> MFG-7111322
A82: Import Expense-purchased Comp Parts&RM from outside supplier | B82: 7111323 | C82: MFG | D82: =C82&"-"&B82 -> MFG-7111323
A83: Cost of Factory Supply | B83: 7211101 | C83: MFG | D83: =C83&"-"&B83 -> MFG-7211101
A84: Cost of Chemical | B84: 7211102 | C84: MFG | D84: =C84&"-"&B84 -> MFG-7211102 | E84: 901 | F84: The expenses of Chemicals consumption
A85: Cost of Packaging | B85: 7211103 | C85: MFG | D85: =C85&"-"&B85 -> MFG-7211103
A86: Cost of Tooling | B86: 7221101 | C86: MFG | D86: =C86&"-"&B86 -> MFG-7221101 | E86: 302 | F86: The expenses of Tooling consumption
A87: Cost of Machinery parts | B87: 7221102 | C87: MFG | D87: =C87&"-"&B87 -> MFG-7221102 | E87: 301 | F87: The expenses of Spare Parts consumption
A88: Salary for Commissioner | B88: 7511101 | C88: MFG | D88: =C88&"-"&B88 -> MFG-7511101 | E88: 602 | F88: Salary for Commissioner
A89: Salary for Director | B89: 7511102 | C89: MFG | D89: =C89&"-"&B89 -> MFG-7511102 | E89: 602 | F89: Salary for Director & Expat
A90: Staff Labor - Baslc Salary | B90: 7511103 | C90: MFG | D90: =C90&"-"&B90 -> MFG-7511103 | E90: 601 | F90: Basic Salary of permanent employee
A91: Staff Labor - Allowance | B91: 7511111 | C91: MFG | D91: =C91&"-"&B91 -> MFG-7511111 | E91: 601 | F91: Employee allowance
A92: Staff Labor - Tax allowance (art.21) | B92: 7511112 | C92: MFG | D92: =C92&"-"&B92 -> MFG-7511112 | E92: 601 | F92: Empployee Tax allowance
A93: Staff Labor - BPJS JK & JKK (1.19%) | B93: 7511121 | C93: MFG | D93: =C93&"-"&B93 -> MFG-7511121 | E93: 601 | F93: BPJS JK & JKK (death warrant, Accident Insurance)
A94: Staff Labor - BPJS Kesehatan (4%) | B94: 7511122 | C94: MFG | D94: =C94&"-"&B94 -> MFG-7511122 | E94: 601 | F94: BPJS health insurance
A95: Staff Overtime | B95: 7511201 | C95: MFG | D95: =C95&"-"&B95 -> MFG-7511201 | E95: 603 | F95: Overtime permanent employee
A96: Staff Welfare - BPJS Dana pensiun (2%) | B96: 7512111 | C96: MFG | D96: =C96&"-"&B96 -> MFG-7512111 | E96: 604 | F96: BPJS pension fund
...

Sheet Upload
A1: Budget Type | B1: Section From (Code) | C1: Section From (Name) | D1: To Section (Code) | E1: To Section (Name) | F1: Coa ID | G1: Coa Name | H1: Asset Name | I1: Acquisition Value | J1: Useful Life | K1: Allocation % | L1: Depre Start | M1: Priority Code | N1: Budget_Period | O1: Budget Allocation
A2: BIP | B2: =_xlfn.IFNA(VLOOKUP(C2,Sheet3!$H:$I,2,FALSE),"") -> B2400 | C2: Information Technology | D2: =_xlfn.IFNA(VLOOKUP(E2,Sheet3!$H:$I,2,FALSE),"") -> B2400 | E2: Information Technology | F2: 2141000 | G2: Tools, furniture & office equipment | H2: UPS For Rack 2 (AX, ASPROVA, Flexnet Server) | I2: 127990800 | J2: 60 | K2: 100 | L2: 43922 | M2: A | O2: 127990800
A3: BIP | B3: =_xlfn.IFNA(VLOOKUP(C3,Sheet3!$H:$I,2,FALSE),"") -> B2400 | C3: Information Technology | D3: =_xlfn.IFNA(VLOOKUP(E3,Sheet3!$H:$I,2,FALSE),"") -> B2400 | E3: Information Technology | F3: 2141000 | G3: Tools, furniture & office equipment | H3: UPS For Rack 1 (Domain, Application Server) | I3: 88905600 | J3: 60 | K3: 100 | L3: 43922 | M3: B | O3: 88905600
A4: BIP | B4: =_xlfn.IFNA(VLOOKUP(C4,Sheet3!$H:$I,2,FALSE),"") -> B2400 | C4: Information Technology | D4: =_xlfn.IFNA(VLOOKUP(E4,Sheet3!$H:$I,2,FALSE),"") -> B2400 | E4: Information Technology | F4: 2141000 | G4: Tools, furniture & office equipment | H4: Notebook for IT Member | I4: 15000000 | J4: 60 | K4: 100 | L4: 43983 | M4: C | O4: 15000000
A5: BIP | B5: =_xlfn.IFNA(VLOOKUP(C5,Sheet3!$H:$I,2,FALSE),"") -> B2210 | C5: GENERAL AFFAIR | D5: =_xlfn.IFNA(VLOOKUP(E5,Sheet3!$H:$I,2,FALSE),"") -> B2210 | E5: GENERAL AFFAIR | F5: 2141000 | G5: Tools, furniture & office equipment | H5: Auto Gate Machine | I5: 40000000 | J5: 60 | K5: 100 | L5: 44197 | M5: C | O5: 40000000
A6: BIP | B6: =_xlfn.IFNA(VLOOKUP(C6,Sheet3!$H:$I,2,FALSE),"") -> B2210 | C6: GENERAL AFFAIR | D6: =_xlfn.IFNA(VLOOKUP(E6,Sheet3!$H:$I,2,FALSE),"") -> B2210 | E6: GENERAL AFFAIR | F6: 2141000 | G6: Tools, furniture & office equipment | H6: AC Central Spark Plug 1 | I6: 40000000 | J6: 60 | K6: 100 | L6: 44197 | M6: C | O6: 40000000
A7: BIP | B7: =_xlfn.IFNA(VLOOKUP(C7,Sheet3!$H:$I,2,FALSE),"") -> B2210 | C7: GENERAL AFFAIR | D7: =_xlfn.IFNA(VLOOKUP(E7,Sheet3!$H:$I,2,FALSE),"") -> B2220 | E7: HUMAN RESOURCE | F7: 2141000 | G7: Tools, furniture & office equipment | H7: Personal Computer Recruitment Staff | I7: 8000000 | J7: 60 | K7: 100 | L7: 44287 | M7: C | O7: 8000000
A8: BIP | B8: =_xlfn.IFNA(VLOOKUP(C8,Sheet3!$H:$I,2,FALSE),"") -> B2210 | C8: GENERAL AFFAIR | D8: =_xlfn.IFNA(VLOOKUP(E8,Sheet3!$H:$I,2,FALSE),"") -> B2210 | E8: GENERAL AFFAIR | F8: 2141000 | G8: Tools, furniture & office equipment | H8: Personal Computer GA Staff | I8: 8000000 | J8: 60 | K8: 100 | L8: 44287 | M8: C | O8: 8000000
A9: BIP | B9: =_xlfn.IFNA(VLOOKUP(C9,Sheet3!$H:$I,2,FALSE),"") -> B2210 | C9: GENERAL AFFAIR | D9: =_xlfn.IFNA(VLOOKUP(E9,Sheet3!$H:$I,2,FALSE),"") -> B2220 | E9: HUMAN RESOURCE | F9: 2141000 | G9: Tools, furniture & office equipment | H9: Laptop Training | I9: 10000000 | J9: 60 | K9: 100 | L9: 44287 | M9: C | O9: 10000000
A10: BIP | B10: =_xlfn.IFNA(VLOOKUP(C10,Sheet3!$H:$I,2,FALSE),"") -> B2210 | C10: GENERAL AFFAIR | D10: =_xlfn.IFNA(VLOOKUP(E10,Sheet3!$H:$I,2,FALSE),"") -> B2210 | E10: GENERAL AFFAIR | F10: 2141000 | G10: Tools, furniture & office equipment | H10: Laptop IR & Legal | I10: 10000000 | J10: 60 | K10: 100 | L10: 44287 | M10: C | O10: 10000000
A11: BIP | B11: =_xlfn.IFNA(VLOOKUP(C11,Sheet3!$H:$I,2,FALSE),"") -> B2210 | C11: GENERAL AFFAIR | D11: =_xlfn.IFNA(VLOOKUP(E11,Sheet3!$H:$I,2,FALSE),"") -> B2210 | E11: GENERAL AFFAIR | F11: 2141000 | G11: Tools, furniture & office equipment | H11: Projector - Spark Plug 1 | I11: 8000000 | J11: 60 | K11: 100 | L11: 44348 | M11: C | O11: 8000000
A12: BIP | B12: =_xlfn.IFNA(VLOOKUP(C12,Sheet3!$H:$I,2,FALSE),"") -> B2210 | C12: GENERAL AFFAIR | D12: =_xlfn.IFNA(VLOOKUP(E12,Sheet3!$H:$I,2,FALSE),"") -> B2210 | E12: GENERAL AFFAIR | F12: 2141000 | G12: Tools, furniture & office equipment | H12: Projector - Spark Plug 2 | I12: 8000000 | J12: 60 | K12: 100 | L12: 44348 | M12: C | O12: 8000000
A13: BIP | B13: =_xlfn.IFNA(VLOOKUP(C13,Sheet3!$H:$I,2,FALSE),"") -> B2210 | C13: GENERAL AFFAIR | D13: =_xlfn.IFNA(VLOOKUP(E13,Sheet3!$H:$I,2,FALSE),"") -> B2210 | E13: GENERAL AFFAIR | F13: 2141000 | G13: Tools, furniture & office equipment | H13: Projector - Office | I13: 8000000 | J13: 60 | K13: 100 | L13: 44348 | M13: C | O13: 8000000
... A54: BIP | B54: =_xlfn.IFNA(VLOOKUP(C54,Sheet3!$H:$I,2,FALSE),"") -> B5500 | C54: Maintenance | D54: =_xlfn.IFNA(VLOOKUP(E54,Sheet3!$H:$I,2,FALSE),"") -> B2230 | E54: Health, Safety & Environment | F54: 2141000 | G54: Tools, furniture & office equipment | H54: Mini Crusher for composting | I54: 30000000 | J54: 60 | K54: 100 | L54: 45231 | M54: C | O54: 30000000
A55: BIP | B55: =_xlfn.IFNA(VLOOKUP(C55,Sheet3!$H:$I,2,FALSE),"") -> B5500 | C55: Maintenance | D55: =_xlfn.IFNA(VLOOKUP(E55,Sheet3!$H:$I,2,FALSE),"") -> B5500 | E55: Maintenance | F55: 2121000 | G55: Machinery & Equipment - New | H55: Transformer from Takenaka& Kinden | I55: 550000000 | J55: 120 | K55: 100 | L55: 44256 | M55: A | O55: =+I55 -> 550000000
A56: BIP | B56: =_xlfn.IFNA(VLOOKUP(C56,Sheet3!$H:$I,2,FALSE),"") -> B5600 | C56: Production Engineering | D56: =_xlfn.IFNA(VLOOKUP(E56,Sheet3!$H:$I,2,FALSE),"") -> B5900 | E56: Quality Control | F56: 2141000 | G56: Tools, furniture & office equipment | H56: Caliper for Rubber Measurement | I56: 14000000 | J56: 60 | K56: 100 | L56: 44378 | M56: B | O56: 14000000
A57: BIP | B57: =_xlfn.IFNA(VLOOKUP(C57,Sheet3!$H:$I,2,FALSE),"") -> B5600 | C57: Production Engineering | D57: =_xlfn.IFNA(VLOOKUP(E57,Sheet3!$H:$I,2,FALSE),"") -> B5900 | E57: Quality Control | F57: 2141000 | G57: Tools, furniture & office equipment | H57: Caliper for Rubber Measurement | I57: 14000000 | J57: 60 | K57: 100 | L57: 44378 | M57: B | O57: 14000000
A58: BIP | B58: =_xlfn.IFNA(VLOOKUP(C58,Sheet3!$H:$I,2,FALSE),"") -> B5600 | C58: Production Engineering | D58: =_xlfn.IFNA(VLOOKUP(E58,Sheet3!$H:$I,2,FALSE),"") -> B5900 | E58: Quality Control | F58: 2141000 | G58: Tools, furniture & office equipment | H58: Caliper for Rubber Measurement | I58: 14000000 | J58: 60 | K58: 100 | L58: 44378 | M58: B | O58: 14000000
A59: BIP | B59: =_xlfn.IFNA(VLOOKUP(C59,Sheet3!$H:$I,2,FALSE),"") -> B5600 | C59: Production Engineering | D59: =_xlfn.IFNA(VLOOKUP(E59,Sheet3!$H:$I,2,FALSE),"") -> B5600 | E59: Production Engineering | F59: 2141000 | G59: Tools, furniture & office equipment | H59: Notebook Replacement for Edy Haryono | I59: 10000000 | J59: 60 | K59: 100 | L59: 44409 | M59: B | O59: 10000000
A60: BIP | B60: =_xlfn.IFNA(VLOOKUP(C60,Sheet3!$H:$I,2,FALSE),"") -> B5600 | C60: Production Engineering | D60: =_xlfn.IFNA(VLOOKUP(E60,Sheet3!$H:$I,2,FALSE),"") -> B5600 | E60: Production Engineering | F60: 2141000 | G60: Tools, furniture & office equipment | H60: PC Replacement for Noviyanto | I60: 8000000 | J60: 60 | K60: 100 | L60: 44409 | M60: B | O60: 8000000
A61: BIP | B61: =_xlfn.IFNA(VLOOKUP(C61,Sheet3!$H:$I,2,FALSE),"") -> B5600 | C61: Production Engineering | D61: =_xlfn.IFNA(VLOOKUP(E61,Sheet3!$H:$I,2,FALSE),"") -> B4101 | E61: SP PD- CF | F61: 2141000 | G61: Tools, furniture & office equipment | H61: CF image inspection device for CF no. 1 | I61: 100000000 | J61: 60 | K61: 100 | L61: 44470 | M61: B | O61: 100000000
A62: BIP | B62: =_xlfn.IFNA(VLOOKUP(C62,Sheet3!$H:$I,2,FALSE),"") -> B5600 | C62: Production Engineering | D62: =_xlfn.IFNA(VLOOKUP(E62,Sheet3!$H:$I,2,FALSE),"") -> B4102 | E62: SP PD- CM | F62: 2121000 | G62: Machinery & Equipment - Second | H62: Periodic Maintenance CM Machine （№4）& Accessories | I62: 11167645280 | J62: 84 | K62: 100 | L62: 44593 | M62: A | O62: 11167645280
A63: BIP | B63: =_xlfn.IFNA(VLOOKUP(C63,Sheet3!$H:$I,2,FALSE),"") -> B5600 | C63: Production Engineering | D63: =_xlfn.IFNA(VLOOKUP(E63,Sheet3!$H:$I,2,FALSE),"") -> B4120 | E63: SP PD- Final Inspection | F63: 2121000 | G63: Machinery & Equipment - New | H63: Semi Auto Packaging Machine №2 | I63: 1.0544116e+09 | J63: 120 | K63: 100 | L63: 44593 | M63: A | O63: 1.0544116e+09
A64: BIP | B64: =_xlfn.IFNA(VLOOKUP(C64,Sheet3!$H:$I,2,FALSE),"") -> B5600 | C64: Production Engineering | D64: =_xlfn.IFNA(VLOOKUP(E64,Sheet3!$H:$I,2,FALSE),"") -> B5600 | E64: Production Engineering | F64: 2141000 | G64: Tools, furniture & office equipment | H64: End Mill Grinder | I64: 30000000 | J64: 60 | K64: 100 | L64: 44713 | M64: C | O64: 30000000
A65: BIP | B65: =_xlfn.IFNA(VLOOKUP(C65,Sheet3!$H:$I,2,FALSE),"") -> B5600 | C65: Production Engineering | D65: =_xlfn.IFNA(VLOOKUP(E65,Sheet3!$H:$I,2,FALSE),"") -> B4106 | E65: SP PD- Insulator Sealing | F65: 2121000 | G65: Machinery & Equipment - Second | H65: Periodic Maintenance Assy Insulator furnace Oven | I65: 1594117400 | J65: 84 | K65: 100 | L65: 44774 | M65: A | O65: 1594117400
A66: BIP | B66: =_xlfn.IFNA(VLOOKUP(C66,Sheet3!$H:$I,2,FALSE),"") -> B5600 | C66: Production Engineering | D66: =_xlfn.IFNA(VLOOKUP(E66,Sheet3!$H:$I,2,FALSE),"") -> B4106 | E66: SP PD- Insulator Sealing | F66: 2121000 | G66: Machinery & Equipment - New | H66: Update Setsugo Machine （№4）C2 NEW | I66: 14748527060 | J66: 120 | K66: 100 | L66: 44805 | M66: C | O66: 14748527060
A67: BIP | B67: =_xlfn.IFNA(VLOOKUP(C67,Sheet3!$H:$I,2,FALSE),"") -> B5600 | C67: Production Engineering | D67: =_xlfn.IFNA(VLOOKUP(E67,Sheet3!$H:$I,2,FALSE),"") -> B4102 | E67: SP PD- CM | F67: 2121000 | G67: Machinery & Equipment - Second | H67: Periodic Maintenance CM No.9 & Accessories | I67: 11167645280 | J67: 84 | K67: 100 | L67: 44866 | M67: A | O67: 11167645280
... A147: BIP | B147: =_xlfn.IFNA(VLOOKUP(C147,Sheet3!$H:$I,2,FALSE),"") -> B5000 | C147: Plant Operation (Indirect Mfg) | D147: =_xlfn.IFNA(VLOOKUP(E147,Sheet3!$H:$I,2,FALSE),"") -> B5000 | E147: Plant Operation (Indirect Mfg) | F147: 2141000 | G147: Tools, furniture & office equipment | H147: PC IWAIZAKO - BIP | I147: 10000000 | J147: 60 | K147: 100 | L147: 44621 | M147: B | O147: 10000000

Sheet Master
A1: Name | B1: BNGK | C1: GROUP COST | D1: GROUP SECTION | E1: Name | G1: Code | H1: Name | J1: Name COA AX | K1: COA AX | L1: Group Cost | M1: UNIQ | N1: COA Budget | O1: Description | Q1: Name | R1: BNGK | S1: GROUP COST | T1: GROUP SECTION | U1: Name | W1: Code | X1: Name | Z1: Priority Code | AA1: Priority Name | AB1: Description | AD1: COA Assets | AE1: Name of Asset | AF1: COA Depre | AG1: Name of Depre | AI1: Priority Code | AJ1: Priority Name | AK1: Description
A2: Top Management | B2: B1000 | C2: SGA | D2: ADM | E2: =A2 -> Top Management | G2: 53450 | H2: NGK BUSI INDONESIA | J2: Salary for Commissioner | K2: 7511101 | L2: SGA | M2: =L2&"-"&K2 -> SGA-7511101 | N2: A502 | O2: Salary for Commissioner | Q2: Top Management | R2: B1000 | S2: SGA | T2: ADM | U2: =Q2 -> Top Management | W2: 53450 | X2: NGK BUSI INDONESIA | Z2: A | AA2: Must | AB2: If this is not done, the company or our team cannot continue its business. | AD2: 2111100 | AE2: Building | AF2: 7611100 | AG2: Depreciation-Building | AI2: A | AJ2: Must | AK2: If this is not done, the company or our team cannot continue its business.
A3: Commissioner | B3: B1001 | C3: SGA | D3: ADM | E3: =A3 -> Commissioner | J3: Salary for Director | K3: 7511102 | L3: SGA | M3: =L3&"-"&K3 -> SGA-7511102 | N3: A502 | O3: Salary for Director & Expat | Q3: Commissioner | R3: B1001 | S3: SGA | T3: ADM | U3: =Q3 -> Commissioner | Z3: B | AA3: Want to | AB3: We want to do it as a team this term. we need it. | AD3: 2121000 | AE3: Machinery & Equipment | AF3: 7611300 | AG3: Depreciation-Machiney & equipment | AI3: B | AJ3: Want to | AK3: We want to do it as a team this term. we need it.
A4: Admin & HR | B4: B2200 | C4: SGA | D4: ADM | E4: =A4 -> Admin & HR | J4: Staff Labor - Baslc Salary | K4: 7511103 | L4: SGA | M4: =L4&"-"&K4 -> SGA-7511103 | N4: A501 | O4: Basic Salary of permanent employee | Q4: Admin & HR | R4: B2200 | S4: SGA | T4: ADM | U4: =Q4 -> Admin & HR | Z4: C | AA4: Challenge | AB4: We want to do it for this term or the future. But it doesn't matter if it's not this term. | AD4: 2131000 | AE4: Vehicles | AF4: 7611500 | AG4: Depreciation-Vehicles | AI4: C | AJ4: Challenge | AK4: We want to do it for this term or the future. But it doesn't matter if it's not this term.
A5: General Affair | B5: B2210 | C5: SGA | D5: ADM | E5: =A5 -> General Affair | J5: Staff Labor - Allowance | K5: 7511111 | L5: SGA | M5: =L5&"-"&K5 -> SGA-7511111 | N5: A501 | O5: Employee allowance | Q5: General Affair | R5: B2210 | S5: SGA | T5: ADM | U5: =Q5 -> General Affair | AD5: 2141000 | AE5: Tools, furniture & office equipment | AF5: 7611600 | AG5: Depreciation-Tools, furniture & office equipment
A6: Human Resource | B6: B2220 | C6: SGA | D6: ADM | E6: =A6 -> Human Resource | J6: Staff Labor - Tax allowance (art.21) | K6: 7511112 | L6: SGA | M6: =L6&"-"&K6 -> SGA-7511112 | N6: A501 | O6: Empployee Tax allowance | Q6: Human Resource | R6: B2220 | S6: SGA | T6: ADM | U6: =Q6 -> Human Resource | AD6: 2221101 | AE6: Software | AF6: 7611700 | AG6: Depreciation-Software
A7: Health, Safety & Environment | B7: B2230 | C7: SGA | D7: ADM | E7: =A7 -> Health, Safety & Environment | J7: Staff Labor - BPJS JK & JKK (1.19%) | K7: 7511121 | L7: SGA | M7: =L7&"-"&K7 -> SGA-7511121 | N7: A501 | O7: BPJS JK & JKK (death warrant, Accident Insurance) | Q7: Health, Safety & Environment | R7: B2230 | S7: SGA | T7: ADM | U7: =Q7 -> Health, Safety & Environment
A8: Accounting & Finance | B8: B2300 | C8: SGA | D8: ADM | E8: =A8 -> Accounting & Finance | J8: Staff Labor - BPJS Kesehatan (4%) | K8: 7511122 | L8: SGA | M8: =L8&"-"&K8 -> SGA-7511122 | N8: A501 | O8: BPJS health insurance | Q8: Accounting & Finance | R8: B2300 | S8: SGA | T8: ADM | U8: =Q8 -> Accounting & Finance
A9: Information Technology | B9: B2400 | C9: SGA | D9: ADM | E9: =A9 -> Information Technology | J9: Staff Overtime | K9: 7511201 | L9: SGA | M9: =L9&"-"&K9 -> SGA-7511201 | N9: A503 | O9: Overtime permanent employee | Q9: Information Technology | R9: B2400 | S9: SGA | T9: ADM | U9: =Q9 -> Information Technology
A10: Sales & MKTG Dept.- Automotive | B10: B3100 | C10: SGA | D10: ADM | E10: =A10 -> Sales & MKTG Dept.- Automotive | J10: Staff Welfare - BPJS Dana pensiun (2%) | K10: 7512111 | L10: SGA | M10: =L10&"-"&K10 -> SGA-7512111 | N10: A504 | O10: BPJS pension fund | Q10: Sales & MKTG Dept.- Automotive | R10: B3100 | S10: SGA | T10: ADM | U10: =Q10 -> Sales & MKTG Dept.- Automotive
A11: Marketing | B11: B3160 | C11: SGA | D11: ADM | E11: =A11 -> Marketing | J11: Staff Welfare - BPJS JHT (3.7%) | K11: 7512112 | L11: SGA | M11: =L11&"-"&K11 -> SGA-7512112 | N11: A504 | O11: BPJS Pension plan | Q11: Marketing | R11: B3160 | S11: SGA | T11: ADM | U11: =Q11 -> Marketing
A12: Sales - OEM | B12: B3110 | C12: SGA | D12: ADM | E12: =A12 -> Sales - OEM | J12: Staff Bonus / TAT | K12: 7514101 | L12: SGA | M12: =L12&"-"&K12 -> SGA-7514101 | N12: A501 | O12: Year-end allowance & Alpha | Q12: Sales - OEM | R12: B3110 | S12: SGA | T12: ADM | U12: =Q12 -> Sales - OEM
A13: Sales - OES | B13: B3120 | C13: SGA | D13: ADM | E13: =A13 -> Sales - OES | J13: Staff Ramadhan / THR | K13: 7514102 | L13: SGA | M13: =L13&"-"&K13 -> SGA-7514102 | N13: A501 | O13: Lebaran bonus | Q13: Sales - OES | R13: B3120 | S13: SGA | T13: ADM | U13: =Q13 -> Sales - OES
A14: Sales - IAM | B14: B3130 | C14: SGA | D14: ADM | E14: =A14 -> Sales - IAM | J14: Staff Welfare - Outpatient (Medical) | K14: 7515401 | L14: SGA | M14: =L14&"-"&K14 -> SGA-7515401 | N14: A504 | O14: outpatient treatment costs | Q14: Sales - IAM | R14: B3130 | S14: SGA | T14: ADM | U14: =Q14 -> Sales - IAM
A15: SP PD- CF | B15: B4101 | C15: MFG | D15: DIR | E15: =A15 -> SP PD- CF | J15: Staff Welfare - Hospitalization | K15: 7515402 | L15: SGA | M15: =L15&"-"&K15 -> SGA-7515402 | N15: A504 | O15: hospitalization costs | Q15: SP PD- CF | R15: B4101 | S15: MFG | T15: DIR | U15: =Q15 -> SP PD- CF
A16: SP PD- CM | B16: B4102 | C16: MFG | D16: DIR | E16: =A16 -> SP PD- CM | J16: Staff Welfare - Glasses | K16: 7515403 | L16: SGA | M16: =L16&"-"&K16 -> SGA-7515403 | N16: A504 | O16: glasses costs | Q16: SP PD- CM | R16: B4102 | S16: MFG | T16: DIR | U16: =Q16 -> SP PD- CM
A17: SP PD- WT | B17: B4103 | C17: MFG | D17: DIR | E17: =A17 -> SP PD- WT | J17: Staff Welfare - Dental | K17: 7515404 | L17: SGA | M17: =L17&"-"&K17 -> SGA-7515404 | N17: A504 | O17: dental costs | Q17: SP PD- WT | R17: B4103 | S17: MFG | T17: DIR | U17: =Q17 -> SP PD- WT
A18: SP PD- Plating | B18: B4105 | C18: MFG | D18: DIR | E18: =A18 -> SP PD- Plating | J18: Staff Welfare - Medical Check Up | K18: 7515405 | L18: SGA | M18: =L18&"-"&K18 -> SGA-7515405 | N18: A504 | O18: Medical Check Up cost | Q18: SP PD- Plating | R18: B4105 | S18: MFG | T18: DIR | U18: =Q18 -> SP PD- Plating
A19: SP PD- MS Insp. | B19: B4109 | C19: MFG | D19: DIR | E19: =A19 -> SP PD- MS Insp. | J19: Staff Welfare - Uniform | K19: 7515406 | L19: SGA | M19: =L19&"-"&K19 -> SGA-7515406 | N19: A504 | O19: uniform costs | Q19: SP PD- MS Insp. | R19: B4109 | S19: MFG | T19: DIR | U19: =Q19 -> SP PD- MS Insp.
A20: SP PD- Insulator Sealing | B20: B4106 | C20: MFG | D20: DIR | E20: =A20 -> SP PD- Insulator Sealing | J20: Staff Welfare - Safety Shoes | K20: 7515407 | L20: SGA | M20: =L20&"-"&K20 -> SGA-7515407 | N20: A504
A21: SP PD- Assy | B21: B4110 | C21: MFG | D21: DIR | E21: =A21 -> SP PD- Assy | J21: Staff Welfare - Family Gathering / Anniversary | K21: 7515408 | L21: SGA | M21: =L21&"-"&K21 -> SGA-7515408 | N21: A504 | O21: Family Gathering / Anniversary | Q21: SP PD- Insulator Sealing | R21: B4106 | S21: MFG | T21: DIR | U21: =Q21 -> SP PD- Insulator Sealing
A22: SP-PD-Assy-Auto Assembly | B22: B4115 | C22: MFG | D22: DIR | E22: =A22 -> SP-PD-Assy-Auto Assembly | J22: Staff Welfare - Meals of canteen & other meals | K22: 7515409 | L22: SGA | M22: =L22&"-"&K22 -> SGA-7515409 | N22: A504 | O22: Meals of canteen & other meals cost | Q22: SP PD- Assy | R22: B4110 | S22: MFG | T22: DIR | U22: =Q22 -> SP PD- Assy
A23: SP PD- Bending | B23: B4114 | C23: MFG | D23: DIR | E23: =A23 -> SP PD- Bending | J23: Staff Welfare - Kaizen & QCC reward | K23: 7515410 | L23: SGA | M23: =L23&"-"&K23 -> SGA-7515410 | N23: A504 | O23: an expense, arising from Kaizen and QCC acitivity | Q23: SP-PD-Assy-Auto Assembly | R23: B4115 | S23: MFG | T23: DIR | U23: =Q23 -> SP-PD-Assy-Auto Assembly
A24: SP PD- Final Inspection | B24: B4120 | C24: MFG | D24: DIR | E24: =A24 -> SP PD- Final Inspection | J24: Staff Welfare - Welfare Others | K24: 7515499 | L24: SGA | M24: =L24&"-"&K24 -> SGA-7515499 | N24: A504 | O24: an other welfare expense, arising besides the above welfare expense | Q24: SP PD- Bending | R24: B4114 | S24: MFG | T24: DIR | U24: =Q24 -> SP PD- Bending
A25: SP PD- QC - OEM | B25: B4121 | C25: MFG | D25: DIR | E25: =A25 -> SP PD- QC - OEM | J25: Retirement Allowance | K25: 7516102 | L25: SGA | M25: =L25&"-"&K25 -> SGA-7516102 | N25: A505 | O25: employee retirement provission costs | Q25: SP PD- Final Inspection | R25: B4120 | S25: MFG | T25: DIR | U25: =Q25 -> SP PD- Final Inspection
A26: PC PD- Injection | B26: B4410 | C26: MFG | D26: DIR | E26: =A26 -> PC PD- Injection | J26: House Rent Allowance | K26: 7519101 | L26: SGA | M26: =L26&"-"&K26 -> SGA-7519101 | N26: A502 | O26: House Rent Allowance for expat | Q26: SP PD- QC - OEM | R26: B4121 | S26: MFG | T26: DIR | U26: =Q26 -> SP PD- QC - OEM
A27: PC PD- Assy | B27: B4430 | C27: MFG | D27: DIR | E27: =A27 -> PC PD- Assy | J27: Casual Staff Labor - Basic Salary | K27: 7521101 | L27: SGA | M27: =L27&"-"&K27 -> SGA-7521101 | N27: A501 | O27: All benefit for temporary worker | Q27: PC PD- Injection | R27: B4410 | S27: MFG | T27: DIR | U27: =Q27 -> PC PD- Injection
A28: PC PD- QC | B28: B4440 | C28: MFG | D28: DIR | E28: =A28 -> PC PD- QC | J28: Casual Staff Labor - Overtime | K28: 7521102 | L28: SGA | M28: =L28&"-"&K28 -> SGA-7521102 | N28: A503 | O28: Overtime temporary worker | Q28: PC PD- Assy | R28: B4430 | S28: MFG | T28: DIR | U28: =Q28 -> PC PD- Assy
A29: Plant Operation (Indirect Mfg) | B29: B5000 | C29: MFG | D29: IND | E29: =A29 -> Plant Operation (Indirect Mfg) | J29: Personnel expense transferred | K29: 7571101 | L29: SGA | M29: =L29&"-"&K29 -> SGA-7571101 | N29: A506 | O29: Transfer Labor cost from one section into another section | Q29: PC PD- QC | R29: B4440 | S29: MFG | T29: DIR | U29: =Q29 -> PC PD- QC
A30: Production Office | B30: B5100 | C30: MFG | D30: IND | E30: =A30 -> Production Office | J30: Depreciation-Building | K30: 7611100 | L30: SGA | M30: =L30&"-"&K30 -> SGA-7611100 | N30: A601 | O30: the amount of depreciation of tangible assets for building | Q30: Plant Operation (Indirect Mfg) | R30: B5000 | S30: MFG | T30: IND | U30: =Q30 -> Plant Operation (Indirect Mfg)
A31: Production Office (SP) | B31: B5101 | C31: MFG | D31: IND | E31: =A31 -> Production Office (SP) | J31: Depreciation-Machiney & equipment | K31: 7611300 | L31: SGA | M31: =L31&"-"&K31 -> SGA-7611300 | N31: A601 | O31: the amount of depreciation of tangible assets for machinery & factory equipment | Q31: Production Office | R31: B5100 | S31: MFG | T31: IND | U31: =Q31 -> Production Office
A32: Production Office (PC) | B32: B5104 | C32: MFG | D32: IND | E32: =A32 -> Production Office (PC) | J32: Depreciation-Lease Machinery & equipment | K32: 7611400 | L32: SGA | M32: =L32&"-"&K32 -> SGA-7611400 | N32: A601 | O32: the amount of depreciation of tangible assets for machinery & factory equipment (Leases) | Q32: Production Office (SP) | R32: B5101 | S32: MFG | T32: IND | U32: =Q32 -> Production Office (SP)
... A42: WH Dept.- KD & RM | B42: B5710 | C42: MFG | D42: IND | E42: =A42 -> WH Dept.- KD & RM | J42: Repair of Equipment | K42: 7641102 | L42: SGA | M42: =L42&"-"&K42 -> SGA-7641102 | N42: A1002 | O42: expenses for repair and maintenance tangible assets, intangible assets and other assets beside building | Q42: Continuous Improvement | R42: B5007 | S42: MFG | T42: IND | U42: =Q42 -> Continuous Improvement
A43: Continuous Improvement | B43: B5007 | C43: MFG | D43: IND | E43: =A43 -> Continuous Improvement | J43: Factory Supply Expense | K43: 7641103 | L43: SGA | M43: =L43&"-"&K43 -> SGA-7641103 | N43: A1099 | O43: All cost that arrising to support factory acitivity | Q43: All | R43: B0000 | U43: =Q43 -> All
J44: Calibration Cost | K44: 7641104 | L44: SGA | M44: =L44&"-"&K44 -> SGA-7641104 | N44: A1099 | O44: Cost of calibration for tools and equipment of factory and others
J45: Transportation Fee for employee | K45: 7651101 | L45: SGA | M45: =L45&"-"&K45 -> SGA-7651101 | N45: A801 | O45: Gasoline of company cars & expense for Local transportation
J46: Travel Expense-Domestic | K46: 7651102 | L46: SGA | M46: =L46&"-"&K46 -> SGA-7651102 | N46: A801 | O46: expenses for business trip, including allowance for business trip to an employee only for domestic travel
J47: Travel Expense-Oversea | K47: 7651103 | L47: SGA | M47: =L47&"-"&K47 -> SGA-7651103 | N47: A801 | O47: expenses for business trip, including allowance for business trip to an employee only for overseas travel
J48: Entertainment | K48: 7661101 | L48: SGA | M48: =L48&"-"&K48 -> SGA-7661101 | N48: A1001 | O48: the amount of expenses for the act of entertaining the business partner
J49: Amortization of Land & Building tax (PBB) | K49: 7671102 | L49: SGA | M49: =L49&"-"&K49 -> SGA-7671102 | N49: A1099 | O49: the amount of depreciation of intangible of Land & Building Tax (PBB)
...

Sheet Sheet3
A1: Name COA AX | B1: COA AX | C1: Group Cost | D1: UNIQ | E1: COA Budget | F1: Description | H1: Name | I1: BNGK | J1: GROUP COST | K1: GROUP SECTION | L1: Name | N1: Code | O1: Name | Q1: Priority Code | R1: Priority Name | S1: Description
A2: Salary for Commissioner | B2: 7511101 | C2: SGA | D2: =C2&"-"&B2 -> SGA-7511101 | E2: A502 | F2: Salary for Commissioner | H2: Top Management | I2: B1000 | J2: SGA | K2: ADM | L2: =H2 -> Top Management | N2: 53450 | O2: NGK BUSI INDONESIA | Q2: A | R2: Must | S2: If this is not done, the company or our team cannot continue its business.
A3: Salary for Director | B3: 7511102 | C3: SGA | D3: =C3&"-"&B3 -> SGA-7511102 | E3: A502 | F3: Salary for Director & Expat | H3: Commissioner | I3: B1001 | J3: SGA | K3: ADM | L3: =H3 -> Commissioner | Q3: B | R3: Want to | S3: We want to do it as a team this term. we need it.
A4: Staff Labor - Baslc Salary | B4: 7511103 | C4: SGA | D4: =C4&"-"&B4 -> SGA-7511103 | E4: A501 | F4: Basic Salary of permanent employee | H4: Admin & HR | I4: B2200 | J4: SGA | K4: ADM | L4: =H4 -> Admin & HR | Q4: C | R4: Challenge | S4: We want to do it for this term or the future. But it doesn't matter if it's not this term.
A5: Staff Labor - Allowance | B5: 7511111 | C5: SGA | D5: =C5&"-"&B5 -> SGA-7511111 | E5: A501 | F5: Employee allowance | H5: General Affair | I5: B2210 | J5: SGA | K5: ADM | L5: =H5 -> General Affair
A6: Staff Labor - Tax allowance (art.21) | B6: 7511112 | C6: SGA | D6: =C6&"-"&B6 -> SGA-7511112 | E6: A501 | F6: Empployee Tax allowance | H6: Human Resource | I6: B2220 | J6: SGA | K6: ADM | L6: =H6 -> Human Resource
A7: Staff Labor - BPJS JK & JKK (1.19%) | B7: 7511121 | C7: SGA | D7: =C7&"-"&B7 -> SGA-7511121 | E7: A501 | F7: BPJS JK & JKK (death warrant, Accident Insurance) | H7: Health, Safety & Environment | I7: B2230 | J7: SGA | K7: ADM | L7: =H7 -> Health, Safety & Environment
A8: Staff Labor - BPJS Kesehatan (4%) | B8: 7511122 | C8: SGA | D8: =C8&"-"&B8 -> SGA-7511122 | E8: A501 | F8: BPJS health insurance | H8: Accounting & Finance | I8: B2300 | J8: SGA | K8: ADM | L8: =H8 -> Accounting & Finance
A9: Staff Overtime | B9: 7511201 | C9: SGA | D9: =C9&"-"&B9 -> SGA-7511201 | E9: A503 | F9: Overtime permanent employee | H9: Information Technology | I9: B2400 | J9: SGA | K9: ADM | L9: =H9 -> Information Technology
A10: Staff Welfare - BPJS Dana pensiun (2%) | B10: 7512111 | C10: SGA | D10: =C10&"-"&B10 -> SGA-7512111 | E10: A504 | F10: BPJS pension fund | H10: Sales & MKTG Dept.- Automotive | I10: B3100 | J10: SGA | K10: ADM | L10: =H10 -> Sales & MKTG Dept.- Automotive
A11: Staff Welfare - BPJS JHT (3.7%) | B11: 7512112 | C11: SGA | D11: =C11&"-"&B11 -> SGA-7512112 | E11: A504 | F11: BPJS Pension plan | H11: Marketing | I11: B3160 | J11: SGA | K11: ADM | L11: =H11 -> Marketing
A12: Staff Bonus / TAT | B12: 7514101 | C12: SGA | D12: =C12&"-"&B12 -> SGA-7514101 | E12: A501 | F12: Year-end allowance & Alpha | H12: Sales - OEM | I12: B3110 | J12: SGA | K12: ADM | L12: =H12 -> Sales - OEM
A13: Staff Ramadhan / THR | B13: 7514102 | C13: SGA | D13: =C13&"-"&B13 -> SGA-7514102 | E13: A501 | F13: Lebaran bonus | H13: Sales - OES | I13: B3120 | J13: SGA | K13: ADM | L13: =H13 -> Sales - OES
A14: Staff Welfare - Outpatient (Medical) | B14: 7515401 | C14: SGA | D14: =C14&"-"&B14 -> SGA-7515401 | E14: A504 | F14: outpatient treatment costs | H14: Sales - IAM | I14: B3130 | J14: SGA | K14: ADM | L14: =H14 -> Sales - IAM
A15: Staff Welfare - Hospitalization | B15: 7515402 | C15: SGA | D15: =C15&"-"&B15 -> SGA-7515402 | E15: A504 | F15: hospitalization costs | H15: SP PD- CF | I15: B4101 | J15: MFG | K15: DIR | L15: =H15 -> SP PD- CF
A16: Staff Welfare - Glasses | B16: 7515403 | C16: SGA | D16: =C16&"-"&B16 -> SGA-7515403 | E16: A504 | F16: glasses costs | H16: SP PD- CM | I16: B4102 | J16: MFG | K16: DIR | L16: =H16 -> SP PD- CM
... A19: Staff Welfare - Uniform | B19: 7515406 | C19: SGA | D19: =C19&"-"&B19 -> SGA-7515406 | E19: A504 | F19: uniform costs | H19: SP PD- MS Insp. | I19: B4109 | J19: MFG | K19: DIR | L19: =H19 -> SP PD- MS Insp.
A20: Staff Welfare - Safety Shoes | B20: 7515407 | C20: SGA | D20: =C20&"-"&B20 -> SGA-7515407 | E20: A504 | H20: SP PD- Insulator Sealing | I20: B4106 | J20: MFG | K20: DIR | L20: =H20 -> SP PD- Insulator Sealing
A21: Staff Welfare - Family Gathering / Anniversary | B21: 7515408 | C21: SGA | D21: =C21&"-"&B21 -> SGA-7515408 | E21: A504 | F21: Family Gathering / Anniversary | H21: SP PD- Assy | I21: B4110 | J21: MFG | K21: DIR | L21: =H21 -> SP PD- Assy
A22: Staff Welfare - Meals of canteen & other meals | B22: 7515409 | C22: SGA | D22: =C22&"-"&B22 -> SGA-7515409 | E22: A504 | F22: Meals of canteen & other meals cost | H22: SP-PD-Assy-Auto Assembly | I22: B4115 | J22: MFG | K22: DIR | L22: =H22 -> SP-PD-Assy-Auto Assembly
A23: Staff Welfare - Kaizen & QCC reward | B23: 7515410 | C23: SGA | D23: =C23&"-"&B23 -> SGA-7515410 | E23: A504 | F23: an expense, arising from Kaizen and QCC acitivity | H23: SP PD- Bending | I23: B4114 | J23: MFG | K23: DIR | L23: =H23 -> SP PD- Bending
A24: Staff Welfare - Welfare Others | B24: 7515499 | C24: SGA | D24: =C24&"-"&B24 -> SGA-7515499 | E24: A504 | F24: an other welfare expense, arising besides the above welfare expense | H24: SP PD- Final Inspection | I24: B4120 | J24: MFG | K24: DIR | L24: =H24 -> SP PD- Final Inspection
A25: Retirement Allowance | B25: 7516102 | C25: SGA | D25: =C25&"-"&B25 -> SGA-7516102 | E25: A505 | F25: employee retirement provission costs | H25: SP PD- QC - OEM | I25: B4121 | J25: MFG | K25: DIR | L25: =H25 -> SP PD- QC - OEM
A26: House Rent Allowance | B26: 7519101 | C26: SGA | D26: =C26&"-"&B26 -> SGA-7519101 | E26: A502 | F26: House Rent Allowance for expat | H26: PC PD- Injection | I26: B4410 | J26: MFG | K26: DIR | L26: =H26 -> PC PD- Injection
A27: Casual Staff Labor - Basic Salary | B27: 7521101 | C27: SGA | D27: =C27&"-"&B27 -> SGA-7521101 | E27: A501 | F27: All benefit for temporary worker | H27: PC PD- Assy | I27: B4430 | J27: MFG | K27: DIR | L27: =H27 -> PC PD- Assy
A28: Casual Staff Labor - Overtime | B28: 7521102 | C28: SGA | D28: =C28&"-"&B28 -> SGA-7521102 | E28: A503 | F28: Overtime temporary worker | H28: PC PD- QC | I28: B4440 | J28: MFG | K28: DIR | L28: =H28 -> PC PD- QC
A29: Personnel expense transferred | B29: 7571101 | C29: SGA | D29: =C29&"-"&B29 -> SGA-7571101 | E29: A506 | F29: Transfer Labor cost from one section into another section | H29: Plant Operation (Indirect Mfg) | I29: B5000 | J29: MFG | K29: IND | L29: =H29 -> Plant Operation (Indirect Mfg)
A30: Depreciation-Building | B30: 7611100 | C30: SGA | D30: =C30&"-"&B30 -> SGA-7611100 | E30: A601 | F30: the amount of depreciation of tangible assets for building | H30: Production Office | I30: B5100 | J30: MFG | K30: IND | L30: =H30 -> Production Office
A31: Depreciation-Machiney & equipment | B31: 7611300 | C31: SGA | D31: =C31&"-"&B31 -> SGA-7611300 | E31: A601 | F31: the amount of depreciation of tangible assets for machinery & factory equipment | H31: Production Office (SP) | I31: B5101 | J31: MFG | K31: IND | L31: =H31 -> Production Office (SP)
A32: Depreciation-Lease Machinery & equipment | B32: 7611400 | C32: SGA | D32: =C32&"-"&B32 -> SGA-7611400 | E32: A601 | F32: the amount of depreciation of tangible assets for machinery & factory equipment (Leases) | H32: Production Office (PC) | I32: B5104 | J32: MFG | K32: IND | L32: =H32 -> Production Office (PC)
... A41: Repair Building | B41: 7641101 | C41: SGA | D41: =C41&"-"&B41 -> SGA-7641101 | E41: A1002 | F41: expenses for repair and maintenance asset building | H41: Continuous Improvement | I41: B5007 | J41: MFG | K41: IND | L41: =H41 -> Continuous Improvement
A42: Repair of Equipment | B42: 7641102 | C42: SGA | D42: =C42&"-"&B42 -> SGA-7641102 | E42: A1002 | F42: expenses for repair and maintenance tangible assets, intangible assets and other assets beside building | H42: All | I42: B0000 | L42: =H42 -> All
A43: Factory Supply Expense | B43: 7641103 | C43: SGA | D43: =C43&"-"&B43 -> SGA-7641103 | E43: A1099 | F43: All cost that arrising to support factory acitivity
A44: Calibration Cost | B44: 7641104 | C44: SGA | D44: =C44&"-"&B44 -> SGA-7641104 | E44: A1099 | F44: Cost of calibration for tools and equipment of factory and others
A45: Transportation Fee for employee | B45: 7651101 | C45: SGA | D45: =C45&"-"&B45 -> SGA-7651101 | E45: A801 | F45: Gasoline of company cars & expense for Local transportation
A46: Travel Expense-Domestic | B46: 7651102 | C46: SGA | D46: =C46&"-"&B46 -> SGA-7651102 | E46: A801 | F46: expenses for business trip, including allowance for business trip to an employee only for domestic travel
A47: Travel Expense-Oversea | B47: 7651103 | C47: SGA | D47: =C47&"-"&B47 -> SGA-7651103 | E47: A801 | F47: expenses for business trip, including allowance for business trip to an employee only for overseas travel
A48: Entertainment | B48: 7661101 | C48: SGA | D48: =C48&"-"&B48 -> SGA-7661101 | E48: A1001 | F48: the amount of expenses for the act of entertaining the business partner
A49: Amortization of Land & Building tax (PBB) | B49: 7671102 | C49: SGA | D49: =C49&"-"&B49 -> SGA-7671102 | E49: A1099 | F49: the amount of depreciation of intangible of Land & Building Tax (PBB)
A50: License fee | B50: 7671103 | C50: SGA | D50: =C50&"-"&B50 -> SGA-7671103 | E50: A1099 | F50: The expense related with the documentation process, such as : KIR, Car lisence, company lisence, etc.
...

Sheet Depre Calculation
A1: No Asset | B1: Asset Name | C1: Coa Name | D1: Coa ID | E1: Acquisition Value | F1: Useful Life | G1: To Section | H1: Allocation % | I1: Depre Start | J1: Status (BIP / CIP) | K1: Section From | L1: Priority Code | M1: Period | N1: Assets Allocation | O1: Montly Depre | P1: End Depre | Q1: 2020_11 | R1: 2020_12 | S1: 2021_01 | T1: 2021_02 | U1: 2021_03 | V1: 2021_04 | W1: 2021_05 | X1: 2021_06 | Y1: 2021_07 | Z1: 2021_08 | AA1: 2021_09 | AB1: 2021_10 | AC1: 2021_11 | AD1: 2021_12 | AE1: 2022_01 | AF1: 2022_02 | AG1: 2022_03 | AH1: 2022_04 | AI1: 2022_05 | AJ1: 2022_06 | AK1: 2022_07 | AL1: 2022_08 | AM1: 2022_09 | AN1: 2022_10 | AO1: 2022_11 | AP1: 2022_12 | AQ1: 2023_01 | AR1: 2023_02 | AS1: 2023_03 | AT1: 2023_04 | AU1: 2023_05 | AV1: 2023_06 | AW1: 2023_07 | AX1: 2023_08 | AY1: 2023_09 | AZ1: 2023_10 | BA1: 2023_11 | BB1: 2023_12 | BC1: 2024_01 | BD1: 2024_02 | BE1: 2024_03 | BF1: TOTAL FY121 | BG1: TOTAL FY122 | BH1: TOTAL FY123 | BI1: TOTAL FY124 | BJ1: COA Depre | BK1: COA Name of Depre
A2: 001 | B2: UPS For Rack 2 (AX, ASPROVA, Flexnet Server) | C2: Tools, furniture & office equipment | D2: 2141000 | E2: 127990800 | F2: 60 | G2: Information Technology | H2: 1 | I2: 43922 | J2: BIP | K2: Information Technology | L2: A | M2: BGT.FY121 | N2: =H2*E2 -> 127990800 | O2: =N2/F2 -> 2133180 | P2: =DATE(YEAR(I2),MONTH(I2)+F2,DAY(I2)) -> 45748 | Q2: =IF(AND(LEFT(Q$1,FIND("_",Q$1)-1)&RIGHT(Q$1,LEN(Q$1)-FIND("_",Q$1)) >= YEAR($I2) & TEXT(MONTH($I2),"00"),LEFT(Q$1,FIND("_",Q$1)-1)&RIGHT(Q$1,LEN(Q$1)-FIND("_",Q$1)) < YEAR($P2) & TEXT(MONTH($P2),"00")),$O2,"") -> 2133180 | R2: =IF(AND(LEFT(R$1,FIND("_",R$1)-1)&RIGHT(R$1,LEN(R$1)-FIND("_",R$1)) >= YEAR($I2) & TEXT(MONTH($I2),"00"),LEFT(R$1,FIND("_",R$1)-1)&RIGHT(R$1,LEN(R$1)-FIND("_",R$1)) < YEAR($P2) & TEXT(MONTH($P2),"00")),$O2,"") -> 2133180 | S2: =IF(AND(LEFT(S$1,FIND("_",S$1)-1)&RIGHT(S$1,LEN(S$1)-FIND("_",S$1)) >= YEAR($I2) & TEXT(MONTH($I2),"00"),LEFT(S$1,FIND("_",S$1)-1)&RIGHT(S$1,LEN(S$1)-FIND("_",S$1)) < YEAR($P2) & TEXT(MONTH($P2),"00")),$O2,"") -> 2133180 | T2: =IF(AND(LEFT(T$1,FIND("_",T$1)-1)&RIGHT(T$1,LEN(T$1)-FIND("_",T$1)) >= YEAR($I2) & TEXT(MONTH($I2),"00"),LEFT(T$1,FIND("_",T$1)-1)&RIGHT(T$1,LEN(T$1)-FIND("_",T$1)) < YEAR($P2) & TEXT(MONTH($P2),"00")),$O2,"") -> 2133180 | U2: =IF(AND(LEFT(U$1,FIND("_",U$1)-1)&RIGHT(U$1,LEN(U$1)-FIND("_",U$1)) >= YEAR($I2) & TEXT(MONTH($I2),"00"),LEFT(U$1,FIND("_",U$1)-1)&RIGHT(U$1,LEN(U$1)-FIND("_",U$1)) < YEAR($P2) & TEXT(MONTH($P2),"00")),$O2,"") -> 2133180 | V2: =IF(AND(LEFT(V$1,FIND("_",V$1)-1)&RIGHT(V$1,LEN(V$1)-FIND("_",V$1)) >= YEAR($I2) & TEXT(MONTH($I2),"00"),LEFT(V$1,FIND("_",V$1)-1)&RIGHT(V$1,LEN(V$1)-FIND("_",V$1)) < YEAR($P2) & TEXT(MONTH($P2),"00")),$O2,"") -> 2133180 | W2: =IF(AND(LEFT(W$1,FIND("_",W$1)-1)&RIGHT(W$1,LEN(W$1)-FIND("_",W$1)) >= YEAR($I2) & TEXT(MONTH($I2),"00"),LEFT(W$1,FIND("_",W$1)-1)&RIGHT(W$1,LEN(W$1)-FIND("_",W$1)) < YEAR($P2) & TEXT(MONTH($P2),"00")),$O2,"") -> 2133180 | X2: =IF(AND(LEFT(X$1,FIND("_",X$1)-1)&RIGHT(X$1,LEN(X$1)-FIND("_",X$1)) >= YEAR($I2) & TEXT(MONTH($I2),"00"),LEFT(X$1,FIND("_",X$1)-1)&RIGHT(X$1,LEN(X$1)-FIND("_",X$1)) < YEAR($P2) & TEXT(MONTH($P2),"00")),$O2,"") -> 2133180 | ... BE2: =IF(AND(LEFT(BE$1,FIND("_",BE$1)-1)&RIGHT(BE$1,LEN(BE$1)-FIND("_",BE$1)) >= YEAR($I2) & TEXT(MONTH($I2),"00"),LEFT(BE$1,FIND("_",BE$1)-1)&RIGHT(BE$1,LEN(BE$1)-FIND("_",BE$1)) < YEAR($P2) & TEXT(MONTH($P2),"00")),$O2,"") -> 2133180 | BF2: =SUM(Q2:U2) -> 10665900 | BG2: =SUM(V2:AG2) -> 25598160 | BH2: =SUM(AH2:AS2) -> 25598160 | BI2: =SUM(AT2:BE2) -> 25598160 | BJ2: =VLOOKUP(D2,Master!AD:AG,3,FALSE) -> 7611600 | BK2: =VLOOKUP(D2,Master!AD:AG,4,FALSE) -> Depreciation-Tools, furniture & office equipment
A3: 002 | B3: UPS For Rack 1 (Domain, Application Server) | C3: Tools, furniture & office equipment | D3: 2141000 | E3: 88905600 | F3: 60 | G3: Information Technology | H3: 1 | I3: 43922 | J3: BIP | K3: Information Technology | L3: B | M3: BGT.FY121 | N3: =H3*E3 -> 88905600 | O3: =N3/F3 -> 1481760 | P3: =DATE(YEAR(I3),MONTH(I3)+F3,DAY(I3)) -> 45748 | Q3: =IF(AND(LEFT(Q$1,FIND("_",Q$1)-1)&RIGHT(Q$1,LEN(Q$1)-FIND("_",Q$1)) >= YEAR($I3) & TEXT(MONTH($I3),"00"),LEFT(Q$1,FIND("_",Q$1)-1)&RIGHT(Q$1,LEN(Q$1)-FIND("_",Q$1)) < YEAR($P3) & TEXT(MONTH($P3),"00")),$O3,"") -> 1481760 | R3: =IF(AND(LEFT(R$1,FIND("_",R$1)-1)&RIGHT(R$1,LEN(R$1)-FIND("_",R$1)) >= YEAR($I3) & TEXT(MONTH($I3),"00"),LEFT(R$1,FIND("_",R$1)-1)&RIGHT(R$1,LEN(R$1)-FIND("_",R$1)) < YEAR($P3) & TEXT(MONTH($P3),"00")),$O3,"") -> 1481760 | S3: =IF(AND(LEFT(S$1,FIND("_",S$1)-1)&RIGHT(S$1,LEN(S$1)-FIND("_",S$1)) >= YEAR($I3) & TEXT(MONTH($I3),"00"),LEFT(S$1,FIND("_",S$1)-1)&RIGHT(S$1,LEN(S$1)-FIND("_",S$1)) < YEAR($P3) & TEXT(MONTH($P3),"00")),$O3,"") -> 1481760 | T3: =IF(AND(LEFT(T$1,FIND("_",T$1)-1)&RIGHT(T$1,LEN(T$1)-FIND("_",T$1)) >= YEAR($I3) & TEXT(MONTH($I3),"00"),LEFT(T$1,FIND("_",T$1)-1)&RIGHT(T$1,LEN(T$1)-FIND("_",T$1)) < YEAR($P3) & TEXT(MONTH($P3),"00")),$O3,"") -> 1481760 | U3: =IF(AND(LEFT(U$1,FIND("_",U$1)-1)&RIGHT(U$1,LEN(U$1)-FIND("_",U$1)) >= YEAR($I3) & TEXT(MONTH($I3),"00"),LEFT(U$1,FIND("_",U$1)-1)&RIGHT(U$1,LEN(U$1)-FIND("_",U$1)) < YEAR($P3) & TEXT(MONTH($P3),"00")),$O3,"") -> 1481760 | V3: =IF(AND(LEFT(V$1,FIND("_",V$1)-1)&RIGHT(V$1,LEN(V$1)-FIND("_",V$1)) >= YEAR($I3) & TEXT(MONTH($I3),"00"),LEFT(V$1,FIND("_",V$1)-1)&RIGHT(V$1,LEN(V$1)-FIND("_",V$1)) < YEAR($P3) & TEXT(MONTH($P3),"00")),$O3,"") -> 1481760 | W3: =IF(AND(LEFT(W$1,FIND("_",W$1)-1)&RIGHT(W$1,LEN(W$1)-FIND("_",W$1)) >= YEAR($I3) & TEXT(MONTH($I3),"00"),LEFT(W$1,FIND("_",W$1)-1)&RIGHT(W$1,LEN(W$1)-FIND("_",W$1)) < YEAR($P3) & TEXT(MONTH($P3),"00")),$O3,"") -> 1481760 | X3: =IF(AND(LEFT(X$1,FIND("_",X$1)-1)&RIGHT(X$1,LEN(X$1)-FIND("_",X$1)) >= YEAR($I3) & TEXT(MONTH($I3),"00"),LEFT(X$1,FIND("_",X$1)-1)&RIGHT(X$1,LEN(X$1)-FIND("_",X$1)) < YEAR($P3) & TEXT(MONTH($P3),"00")),$O3,"") -> 1481760 | ... BE3: =IF(AND(LEFT(BE$1,FIND("_",BE$1)-1)&RIGHT(BE$1,LEN(BE$1)-FIND("_",BE$1)) >= YEAR($I3) & TEXT(MONTH($I3),"00"),LEFT(BE$1,FIND("_",BE$1)-1)&RIGHT(BE$1,LEN(BE$1)-FIND("_",BE$1)) < YEAR($P3) & TEXT(MONTH($P3),"00")),$O3,"") -> 1481760 | BF3: =SUM(Q3:U3) -> 7408800 | BG3: =SUM(V3:AG3) -> 17781120 | BH3: =SUM(AH3:AS3) -> 17781120 | BI3: =SUM(AT3:BE3) -> 17781120 | BJ3: =VLOOKUP(D3,Master!AD:AG,3,FALSE) -> 7611600 | BK3: =VLOOKUP(D3,Master!AD:AG,4,FALSE) -> Depreciation-Tools, furniture & office equipment
A4: 003 | B4: Notebook for IT Member | C4: Tools, furniture & office equipment | D4: 2141000 | E4: 15000000 | F4: 60 | G4: Information Technology | H4: 1 | I4: 43983 | J4: BIP | K4: Information Technology | L4: C | M4: BGT.FY121 | N4: =H4*E4 -> 15000000 | O4: =N4/F4 -> 250000 | P4: =DATE(YEAR(I4),MONTH(I4)+F4,DAY(I4)) -> 45809 | Q4: =IF(AND(LEFT(Q$1,FIND("_",Q$1)-1)&RIGHT(Q$1,LEN(Q$1)-FIND("_",Q$1)) >= YEAR($I4) & TEXT(MONTH($I4),"00"),LEFT(Q$1,FIND("_",Q$1)-1)&RIGHT(Q$1,LEN(Q$1)-FIND("_",Q$1)) < YEAR($P4) & TEXT(MONTH($P4),"00")),$O4,"") -> 250000 | R4: =IF(AND(LEFT(R$1,FIND("_",R$1)-1)&RIGHT(R$1,LEN(R$1)-FIND("_",R$1)) >= YEAR($I4) & TEXT(MONTH($I4),"00"),LEFT(R$1,FIND("_",R$1)-1)&RIGHT(R$1,LEN(R$1)-FIND("_",R$1)) < YEAR($P4) & TEXT(MONTH($P4),"00")),$O4,"") -> 250000 | S4: =IF(AND(LEFT(S$1,FIND("_",S$1)-1)&RIGHT(S$1,LEN(S$1)-FIND("_",S$1)) >= YEAR($I4) & TEXT(MONTH($I4),"00"),LEFT(S$1,FIND("_",S$1)-1)&RIGHT(S$1,LEN(S$1)-FIND("_",S$1)) < YEAR($P4) & TEXT(MONTH($P4),"00")),$O4,"") -> 250000 | T4: =IF(AND(LEFT(T$1,FIND("_",T$1)-1)&RIGHT(T$1,LEN(T$1)-FIND("_",T$1)) >= YEAR($I4) & TEXT(MONTH($I4),"00"),LEFT(T$1,FIND("_",T$1)-1)&RIGHT(T$1,LEN(T$1)-FIND("_",T$1)) < YEAR($P4) & TEXT(MONTH($P4),"00")),$O4,"") -> 250000 | U4: =IF(AND(LEFT(U$1,FIND("_",U$1)-1)&RIGHT(U$1,LEN(U$1)-FIND("_",U$1)) >= YEAR($I4) & TEXT(MONTH($I4),"00"),LEFT(U$1,FIND("_",U$1)-1)&RIGHT(U$1,LEN(U$1)-FIND("_",U$1)) < YEAR($P4) & TEXT(MONTH($P4),"00")),$O4,"") -> 250000 | V4: =IF(AND(LEFT(V$1,FIND("_",V$1)-1)&RIGHT(V$1,LEN(V$1)-FIND("_",V$1)) >= YEAR($I4) & TEXT(MONTH($I4),"00"),LEFT(V$1,FIND("_",V$1)-1)&RIGHT(V$1,LEN(V$1)-FIND("_",V$1)) < YEAR($P4) & TEXT(MONTH($P4),"00")),$O4,"") -> 250000 | W4: =IF(AND(LEFT(W$1,FIND("_",W$1)-1)&RIGHT(W$1,LEN(W$1)-FIND("_",W$1)) >= YEAR($I4) & TEXT(MONTH($I4),"00"),LEFT(W$1,FIND("_",W$1)-1)&RIGHT(W$1,LEN(W$1)-FIND("_",W$1)) < YEAR($P4) & TEXT(MONTH($P4),"00")),$O4,"") -> 250000 | X4: =IF(AND(LEFT(X$1,FIND("_",X$1)-1)&RIGHT(X$1,LEN(X$1)-FIND("_",X$1)) >= YEAR($I4) & TEXT(MONTH($I4),"00"),LEFT(X$1,FIND("_",X$1)-1)&RIGHT(X$1,LEN(X$1)-FIND("_",X$1)) < YEAR($P4) & TEXT(MONTH($P4),"00")),$O4,"") -> 250000 | ... BE4: =IF(AND(LEFT(BE$1,FIND("_",BE$1)-1)&RIGHT(BE$1,LEN(BE$1)-FIND("_",BE$1)) >= YEAR($I4) & TEXT(MONTH($I4),"00"),LEFT(BE$1,FIND("_",BE$1)-1)&RIGHT(BE$1,LEN(BE$1)-FIND("_",BE$1)) < YEAR($P4) & TEXT(MONTH($P4),"00")),$O4,"") -> 250000 | BF4: =SUM(Q4:U4) -> 1250000 | BG4: =SUM(V4:AG4) -> 3000000 | BH4: =SUM(AH4:AS4) -> 3000000 | BI4: =SUM(AT4:BE4) -> 3000000 | BJ4: =VLOOKUP(D4,Master!AD:AG,3,FALSE) -> 7611600 | BK4: =VLOOKUP(D4,Master!AD:AG,4,FALSE) -> Depreciation-Tools, furniture & office equipment
A5: 001 | B5: Auto Gate Machine | C5: Tools, furniture & office equipment | D5: 2141000 | E5: 40000000 | F5: 60 | G5: GENERAL AFFAIR | H5: 1 | I5: 44197 | J5: BIP | K5: GENERAL AFFAIR | M5: BGT.FY121 | N5: =H5*E5 -> 40000000 | O5: =N5/F5 -> 666666.67 | P5: =DATE(YEAR(I5),MONTH(I5)+F5,DAY(I5)) -> 46023 | Q5: =IF(AND(LEFT(Q$1,FIND("_",Q$1)-1)&RIGHT(Q$1,LEN(Q$1)-FIND("_",Q$1)) >= YEAR($I5) & TEXT(MONTH($I5),"00"),LEFT(Q$1,FIND("_",Q$1)-1)&RIGHT(Q$1,LEN(Q$1)-FIND("_",Q$1)) < YEAR($P5) & TEXT(MONTH($P5),"00")),$O5,"") | R5: =IF(AND(LEFT(R$1,FIND("_",R$1)-1)&RIGHT(R$1,LEN(R$1)-FIND("_",R$1)) >= YEAR($I5) & TEXT(MONTH($I5),"00"),LEFT(R$1,FIND("_",R$1)-1)&RIGHT(R$1,LEN(R$1)-FIND("_",R$1)) < YEAR($P5) & TEXT(MONTH($P5),"00")),$O5,"") | S5: =IF(AND(LEFT(S$1,FIND("_",S$1)-1)&RIGHT(S$1,LEN(S$1)-FIND("_",S$1)) >= YEAR($I5) & TEXT(MONTH($I5),"00"),LEFT(S$1,FIND("_",S$1)-1)&RIGHT(S$1,LEN(S$1)-FIND("_",S$1)) < YEAR($P5) & TEXT(MONTH($P5),"00")),$O5,"") -> 666666.67 | T5: =IF(AND(LEFT(T$1,FIND("_",T$1)-1)&RIGHT(T$1,LEN(T$1)-FIND("_",T$1)) >= YEAR($I5) & TEXT(MONTH($I5),"00"),LEFT(T$1,FIND("_",T$1)-1)&RIGHT(T$1,LEN(T$1)-FIND("_",T$1)) < YEAR($P5) & TEXT(MONTH($P5),"00")),$O5,"") -> 666666.67 | U5: =IF(AND(LEFT(U$1,FIND("_",U$1)-1)&RIGHT(U$1,LEN(U$1)-FIND("_",U$1)) >= YEAR($I5) & TEXT(MONTH($I5),"00"),LEFT(U$1,FIND("_",U$1)-1)&RIGHT(U$1,LEN(U$1)-FIND("_",U$1)) < YEAR($P5) & TEXT(MONTH($P5),"00")),$O5,"") -> 666666.67 | V5: =IF(AND(LEFT(V$1,FIND("_",V$1)-1)&RIGHT(V$1,LEN(V$1)-FIND("_",V$1)) >= YEAR($I5) & TEXT(MONTH($I5),"00"),LEFT(V$1,FIND("_",V$1)-1)&RIGHT(V$1,LEN(V$1)-FIND("_",V$1)) < YEAR($P5) & TEXT(MONTH($P5),"00")),$O5,"") -> 666666.67 | W5: =IF(AND(LEFT(W$1,FIND("_",W$1)-1)&RIGHT(W$1,LEN(W$1)-FIND("_",W$1)) >= YEAR($I5) & TEXT(MONTH($I5),"00"),LEFT(W$1,FIND("_",W$1)-1)&RIGHT(W$1,LEN(W$1)-FIND("_",W$1)) < YEAR($P5) & TEXT(MONTH($P5),"00")),$O5,"") -> 666666.67 | X5: =IF(AND(LEFT(X$1,FIND("_",X$1)-1)&RIGHT(X$1,LEN(X$1)-FIND("_",X$1)) >= YEAR($I5) & TEXT(MONTH($I5),"00"),LEFT(X$1,FIND("_",X$1)-1)&RIGHT(X$1,LEN(X$1)-FIND("_",X$1)) < YEAR($P5) & TEXT(MONTH($P5),"00")),$O5,"") -> 666666.67 | ... BE5: =IF(AND(LEFT(BE$1,FIND("_",BE$1)-1)&RIGHT(BE$1,LEN(BE$1)-FIND("_",BE$1)) >= YEAR($I5) & TEXT(MONTH($I5),"00"),LEFT(BE$1,FIND("_",BE$1)-1)&RIGHT(BE$1,LEN(BE$1)-FIND("_",BE$1)) < YEAR($P5) & TEXT(MONTH($P5),"00")),$O5,"") -> 666666.67 | BF5: =SUM(Q5:U5) -> 2000000 | BG5: =SUM(V5:AG5) -> 8000000 | BH5: =SUM(AH5:AS5) -> 8000000 | BI5: =SUM(AT5:BE5) -> 8000000 | BJ5: =VLOOKUP(D5,Master!AD:AG,3,FALSE) -> 7611600 | BK5: =VLOOKUP(D5,Master!AD:AG,4,FALSE) -> Depreciation-Tools, furniture & office equipment
A6: 002 | B6: AC Central Spark Plug 1 | C6: Tools, furniture & office equipment | D6: 2141000 | E6: 40000000 | F6: 60 | G6: GENERAL AFFAIR | H6: 1 | I6: 44197 | J6: BIP | K6: GENERAL AFFAIR | M6: BGT.FY121 | N6: =H6*E6 -> 40000000 | O6: =N6/F6 -> 666666.67 | P6: =DATE(YEAR(I6),MONTH(I6)+F6,DAY(I6)) -> 46023 | Q6: =IF(AND(LEFT(Q$1,FIND("_",Q$1)-1)&RIGHT(Q$1,LEN(Q$1)-FIND("_",Q$1)) >= YEAR($I6) & TEXT(MONTH($I6),"00"),LEFT(Q$1,FIND("_",Q$1)-1)&RIGHT(Q$1,LEN(Q$1)-FIND("_",Q$1)) < YEAR($P6) & TEXT(MONTH($P6),"00")),$O6,"") | R6: =IF(AND(LEFT(R$1,FIND("_",R$1)-1)&RIGHT(R$1,LEN(R$1)-FIND("_",R$1)) >= YEAR($I6) & TEXT(MONTH($I6),"00"),LEFT(R$1,FIND("_",R$1)-1)&RIGHT(R$1,LEN(R$1)-FIND("_",R$1)) < YEAR($P6) & TEXT(MONTH($P6),"00")),$O6,"") | S6: =IF(AND(LEFT(S$1,FIND("_",S$1)-1)&RIGHT(S$1,LEN(S$1)-FIND("_",S$1)) >= YEAR($I6) & TEXT(MONTH($I6),"00"),LEFT(S$1,FIND("_",S$1)-1)&RIGHT(S$1,LEN(S$1)-FIND("_",S$1)) < YEAR($P6) & TEXT(MONTH($P6),"00")),$O6,"") -> 666666.67 | T6: =IF(AND(LEFT(T$1,FIND("_",T$1)-1)&RIGHT(T$1,LEN(T$1)-FIND("_",T$1)) >= YEAR($I6) & TEXT(MONTH($I6),"00"),LEFT(T$1,FIND("_",T$1)-1)&RIGHT(T$1,LEN(T$1)-FIND("_",T$1)) < YEAR($P6) & TEXT(MONTH($P6),"00")),$O6,"") -> 666666.67 | U6: =IF(AND(LEFT(U$1,FIND("_",U$1)-1)&RIGHT(U$1,LEN(U$1)-FIND("_",U$1)) >= YEAR($I6) & TEXT(MONTH($I6),"00"),LEFT(U$1,FIND("_",U$1)-1)&RIGHT(U$1,LEN(U$1)-FIND("_",U$1)) < YEAR($P6) & TEXT(MONTH($P6),"00")),$O6,"") -> 666666.67 | V6: =IF(AND(LEFT(V$1,FIND("_",V$1)-1)&RIGHT(V$1,LEN(V$1)-FIND("_",V$1)) >= YEAR($I6) & TEXT(MONTH($I6),"00"),LEFT(V$1,FIND("_",V$1)-1)&RIGHT(V$1,LEN(V$1)-FIND("_",V$1)) < YEAR($P6) & TEXT(MONTH($P6),"00")),$O6,"") -> 666666.67 | W6: =IF(AND(LEFT(W$1,FIND("_",W$1)-1)&RIGHT(W$1,LEN(W$1)-FIND("_",W$1)) >= YEAR($I6) & TEXT(MONTH($I6),"00"),LEFT(W$1,FIND("_",W$1)-1)&RIGHT(W$1,LEN(W$1)-FIND("_",W$1)) < YEAR($P6) & TEXT(MONTH($P6),"00")),$O6,"") -> 666666.67 | X6: =IF(AND(LEFT(X$1,FIND("_",X$1)-1)&RIGHT(X$1,LEN(X$1)-FIND("_",X$1)) >= YEAR($I6) & TEXT(MONTH($I6),"00"),LEFT(X$1,FIND("_",X$1)-1)&RIGHT(X$1,LEN(X$1)-FIND("_",X$1)) < YEAR($P6) & TEXT(MONTH($P6),"00")),$O6,"") -> 666666.67 | ... BE6: =IF(AND(LEFT(BE$1,FIND("_",BE$1)-1)&RIGHT(BE$1,LEN(BE$1)-FIND("_",BE$1)) >= YEAR($I6) & TEXT(MONTH($I6),"00"),LEFT(BE$1,FIND("_",BE$1)-1)&RIGHT(BE$1,LEN(BE$1)-FIND("_",BE$1)) < YEAR($P6) & TEXT(MONTH($P6),"00")),$O6,"") -> 666666.67 | BF6: =SUM(Q6:U6) -> 2000000 | BG6: =SUM(V6:AG6) -> 8000000 | BH6: =SUM(AH6:AS6) -> 8000000 | BI6: =SUM(AT6:BE6) -> 8000000 | BJ6: =VLOOKUP(D6,Master!AD:AG,3,FALSE) -> 7611600 | BK6: =VLOOKUP(D6,Master!AD:AG,4,FALSE) -> Depreciation-Tools, furniture & office equipment
A7: 003 | B7: Personal Computer Recruitment Staff | C7: Tools, furniture & office equipment | D7: 2141000 | E7: 8000000 | F7: 60 | G7: HUMAN RESOURCE | H7: 1 | I7: 44287 | J7: BIP | K7: GENERAL AFFAIR | M7: BGT.FY122 | N7: =H7*E7 -> 8000000 | O7: =N7/F7 -> 133333.33 | P7: =DATE(YEAR(I7),MONTH(I7)+F7,DAY(I7)) -> 46113 | Q7: =IF(AND(LEFT(Q$1,FIND("_",Q$1)-1)&RIGHT(Q$1,LEN(Q$1)-FIND("_",Q$1)) >= YEAR($I7) & TEXT(MONTH($I7),"00"),LEFT(Q$1,FIND("_",Q$1)-1)&RIGHT(Q$1,LEN(Q$1)-FIND("_",Q$1)) < YEAR($P7) & TEXT(MONTH($P7),"00")),$O7,"") | R7: =IF(AND(LEFT(R$1,FIND("_",R$1)-1)&RIGHT(R$1,LEN(R$1)-FIND("_",R$1)) >= YEAR($I7) & TEXT(MONTH($I7),"00"),LEFT(R$1,FIND("_",R$1)-1)&RIGHT(R$1,LEN(R$1)-FIND("_",R$1)) < YEAR($P7) & TEXT(MONTH($P7),"00")),$O7,"") | S7: =IF(AND(LEFT(S$1,FIND("_",S$1)-1)&RIGHT(S$1,LEN(S$1)-FIND("_",S$1)) >= YEAR($I7) & TEXT(MONTH($I7),"00"),LEFT(S$1,FIND("_",S$1)-1)&RIGHT(S$1,LEN(S$1)-FIND("_",S$1)) < YEAR($P7) & TEXT(MONTH($P7),"00")),$O7,"") | T7: =IF(AND(LEFT(T$1,FIND("_",T$1)-1)&RIGHT(T$1,LEN(T$1)-FIND("_",T$1)) >= YEAR($I7) & TEXT(MONTH($I7),"00"),LEFT(T$1,FIND("_",T$1)-1)&RIGHT(T$1,LEN(T$1)-FIND("_",T$1)) < YEAR($P7) & TEXT(MONTH($P7),"00")),$O7,"") | U7: =IF(AND(LEFT(U$1,FIND("_",U$1)-1)&RIGHT(U$1,LEN(U$1)-FIND("_",U$1)) >= YEAR($I7) & TEXT(MONTH($I7),"00"),LEFT(U$1,FIND("_",U$1)-1)&RIGHT(U$1,LEN(U$1)-FIND("_",U$1)) < YEAR($P7) & TEXT(MONTH($P7),"00")),$O7,"") | V7: =IF(AND(LEFT(V$1,FIND("_",V$1)-1)&RIGHT(V$1,LEN(V$1)-FIND("_",V$1)) >= YEAR($I7) & TEXT(MONTH($I7),"00"),LEFT(V$1,FIND("_",V$1)-1)&RIGHT(V$1,LEN(V$1)-FIND("_",V$1)) < YEAR($P7) & TEXT(MONTH($P7),"00")),$O7,"") -> 133333.33 | W7: =IF(AND(LEFT(W$1,FIND("_",W$1)-1)&RIGHT(W$1,LEN(W$1)-FIND("_",W$1)) >= YEAR($I7) & TEXT(MONTH($I7),"00"),LEFT(W$1,FIND("_",W$1)-1)&RIGHT(W$1,LEN(W$1)-FIND("_",W$1)) < YEAR($P7) & TEXT(MONTH($P7),"00")),$O7,"") -> 133333.33 | X7: =IF(AND(LEFT(X$1,FIND("_",X$1)-1)&RIGHT(X$1,LEN(X$1)-FIND("_",X$1)) >= YEAR($I7) & TEXT(MONTH($I7),"00"),LEFT(X$1,FIND("_",X$1)-1)&RIGHT(X$1,LEN(X$1)-FIND("_",X$1)) < YEAR($P7) & TEXT(MONTH($P7),"00")),$O7,"") -> 133333.33 | ... BE7: =IF(AND(LEFT(BE$1,FIND("_",BE$1)-1)&RIGHT(BE$1,LEN(BE$1)-FIND("_",BE$1)) >= YEAR($I7) & TEXT(MONTH($I7),"00"),LEFT(BE$1,FIND("_",BE$1)-1)&RIGHT(BE$1,LEN(BE$1)-FIND("_",BE$1)) < YEAR($P7) & TEXT(MONTH($P7),"00")),$O7,"") -> 133333.33 | BF7: =SUM(Q7:U7) -> 0 | BG7: =SUM(V7:AG7) -> 1600000 | BH7: =SUM(AH7:AS7) -> 1600000 | BI7: =SUM(AT7:BE7) -> 1600000 | BJ7: =VLOOKUP(D7,Master!AD:AG,3,FALSE) -> 7611600 | BK7: =VLOOKUP(D7,Master!AD:AG,4,FALSE) -> Depreciation-Tools, furniture & office equipment
A8: 004 | B8: Personal Computer GA Staff | C8: Tools, furniture & office equipment | D8: 2141000 | E8: 8000000 | F8: 60 | G8: GENERAL AFFAIR | H8: 1 | I8: 44287 | J8: BIP | K8: GENERAL AFFAIR | M8: BGT.FY122 | N8: =H8*E8 -> 8000000 | O8: =N8/F8 -> 133333.33 | P8: =DATE(YEAR(I8),MONTH(I8)+F8,DAY(I8)) -> 46113 | Q8: =IF(AND(LEFT(Q$1,FIND("_",Q$1)-1)&RIGHT(Q$1,LEN(Q$1)-FIND("_",Q$1)) >= YEAR($I8) & TEXT(MONTH($I8),"00"),LEFT(Q$1,FIND("_",Q$1)-1)&RIGHT(Q$1,LEN(Q$1)-FIND("_",Q$1)) < YEAR($P8) & TEXT(MONTH($P8),"00")),$O8,"") | R8: =IF(AND(LEFT(R$1,FIND("_",R$1)-1)&RIGHT(R$1,LEN(R$1)-FIND("_",R$1)) >= YEAR($I8) & TEXT(MONTH($I8),"00"),LEFT(R$1,FIND("_",R$1)-1)&RIGHT(R$1,LEN(R$1)-FIND("_",R$1)) < YEAR($P8) & TEXT(MONTH($P8),"00")),$O8,"") | S8: =IF(AND(LEFT(S$1,FIND("_",S$1)-1)&RIGHT(S$1,LEN(S$1)-FIND("_",S$1)) >= YEAR($I8) & TEXT(MONTH($I8),"00"),LEFT(S$1,FIND("_",S$1)-1)&RIGHT(S$1,LEN(S$1)-FIND("_",S$1)) < YEAR($P8) & TEXT(MONTH($P8),"00")),$O8,"") | T8: =IF(AND(LEFT(T$1,FIND("_",T$1)-1)&RIGHT(T$1,LEN(T$1)-FIND("_",T$1)) >= YEAR($I8) & TEXT(MONTH($I8),"00"),LEFT(T$1,FIND("_",T$1)-1)&RIGHT(T$1,LEN(T$1)-FIND("_",T$1)) < YEAR($P8) & TEXT(MONTH($P8),"00")),$O8,"") | U8: =IF(AND(LEFT(U$1,FIND("_",U$1)-1)&RIGHT(U$1,LEN(U$1)-FIND("_",U$1)) >= YEAR($I8) & TEXT(MONTH($I8),"00"),LEFT(U$1,FIND("_",U$1)-1)&RIGHT(U$1,LEN(U$1)-FIND("_",U$1)) < YEAR($P8) & TEXT(MONTH($P8),"00")),$O8,"") | V8: =IF(AND(LEFT(V$1,FIND("_",V$1)-1)&RIGHT(V$1,LEN(V$1)-FIND("_",V$1)) >= YEAR($I8) & TEXT(MONTH($I8),"00"),LEFT(V$1,FIND("_",V$1)-1)&RIGHT(V$1,LEN(V$1)-FIND("_",V$1)) < YEAR($P8) & TEXT(MONTH($P8),"00")),$O8,"") -> 133333.33 | W8: =IF(AND(LEFT(W$1,FIND("_",W$1)-1)&RIGHT(W$1,LEN(W$1)-FIND("_",W$1)) >= YEAR($I8) & TEXT(MONTH($I8),"00"),LEFT(W$1,FIND("_",W$1)-1)&RIGHT(W$1,LEN(W$1)-FIND("_",W$1)) < YEAR($P8) & TEXT(MONTH($P8),"00")),$O8,"") -> 133333.33 | X8: =IF(AND(LEFT(X$1,FIND("_",X$1)-1)&RIGHT(X$1,LEN(X$1)-FIND("_",X$1)) >= YEAR($I8) & TEXT(MONTH($I8),"00"),LEFT(X$1,FIND("_",X$1)-1)&RIGHT(X$1,LEN(X$1)-FIND("_",X$1)) < YEAR($P8) & TEXT(MONTH($P8),"00")),$O8,"") -> 133333.33 | ... BE8: =IF(AND(LEFT(BE$1,FIND("_",BE$1)-1)&RIGHT(BE$1,LEN(BE$1)-FIND("_",BE$1)) >= YEAR($I8) & TEXT(MONTH($I8),"00"),LEFT(BE$1,FIND("_",BE$1)-1)&RIGHT(BE$1,LEN(BE$1)-FIND("_",BE$1)) < YEAR($P8) & TEXT(MONTH($P8),"00")),$O8,"") -> 133333.33 | BF8: =SUM(Q8:U8) -> 0 | BG8: =SUM(V8:AG8) -> 1600000 | BH8: =SUM(AH8:AS8) -> 1600000 | BI8: =SUM(AT8:BE8) -> 1600000 | BJ8: =VLOOKUP(D8,Master!AD:AG,3,FALSE) -> 7611600 | BK8: =VLOOKUP(D8,Master!AD:AG,4,FALSE) -> Depreciation-Tools, furniture & office equipment
